Workbook
Name AnnullaInseriscidata: #REF!
Name AnnullaInseriscidata: #REF!
Name InserisciData: #REF!
Name InserisciData: #REF!

Sheet CI
W1: HEAD OFFICE & CHANGWON PLANT
W2: 22, DoosanVolvo-ro, Seongsan-gu, Changwon-Si,
W3: Gyeongsangnam-do, Korea
W4: (P.O.BOX 77, Changwon, Korea)
W5: TEL:(055)278-6114,7114 FAX:(055)264-5551/2
A6: PROFORMA INVOICE ПРОФОРМА ИНВОЙС
A8: 1. Shipper / Грузоотправитель | R8: 11. Invoice № : | V8: PGU-DE-0220
B9: Doosan Enerbility Co., Ltd (DOOSAN) | R9: Инвойс №
B10: 22, DoosanVolvo-ro, Seongsan-gu, Changwon-si, Gyeongsangnam-do, | R10: 12. Date : | V10: 45693
B11: Republic of Korea | R11: Дата
A12: 2. Consignee / Грузополучатель | R12: 13. Remarks / Примечания
B13: Branch of JSC "Doosan Enerbility" in the Turkestan region
B14: 321 Tauke Khan Avenue, Turkestan region, Turkestan, Kazakhstan, 161200 | S14: *Project Name / Название Проекта
B15: BIN: 230741006561 | S15: Construction of a 1000 MW CCGT Power Plant in the Sairam District of
S16: Turkistan Region, Main Site. Without External Engineering Networks
S17: *MANUFACTURER'S NAME / НАЗВАНИЕ ПРОИЗВОДИТЕЛЯ
S18: Siemens-energy
A19: 3. Notify party / Уведомляемая сторона | S19: *MANUFACTURE YEAR / ГОД ИЗГОТОВЛЕНИЯ
B20: Wise Logistics | S20: 2024
B21: ATTAN: MS. Aliya | S21: *COUNTRY OF ORIGIN / СТРАНА ПРОИСХОЖДЕНИЯ
B22: (E): a.kipshakbayeva@wiselogistics.kz | S22: KOREA
B23: (T): +7 701 512 19 69 | S23: *INCOTERMS / УСЛОВИЯ ПОСТАВКИ СОГЛАСНО ИНКОТЕРМС
S24: DDP Turkistan
S25: * CONTRACT NO. / НОМЕР КОНТРАКТ
A26: 4. Port of Loading / Порт погрузки | I26: 5. Carrier / Перевозчик | S26: 0123-ПГУТ-8Д date 14.03.2023
B27: Busan, Korea | J27: Later
A29: 6. Port of Unloading / Порт разгрузки | I29: 7. Final Destination / Конечный пункт назначения | R29: 14. Mark and Numbers of PKGS / Маркировка и количество упаковок
B31: Lianyungang, China | I31: Turkistan Region, Sairam District | S31: PKG No. | X31: : | Y31: PGU-DE-0220-DCS-CBN-001~036
S32: Q-ty of Package | X32: : | Y32: 36 | AC32: PKGS
A33: 8. Voyage No / Рейс № | I33: 9. Sailing on or about / Дата или ожидаемая дата | S33: Net Weight (kg) | X33: : | Y33: ='Summary PL'!L50 -> 17516.1 | AC33: KG
S34: Gross Weight (kg) | X34: : | Y34: ='Summary PL'!M50 -> 21866.1 | AC34: KG
B35: HUI DE 2556W | J35: 45946 | S35: Dimension (m3) | X35: : | Y35: ='Summary PL'!K50 -> 140.238 | AC35: m3
A37: 10. Customs Place / Место таможенного оформления
A40: 15. Description of Goods / Описание товара | R40: 16. HS CODE / | W40: 17. Quantity / | AA40: 18. Total Price (USD)
R41: Код ТН ВЭД | W41: Количество | AA41: Общая сумма (Дол. США)
B42: Distributed Control System (DCS) / | R42: 8537.10-5090 | W42: 1 | AC42: =CI_BD!H45 -> 1756846.5 | AD42: CD #2 (Electrical System)
B43: Распределенная система управления | AD43: Item 9.1 BOM
I45: Total (DDP Value) | AA45: =SUM(AC42:AC44) -> 1756846.5
S53: Signed by
A54: Doosan Enerbility Co., Ltd
...

Sheet CI_BD
I1: HEAD OFFICE & CHANGWON PLANT
I2: 22, DoosanVolvo-ro, Seongsan-gu, Changwon-Si,
I3: Gyeongsangnam-do, Korea
I4: (P.O.BOX 77, Changwon, Korea)
I5: TEL:(055)278-6114,7114 FAX:(055)264-5551/2
A6: INVOICE (Break-down)
A7: Invoice № : | B7: =CI!V8 -> PGU-DE-0220
A8: № | B8: № Package | C8: Description of Goods Specification | D8: HS CODE | E8: Quantity | F8: Unit | G8: U/Price (USD) | H8: Amount (USD) | I8: Country of Origin | J8: Remark
A9: 1 | B9: PGU-DE-0220-DCS-CBN-001 | C9: DCS Cabinet | E9: 1 | F9: EA / ШТ. | G9: 104712.11 | H9: 104712.11 | I9: Korea
A10: 2 | B10: PGU-DE-0220-DCS-CBN-002 | C10: DCS Cabinet | E10: 1 | F10: EA / ШТ. | G10: 104511.51 | H10: 104511.51 | I10: Korea
A11: 3 | B11: PGU-DE-0220-DCS-CBN-003 | C11: DCS Cabinet | E11: 1 | F11: EA / ШТ. | G11: 102104.34 | H11: 102104.34 | I11: Korea
A12: 4 | B12: PGU-DE-0220-DCS-CBN-004 | C12: DCS Cabinet | E12: 1 | F12: EA / ШТ. | G12: 105013.01 | H12: 105013.01 | I12: Korea
A13: 5 | B13: PGU-DE-0220-DCS-CBN-005 | C13: DCS Cabinet | E13: 1 | F13: EA / ШТ. | G13: 101301.95 | H13: 101301.95 | I13: Korea
A14: 6 | B14: PGU-DE-0220-DCS-CBN-006 | C14: DCS Cabinet | E14: 1 | F14: EA / ШТ. | G14: 101703.14 | H14: 101703.14 | I14: Korea
A15: 7 | B15: PGU-DE-0220-DCS-CBN-007 | C15: DCS Cabinet | E15: 1 | F15: EA / ШТ. | G15: 101803.44 | H15: 101803.44 | I15: Korea
A16: 8 | B16: PGU-DE-0220-DCS-CBN-008 | C16: DCS Cabinet | E16: 1 | F16: EA / ШТ. | G16: 99295.97 | H16: 99295.97 | I16: Korea
A17: 9 | B17: PGU-DE-0220-DCS-CBN-009 | C17: DCS Cabinet | E17: 1 | F17: EA / ШТ. | G17: 68303.59 | H17: 68303.59 | I17: Korea
A18: 10 | B18: PGU-DE-0220-DCS-CBN-010 | C18: DCS Cabinet | E18: 1 | F18: EA / ШТ. | G18: 67701.8 | H18: 67701.8 | I18: Korea
A19: 11 | B19: PGU-DE-0220-DCS-CBN-011 | C19: DCS Cabinet | E19: 1 | F19: EA / ШТ. | G19: 70911.36 | H19: 70911.36 | I19: Korea
A20: 12 | B20: PGU-DE-0220-DCS-CBN-012 | C20: DCS Cabinet | E20: 1 | F20: EA / ШТ. | G20: 68905.38 | H20: 68905.38 | I20: Korea
... A44: 36 | B44: PGU-DE-0220-DCS-CBN-036 | C44: UPS | E44: 1 | F44: EA / ШТ. | G44: 12035.87 | H44: 12035.87 | I44: Korea
C45: TOTAL | H45: =SUM(H9:H44) -> 1756846.5

Sheet PL
W1: HEAD OFFICE & CHANGWON PLANT
W2: 22, DoosanVolvo-ro, Seongsan-gu, Changwon-Si,
W3: Gyeongsangnam-do, Korea
W4: (P.O.BOX 77, Changwon, Korea)
W5: TEL:(055)278-6114,7114 FAX:(055)264-5551/2
A6: PACKING LIST УПАКОВОЧНЫЙ ЛИСТ
A8: 1. Shipper / Грузоотправитель | R8: 11. Invoice № : | V8: =CI!V8 -> PGU-DE-0220
B9: Doosan Enerbility Co., Ltd (DOOSAN) | R9: Инвойс №
B10: 22, DoosanVolvo-ro, Seongsan-gu, Changwon-si, Gyeongsangnam-do, | R10: 12. Date : | V10: =CI!V10 -> 45693
B11: Republic of Korea | R11: Дата
A12: 2. Consignee / Грузополучатель | R12: 13. Remarks / Примечания
B13: Branch of JSC "Doosan Enerbility" in the Turkestan region
B14: 321 Tauke Khan Avenue, Turkestan region, Turkestan, Kazakhstan, 161200 | S14: *Project Name / Название Проекта
B15: BIN: 230741006561 | S15: Construction of a 1000 MW CCGT Power Plant in the Sairam District of
S16: Turkistan Region, Main Site. Without External Engineering Networks
S17: *MANUFACTURER'S NAME / НАЗВАНИЕ ПРОИЗВОДИТЕЛЯ
S18: =CI!S18 -> Siemens-energy
A19: 3. Notify party / Уведомляемая сторона | S19: *MANUFACTURE YEAR / ГОД ИЗГОТОВЛЕНИЯ
B20: =CI!B20 -> Wise Logistics | S20: =CI!S20 -> 2024
B21: =CI!B21 -> ATTAN: MS. Aliya | S21: *COUNTRY OF ORIGIN / СТРАНА ПРОИСХОЖДЕНИЯ
B22: =CI!B22 -> (E): a.kipshakbayeva@wiselogistics.kz | S22: =CI!S22 -> KOREA
B23: =CI!B23 -> (T): +7 701 512 19 69 | S23: *INCOTERMS / УСЛОВИЯ ПОСТАВКИ СОГЛАСНО ИНКОТЕРМС
S24: =CI!S24 -> DDP Turkistan
S25: * CONTRACT NO. / НОМЕР КОНТРАКТ
S26: 0123-ПГУТ-8Д date 14.03.2023
A27: 4. Port of Loading / Порт погрузки | I27: 5. Carrier / Перевозчик
B28: Busan, Korea | J28: Later
A30: 6. Port of Unloading / Порт разгрузки | I30: 7. Final Destination / Конечный пункт назначения | R30: 14. Mark and Numbers of PKGS / Маркировка и количество упаковок
B32: Lianyungang, China | I32: Turkistan Region, Sairam District | S32: PKG No. | X32: : | Y32: PGU-DE-0220-DCS-CBN-001~036
S33: Q-ty of Package | X33: : | Y33: =COUNT('Summary PL'!A14:A49) -> 36 | AC33: PKGS
A34: 8. Voyage No / Рейс № | I34: 9. Sailing on or about / Дата или ожидаемая дата | S34: Net Weight (kg) | X34: : | Y34: ='Summary PL'!L50 -> 17516.1 | AC34: KG
S35: Gross Weight (kg) | X35: : | Y35: ='Summary PL'!M50 -> 21866.1 | AC35: KG
B36: HUI DE 2556W | J36: =CI!J35 -> 45946 | S36: Dimension (m3) | X36: : | Y36: ='Summary PL'!K50 -> 140.238 | AC36: m3
A38: 10. Customs Place / Место таможенного оформления
A41: 15. Description of Goods / Описание товара | R41: 16. Q-ty | U41: 17. Net Weight | Y41: 18. Gross Weight | AC41: 19. Measurement
R42: (EA) | U42: (kg) | Y42: (kg) | AC42: (CBM)
B43: Distributed Control System / | R43: 1 | U43: ='Summary PL'!L50 -> 17516.1 | Y43: ='Summary PL'!M50 -> 21866.1 | AC43: ='Summary PL'!K50 -> 140.238
B44: =CI!B43 -> Распределенная система управления
U47: ='Summary PL'!L50 -> 17516.1 | Y47: ='Summary PL'!M50 -> 21866.1 | AC47: ='Summary PL'!K50 -> 140.238
S55: Signed by
...

Sheet Summary PL
O1: HEAD OFFICE & CHANGWON PLANT | Q1: Note> | S1: Storage Classification "A" : | T1: Indoor with Air-conditioning
O2: 22, DoosanVolvo-ro, Seongsan-gu, Changwon-Si, | S2: Storage Classification "B" : | T2: Indoor without Air-conditioning
O3: Gyeongsangnam-do, Korea | S3: Storage Classification "C" : | T3: Outdoor with Waterproofing
O4: (P.O.BOX 77, Changwon, Korea) | S4: Storage Classification "D" : | T4: Outdoor without Waterproofing
O5: TEL:(055)278-6114,7114 FAX:(055)264-5551/2
A6: SUMMARY PACKING LIST CВОДНЫЙ УПАКОВОЧНЫЙ ЛИСТ
A7: Project Name: | B7: Construction of a 1000 MW CCGT Power Plant in the Sairam District of the Turkistan Region
B8: Main Site. Without External Engineering Networks
A9: Invoice №: | B9: =PL!V8 -> PGU-DE-0220
A10: Name of Consignee: | B10: Branch of JSC "Doosan Enerbility" in the Turkestan region
A11: Consignee address: | B11: Republic of Kazakhstan, Turkistan Region, Sairam District, Karamurt Rural District, Quarter 171
A12: № | B12: CNTR No. / Seal No. / № контейнера / № пломбы | C12: Package No. / № упаковки | D12: Description / Описание | E12: Packing Style / Вид упаковки | F12: Quantity / Количество | H12: Shipping Dimension / Отгрузочные параметры | L12: Net Weight (kg) / Вес нетто (кг) | M12: Gross Weight (kg) / Вес брутто (кг) | N12: Hazardous Material (UN Number) | O12: Storage Class / Класс хранения | P12: Stackable / Штабелируемый
F13: Q'ty / Количество | G13: Unit / Ед.изм. | H13: L (cm) / Д (см) | I13: W (cm) / Ш (см) | J13: H (cm) / В (см) | K13: CBM (m3) / Объем (м3)
A14: 1 | C14: PGU-DE-0220-DCS-CBN-001 | D14: DCS Cabinet | E14: wooden | F14: 1 | G14: EA / ШТ. | H14: 320 | I14: 98 | J14: 238 | K14: =ROUND(J14*I14*H14/1000000,3) -> 7.464 | L14: 1044 | M14: =L14+225 -> 1269 | N14: N/A | O14: A | P14: N
A15: 2 | C15: PGU-DE-0220-DCS-CBN-002 | D15: DCS Cabinet | E15: wooden | F15: 1 | G15: EA / ШТ. | H15: 320 | I15: 98 | J15: 238 | K15: =ROUND(J15*I15*H15/1000000,3) -> 7.464 | L15: 1042 | M15: =L15+225 -> 1267 | N15: N/A | O15: A | P15: N
A16: 3 | C16: PGU-DE-0220-DCS-CBN-003 | D16: DCS Cabinet | E16: wooden | F16: 1 | G16: EA / ШТ. | H16: 320 | I16: 98 | J16: 238 | K16: =ROUND(J16*I16*H16/1000000,3) -> 7.464 | L16: 1018 | M16: =L16+225 -> 1243 | N16: N/A | O16: A | P16: N
A17: 4 | C17: PGU-DE-0220-DCS-CBN-004 | D17: DCS Cabinet | E17: wooden | F17: 1 | G17: EA / ШТ. | H17: 320 | I17: 98 | J17: 238 | K17: =ROUND(J17*I17*H17/1000000,3) -> 7.464 | L17: 1047 | M17: =L17+225 -> 1272 | N17: N/A | O17: A | P17: N
A18: 5 | C18: PGU-DE-0220-DCS-CBN-005 | D18: DCS Cabinet | E18: wooden | F18: 1 | G18: EA / ШТ. | H18: 320 | I18: 98 | J18: 238 | K18: =ROUND(J18*I18*H18/1000000,3) -> 7.464 | L18: 1010 | M18: =L18+225 -> 1235 | N18: N/A | O18: A | P18: N
A19: 6 | C19: PGU-DE-0220-DCS-CBN-006 | D19: DCS Cabinet | E19: wooden | F19: 1 | G19: EA / ШТ. | H19: 320 | I19: 98 | J19: 238 | K19: =ROUND(J19*I19*H19/1000000,3) -> 7.464 | L19: 1014 | M19: =L19+225 -> 1239 | N19: N/A | O19: A | P19: N
A20: 7 | C20: PGU-DE-0220-DCS-CBN-007 | D20: DCS Cabinet | E20: wooden | F20: 1 | G20: EA / ШТ. | H20: 320 | I20: 98 | J20: 238 | K20: =ROUND(J20*I20*H20/1000000,3) -> 7.464 | L20: 1015 | M20: =L20+225 -> 1240 | N20: N/A | O20: A | P20: N
A21: 8 | C21: PGU-DE-0220-DCS-CBN-008 | D21: DCS Cabinet | E21: wooden | F21: 1 | G21: EA / ШТ. | H21: 320 | I21: 98 | J21: 238 | K21: =ROUND(J21*I21*H21/1000000,3) -> 7.464 | L21: 990 | M21: =L21+225 -> 1215 | N21: N/A | O21: A | P21: N
A22: 9 | C22: PGU-DE-0220-DCS-CBN-009 | D22: DCS Cabinet | E22: wooden | F22: 1 | G22: EA / ШТ. | H22: 221 | I22: 98 | J22: 238 | K22: =ROUND(J22*I22*H22/1000000,3) -> 5.155 | L22: 681 | M22: =L22+160 -> 841 | N22: N/A | O22: A | P22: N
A23: 10 | C23: PGU-DE-0220-DCS-CBN-010 | D23: DCS Cabinet | E23: wooden | F23: 1 | G23: EA / ШТ. | H23: 221 | I23: 98 | J23: 238 | K23: =ROUND(J23*I23*H23/1000000,3) -> 5.155 | L23: 675 | M23: =L23+160 -> 835 | N23: N/A | O23: A | P23: N
A24: 11 | C24: PGU-DE-0220-DCS-CBN-011 | D24: DCS Cabinet | E24: wooden | F24: 1 | G24: EA / ШТ. | H24: 221 | I24: 98 | J24: 238 | K24: =ROUND(J24*I24*H24/1000000,3) -> 5.155 | L24: 707 | M24: =L24+160 -> 867 | N24: N/A | O24: A | P24: N
A25: 12 | C25: PGU-DE-0220-DCS-CBN-012 | D25: DCS Cabinet | E25: wooden | F25: 1 | G25: EA / ШТ. | H25: 221 | I25: 98 | J25: 238 | K25: =ROUND(J25*I25*H25/1000000,3) -> 5.155 | L25: 687 | M25: =L25+160 -> 847 | N25: N/A | O25: A | P25: N
A26: 13 | C26: PGU-DE-0220-DCS-CBN-013 | D26: Power Distribution Cabinet | E26: wooden | F26: 1 | G26: EA / ШТ. | H26: 100 | I26: 98 | J26: 238 | K26: =ROUND(J26*I26*H26/1000000,3) -> 2.332 | L26: 300 | M26: =L26+70 -> 370 | N26: N/A | O26: A | P26: N
A27: 14 | C27: PGU-DE-0220-DCS-CBN-014 | D27: Power Distribution Cabinet | E27: wooden | F27: 1 | G27: EA / ШТ. | H27: 100 | I27: 98 | J27: 238 | K27: =ROUND(J27*I27*H27/1000000,3) -> 2.332 | L27: 297 | M27: =L27+70 -> 367 | N27: N/A | O27: A | P27: N
A28: 15 | C28: PGU-DE-0220-DCS-CBN-015 | D28: Power Distribution Cabinet | E28: wooden | F28: 1 | G28: EA / ШТ. | H28: 100 | I28: 98 | J28: 238 | K28: =ROUND(J28*I28*H28/1000000,3) -> 2.332 | L28: 306 | M28: =L28+70 -> 376 | N28: N/A | O28: A | P28: N
A29: 16 | C29: PGU-DE-0220-DCS-CBN-016 | D29: Power Distribution Cabinet | E29: wooden | F29: 1 | G29: EA / ШТ. | H29: 100 | I29: 98 | J29: 238 | K29: =ROUND(J29*I29*H29/1000000,3) -> 2.332 | L29: 295 | M29: =L29+70 -> 365 | N29: N/A | O29: A | P29: N
A30: 17 | C30: PGU-DE-0220-DCS-CBN-017 | D30: Power Distribution Cabinet | E30: wooden | F30: 1 | G30: EA / ШТ. | H30: 100 | I30: 98 | J30: 238 | K30: =ROUND(J30*I30*H30/1000000,3) -> 2.332 | L30: 306 | M30: =L30+70 -> 376 | N30: N/A | O30: A | P30: N
A31: 18 | C31: PGU-DE-0220-DCS-CBN-018 | D31: DCS Cabinet | E31: wooden | F31: 1 | G31: EA / ШТ. | H31: 100 | I31: 98 | J31: 238 | K31: =ROUND(J31*I31*H31/1000000,3) -> 2.332 | L31: 303 | M31: =L31+70 -> 373 | N31: N/A | O31: A | P31: N
A32: 19 | C32: PGU-DE-0220-DCS-CBN-019 | D32: DCS Cabinet | E32: wooden | F32: 1 | G32: EA / ШТ. | H32: 100 | I32: 98 | J32: 238 | K32: =ROUND(J32*I32*H32/1000000,3) -> 2.332 | L32: 295 | M32: =L32+70 -> 365 | N32: N/A | O32: A | P32: N
A33: 20 | C33: PGU-DE-0220-DCS-CBN-020 | D33: DCS Cabinet | E33: wooden | F33: 1 | G33: EA / ШТ. | H33: 100 | I33: 122 | J33: 238 | K33: =ROUND(J33*I33*H33/1000000,3) -> 2.904 | L33: 350 | M33: =L33+90 -> 440 | N33: N/A | O33: A | P33: N
A34: 21 | C34: PGU-DE-0220-DCS-CBN-021 | D34: DCS Cabinet | E34: wooden | F34: 1 | G34: EA / ШТ. | H34: 100 | I34: 122 | J34: 238 | K34: =ROUND(J34*I34*H34/1000000,3) -> 2.904 | L34: 345.1 | M34: =L34+90 -> 435.1 | N34: N/A | O34: A | P34: N
A35: 22 | C35: PGU-DE-0220-DCS-CBN-022 | D35: DCS Cabinet | E35: wooden | F35: 1 | G35: EA / ШТ. | H35: 100 | I35: 122 | J35: 238 | K35: =ROUND(J35*I35*H35/1000000,3) -> 2.904 | L35: 340 | M35: =L35+90 -> 430 | N35: N/A | O35: A | P35: N
A36: 23 | C36: PGU-DE-0220-DCS-CBN-023 | D36: DCS Cabinet | E36: wooden | F36: 1 | G36: EA / ШТ. | H36: 100 | I36: 122 | J36: 238 | K36: =ROUND(J36*I36*H36/1000000,3) -> 2.904 | L36: 345 | M36: =L36+90 -> 435 | N36: N/A | O36: A | P36: N
A37: 24 | C37: PGU-DE-0220-DCS-CBN-024 | D37: DCS Cabinet | E37: wooden | F37: 1 | G37: EA / ШТ. | H37: 100 | I37: 122 | J37: 238 | K37: =ROUND(J37*I37*H37/1000000,3) -> 2.904 | L37: 342 | M37: =L37+90 -> 432 | N37: N/A | O37: A | P37: N
A38: 25 | C38: PGU-DE-0220-DCS-CBN-025 | D38: DCS Cabinet | E38: wooden | F38: 1 | G38: EA / ШТ. | H38: 100 | I38: 122 | J38: 238 | K38: =ROUND(J38*I38*H38/1000000,3) -> 2.904 | L38: 319 | M38: =L38+90 -> 409 | N38: N/A | O38: A | P38: N
A39: 26 | C39: PGU-DE-0220-DCS-CBN-026 | D39: DCS Cabinet | E39: wooden | F39: 1 | G39: EA / ШТ. | H39: 100 | I39: 122 | J39: 238 | K39: =ROUND(J39*I39*H39/1000000,3) -> 2.904 | L39: 404 | M39: =L39+90 -> 494 | N39: N/A | O39: A | P39: N
A40: 27 | C40: PGU-DE-0220-DCS-CBN-027 | D40: DCS Cabinet | E40: wooden | F40: 1 | G40: EA / ШТ. | H40: 100 | I40: 122 | J40: 238 | K40: =ROUND(J40*I40*H40/1000000,3) -> 2.904 | L40: 390 | M40: =L40+90 -> 480 | N40: N/A | O40: A | P40: N
...

Sheet Detail PL
P1: HEAD OFFICE & CHANGWON PLANT
P2: 22, DoosanVolvo-ro, Seongsan-gu, Changwon-Si, | R2: Note> | S2: Storage Classification "A" : | T2: Indoor with Air-conditioning
P3: Gyeongsangnam-do, Korea | S3: Storage Classification "B" : | T3: Indoor without Air-conditioning
P4: (P.O.BOX 77, Changwon, Korea) | S4: Storage Classification "C" : | T4: Outdoor with Waterproofing
P5: TEL:(055)278-6114,7114 FAX:(055)264-5551/2 | S5: Storage Classification "D" : | T5: Outdoor without Waterproofing
A6: DETAILED PACKING LIST ПОДРОБНЫЙ УПАКОВОЧНЫЙ ЛИСТ
A7: Project Name: | B7: Construction of a 1000 MW CCGT Power Plant in the Sairam District of the Turkistan Region
B8: Main Site. Without External Engineering Networks
A9: Invoice №: | B9: =CI!V8 -> PGU-DE-0220
A10: Name of Consignee: | B10: Branch of JSC "Doosan Enerbility" in the Turkestan region
A11: Consignee address: | B11: Republic of Kazakhstan, Turkistan Region, Sairam District, Karamurt Rural District, Quarter 171
A12: № | B12: Package No./ Номер упаковки | C12: Description / Описание | D12: HS Code / Код ТН ВЭД | E12: Quantity / Количество | G12: Shipping Dimension / Отгрузочные параметры | K12: Net Weight (kg) / Вес нетто (кг) | L12: Gross Weight (kg) / Вес брутто (кг) | M12: Drawing No. / № чертежа | N12: Tag No. / № Тег | O12: Unit Price (US$) / Цена за единицу | P12: Total Price (US$) / Общая цена | Q12: Remark / Примечания
E13: Q'ty / Количество | F13: Unit / Ед.изм. | G13: L (cm) / Д (см) | H13: W (cm) / Ш (см) | I13: H (cm) / В (см) | J13: CBM (m3) / Объем (м3)
A14: 1 | B14: PGU-DE-0220-DCS-CBN-001 | C14: B1-D-0010 + B1-MD-0010 + B1-MD-0011 B#1 System + Marshalling Cabinet for GT/HRSG#11 | E14: 3 | F14: EA / ШТ.
G15: 320 | H15: 98 | I15: 238 | J15: =ROUND(I15*H15*G15/1000000,3) -> 7.464 | K15: 1044 | L15: ='Summary PL'!M14 -> 1269
A16: 2 | B16: PGU-DE-0220-DCS-CBN-002 | C16: B1-D-0020 + B1-MD-0020 + B1-MD-0021 B#1 System + Marshalling Cabinet for GT/HRSG#12 | E16: 3 | F16: EA / ШТ.
G17: 320 | H17: 98 | I17: 238 | J17: =ROUND(I17*H17*G17/1000000,3) -> 7.464 | K17: 1042 | L17: ='Summary PL'!M15 -> 1267
A18: 3 | B18: PGU-DE-0220-DCS-CBN-003 | C18: B1-D-0040 + B1-MD-0040 + B1-MD-0041 B#1 System + Marshalling Cabinet for Block BOP#1 | E18: 3 | F18: EA / ШТ.
G19: 320 | H19: 98 | I19: 238 | J19: =ROUND(I19*H19*G19/1000000,3) -> 7.464 | K19: 1018 | L19: ='Summary PL'!M16 -> 1243
A20: 4 | B20: PGU-DE-0220-DCS-CBN-004 | C20: B2-D-0010 + B2-MD-0010 + B2-MD-0011 B#2 System + Marshalling Cabinet for GT/HRSG#21 | E20: 3 | F20: EA / ШТ.
G21: 320 | H21: 98 | I21: 238 | J21: =ROUND(I21*H21*G21/1000000,3) -> 7.464 | K21: 1047 | L21: ='Summary PL'!M17 -> 1272
A22: 5 | B22: PGU-DE-0220-DCS-CBN-005 | C22: B2-D-0020 + B2-MD-0020 + B2-MD-0021 B#2 System + Marshalling Cabinet for GT/HRSG#22 | E22: 3 | F22: EA / ШТ.
G23: 320 | H23: 98 | I23: 238 | J23: =ROUND(I23*H23*G23/1000000,3) -> 7.464 | K23: 1010 | L23: ='Summary PL'!M18 -> 1235
A24: 6 | B24: PGU-DE-0220-DCS-CBN-006 | C24: B2-D-0040 + B2-MD-0040 + B2-MD-0041 B#2 System + Marshalling Cabinet for Block BOP#2 | E24: 3 | F24: EA / ШТ.
G25: 320 | H25: 98 | I25: 238 | J25: =ROUND(I25*H25*G25/1000000,3) -> 7.464 | K25: 1014 | L25: ='Summary PL'!M19 -> 1239
A26: 7 | B26: PGU-DE-0220-DCS-CBN-007 | C26: B0-D-0020 + B0-MD-0020 + B0-MD-0021 COM System + Marshalling Cabinet for Plant Common Electrical | E26: 3 | F26: EA / ШТ.
G27: 320 | H27: 98 | I27: 238 | J27: =ROUND(I27*H27*G27/1000000,3) -> 7.464 | K27: 1015 | L27: ='Summary PL'!M20 -> 1240
A28: 8 | B28: PGU-DE-0220-DCS-CBN-008 | C28: B0-D-0011 + B0-MD-0011 + B0-MD-0012 COM Remote I/O + Marshalling Cabinet for WT/WWT LER | E28: 3 | F28: EA / ШТ.
G29: 320 | H29: 98 | I29: 238 | J29: =ROUND(I29*H29*G29/1000000,3) -> 7.464 | K29: 990 | L29: ='Summary PL'!M21 -> 1215
A30: 9 | B30: PGU-DE-0220-DCS-CBN-009 | C30: B1-D-0041 + B1-MD-0042 B#1 Remote I/O + Marshalling Cabinet for Block BOP | E30: 2 | F30: EA / ШТ.
G31: 221 | H31: 98 | I31: 238 | J31: =ROUND(I31*H31*G31/1000000,3) -> 5.155 | K31: 681 | L31: ='Summary PL'!M22 -> 841
A32: 10 | B32: PGU-DE-0220-DCS-CBN-010 | C32: B2-D-0041 + B2-MD-0042 B#2 Remote I/O + Marshalling Cabinet for Block BOP | E32: 2 | F32: EA / ШТ.
G33: 221 | H33: 98 | I33: 238 | J33: =ROUND(I33*H33*G33/1000000,3) -> 5.155 | K33: 675 | L33: ='Summary PL'!M23 -> 835
A34: 11 | B34: PGU-DE-0220-DCS-CBN-011 | C34: B0-D-0010 + B0-MD-0010 COM System + Marshalling Cabinet for Plant Common | E34: 2 | F34: EA / ШТ.
G35: 221 | H35: 98 | I35: 238 | J35: =ROUND(I35*H35*G35/1000000,3) -> 5.155 | K35: 707 | L35: ='Summary PL'!M24 -> 867
A36: 12 | B36: PGU-DE-0220-DCS-CBN-012 | C36: B0-D-0021 + B0-MD-0022 COM I/O Extension + Marshalling Cabinet for Plant Block#2 Electrical | E36: 2 | F36: EA / ШТ.
G37: 221 | H37: 98 | I37: 238 | J37: =ROUND(I37*H37*G37/1000000,3) -> 5.155 | K37: 687 | L37: ='Summary PL'!M25 -> 847
A38: 13 | B38: PGU-DE-0220-DCS-CBN-013 | C38: B1-PDP-0001 B#1 Power Distribution Cabinet#1 | E38: 1 | F38: EA / ШТ.
G39: 100 | H39: 98 | I39: 238 | J39: =ROUND(I39*H39*G39/1000000,3) -> 2.332 | K39: 300 | L39: ='Summary PL'!M26 -> 370
A40: 14 | B40: PGU-DE-0220-DCS-CBN-014 | C40: B1-PDP-0011 B#1 Power Distribution Cabinet#2 | E40: 1 | F40: EA / ШТ.
...

Sheet PGU-DE-0220-DCS-CBN-001
A1: SHIPPING MARK ГРУЗОВАЯ МАРКИРОВКА | P1: SHIPPING MARK ГРУЗОВАЯ МАРКИРОВКА
A2: ● NAME OF THE PROJECT | F2: : | G2: Construction of a 1000 MW CCGT Power Plant in the Sairam District of the | P2: ● NAME OF THE PROJECT | U2: : | V2: Construction of a 1000 MW CCGT Power Plant in the Sairam District of the
A3: НАЗВАНИЕ ПРОЕКТА | G3: Turkistan Region, Main Site. Without External Engineering Networks | P3: НАЗВАНИЕ ПРОЕКТА | V3: Turkistan Region, Main Site. Without External Engineering Networks
A5: ● CONSIGNEE | F5: : | G5: =CI!B13 -> Branch of JSC "Doosan Enerbility" in the Turkestan region | P5: ● CONSIGNEE | U5: : | V5: =G5 -> Branch of JSC "Doosan Enerbility" in the Turkestan region
A6: ГРУЗОПОЛУЧАТЕЛЬ | P6: ГРУЗОПОЛУЧАТЕЛЬ
A8: ● Shipper/Exporter | F8: : Doosan Enerbility Co., LTD | P8: ● Shipper/Exporter | U8: : Doosan Enerbility Co., LTD
A9: Грузоотправитель/Экспортер | F9: 22, Doosan Volvo-ro, Sengsan-gu, Changwon, Gyeongnam, South Korea | P9: Грузоотправитель/Экспортер | U9: 22, Doosan Volvo-ro, Sengsan-gu, Changwon, Gyeongnam, South Korea
A11: ● Number of Invoice | F11: : | G11: =CI!V8 -> PGU-DE-0220 | P11: ● Number of Invoice | U11: : | V11: =CI!V8 -> PGU-DE-0220
A12: № инвойса | P12: № инвойса
A14: ● CARGO DESCRIPTION | F14: : | G14: ='Summary PL'!D14 -> DCS Cabinet | P14: ● CARGO DESCRIPTION | U14: : | V14: =G14 -> DCS Cabinet
A15: ОПИСАНИЕ ГРУЗА | P15: ОПИСАНИЕ ГРУЗА
A17: ● PACKAGE NO. | F17: : | G17: ='Summary PL'!C14 -> PGU-DE-0220-DCS-CBN-001 | P17: ● PACKAGE NO. | U17: : | V17: =G17 -> PGU-DE-0220-DCS-CBN-001
A18: УПАКОВОЧНЫЙ НОМЕР | P18: УПАКОВОЧНЫЙ НОМЕР
A20: ● NET WEIGHT | F20: : | G20: ='Summary PL'!L14 -> 1044 | H20: Kg | P20: ● NET WEIGHT | U20: : | V20: =G20 -> 1044 | W20: Kg
A21: ВЕС НЕТТО | P21: ВЕС НЕТТО
A23: ● GROSS WEIGHT | F23: : | G23: ='Summary PL'!M14 -> 1269 | H23: Kg | P23: ● GROSS WEIGHT | U23: : | V23: =G23 -> 1269 | W23: Kg
A24: ВЕС БРУТТО | P24: ВЕС БРУТТО
A26: ● CBM(m3) | F26: : | G26: ='Summary PL'!K14 -> 7.464 | H26: m3 | P26: ● CBM(m3) | U26: : | V26: =G26 -> 7.464 | W26: m3
A27: РАЗМЕРЫ | P27: РАЗМЕРЫ
A29: ● FINAL DESTINATION | F29: : | G29: Turkestan Oblast, Sairam district, Karamurt rural district, quarter 171, Republic of Kazakhstan | P29: ● FINAL DESTINATION | U29: : | V29: =G29 -> Turkestan Oblast, Sairam district, Karamurt rural district, quarter 171, Republic of Kazakhstan
A30: КОНЕЧНЫЙ ПУНКТ НАЗНАЧЕНИЯ | P30: КОНЕЧНЫЙ ПУНКТ НАЗНАЧЕНИЯ
E31: Doosan Enerbility | T31: Doosan Enerbility

Sheet PGU-DE-0220-DCS-CBN-002
A1: SHIPPING MARK ГРУЗОВАЯ МАРКИРОВКА | P1: SHIPPING MARK ГРУЗОВАЯ МАРКИРОВКА
A2: ● NAME OF THE PROJECT | F2: : | G2: Construction of a 1000 MW CCGT Power Plant in the Sairam District of the | P2: ● NAME OF THE PROJECT | U2: : | V2: Construction of a 1000 MW CCGT Power Plant in the Sairam District of the
A3: НАЗВАНИЕ ПРОЕКТА | G3: Turkistan Region, Main Site. Without External Engineering Networks | P3: НАЗВАНИЕ ПРОЕКТА | V3: Turkistan Region, Main Site. Without External Engineering Networks
A5: ● CONSIGNEE | F5: : | G5: =CI!B13 -> Branch of JSC "Doosan Enerbility" in the Turkestan region | P5: ● CONSIGNEE | U5: : | V5: =G5 -> Branch of JSC "Doosan Enerbility" in the Turkestan region
A6: ГРУЗОПОЛУЧАТЕЛЬ | P6: ГРУЗОПОЛУЧАТЕЛЬ
A8: ● Shipper/Exporter | F8: : Doosan Enerbility Co., LTD | P8: ● Shipper/Exporter | U8: : Doosan Enerbility Co., LTD
A9: Грузоотправитель/Экспортер | F9: 22, Doosan Volvo-ro, Sengsan-gu, Changwon, Gyeongnam, South Korea | P9: Грузоотправитель/Экспортер | U9: 22, Doosan Volvo-ro, Sengsan-gu, Changwon, Gyeongnam, South Korea
A11: ● Number of Invoice | F11: : | G11: =CI!V8 -> PGU-DE-0220 | P11: ● Number of Invoice | U11: : | V11: =CI!V8 -> PGU-DE-0220
A12: № инвойса | P12: № инвойса
A14: ● CARGO DESCRIPTION | F14: : | G14: ='Summary PL'!D15 -> DCS Cabinet | P14: ● CARGO DESCRIPTION | U14: : | V14: =G14 -> DCS Cabinet
A15: ОПИСАНИЕ ГРУЗА | P15: ОПИСАНИЕ ГРУЗА
A17: ● PACKAGE NO. | F17: : | G17: ='Summary PL'!C15 -> PGU-DE-0220-DCS-CBN-002 | P17: ● PACKAGE NO. | U17: : | V17: =G17 -> PGU-DE-0220-DCS-CBN-002
A18: УПАКОВОЧНЫЙ НОМЕР | P18: УПАКОВОЧНЫЙ НОМЕР
A20: ● NET WEIGHT | F20: : | G20: ='Summary PL'!L15 -> 1042 | H20: Kg | P20: ● NET WEIGHT | U20: : | V20: =G20 -> 1042 | W20: Kg
A21: ВЕС НЕТТО | P21: ВЕС НЕТТО
A23: ● GROSS WEIGHT | F23: : | G23: ='Summary PL'!M15 -> 1267 | H23: Kg | P23: ● GROSS WEIGHT | U23: : | V23: =G23 -> 1267 | W23: Kg
A24: ВЕС БРУТТО | P24: ВЕС БРУТТО
A26: ● CBM(m3) | F26: : | G26: ='Summary PL'!K14 -> 7.464 | H26: m3 | P26: ● CBM(m3) | U26: : | V26: =G26 -> 7.464 | W26: m3
A27: РАЗМЕРЫ | P27: РАЗМЕРЫ
A29: ● FINAL DESTINATION | F29: : | G29: Turkestan Oblast, Sairam district, Karamurt rural district, quarter 171, Republic of Kazakhstan | P29: ● FINAL DESTINATION | U29: : | V29: =G29 -> Turkestan Oblast, Sairam district, Karamurt rural district, quarter 171, Republic of Kazakhstan
A30: КОНЕЧНЫЙ ПУНКТ НАЗНАЧЕНИЯ | P30: КОНЕЧНЫЙ ПУНКТ НАЗНАЧЕНИЯ
E31: Doosan Enerbility | T31: Doosan Enerbility

Sheet PGU-DE-0220-DCS-CBN-003
A1: SHIPPING MARK ГРУЗОВАЯ МАРКИРОВКА | P1: SHIPPING MARK ГРУЗОВАЯ МАРКИРОВКА
A2: ● NAME OF THE PROJECT | F2: : | G2: Construction of a 1000 MW CCGT Power Plant in the Sairam District of the | P2: ● NAME OF THE PROJECT | U2: : | V2: Construction of a 1000 MW CCGT Power Plant in the Sairam District of the
A3: НАЗВАНИЕ ПРОЕКТА | G3: Turkistan Region, Main Site. Without External Engineering Networks | P3: НАЗВАНИЕ ПРОЕКТА | V3: Turkistan Region, Main Site. Without External Engineering Networks
A5: ● CONSIGNEE | F5: : | G5: =CI!B13 -> Branch of JSC "Doosan Enerbility" in the Turkestan region | P5: ● CONSIGNEE | U5: : | V5: =G5 -> Branch of JSC "Doosan Enerbility" in the Turkestan region
A6: ГРУЗОПОЛУЧАТЕЛЬ | P6: ГРУЗОПОЛУЧАТЕЛЬ
A8: ● Shipper/Exporter | F8: : Doosan Enerbility Co., LTD | P8: ● Shipper/Exporter | U8: : Doosan Enerbility Co., LTD
A9: Грузоотправитель/Экспортер | F9: 22, Doosan Volvo-ro, Sengsan-gu, Changwon, Gyeongnam, South Korea | P9: Грузоотправитель/Экспортер | U9: 22, Doosan Volvo-ro, Sengsan-gu, Changwon, Gyeongnam, South Korea
A11: ● Number of Invoice | F11: : | G11: =CI!V8 -> PGU-DE-0220 | P11: ● Number of Invoice | U11: : | V11: =CI!V8 -> PGU-DE-0220
A12: № инвойса | P12: № инвойса
A14: ● CARGO DESCRIPTION | F14: : | G14: ='Summary PL'!D16 -> DCS Cabinet | P14: ● CARGO DESCRIPTION | U14: : | V14: =G14 -> DCS Cabinet
A15: ОПИСАНИЕ ГРУЗА | P15: ОПИСАНИЕ ГРУЗА
A17: ● PACKAGE NO. | F17: : | G17: ='Summary PL'!C16 -> PGU-DE-0220-DCS-CBN-003 | P17: ● PACKAGE NO. | U17: : | V17: =G17 -> PGU-DE-0220-DCS-CBN-003
A18: УПАКОВОЧНЫЙ НОМЕР | P18: УПАКОВОЧНЫЙ НОМЕР
A20: ● NET WEIGHT | F20: : | G20: ='Summary PL'!L16 -> 1018 | H20: Kg | P20: ● NET WEIGHT | U20: : | V20: =G20 -> 1018 | W20: Kg
A21: ВЕС НЕТТО | P21: ВЕС НЕТТО
A23: ● GROSS WEIGHT | F23: : | G23: ='Summary PL'!M16 -> 1243 | H23: Kg | P23: ● GROSS WEIGHT | U23: : | V23: =G23 -> 1243 | W23: Kg
A24: ВЕС БРУТТО | P24: ВЕС БРУТТО
A26: ● CBM(m3) | F26: : | G26: ='Summary PL'!K14 -> 7.464 | H26: m3 | P26: ● CBM(m3) | U26: : | V26: =G26 -> 7.464 | W26: m3
A27: РАЗМЕРЫ | P27: РАЗМЕРЫ
A29: ● FINAL DESTINATION | F29: : | G29: Turkestan Oblast, Sairam district, Karamurt rural district, quarter 171, Republic of Kazakhstan | P29: ● FINAL DESTINATION | U29: : | V29: =G29 -> Turkestan Oblast, Sairam district, Karamurt rural district, quarter 171, Republic of Kazakhstan
A30: КОНЕЧНЫЙ ПУНКТ НАЗНАЧЕНИЯ | P30: КОНЕЧНЫЙ ПУНКТ НАЗНАЧЕНИЯ
E31: Doosan Enerbility | T31: Doosan Enerbility

Sheet PGU-DE-0220-DCS-CBN-004
A1: SHIPPING MARK ГРУЗОВАЯ МАРКИРОВКА | P1: SHIPPING MARK ГРУЗОВАЯ МАРКИРОВКА
A2: ● NAME OF THE PROJECT | F2: : | G2: Construction of a 1000 MW CCGT Power Plant in the Sairam District of the | P2: ● NAME OF THE PROJECT | U2: : | V2: Construction of a 1000 MW CCGT Power Plant in the Sairam District of the
A3: НАЗВАНИЕ ПРОЕКТА | G3: Turkistan Region, Main Site. Without External Engineering Networks | P3: НАЗВАНИЕ ПРОЕКТА | V3: Turkistan Region, Main Site. Without External Engineering Networks
A5: ● CONSIGNEE | F5: : | G5: =CI!B13 -> Branch of JSC "Doosan Enerbility" in the Turkestan region | P5: ● CONSIGNEE | U5: : | V5: =G5 -> Branch of JSC "Doosan Enerbility" in the Turkestan region
A6: ГРУЗОПОЛУЧАТЕЛЬ | P6: ГРУЗОПОЛУЧАТЕЛЬ
A8: ● Shipper/Exporter | F8: : Doosan Enerbility Co., LTD | P8: ● Shipper/Exporter | U8: : Doosan Enerbility Co., LTD
A9: Грузоотправитель/Экспортер | F9: 22, Doosan Volvo-ro, Sengsan-gu, Changwon, Gyeongnam, South Korea | P9: Грузоотправитель/Экспортер | U9: 22, Doosan Volvo-ro, Sengsan-gu, Changwon, Gyeongnam, South Korea
A11: ● Number of Invoice | F11: : | G11: =CI!V8 -> PGU-DE-0220 | P11: ● Number of Invoice | U11: : | V11: =CI!V8 -> PGU-DE-0220
A12: № инвойса | P12: № инвойса
A14: ● CARGO DESCRIPTION | F14: : | G14: ='Summary PL'!D17 -> DCS Cabinet | P14: ● CARGO DESCRIPTION | U14: : | V14: =G14 -> DCS Cabinet
A15: ОПИСАНИЕ ГРУЗА | P15: ОПИСАНИЕ ГРУЗА
A17: ● PACKAGE NO. | F17: : | G17: ='Summary PL'!C17 -> PGU-DE-0220-DCS-CBN-004 | P17: ● PACKAGE NO. | U17: : | V17: =G17 -> PGU-DE-0220-DCS-CBN-004
A18: УПАКОВОЧНЫЙ НОМЕР | P18: УПАКОВОЧНЫЙ НОМЕР
A20: ● NET WEIGHT | F20: : | G20: ='Summary PL'!L17 -> 1047 | H20: Kg | P20: ● NET WEIGHT | U20: : | V20: =G20 -> 1047 | W20: Kg
A21: ВЕС НЕТТО | P21: ВЕС НЕТТО
A23: ● GROSS WEIGHT | F23: : | G23: ='Summary PL'!M17 -> 1272 | H23: Kg | P23: ● GROSS WEIGHT | U23: : | V23: =G23 -> 1272 | W23: Kg
A24: ВЕС БРУТТО | P24: ВЕС БРУТТО
A26: ● CBM(m3) | F26: : | G26: ='Summary PL'!K14 -> 7.464 | H26: m3 | P26: ● CBM(m3) | U26: : | V26: =G26 -> 7.464 | W26: m3
A27: РАЗМЕРЫ | P27: РАЗМЕРЫ
A29: ● FINAL DESTINATION | F29: : | G29: Turkestan Oblast, Sairam district, Karamurt rural district, quarter 171, Republic of Kazakhstan | P29: ● FINAL DESTINATION | U29: : | V29: =G29 -> Turkestan Oblast, Sairam district, Karamurt rural district, quarter 171, Republic of Kazakhstan
A30: КОНЕЧНЫЙ ПУНКТ НАЗНАЧЕНИЯ | P30: КОНЕЧНЫЙ ПУНКТ НАЗНАЧЕНИЯ
E31: Doosan Enerbility | T31: Doosan Enerbility

Sheet PGU-DE-0220-DCS-CBN-005
A1: SHIPPING MARK ГРУЗОВАЯ МАРКИРОВКА | P1: SHIPPING MARK ГРУЗОВАЯ МАРКИРОВКА
A2: ● NAME OF THE PROJECT | F2: : | G2: Construction of a 1000 MW CCGT Power Plant in the Sairam District of the | P2: ● NAME OF THE PROJECT | U2: : | V2: Construction of a 1000 MW CCGT Power Plant in the Sairam District of the
A3: НАЗВАНИЕ ПРОЕКТА | G3: Turkistan Region, Main Site. Without External Engineering Networks | P3: НАЗВАНИЕ ПРОЕКТА | V3: Turkistan Region, Main Site. Without External Engineering Networks
A5: ● CONSIGNEE | F5: : | G5: =CI!B13 -> Branch of JSC "Doosan Enerbility" in the Turkestan region | P5: ● CONSIGNEE | U5: : | V5: =G5 -> Branch of JSC "Doosan Enerbility" in the Turkestan region
A6: ГРУЗОПОЛУЧАТЕЛЬ | P6: ГРУЗОПОЛУЧАТЕЛЬ
A8: ● Shipper/Exporter | F8: : Doosan Enerbility Co., LTD | P8: ● Shipper/Exporter | U8: : Doosan Enerbility Co., LTD
A9: Грузоотправитель/Экспортер | F9: 22, Doosan Volvo-ro, Sengsan-gu, Changwon, Gyeongnam, South Korea | P9: Грузоотправитель/Экспортер | U9: 22, Doosan Volvo-ro, Sengsan-gu, Changwon, Gyeongnam, South Korea
A11: ● Number of Invoice | F11: : | G11: =CI!V8 -> PGU-DE-0220 | P11: ● Number of Invoice | U11: : | V11: =CI!V8 -> PGU-DE-0220
A12: № инвойса | P12: № инвойса
A14: ● CARGO DESCRIPTION | F14: : | G14: ='Summary PL'!D18 -> DCS Cabinet | P14: ● CARGO DESCRIPTION | U14: : | V14: =G14 -> DCS Cabinet
A15: ОПИСАНИЕ ГРУЗА | P15: ОПИСАНИЕ ГРУЗА
A17: ● PACKAGE NO. | F17: : | G17: ='Summary PL'!C18 -> PGU-DE-0220-DCS-CBN-005 | P17: ● PACKAGE NO. | U17: : | V17: =G17 -> PGU-DE-0220-DCS-CBN-005
A18: УПАКОВОЧНЫЙ НОМЕР | P18: УПАКОВОЧНЫЙ НОМЕР
A20: ● NET WEIGHT | F20: : | G20: ='Summary PL'!L18 -> 1010 | H20: Kg | P20: ● NET WEIGHT | U20: : | V20: =G20 -> 1010 | W20: Kg
A21: ВЕС НЕТТО | P21: ВЕС НЕТТО
A23: ● GROSS WEIGHT | F23: : | G23: ='Summary PL'!M18 -> 1235 | H23: Kg | P23: ● GROSS WEIGHT | U23: : | V23: =G23 -> 1235 | W23: Kg
A24: ВЕС БРУТТО | P24: ВЕС БРУТТО
A26: ● CBM(m3) | F26: : | G26: ='Summary PL'!K14 -> 7.464 | H26: m3 | P26: ● CBM(m3) | U26: : | V26: =G26 -> 7.464 | W26: m3
A27: РАЗМЕРЫ | P27: РАЗМЕРЫ
A29: ● FINAL DESTINATION | F29: : | G29: Turkestan Oblast, Sairam district, Karamurt rural district, quarter 171, Republic of Kazakhstan | P29: ● FINAL DESTINATION | U29: : | V29: =G29 -> Turkestan Oblast, Sairam district, Karamurt rural district, quarter 171, Republic of Kazakhstan
A30: КОНЕЧНЫЙ ПУНКТ НАЗНАЧЕНИЯ | P30: КОНЕЧНЫЙ ПУНКТ НАЗНАЧЕНИЯ
E31: Doosan Enerbility | T31: Doosan Enerbility

Sheet PGU-DE-0220-DCS-CBN-006
A1: SHIPPING MARK ГРУЗОВАЯ МАРКИРОВКА | P1: SHIPPING MARK ГРУЗОВАЯ МАРКИРОВКА
A2: ● NAME OF THE PROJECT | F2: : | G2: Construction of a 1000 MW CCGT Power Plant in the Sairam District of the | P2: ● NAME OF THE PROJECT | U2: : | V2: Construction of a 1000 MW CCGT Power Plant in the Sairam District of the
A3: НАЗВАНИЕ ПРОЕКТА | G3: Turkistan Region, Main Site. Without External Engineering Networks | P3: НАЗВАНИЕ ПРОЕКТА | V3: Turkistan Region, Main Site. Without External Engineering Networks
A5: ● CONSIGNEE | F5: : | G5: =CI!B13 -> Branch of JSC "Doosan Enerbility" in the Turkestan region | P5: ● CONSIGNEE | U5: : | V5: =G5 -> Branch of JSC "Doosan Enerbility" in the Turkestan region
A6: ГРУЗОПОЛУЧАТЕЛЬ | P6: ГРУЗОПОЛУЧАТЕЛЬ
A8: ● Shipper/Exporter | F8: : Doosan Enerbility Co., LTD | P8: ● Shipper/Exporter | U8: : Doosan Enerbility Co., LTD
A9: Грузоотправитель/Экспортер | F9: 22, Doosan Volvo-ro, Sengsan-gu, Changwon, Gyeongnam, South Korea | P9: Грузоотправитель/Экспортер | U9: 22, Doosan Volvo-ro, Sengsan-gu, Changwon, Gyeongnam, South Korea
A11: ● Number of Invoice | F11: : | G11: =CI!V8 -> PGU-DE-0220 | P11: ● Number of Invoice | U11: : | V11: =CI!V8 -> PGU-DE-0220
A12: № инвойса | P12: № инвойса
A14: ● CARGO DESCRIPTION | F14: : | G14: ='Summary PL'!D19 -> DCS Cabinet | P14: ● CARGO DESCRIPTION | U14: : | V14: =G14 -> DCS Cabinet
A15: ОПИСАНИЕ ГРУЗА | P15: ОПИСАНИЕ ГРУЗА
A17: ● PACKAGE NO. | F17: : | G17: ='Summary PL'!C19 -> PGU-DE-0220-DCS-CBN-006 | P17: ● PACKAGE NO. | U17: : | V17: =G17 -> PGU-DE-0220-DCS-CBN-006
A18: УПАКОВОЧНЫЙ НОМЕР | P18: УПАКОВОЧНЫЙ НОМЕР
A20: ● NET WEIGHT | F20: : | G20: ='Summary PL'!L19 -> 1014 | H20: Kg | P20: ● NET WEIGHT | U20: : | V20: =G20 -> 1014 | W20: Kg
A21: ВЕС НЕТТО | P21: ВЕС НЕТТО
A23: ● GROSS WEIGHT | F23: : | G23: ='Summary PL'!M19 -> 1239 | H23: Kg | P23: ● GROSS WEIGHT | U23: : | V23: =G23 -> 1239 | W23: Kg
A24: ВЕС БРУТТО | P24: ВЕС БРУТТО
A26: ● CBM(m3) | F26: : | G26: ='Summary PL'!K14 -> 7.464 | H26: m3 | P26: ● CBM(m3) | U26: : | V26: =G26 -> 7.464 | W26: m3
A27: РАЗМЕРЫ | P27: РАЗМЕРЫ
A29: ● FINAL DESTINATION | F29: : | G29: Turkestan Oblast, Sairam district, Karamurt rural district, quarter 171, Republic of Kazakhstan | P29: ● FINAL DESTINATION | U29: : | V29: =G29 -> Turkestan Oblast, Sairam district, Karamurt rural district, quarter 171, Republic of Kazakhstan
A30: КОНЕЧНЫЙ ПУНКТ НАЗНАЧЕНИЯ | P30: КОНЕЧНЫЙ ПУНКТ НАЗНАЧЕНИЯ
E31: Doosan Enerbility | T31: Doosan Enerbility

Sheet PGU-DE-0220-DCS-CBN-007
A1: SHIPPING MARK ГРУЗОВАЯ МАРКИРОВКА | P1: SHIPPING MARK ГРУЗОВАЯ МАРКИРОВКА
A2: ● NAME OF THE PROJECT | F2: : | G2: Construction of a 1000 MW CCGT Power Plant in the Sairam District of the | P2: ● NAME OF THE PROJECT | U2: : | V2: Construction of a 1000 MW CCGT Power Plant in the Sairam District of the
A3: НАЗВАНИЕ ПРОЕКТА | G3: Turkistan Region, Main Site. Without External Engineering Networks | P3: НАЗВАНИЕ ПРОЕКТА | V3: Turkistan Region, Main Site. Without External Engineering Networks
A5: ● CONSIGNEE | F5: : | G5: =CI!B13 -> Branch of JSC "Doosan Enerbility" in the Turkestan region | P5: ● CONSIGNEE | U5: : | V5: =G5 -> Branch of JSC "Doosan Enerbility" in the Turkestan region
A6: ГРУЗОПОЛУЧАТЕЛЬ | P6: ГРУЗОПОЛУЧАТЕЛЬ
A8: ● Shipper/Exporter | F8: : Doosan Enerbility Co., LTD | P8: ● Shipper/Exporter | U8: : Doosan Enerbility Co., LTD
A9: Грузоотправитель/Экспортер | F9: 22, Doosan Volvo-ro, Sengsan-gu, Changwon, Gyeongnam, South Korea | P9: Грузоотправитель/Экспортер | U9: 22, Doosan Volvo-ro, Sengsan-gu, Changwon, Gyeongnam, South Korea
A11: ● Number of Invoice | F11: : | G11: =CI!V8 -> PGU-DE-0220 | P11: ● Number of Invoice | U11: : | V11: =CI!V8 -> PGU-DE-0220
A12: № инвойса | P12: № инвойса
A14: ● CARGO DESCRIPTION | F14: : | G14: ='Summary PL'!D20 -> DCS Cabinet | P14: ● CARGO DESCRIPTION | U14: : | V14: =G14 -> DCS Cabinet
A15: ОПИСАНИЕ ГРУЗА | P15: ОПИСАНИЕ ГРУЗА
A17: ● PACKAGE NO. | F17: : | G17: ='Summary PL'!C20 -> PGU-DE-0220-DCS-CBN-007 | P17: ● PACKAGE NO. | U17: : | V17: =G17 -> PGU-DE-0220-DCS-CBN-007
A18: УПАКОВОЧНЫЙ НОМЕР | P18: УПАКОВОЧНЫЙ НОМЕР
A20: ● NET WEIGHT | F20: : | G20: ='Summary PL'!L20 -> 1015 | H20: Kg | P20: ● NET WEIGHT | U20: : | V20: =G20 -> 1015 | W20: Kg
A21: ВЕС НЕТТО | P21: ВЕС НЕТТО
A23: ● GROSS WEIGHT | F23: : | G23: ='Summary PL'!M20 -> 1240 | H23: Kg | P23: ● GROSS WEIGHT | U23: : | V23: =G23 -> 1240 | W23: Kg
A24: ВЕС БРУТТО | P24: ВЕС БРУТТО
A26: ● CBM(m3) | F26: : | G26: ='Summary PL'!K14 -> 7.464 | H26: m3 | P26: ● CBM(m3) | U26: : | V26: =G26 -> 7.464 | W26: m3
A27: РАЗМЕРЫ | P27: РАЗМЕРЫ
A29: ● FINAL DESTINATION | F29: : | G29: Turkestan Oblast, Sairam district, Karamurt rural district, quarter 171, Republic of Kazakhstan | P29: ● FINAL DESTINATION | U29: : | V29: =G29 -> Turkestan Oblast, Sairam district, Karamurt rural district, quarter 171, Republic of Kazakhstan
A30: КОНЕЧНЫЙ ПУНКТ НАЗНАЧЕНИЯ | P30: КОНЕЧНЫЙ ПУНКТ НАЗНАЧЕНИЯ
E31: Doosan Enerbility | T31: Doosan Enerbility

Sheet PGU-DE-0220-DCS-CBN-008
A1: SHIPPING MARK ГРУЗОВАЯ МАРКИРОВКА | P1: SHIPPING MARK ГРУЗОВАЯ МАРКИРОВКА
A2: ● NAME OF THE PROJECT | F2: : | G2: Construction of a 1000 MW CCGT Power Plant in the Sairam District of the | P2: ● NAME OF THE PROJECT | U2: : | V2: Construction of a 1000 MW CCGT Power Plant in the Sairam District of the
A3: НАЗВАНИЕ ПРОЕКТА | G3: Turkistan Region, Main Site. Without External Engineering Networks | P3: НАЗВАНИЕ ПРОЕКТА | V3: Turkistan Region, Main Site. Without External Engineering Networks
A5: ● CONSIGNEE | F5: : | G5: =CI!B13 -> Branch of JSC "Doosan Enerbility" in the Turkestan region | P5: ● CONSIGNEE | U5: : | V5: =G5 -> Branch of JSC "Doosan Enerbility" in the Turkestan region
A6: ГРУЗОПОЛУЧАТЕЛЬ | P6: ГРУЗОПОЛУЧАТЕЛЬ
A8: ● Shipper/Exporter | F8: : Doosan Enerbility Co., LTD | P8: ● Shipper/Exporter | U8: : Doosan Enerbility Co., LTD
A9: Грузоотправитель/Экспортер | F9: 22, Doosan Volvo-ro, Sengsan-gu, Changwon, Gyeongnam, South Korea | P9: Грузоотправитель/Экспортер | U9: 22, Doosan Volvo-ro, Sengsan-gu, Changwon, Gyeongnam, South Korea
A11: ● Number of Invoice | F11: : | G11: =CI!V8 -> PGU-DE-0220 | P11: ● Number of Invoice | U11: : | V11: =CI!V8 -> PGU-DE-0220
A12: № инвойса | P12: № инвойса
A14: ● CARGO DESCRIPTION | F14: : | G14: ='Summary PL'!D21 -> DCS Cabinet | P14: ● CARGO DESCRIPTION | U14: : | V14: =G14 -> DCS Cabinet
A15: ОПИСАНИЕ ГРУЗА | P15: ОПИСАНИЕ ГРУЗА
A17: ● PACKAGE NO. | F17: : | G17: ='Summary PL'!C21 -> PGU-DE-0220-DCS-CBN-008 | P17: ● PACKAGE NO. | U17: : | V17: =G17 -> PGU-DE-0220-DCS-CBN-008
A18: УПАКОВОЧНЫЙ НОМЕР | P18: УПАКОВОЧНЫЙ НОМЕР
A20: ● NET WEIGHT | F20: : | G20: ='Summary PL'!L21 -> 990 | H20: Kg | P20: ● NET WEIGHT | U20: : | V20: =G20 -> 990 | W20: Kg
A21: ВЕС НЕТТО | P21: ВЕС НЕТТО
A23: ● GROSS WEIGHT | F23: : | G23: ='Summary PL'!M21 -> 1215 | H23: Kg | P23: ● GROSS WEIGHT | U23: : | V23: =G23 -> 1215 | W23: Kg
A24: ВЕС БРУТТО | P24: ВЕС БРУТТО
A26: ● CBM(m3) | F26: : | G26: ='Summary PL'!K14 -> 7.464 | H26: m3 | P26: ● CBM(m3) | U26: : | V26: =G26 -> 7.464 | W26: m3
A27: РАЗМЕРЫ | P27: РАЗМЕРЫ
A29: ● FINAL DESTINATION | F29: : | G29: Turkestan Oblast, Sairam district, Karamurt rural district, quarter 171, Republic of Kazakhstan | P29: ● FINAL DESTINATION | U29: : | V29: =G29 -> Turkestan Oblast, Sairam district, Karamurt rural district, quarter 171, Republic of Kazakhstan
A30: КОНЕЧНЫЙ ПУНКТ НАЗНАЧЕНИЯ | P30: КОНЕЧНЫЙ ПУНКТ НАЗНАЧЕНИЯ
E31: Doosan Enerbility | T31: Doosan Enerbility

Sheet PGU-DE-0220-DCS-CBN-009
A1: SHIPPING MARK ГРУЗОВАЯ МАРКИРОВКА | P1: SHIPPING MARK ГРУЗОВАЯ МАРКИРОВКА
A2: ● NAME OF THE PROJECT | F2: : | G2: Construction of a 1000 MW CCGT Power Plant in the Sairam District of the | P2: ● NAME OF THE PROJECT | U2: : | V2: Construction of a 1000 MW CCGT Power Plant in the Sairam District of the
A3: НАЗВАНИЕ ПРОЕКТА | G3: Turkistan Region, Main Site. Without External Engineering Networks | P3: НАЗВАНИЕ ПРОЕКТА | V3: Turkistan Region, Main Site. Without External Engineering Networks
A5: ● CONSIGNEE | F5: : | G5: =CI!B13 -> Branch of JSC "Doosan Enerbility" in the Turkestan region | P5: ● CONSIGNEE | U5: : | V5: =G5 -> Branch of JSC "Doosan Enerbility" in the Turkestan region
A6: ГРУЗОПОЛУЧАТЕЛЬ | P6: ГРУЗОПОЛУЧАТЕЛЬ
A8: ● Shipper/Exporter | F8: : Doosan Enerbility Co., LTD | P8: ● Shipper/Exporter | U8: : Doosan Enerbility Co., LTD
A9: Грузоотправитель/Экспортер | F9: 22, Doosan Volvo-ro, Sengsan-gu, Changwon, Gyeongnam, South Korea | P9: Грузоотправитель/Экспортер | U9: 22, Doosan Volvo-ro, Sengsan-gu, Changwon, Gyeongnam, South Korea
A11: ● Number of Invoice | F11: : | G11: =CI!V8 -> PGU-DE-0220 | P11: ● Number of Invoice | U11: : | V11: =CI!V8 -> PGU-DE-0220
A12: № инвойса | P12: № инвойса
A14: ● CARGO DESCRIPTION | F14: : | G14: ='Summary PL'!D22 -> DCS Cabinet | P14: ● CARGO DESCRIPTION | U14: : | V14: =G14 -> DCS Cabinet
A15: ОПИСАНИЕ ГРУЗА | P15: ОПИСАНИЕ ГРУЗА
A17: ● PACKAGE NO. | F17: : | G17: ='Summary PL'!C22 -> PGU-DE-0220-DCS-CBN-009 | P17: ● PACKAGE NO. | U17: : | V17: =G17 -> PGU-DE-0220-DCS-CBN-009
A18: УПАКОВОЧНЫЙ НОМЕР | P18: УПАКОВОЧНЫЙ НОМЕР
A20: ● NET WEIGHT | F20: : | G20: ='Summary PL'!L22 -> 681 | H20: Kg | P20: ● NET WEIGHT | U20: : | V20: =G20 -> 681 | W20: Kg
A21: ВЕС НЕТТО | P21: ВЕС НЕТТО
A23: ● GROSS WEIGHT | F23: : | G23: ='Summary PL'!M22 -> 841 | H23: Kg | P23: ● GROSS WEIGHT | U23: : | V23: =G23 -> 841 | W23: Kg
A24: ВЕС БРУТТО | P24: ВЕС БРУТТО
A26: ● CBM(m3) | F26: : | G26: ='Summary PL'!K22 -> 5.155 | H26: m3 | P26: ● CBM(m3) | U26: : | V26: =G26 -> 5.155 | W26: m3
A27: РАЗМЕРЫ | P27: РАЗМЕРЫ
A29: ● FINAL DESTINATION | F29: : | G29: Turkestan Oblast, Sairam district, Karamurt rural district, quarter 171, Republic of Kazakhstan | P29: ● FINAL DESTINATION | U29: : | V29: =G29 -> Turkestan Oblast, Sairam district, Karamurt rural district, quarter 171, Republic of Kazakhstan
A30: КОНЕЧНЫЙ ПУНКТ НАЗНАЧЕНИЯ | P30: КОНЕЧНЫЙ ПУНКТ НАЗНАЧЕНИЯ
E31: Doosan Enerbility | T31: Doosan Enerbility

Sheet PGU-DE-0220-DCS-CBN-010
A1: SHIPPING MARK ГРУЗОВАЯ МАРКИРОВКА | P1: SHIPPING MARK ГРУЗОВАЯ МАРКИРОВКА
A2: ● NAME OF THE PROJECT | F2: : | G2: Construction of a 1000 MW CCGT Power Plant in the Sairam District of the | P2: ● NAME OF THE PROJECT | U2: : | V2: Construction of a 1000 MW CCGT Power Plant in the Sairam District of the
A3: НАЗВАНИЕ ПРОЕКТА | G3: Turkistan Region, Main Site. Without External Engineering Networks | P3: НАЗВАНИЕ ПРОЕКТА | V3: Turkistan Region, Main Site. Without External Engineering Networks
A5: ● CONSIGNEE | F5: : | G5: =CI!B13 -> Branch of JSC "Doosan Enerbility" in the Turkestan region | P5: ● CONSIGNEE | U5: : | V5: =G5 -> Branch of JSC "Doosan Enerbility" in the Turkestan region
A6: ГРУЗОПОЛУЧАТЕЛЬ | P6: ГРУЗОПОЛУЧАТЕЛЬ
A8: ● Shipper/Exporter | F8: : Doosan Enerbility Co., LTD | P8: ● Shipper/Exporter | U8: : Doosan Enerbility Co., LTD
A9: Грузоотправитель/Экспортер | F9: 22, Doosan Volvo-ro, Sengsan-gu, Changwon, Gyeongnam, South Korea | P9: Грузоотправитель/Экспортер | U9: 22, Doosan Volvo-ro, Sengsan-gu, Changwon, Gyeongnam, South Korea
A11: ● Number of Invoice | F11: : | G11: =CI!V8 -> PGU-DE-0220 | P11: ● Number of Invoice | U11: : | V11: =CI!V8 -> PGU-DE-0220
A12: № инвойса | P12: № инвойса
A14: ● CARGO DESCRIPTION | F14: : | G14: ='Summary PL'!D23 -> DCS Cabinet | P14: ● CARGO DESCRIPTION | U14: : | V14: =G14 -> DCS Cabinet
A15: ОПИСАНИЕ ГРУЗА | P15: ОПИСАНИЕ ГРУЗА
A17: ● PACKAGE NO. | F17: : | G17: ='Summary PL'!C23 -> PGU-DE-0220-DCS-CBN-010 | P17: ● PACKAGE NO. | U17: : | V17: =G17 -> PGU-DE-0220-DCS-CBN-010
A18: УПАКОВОЧНЫЙ НОМЕР | P18: УПАКОВОЧНЫЙ НОМЕР
A20: ● NET WEIGHT | F20: : | G20: ='Summary PL'!L23 -> 675 | H20: Kg | P20: ● NET WEIGHT | U20: : | V20: =G20 -> 675 | W20: Kg
A21: ВЕС НЕТТО | P21: ВЕС НЕТТО
A23: ● GROSS WEIGHT | F23: : | G23: ='Summary PL'!M23 -> 835 | H23: Kg | P23: ● GROSS WEIGHT | U23: : | V23: =G23 -> 835 | W23: Kg
A24: ВЕС БРУТТО | P24: ВЕС БРУТТО
A26: ● CBM(m3) | F26: : | G26: ='Summary PL'!K22 -> 5.155 | H26: m3 | P26: ● CBM(m3) | U26: : | V26: =G26 -> 5.155 | W26: m3
A27: РАЗМЕРЫ | P27: РАЗМЕРЫ
A29: ● FINAL DESTINATION | F29: : | G29: Turkestan Oblast, Sairam district, Karamurt rural district, quarter 171, Republic of Kazakhstan | P29: ● FINAL DESTINATION | U29: : | V29: =G29 -> Turkestan Oblast, Sairam district, Karamurt rural district, quarter 171, Republic of Kazakhstan
A30: КОНЕЧНЫЙ ПУНКТ НАЗНАЧЕНИЯ | P30: КОНЕЧНЫЙ ПУНКТ НАЗНАЧЕНИЯ
E31: Doosan Enerbility | T31: Doosan Enerbility

Sheet PGU-DE-0220-DCS-CBN-011
A1: SHIPPING MARK ГРУЗОВАЯ МАРКИРОВКА | P1: SHIPPING MARK ГРУЗОВАЯ МАРКИРОВКА
A2: ● NAME OF THE PROJECT | F2: : | G2: Construction of a 1000 MW CCGT Power Plant in the Sairam District of the | P2: ● NAME OF THE PROJECT | U2: : | V2: Construction of a 1000 MW CCGT Power Plant in the Sairam District of the
A3: НАЗВАНИЕ ПРОЕКТА | G3: Turkistan Region, Main Site. Without External Engineering Networks | P3: НАЗВАНИЕ ПРОЕКТА | V3: Turkistan Region, Main Site. Without External Engineering Networks
A5: ● CONSIGNEE | F5: : | G5: =CI!B13 -> Branch of JSC "Doosan Enerbility" in the Turkestan region | P5: ● CONSIGNEE | U5: : | V5: =G5 -> Branch of JSC "Doosan Enerbility" in the Turkestan region
A6: ГРУЗОПОЛУЧАТЕЛЬ | P6: ГРУЗОПОЛУЧАТЕЛЬ
A8: ● Shipper/Exporter | F8: : Doosan Enerbility Co., LTD | P8: ● Shipper/Exporter | U8: : Doosan Enerbility Co., LTD
A9: Грузоотправитель/Экспортер | F9: 22, Doosan Volvo-ro, Sengsan-gu, Changwon, Gyeongnam, South Korea | P9: Грузоотправитель/Экспортер | U9: 22, Doosan Volvo-ro, Sengsan-gu, Changwon, Gyeongnam, South Korea
A11: ● Number of Invoice | F11: : | G11: =CI!V8 -> PGU-DE-0220 | P11: ● Number of Invoice | U11: : | V11: =CI!V8 -> PGU-DE-0220
A12: № инвойса | P12: № инвойса
A14: ● CARGO DESCRIPTION | F14: : | G14: ='Summary PL'!D24 -> DCS Cabinet | P14: ● CARGO DESCRIPTION | U14: : | V14: =G14 -> DCS Cabinet
A15: ОПИСАНИЕ ГРУЗА | P15: ОПИСАНИЕ ГРУЗА
A17: ● PACKAGE NO. | F17: : | G17: ='Summary PL'!C24 -> PGU-DE-0220-DCS-CBN-011 | P17: ● PACKAGE NO. | U17: : | V17: =G17 -> PGU-DE-0220-DCS-CBN-011
A18: УПАКОВОЧНЫЙ НОМЕР | P18: УПАКОВОЧНЫЙ НОМЕР
A20: ● NET WEIGHT | F20: : | G20: ='Summary PL'!L24 -> 707 | H20: Kg | P20: ● NET WEIGHT | U20: : | V20: =G20 -> 707 | W20: Kg
A21: ВЕС НЕТТО | P21: ВЕС НЕТТО
A23: ● GROSS WEIGHT | F23: : | G23: ='Summary PL'!M24 -> 867 | H23: Kg | P23: ● GROSS WEIGHT | U23: : | V23: =G23 -> 867 | W23: Kg
A24: ВЕС БРУТТО | P24: ВЕС БРУТТО
A26: ● CBM(m3) | F26: : | G26: ='Summary PL'!K22 -> 5.155 | H26: m3 | P26: ● CBM(m3) | U26: : | V26: =G26 -> 5.155 | W26: m3
A27: РАЗМЕРЫ | P27: РАЗМЕРЫ
A29: ● FINAL DESTINATION | F29: : | G29: Turkestan Oblast, Sairam district, Karamurt rural district, quarter 171, Republic of Kazakhstan | P29: ● FINAL DESTINATION | U29: : | V29: =G29 -> Turkestan Oblast, Sairam district, Karamurt rural district, quarter 171, Republic of Kazakhstan
A30: КОНЕЧНЫЙ ПУНКТ НАЗНАЧЕНИЯ | P30: КОНЕЧНЫЙ ПУНКТ НАЗНАЧЕНИЯ
E31: Doosan Enerbility | T31: Doosan Enerbility

Sheet PGU-DE-0220-DCS-CBN-012
A1: SHIPPING MARK ГРУЗОВАЯ МАРКИРОВКА | P1: SHIPPING MARK ГРУЗОВАЯ МАРКИРОВКА
A2: ● NAME OF THE PROJECT | F2: : | G2: Construction of a 1000 MW CCGT Power Plant in the Sairam District of the | P2: ● NAME OF THE PROJECT | U2: : | V2: Construction of a 1000 MW CCGT Power Plant in the Sairam District of the
A3: НАЗВАНИЕ ПРОЕКТА | G3: Turkistan Region, Main Site. Without External Engineering Networks | P3: НАЗВАНИЕ ПРОЕКТА | V3: Turkistan Region, Main Site. Without External Engineering Networks
A5: ● CONSIGNEE | F5: : | G5: =CI!B13 -> Branch of JSC "Doosan Enerbility" in the Turkestan region | P5: ● CONSIGNEE | U5: : | V5: =G5 -> Branch of JSC "Doosan Enerbility" in the Turkestan region
A6: ГРУЗОПОЛУЧАТЕЛЬ | P6: ГРУЗОПОЛУЧАТЕЛЬ
A8: ● Shipper/Exporter | F8: : Doosan Enerbility Co., LTD | P8: ● Shipper/Exporter | U8: : Doosan Enerbility Co., LTD
A9: Грузоотправитель/Экспортер | F9: 22, Doosan Volvo-ro, Sengsan-gu, Changwon, Gyeongnam, South Korea | P9: Грузоотправитель/Экспортер | U9: 22, Doosan Volvo-ro, Sengsan-gu, Changwon, Gyeongnam, South Korea
A11: ● Number of Invoice | F11: : | G11: =CI!V8 -> PGU-DE-0220 | P11: ● Number of Invoice | U11: : | V11: =CI!V8 -> PGU-DE-0220
A12: № инвойса | P12: № инвойса
A14: ● CARGO DESCRIPTION | F14: : | G14: ='Summary PL'!D25 -> DCS Cabinet | P14: ● CARGO DESCRIPTION | U14: : | V14: =G14 -> DCS Cabinet
A15: ОПИСАНИЕ ГРУЗА | P15: ОПИСАНИЕ ГРУЗА
A17: ● PACKAGE NO. | F17: : | G17: ='Summary PL'!C25 -> PGU-DE-0220-DCS-CBN-012 | P17: ● PACKAGE NO. | U17: : | V17: =G17 -> PGU-DE-0220-DCS-CBN-012
A18: УПАКОВОЧНЫЙ НОМЕР | P18: УПАКОВОЧНЫЙ НОМЕР
A20: ● NET WEIGHT | F20: : | G20: ='Summary PL'!L25 -> 687 | H20: Kg | P20: ● NET WEIGHT | U20: : | V20: =G20 -> 687 | W20: Kg
A21: ВЕС НЕТТО | P21: ВЕС НЕТТО
A23: ● GROSS WEIGHT | F23: : | G23: ='Summary PL'!M25 -> 847 | H23: Kg | P23: ● GROSS WEIGHT | U23: : | V23: =G23 -> 847 | W23: Kg
A24: ВЕС БРУТТО | P24: ВЕС БРУТТО
A26: ● CBM(m3) | F26: : | G26: ='Summary PL'!K22 -> 5.155 | H26: m3 | P26: ● CBM(m3) | U26: : | V26: =G26 -> 5.155 | W26: m3
A27: РАЗМЕРЫ | P27: РАЗМЕРЫ
A29: ● FINAL DESTINATION | F29: : | G29: Turkestan Oblast, Sairam district, Karamurt rural district, quarter 171, Republic of Kazakhstan | P29: ● FINAL DESTINATION | U29: : | V29: =G29 -> Turkestan Oblast, Sairam district, Karamurt rural district, quarter 171, Republic of Kazakhstan
A30: КОНЕЧНЫЙ ПУНКТ НАЗНАЧЕНИЯ | P30: КОНЕЧНЫЙ ПУНКТ НАЗНАЧЕНИЯ
E31: Doosan Enerbility | T31: Doosan Enerbility

Sheet PGU-DE-0220-DCS-CBN-013
A1: SHIPPING MARK ГРУЗОВАЯ МАРКИРОВКА | P1: SHIPPING MARK ГРУЗОВАЯ МАРКИРОВКА
A2: ● NAME OF THE PROJECT | F2: : | G2: Construction of a 1000 MW CCGT Power Plant in the Sairam District of the | P2: ● NAME OF THE PROJECT | U2: : | V2: Construction of a 1000 MW CCGT Power Plant in the Sairam District of the
A3: НАЗВАНИЕ ПРОЕКТА | G3: Turkistan Region, Main Site. Without External Engineering Networks | P3: НАЗВАНИЕ ПРОЕКТА | V3: Turkistan Region, Main Site. Without External Engineering Networks
A5: ● CONSIGNEE | F5: : | G5: =CI!B13 -> Branch of JSC "Doosan Enerbility" in the Turkestan region | P5: ● CONSIGNEE | U5: : | V5: =G5 -> Branch of JSC "Doosan Enerbility" in the Turkestan region
A6: ГРУЗОПОЛУЧАТЕЛЬ | P6: ГРУЗОПОЛУЧАТЕЛЬ
A8: ● Shipper/Exporter | F8: : Doosan Enerbility Co., LTD | P8: ● Shipper/Exporter | U8: : Doosan Enerbility Co., LTD
A9: Грузоотправитель/Экспортер | F9: 22, Doosan Volvo-ro, Sengsan-gu, Changwon, Gyeongnam, South Korea | P9: Грузоотправитель/Экспортер | U9: 22, Doosan Volvo-ro, Sengsan-gu, Changwon, Gyeongnam, South Korea
A11: ● Number of Invoice | F11: : | G11: =CI!V8 -> PGU-DE-0220 | P11: ● Number of Invoice | U11: : | V11: =CI!V8 -> PGU-DE-0220
A12: № инвойса | P12: № инвойса
A14: ● CARGO DESCRIPTION | F14: : | G14: ='Summary PL'!D26 -> Power Distribution Cabinet | P14: ● CARGO DESCRIPTION | U14: : | V14: =G14 -> Power Distribution Cabinet
A15: ОПИСАНИЕ ГРУЗА | P15: ОПИСАНИЕ ГРУЗА
A17: ● PACKAGE NO. | F17: : | G17: ='Summary PL'!C26 -> PGU-DE-0220-DCS-CBN-013 | P17: ● PACKAGE NO. | U17: : | V17: =G17 -> PGU-DE-0220-DCS-CBN-013
A18: УПАКОВОЧНЫЙ НОМЕР | P18: УПАКОВОЧНЫЙ НОМЕР
A20: ● NET WEIGHT | F20: : | G20: ='Summary PL'!L26 -> 300 | H20: Kg | P20: ● NET WEIGHT | U20: : | V20: =G20 -> 300 | W20: Kg
A21: ВЕС НЕТТО | P21: ВЕС НЕТТО
A23: ● GROSS WEIGHT | F23: : | G23: ='Summary PL'!M26 -> 370 | H23: Kg | P23: ● GROSS WEIGHT | U23: : | V23: =G23 -> 370 | W23: Kg
A24: ВЕС БРУТТО | P24: ВЕС БРУТТО
A26: ● CBM(m3) | F26: : | G26: ='Summary PL'!K26 -> 2.332 | H26: m3 | P26: ● CBM(m3) | U26: : | V26: =G26 -> 2.332 | W26: m3
A27: РАЗМЕРЫ | P27: РАЗМЕРЫ
A29: ● FINAL DESTINATION | F29: : | G29: Turkestan Oblast, Sairam district, Karamurt rural district, quarter 171, Republic of Kazakhstan | P29: ● FINAL DESTINATION | U29: : | V29: =G29 -> Turkestan Oblast, Sairam district, Karamurt rural district, quarter 171, Republic of Kazakhstan
A30: КОНЕЧНЫЙ ПУНКТ НАЗНАЧЕНИЯ | P30: КОНЕЧНЫЙ ПУНКТ НАЗНАЧЕНИЯ
E31: Doosan Enerbility | T31: Doosan Enerbility

Sheet PGU-DE-0220-DCS-CBN-014
A1: SHIPPING MARK ГРУЗОВАЯ МАРКИРОВКА | P1: SHIPPING MARK ГРУЗОВАЯ МАРКИРОВКА
A2: ● NAME OF THE PROJECT | F2: : | G2: Construction of a 1000 MW CCGT Power Plant in the Sairam District of the | P2: ● NAME OF THE PROJECT | U2: : | V2: Construction of a 1000 MW CCGT Power Plant in the Sairam District of the
A3: НАЗВАНИЕ ПРОЕКТА | G3: Turkistan Region, Main Site. Without External Engineering Networks | P3: НАЗВАНИЕ ПРОЕКТА | V3: Turkistan Region, Main Site. Without External Engineering Networks
A5: ● CONSIGNEE | F5: : | G5: =CI!B13 -> Branch of JSC "Doosan Enerbility" in the Turkestan region | P5: ● CONSIGNEE | U5: : | V5: =G5 -> Branch of JSC "Doosan Enerbility" in the Turkestan region
A6: ГРУЗОПОЛУЧАТЕЛЬ | P6: ГРУЗОПОЛУЧАТЕЛЬ
A8: ● Shipper/Exporter | F8: : Doosan Enerbility Co., LTD | P8: ● Shipper/Exporter | U8: : Doosan Enerbility Co., LTD
A9: Грузоотправитель/Экспортер | F9: 22, Doosan Volvo-ro, Sengsan-gu, Changwon, Gyeongnam, South Korea | P9: Грузоотправитель/Экспортер | U9: 22, Doosan Volvo-ro, Sengsan-gu, Changwon, Gyeongnam, South Korea
A11: ● Number of Invoice | F11: : | G11: =CI!V8 -> PGU-DE-0220 | P11: ● Number of Invoice | U11: : | V11: =CI!V8 -> PGU-DE-0220
A12: № инвойса | P12: № инвойса
A14: ● CARGO DESCRIPTION | F14: : | G14: ='Summary PL'!D27 -> Power Distribution Cabinet | P14: ● CARGO DESCRIPTION | U14: : | V14: =G14 -> Power Distribution Cabinet
A15: ОПИСАНИЕ ГРУЗА | P15: ОПИСАНИЕ ГРУЗА
A17: ● PACKAGE NO. | F17: : | G17: ='Summary PL'!C27 -> PGU-DE-0220-DCS-CBN-014 | P17: ● PACKAGE NO. | U17: : | V17: =G17 -> PGU-DE-0220-DCS-CBN-014
A18: УПАКОВОЧНЫЙ НОМЕР | P18: УПАКОВОЧНЫЙ НОМЕР
A20: ● NET WEIGHT | F20: : | G20: ='Summary PL'!L27 -> 297 | H20: Kg | P20: ● NET WEIGHT | U20: : | V20: =G20 -> 297 | W20: Kg
A21: ВЕС НЕТТО | P21: ВЕС НЕТТО
A23: ● GROSS WEIGHT | F23: : | G23: ='Summary PL'!M27 -> 367 | H23: Kg | P23: ● GROSS WEIGHT | U23: : | V23: =G23 -> 367 | W23: Kg
A24: ВЕС БРУТТО | P24: ВЕС БРУТТО
A26: ● CBM(m3) | F26: : | G26: ='Summary PL'!K27 -> 2.332 | H26: m3 | P26: ● CBM(m3) | U26: : | V26: =G26 -> 2.332 | W26: m3
A27: РАЗМЕРЫ | P27: РАЗМЕРЫ
A29: ● FINAL DESTINATION | F29: : | G29: Turkestan Oblast, Sairam district, Karamurt rural district, quarter 171, Republic of Kazakhstan | P29: ● FINAL DESTINATION | U29: : | V29: =G29 -> Turkestan Oblast, Sairam district, Karamurt rural district, quarter 171, Republic of Kazakhstan
A30: КОНЕЧНЫЙ ПУНКТ НАЗНАЧЕНИЯ | P30: КОНЕЧНЫЙ ПУНКТ НАЗНАЧЕНИЯ
E31: Doosan Enerbility | T31: Doosan Enerbility

Sheet PGU-DE-0220-DCS-CBN-015
A1: SHIPPING MARK ГРУЗОВАЯ МАРКИРОВКА | P1: SHIPPING MARK ГРУЗОВАЯ МАРКИРОВКА
A2: ● NAME OF THE PROJECT | F2: : | G2: Construction of a 1000 MW CCGT Power Plant in the Sairam District of the | P2: ● NAME OF THE PROJECT | U2: : | V2: Construction of a 1000 MW CCGT Power Plant in the Sairam District of the
A3: НАЗВАНИЕ ПРОЕКТА | G3: Turkistan Region, Main Site. Without External Engineering Networks | P3: НАЗВАНИЕ ПРОЕКТА | V3: Turkistan Region, Main Site. Without External Engineering Networks
A5: ● CONSIGNEE | F5: : | G5: =CI!B13 -> Branch of JSC "Doosan Enerbility" in the Turkestan region | P5: ● CONSIGNEE | U5: : | V5: =G5 -> Branch of JSC "Doosan Enerbility" in the Turkestan region
A6: ГРУЗОПОЛУЧАТЕЛЬ | P6: ГРУЗОПОЛУЧАТЕЛЬ
A8: ● Shipper/Exporter | F8: : Doosan Enerbility Co., LTD | P8: ● Shipper/Exporter | U8: : Doosan Enerbility Co., LTD
A9: Грузоотправитель/Экспортер | F9: 22, Doosan Volvo-ro, Sengsan-gu, Changwon, Gyeongnam, South Korea | P9: Грузоотправитель/Экспортер | U9: 22, Doosan Volvo-ro, Sengsan-gu, Changwon, Gyeongnam, South Korea
A11: ● Number of Invoice | F11: : | G11: =CI!V8 -> PGU-DE-0220 | P11: ● Number of Invoice | U11: : | V11: =CI!V8 -> PGU-DE-0220
A12: № инвойса | P12: № инвойса
A14: ● CARGO DESCRIPTION | F14: : | G14: ='Summary PL'!D28 -> Power Distribution Cabinet | P14: ● CARGO DESCRIPTION | U14: : | V14: =G14 -> Power Distribution Cabinet
A15: ОПИСАНИЕ ГРУЗА | P15: ОПИСАНИЕ ГРУЗА
A17: ● PACKAGE NO. | F17: : | G17: ='Summary PL'!C28 -> PGU-DE-0220-DCS-CBN-015 | P17: ● PACKAGE NO. | U17: : | V17: =G17 -> PGU-DE-0220-DCS-CBN-015
A18: УПАКОВОЧНЫЙ НОМЕР | P18: УПАКОВОЧНЫЙ НОМЕР
A20: ● NET WEIGHT | F20: : | G20: ='Summary PL'!L28 -> 306 | H20: Kg | P20: ● NET WEIGHT | U20: : | V20: =G20 -> 306 | W20: Kg
A21: ВЕС НЕТТО | P21: ВЕС НЕТТО
A23: ● GROSS WEIGHT | F23: : | G23: ='Summary PL'!M28 -> 376 | H23: Kg | P23: ● GROSS WEIGHT | U23: : | V23: =G23 -> 376 | W23: Kg
A24: ВЕС БРУТТО | P24: ВЕС БРУТТО
A26: ● CBM(m3) | F26: : | G26: ='Summary PL'!K28 -> 2.332 | H26: m3 | P26: ● CBM(m3) | U26: : | V26: =G26 -> 2.332 | W26: m3
A27: РАЗМЕРЫ | P27: РАЗМЕРЫ
A29: ● FINAL DESTINATION | F29: : | G29: Turkestan Oblast, Sairam district, Karamurt rural district, quarter 171, Republic of Kazakhstan | P29: ● FINAL DESTINATION | U29: : | V29: =G29 -> Turkestan Oblast, Sairam district, Karamurt rural district, quarter 171, Republic of Kazakhstan
A30: КОНЕЧНЫЙ ПУНКТ НАЗНАЧЕНИЯ | P30: КОНЕЧНЫЙ ПУНКТ НАЗНАЧЕНИЯ
E31: Doosan Enerbility | T31: Doosan Enerbility

Sheet PGU-DE-0220-DCS-CBN-016
A1: SHIPPING MARK ГРУЗОВАЯ МАРКИРОВКА | P1: SHIPPING MARK ГРУЗОВАЯ МАРКИРОВКА
A2: ● NAME OF THE PROJECT | F2: : | G2: Construction of a 1000 MW CCGT Power Plant in the Sairam District of the | P2: ● NAME OF THE PROJECT | U2: : | V2: Construction of a 1000 MW CCGT Power Plant in the Sairam District of the
A3: НАЗВАНИЕ ПРОЕКТА | G3: Turkistan Region, Main Site. Without External Engineering Networks | P3: НАЗВАНИЕ ПРОЕКТА | V3: Turkistan Region, Main Site. Without External Engineering Networks
A5: ● CONSIGNEE | F5: : | G5: =CI!B13 -> Branch of JSC "Doosan Enerbility" in the Turkestan region | P5: ● CONSIGNEE | U5: : | V5: =G5 -> Branch of JSC "Doosan Enerbility" in the Turkestan region
A6: ГРУЗОПОЛУЧАТЕЛЬ | P6: ГРУЗОПОЛУЧАТЕЛЬ
A8: ● Shipper/Exporter | F8: : Doosan Enerbility Co., LTD | P8: ● Shipper/Exporter | U8: : Doosan Enerbility Co., LTD
A9: Грузоотправитель/Экспортер | F9: 22, Doosan Volvo-ro, Sengsan-gu, Changwon, Gyeongnam, South Korea | P9: Грузоотправитель/Экспортер | U9: 22, Doosan Volvo-ro, Sengsan-gu, Changwon, Gyeongnam, South Korea
