Workbook

Sheet CI
W1: HEAD OFFICE & CHANGWON PLANT
W2: 22, DoosanVolvo-ro, Seongsan-gu, Changwon-Si,
W3: Gyeongsangnam-do, Korea
W4: (P.O.BOX 77, Changwon, Korea)
W5: TEL:(055)278-6114,7114 FAX:(055)264-5551/2
A6: INVOICE ИНВОЙС
A8: 1. Shipper / Грузоотправитель | R8: 11. Invoice № : | V8: PGU-DE-0149
B9: Doosan Enerbility Co., Ltd (DOOSAN) | R9: Инвойс №
B10: 22, DoosanVolvo-ro, Seongsan-gu, Changwon-si, | R10: 12. Date : | V10: =TODAY() -> 46202
B11: Gyeongsangnam-do, Republic of Korea | R11: Дата
A12: 2. Consignee / Грузополучатель | R12: 13. Remarks / Примечания
B13: Branch of JSC "Doosan Enerbility" in the Turkestan region
B14: 321 Tauke Khan Avenue, Turkestan region, Turkestan, Kazakhstan, 161200 | S14: *Project Name / Название Проекта
B15: BIN: 230741006561 | S15: Construction of a 1000 MW CCGT Power Plant in the Sairam District of the Turkistan Region, Main Site. Without External Engineering Networks
S17: *MANUFACTURER'S NAME / НАЗВАНИЕ ПРОИЗВОДИТЕЛЯ
S18: Doosan Škoda Power a.s. (Profess)
A19: 3. Notify party / Уведомляемая сторона | S19: *MANUFACTURE YEAR / ГОД ИЗГОТОВЛЕНИЯ
B20: Wise Logistics | S20: 2024
B21: ATTAN: MS. Aliya | S21: *COUNTRY OF ORIGIN / СТРАНА ПРОИСХОЖДЕНИЯ
B22: (E): a.kipshakbayeva@wiselogistics.kz | S22: Czech Republic
B23: (T): +7 701 512 19 69 | S23: *INCOTERMS / УСЛОВИЯ ПОСТАВКИ СОГЛАСНО ИНКОТЕРМС
S24: DDP Turkistan
A26: 4. Port of Loading / Порт погрузки | I26: 5. Carrier / Перевозчик | R26: 14. Mark and Numbers of PKGS / Маркировка и количество упаковок
B27: Hamburg, Germany | J27: Later
S28: PKG No. | X28: : | Y28: PGU-DE-0149-STG-MMS-001, 002
A29: 6. Port of Unloading / Порт разгрузки | I29: 7. Final Destination / Конечный пункт назначения | S29: Q-ty of Package | X29: : | Y29: =COUNT('Summary PL'!A14:A15) -> 2 | AB29: PKGS
S30: Net Weight (kg) | X30: : | Y30: ='Summary PL'!L16 -> 367 | AB30: KG
B31: Later | I31: Turkestan Oblast, Sairam district, Karamurt rural district, quarter 171 | S31: Gross Weight (kg) | X31: : | Y31: ='Summary PL'!M16 -> 607 | AB31: KG
S32: Dimension (m3) | X32: : | Y32: ='Summary PL'!K16 -> 3.692988 | AB32: m3
A33: 8. Voyage No / Рейс № | I33: 9. Sailing on or about / Дата или ожидаемая дата
B35: Later | J35: Later
A37: 10. Customs Place / Место таможенного оформления
B38: Turkestan Oblast, Sairam district, Karamurt rural district, quarter 171
A40: 15. Description of Goods / Описание товара | R40: 16. HS CODE / | W40: 17. Quantity / | AA40: 18. Total Price (USD)
R41: Код ТН ВЭД | W41: Количество | AA41: Общая сумма (Дол. США)
A42: =+PL!A42 -> STG_VMS Unit 1 | W42: 1 SET | AC42: =CI_BD!I11 -> 179358.86
I47: Total (DDP Value) | AA47: =AC42 -> 179358.86
S55: Signed by
A56: Doosan Enerbility Co., Ltd
A57: 155, Jeongjail-ro, Bundang-gu, Seongnam-si, Gyeonggi-do, Korea
...

Sheet CI_BD
J1: HEAD OFFICE & CHANGWON PLANT
J2: 22, DoosanVolvo-ro, Seongsan-gu, Changwon-Si,
J3: Gyeongsangnam-do, Korea
J4: (P.O.BOX 77, Changwon, Korea)
J5: TEL:(055)278-6114,7114 FAX:(055)264-5551/2
A6: PROFORMA INVOICE (Break-down) ПРОФОРМА-ИНВОЙС (Разбивка)
A7: Invoice № : | B7: =CI!V8 -> PGU-DE-0149
A8: № | B8: № Package | C8: Description of Goods Specification | D8: Material | E8: HS CODE | F8: Quantity | G8: Unit | H8: U/Price (USD) | I8: Amount (USD) | J8: Country of Origin | K8: Remark
A9: 1 | B9: PGU-DE-0149-STG-MMS-001 | C9: VMS - System Cabinet | F9: 1 | G9: EA / ШТ. | H9: 97743.24 | I9: =H9*F9 -> 97743.24
A10: 2 | B10: PGU-DE-0149-STG-MMS-002 | C10: VMS - Accessories | F10: 1 | G10: EA / ШТ. | H10: 81615.62 | I10: =H10*F10 -> 81615.62
C11: TOTAL | I11: =SUM(I9:I10) -> 179358.86

Sheet PL
W1: HEAD OFFICE & CHANGWON PLANT
W2: 22, DoosanVolvo-ro, Seongsan-gu, Changwon-Si,
W3: Gyeongsangnam-do, Korea
W4: (P.O.BOX 77, Changwon, Korea)
W5: TEL:(055)278-6114,7114 FAX:(055)264-5551/2
A6: PACKING LIST УПАКОВОЧНЫЙ ЛИСТ
A8: 1. Shipper / Грузоотправитель | R8: 11. Invoice № : | V8: =CI!V8 -> PGU-DE-0149
B9: Doosan Enerbility Co., Ltd (DOOSAN) | R9: Инвойс №
B10: 22, DoosanVolvo-ro, Seongsan-gu, Changwon-si, | R10: 12. Date : | V10: =CI!V10 -> 46202
B11: Gyeongsangnam-do, Republic of Korea | R11: Дата
A12: 2. Consignee / Грузополучатель | R12: 13. Remarks / Примечания
B13: Branch of JSC "Doosan Enerbility" in the Turkestan region
B14: 321 Tauke Khan Avenue, Turkestan region, Turkestan, Kazakhstan, 161200 | S14: *Project Name / Название Проекта
B15: BIN: 230741006561 | S15: Construction of a 1000 MW CCGT Power Plant in the Sairam District of the Turkistan Region, Main Site. Without External Engineering Networks
S17: *MANUFACTURER'S NAME / НАЗВАНИЕ ПРОИЗВОДИТЕЛЯ
S18: Doosan Škoda Power a.s. (Profess)
A19: 3. Notify party / Уведомляемая сторона | S19: *MANUFACTURE YEAR / ГОД ИЗГОТОВЛЕНИЯ
B20: =CI!B20 -> Wise Logistics | S20: 2024
B21: =CI!B21 -> ATTAN: MS. Aliya | S21: *COUNTRY OF ORIGIN / СТРАНА ПРОИСХОЖДЕНИЯ
B22: =CI!B22 -> (E): a.kipshakbayeva@wiselogistics.kz | S22: Czech Republic
B23: =CI!B23 -> (T): +7 701 512 19 69 | S23: *INCOTERMS / УСЛОВИЯ ПОСТАВКИ СОГЛАСНО ИНКОТЕРМС
S24: DDP Turkistan
A26: 4. Port of Loading / Порт погрузки | I26: 5. Carrier / Перевозчик | R26: 14. Mark and Numbers of PKGS / Маркировка и количество упаковок
B27: Hamburg, Germany | J27: Later
S28: PKG No. | X28: : | Y28: =CI!Y28 -> PGU-DE-0149-STG-MMS-001, 002
A29: 6. Port of Unloading / Порт разгрузки | I29: 7. Final Destination / Конечный пункт назначения | S29: Q-ty of Package | X29: : | Y29: =COUNT('Summary PL'!A14:A15) -> 2 | AC29: PKGS
S30: Net Weight (kg) | X30: : | Y30: =U46 -> 367 | AC30: KG
B31: Later | I31: Turkestan Oblast, Sairam district, Karamurt rural district, quarter 171 | S31: Gross Weight (kg) | X31: : | Y31: =Y46 -> 607 | AC31: KG
S32: Dimension (m3) | X32: : | Y32: =AC46 -> 3.692988 | AC32: m3
A33: 8. Voyage No / Рейс № | I33: 9. Sailing on or about / Дата или ожидаемая дата
B34: Later
J35: Later
A37: 10. Customs Place / Место таможенного оформления
B38: Turkestan Oblast, Sairam district, Karamurt rural district, quarter 171
A40: 15. Description of Goods / Описание товара | R40: 16. Q-ty | U40: 17. Net Weight | Y40: 18. Gross Weight | AC40: 19. Measurement
R41: (EA) | U41: (kg) | Y41: (kg) | AC41: (CBM)
A42: STG_VMS Unit 1 | R42: 1 SET | U42: =+'Summary PL'!L16 -> 367 | Y42: =+'Summary PL'!M16 -> 607 | AC42: =+'Summary PL'!K16 -> 3.692988
U46: =SUM(U42:X44) -> 367 | Y46: =SUM(Y42:AB44) -> 607 | AC46: =SUM(AC42:AC44) -> 3.692988
S54: Signed by
A55: Doosan Enerbility Co., Ltd
...

Sheet Summary PL
O1: HEAD OFFICE & CHANGWON PLANT | R1: Note> | S1: Storage Classification "A" : | T1: Indoor with Air-conditioning
O2: 22, DoosanVolvo-ro, Seongsan-gu, Changwon-Si, | S2: Storage Classification "B" : | T2: Indoor without Air-conditioning
O3: Gyeongsangnam-do, Korea | S3: Storage Classification "C" : | T3: Outdoor with Waterproofing
O4: (P.O.BOX 77, Changwon, Korea) | S4: Storage Classification "D" : | T4: Outdoor without Waterproofing
O5: TEL:(055)278-6114,7114 FAX:(055)264-5551/2
A6: SUMMARY PACKING LIST CВОДНЫЙ УПАКОВОЧНЫЙ ЛИСТ
A7: Project Name: | B7: Construction of a 1000 MW CCGT Power Plant in the Sairam District of the Turkistan Region
B8: Main Site. Without External Engineering Networks
A9: Invoice №: | B9: =PL!V8 -> PGU-DE-0149
A10: Name of Consignee: | B10: =PL!B13 -> Branch of JSC "Doosan Enerbility" in the Turkestan region
A11: Consignee address: | B11: =PL!B14 -> 321 Tauke Khan Avenue, Turkestan region, Turkestan, Kazakhstan, 161200
A12: № | B12: CNTR No. / Seal No. / № контейнера / № пломбы | C12: Package No. / № упаковки | D12: Description / Описание | E12: Packing Style / Вид упаковки | F12: Quantity / Количество | H12: Shipping Dimension / Отгрузочные параметры | L12: Net Weight (kg) / Вес нетто (кг) | M12: Gross Weight (kg) / Вес брутто (кг) | N12: Hazardous Material (UN Number) | O12: Storage Class / Класс хранения | P12: Stackable / Штабелируемый | Q12: RT (Revenue Ton)
F13: Q'ty / Количество | G13: Unit / Ед.изм. | H13: L (cm) / Д (см) | I13: W (cm) / Ш (см) | J13: H (cm) / В (см) | K13: CBM (m3) / Объем (м3)
A14: 1 | C14: PGU-DE-0149-STG-MMS-001 | D14: VMS - System Cabinet | E14: Wooden box | F14: 1 | G14: EA | H14: 102 | I14: 102 | J14: 232 | K14: =(H14*I14*J14)/1000000 -> 2.413728 | L14: 200 | M14: 335 | N14: NO | O14: A | P14: N
A15: 2 | C15: PGU-DE-0149-STG-MMS-002 | D15: VMS - Accessories | E15: Wooden box | F15: 1 | G15: EA | H15: 135 | I15: 103 | J15: 92 | K15: =(H15*I15*J15)/1000000 -> 1.27926 | L15: 167 | M15: 272 | N15: NO | O15: A | P15: N
A16: TOTAL / ИТОГО | F16: =SUM(F14:F15) -> 2 | K16: =SUM(K14:K15) -> 3.692988 | L16: =SUM(L14:L15) -> 367 | M16: =SUM(M14:M15) -> 607

Sheet Detail PL
P1: HEAD OFFICE & CHANGWON PLANT
P2: 22, DoosanVolvo-ro, Seongsan-gu, Changwon-Si, | R2: Note> | S2: Storage Classification "A" : | T2: Indoor with Air-conditioning
P3: Gyeongsangnam-do, Korea | S3: Storage Classification "B" : | T3: Indoor without Air-conditioning
P4: (P.O.BOX 77, Changwon, Korea) | S4: Storage Classification "C" : | T4: Outdoor with Waterproofing
P5: TEL:(055)278-6114,7114 FAX:(055)264-5551/2 | S5: Storage Classification "D" : | T5: Outdoor without Waterproofing
A6: DETAILED PACKING LIST ПОДРОБНЫЙ УПАКОВОЧНЫЙ ЛИСТ
A7: Project Name: | B7: Construction of a 1000 MW CCGT Power Plant in the Sairam District of the Turkistan Region
B8: Main Site. Without External Engineering Networks
A9: Invoice №: | B9: =PL!V8 -> PGU-DE-0149
A10: Name of Consignee: | B10: =PL!B13 -> Branch of JSC "Doosan Enerbility" in the Turkestan region
A11: Consignee address: | B11: =PL!B14 -> 321 Tauke Khan Avenue, Turkestan region, Turkestan, Kazakhstan, 161200
A12: № | B12: Package No./ Номер упаковки | C12: Description / Описание | D12: HS Code / Код ТН ВЭД | E12: Quantity / Количество | G12: Shipping Dimension / Отгрузочные параметры | K12: Net Weight (kg) / Вес нетто (кг) | L12: Gross Weight (kg) / Вес брутто (кг) | M12: Drawing No. / № чертежа | N12: Tag No. / № Тег | O12: Unit Price (US$) / Цена за единицу | P12: Total Price (US$) / Общая цена | Q12: Remark / Примечания
E13: Q'ty / Кол-во | F13: Unit / Ед. изм. | G13: L (cm) / Д (см) | H13: W (cm) / Ш (см) | I13: H (cm) / В (см) | J13: CBM (m3) / Объем (м3)
A14: 1 | B14: PGU-DE-0149-STG-MMS-001 | C14: VMS - System cabinet 1. block VMS - системный шкаф 1. блок | E14: 1 | F14: EA/ШТ. | M14: WD_13475_ MMS_24 | N14: B1-TCS-1321
G15: 102 | H15: 102 | I15: 232 | J15: =(G15*H15*I15)/1000000 -> 2.413728 | K15: 200 | L15: 335
A16: 2 | B16: PGU-DE-0149-STG-MMS-002 | C16: A6910 - configuration software, connection cables and adapters A6910 - программное обеспечение для настройки, соединительные кабели и адаптеры | E16: 1 | F16: pc | M16: WD_13475_MMS_24
C17: Universal measuring card A6500-UM Универсальная измерительная карта A6500-UM | E17: 8 | F17: pc | M17: WD_13475_MMS_24 | Q17: 51394, 51395, 51487, 51493, 51494, 51495, 51496, 51513
C18: System Communication Card A 6500-CC Системная коммуникационная карта A 6500-CC | E18: 1 | F18: pc | M18: WD_13475_MMS_24 | Q18: 7634
C19: Dual Channel eccentricity monitor PM6000- BD Двухканальный монитор эксцентриситета PM6000- BD | E19: 1 | F19: pc | M19: WD_13475_MMS_24 | Q19: 23060034
C20: Piezo velocity sensor 793V-5 incl. mounting stud M8x1,25 Пьезодатчик скорости 793V-5 с монтажной шпилькой M8x1,25 | E20: 4 | F20: pcs | M20: WD_13475_MMS_24 | N20: B1-VE-13-301-B01 B1-VE-13-302-B01 B1-VE-13-011-B01 B1-VE-13-061-B01 | Q20: 20395, 20396, 20397, 20398
C21: Cable with protection tube RAA-J9T2A-5-MPT-OE Кабель с защитной трубкой RAA-J9T2A-5-MPT-OE | E21: 3 | F21: pcs | M21: WD_13475_MMS_24 | N21: PI-I-5212 PI-I-5222 PI-I-5225
C22: Cable RAA-J9T2A-10-OE Кабель RAA-J9T2A-10-OE | E22: 1 | F22: pc | M22: WD_13475_MMS_24 | N22: PI-I-5218
C23: Sensor EZ1080-03-00-050 Датчик EZ1080-03-00-050 | E23: 8 | F23: pcs | M23: WD_13475_MMS_24 | N23: PI-I-5210 PI-I-5211 PI-I-5213 PI-I-5215 PI-I-5220 PI-I-5221 PI-I-5223 PI-I-5224 | Q23: 28679, 28907, 28909, 28910, 15877, 28911, 28912, 28913
C24: Sensor EZ1080-03-00-100 Датчик EZ1080-03-00-100 | E24: 2 | F24: pcs | M24: WD_13475_MMS_24 | N24: PI-I-5216 PI-I-5217 | Q24: 26077, 26078
C25: Sensor PR 6426/000-141 Датчик PR 6426/000-141 | E25: 1 | F25: pc | M25: WD_13475_MMS_24 | N25: PI-I-5219 | Q25: 8095
C26: Converter EZ1000 (installed in junction boxes - items 17, 18) Преобразователь EZ1000 (устанавливается в распределительные коробки - поз. 17, 18) | E26: 10 | F26: pcs | M26: WD_13475_MMS_24 | N26: B1-VXE-13-301-U01 B1-VYE-13-301-U01 B1-VT-13-306-U01 B1-KT-13-308-U01 B1-VXE-13-302-U01 B1-VYE-13-302-U01 B1-VXE-13-001-U01 B1-VYE-13-001-U01 B1-VXE-13-051-U01 B1-VYE-13-052-U01 | Q26: P242950164, P242950102, P242950377, P242950323, P243150077, P243150081, P231400250, P242950289, P242950212, P242950384
C27: Converter CON041/916-160 (installed in junction boxes - item 17) Преобразователь CON041/916-160 (устанавливается в распределительные коробки - поз. 17) | E27: 1 | F27: pc | M27: WD_13475_MMS_24 | N27: B1-VT-13-305-U01 | Q27: 53811
C28: Linear position sensor ADT 03-50 with 5m cable, incl. MPT, COMBI M20, Nut M20 Датчик линейного положения ADT 03-50 с кабелем 5 м, вкл. MPT, COMBI M20, гайка M20 | E28: 1 | F28: pc | M28: WD_13475_MMS_24 | N28: B1-VE-13-307-B01 | Q28: 70439702
C29: Coil with metal protection tube MPT (79m) - part 1 Змеевик с металлической защитной трубой MPT (79m) - часть 1 Coil with metal protection tube MPT (54m) - part 2 Змеевик с металлической защитной трубкой MPT (54m) - часть 2 | E29: 2 | F29: pc | M29: WD_13475_MMS_24
C30: Set of accessories for metal protection tube MPT 13/320-320/xm (11 sets) (13x Sleeve Combi 3- M20, 3x Sleeve Combi 4- M20, 14x nut M20, 25x ring for hose, 40x Mounting clip+boltM5, , set of plastic KKS labels and ties) Набор аксессуаров для металлической защитной трубки MPT 13/320-320/xm (11 комплектов) (13x рукав Combi 3- M20, 3x рукав Combi 4- M20, 14x гайка M20, 40x кольцо для шланга, 24x монтажный хомут+болтM5, , набор пластиковых этикеток и стяжек KKS) | E30: 1 | F30: pc | M30: WD_13475_MMS_24
C31: SPIRALITE - cable protection SPIRALITE - защита кабеля | E31: 1 | F31: pc | M31: WD_13475_MMS_24
C32: Junction box KASR1004 + accessories incl.pre-installed converters and terminals acc. to project Распределительная коробка KASR1004 + аксессуары включая предварительно установленные преобразователи и клеммы в соответствии с проектом | E32: 2 | F32: pcs | M32: WD_13475_MMS_24 | N32: B1-JBX-1321 B1-JBX-1322
C33: Junction box KASR1002 + accessories incl.pre-installed converters and terminals acc. to project Распределительная коробка KASR1002 + аксессуары включая предварительно установленные преобразователи и клеммы в соответствии с проектом | E33: 2 | F33: pcs | M33: WD_13475_MMS_24 | N33: B1-JBX-1323 B1-JBX-1324
C34: Montage kit FS-US3 for system cabinet installation consists of part 2 - Set of angle brackets part 3 - Set of strut channels Монтажный комплект FS-US3 для установки системного шкафа состоит из часть 2 - Комплект угловых кронштейнов часть 3 - Комплект швеллеров для стоек | E34: 4 | F34: pcs | M34: WD_13475_MMS_24
C35: Montage kit FS-US3 for system cabinet installation consists of part 1 - Set of suspended support length 500mm Монтажный комплект FS-US3 для установки системного шкафа состоит из часть 1 - Набор подвесных опор длиной 500 мм | E35: 2 | F35: pcs | M35: WD_13475_MMS_24
C36: Montage kit FS-US3 for system cabinet installation consists of part 1 - Set of suspended support length 300mm Монтажный комплект FS-US3 для установки системного шкафа состоит из часть 1 - Набор подвесных опор длиной 300 мм | E36: 2 | F36: pcs | M36: WD_13475_MMS_24
C37: Set of mounting material for Montage kit FS-US3 Набор крепежных материалов для монтажного комплекта FS-US3 | E37: 1 | F37: pc | M37: WD_13475_MMS_24
C38: Holders of relative vibration sensors on generator, incl. small nut M10x1 and MPT bushing M16 P6492/340-02 (spindle length 340mm) Держатели датчиков относительной вибрации на генераторе, вкл. малую гайку M10x1 и втулку MPT M16 P6492/340-02 (длина шпинделя 340 мм) | E38: 4 | F38: pcs | M38: WD_13475_MMS_24
C39: Push-button Schneider IPB-1261 Кнопка Schneider IPB-1261 | E39: 2 | F39: pcs | M39: WD_13475_MMS_24 | N39: B1-HZ-13-302 B1-HZ-13-303
C40: Sensor A5S0DS0M1210T50-10m Датчик A5S0DS0M1210T50-10m | E40: 3 | F40: pcs | M40: WD_13475_MMS_24 | N40: B1-SE-13-311A-B01 B1-SE-13-311B-B01 B1-SE-13-311C-B01 | Q40: 2407020007, 2407020008, 2407020009
...

Sheet Description
A1: Technical Description
A2: № | B2: Name | C2: Model-Part No. | D2: Kind of material | E2: Size/specification/ Usage | F2: Photo | G2: Manufacturer / Origin
A3: 1
A4: 2
A5: 3
A6: 4
A7: 5
A8: 6
A9: 7

Sheet Marking
A1: SHIPPING MARK ГРУЗОВАЯ МАРКИРОВКА
A2: ● NAME OF THE PROJECT | F2: : | G2: Construction of a 1000 MW CCGT Power Plant in the Sairam District of the
A3: НАЗВАНИЕ ПРОЕКТА | G3: Turkistan Region, Main Site. Without External Engineering Networks
A5: ● CONSIGNEE | F5: : | G5: ='Detail PL'!B10 -> Branch of JSC "Doosan Enerbility" in the Turkestan region
A6: ГРУЗОПОЛУЧАТЕЛЬ
A8: ● Shipper/Exporter | F8: : Doosan Enerbility Co., LTD
A9: Грузоотправитель/Экспортер | F9: 22, Doosan Volvo-ro, Sengsan-gu, Changwon, Gyeongnam, South Korea
A11: ● Number of Invoice | F11: : | G11: =CI!V8 -> PGU-DE-0149
A12: № инвойса
A14: ● CARGO DESCRIPTION | F14: : | G14: ='Summary PL'!D14 -> VMS - System Cabinet
A15: ОПИСАНИЕ ГРУЗА
A17: ● PACKAGE NO. | F17: : | G17: ='Summary PL'!C14 -> PGU-DE-0149-STG-MMS-001
A18: УПАКОВОЧНЫЙ НОМЕР
A20: ● NET WEIGHT | F20: : | G20: ='Summary PL'!L14 -> 200 | H20: Kg
A21: ВЕС НЕТТО
A23: ● GROSS WEIGHT | F23: : | G23: ='Summary PL'!M14 -> 335 | H23: Kg
A24: ВЕС БРУТТО
A26: ● CBM(m3) | F26: : | G26: ='Summary PL'!K14 -> 2.413728 | H26: m3
A27: РАЗМЕРЫ
A28: ● Port of Discharge | F28: : | G28: Tianjin Port, China
A29: Порт разгрузки
A31: ● FINAL DESTINATION | F31: : | G31: Turkestan Oblast, Sairam district, Karamurt rural district, quarter 171, Republic of Kazakhstan
A32: КОНЕЧНЫЙ ПУНКТ НАЗНАЧЕНИЯ
E33: Doosan Enerbility
A35: SHIPPING MARK ГРУЗОВАЯ МАРКИРОВКА
A36: ● NAME OF THE PROJECT | F36: : | G36: Construction of a 1000 MW CCGT Power Plant in the Sairam District of the
A37: НАЗВАНИЕ ПРОЕКТА | G37: Turkistan Region, Main Site. Without External Engineering Networks
A39: ● CONSIGNEE | F39: : | G39: ='Detail PL'!B10 -> Branch of JSC "Doosan Enerbility" in the Turkestan region
A40: ГРУЗОПОЛУЧАТЕЛЬ
A42: ● Shipper/Exporter | F42: : Doosan Enerbility Co., LTD
A43: Грузоотправитель/Экспортер | F43: 22, Doosan Volvo-ro, Sengsan-gu, Changwon, Gyeongnam, South Korea
A45: ● Number of Invoice | F45: : | G45: =CI!V8 -> PGU-DE-0149
A46: № инвойса
A48: ● CARGO DESCRIPTION | F48: : | G48: ='Summary PL'!D15 -> VMS - Accessories
A49: ОПИСАНИЕ ГРУЗА
A51: ● PACKAGE NO. | F51: : | G51: ='Summary PL'!C15 -> PGU-DE-0149-STG-MMS-002
A52: УПАКОВОЧНЫЙ НОМЕР
A54: ● NET WEIGHT | F54: : | G54: ='Summary PL'!L15 -> 167 | H54: Kg
A55: ВЕС НЕТТО
A57: ● GROSS WEIGHT | F57: : | G57: ='Summary PL'!M15 -> 272 | H57: Kg
...
