Workbook

Sheet CI
W1: HEAD OFFICE & CHANGWON PLANT
W2: 22, DoosanVolvo-ro, Seongsan-gu, Changwon-Si,
W3: Gyeongsangnam-do, Korea
W4: (P.O.BOX 77, Changwon, Korea)
W5: TEL:(055)278-6114,7114 FAX:(055)264-5551/2
A6: PROFORMA INVOICE ПРОФОРМА ИНВОЙС
A8: 1. Shipper / Грузоотправитель | R8: 11. Invoice № : | V8: PGU-DE-0175
B9: Doosan Enerbility Co., Ltd (DOOSAN) | R9: Инвойс №
B10: 22, DoosanVolvo-ro, Seongsan-gu, Changwon-si, Gyeongsangnam-do | R10: 12. Date : | V10: 45720
B11: Republic of Korea | R11: Дата
A12: 2. Consignee / Грузополучатель | R12: 13. Remarks / Примечания
B13: CCGT Turkestan LLP
B14: Republic of Kazakhstan, Turkestan region, Sairam district, | S14: *Project Name / Название Проекта
B15: Aksukent rural district, Aksu village, Zhibek Zholy street, building 55 | S15: Construction of a 1000 MW CCGT Power Plant in the Sairam District of Turkistan Region, Main Site. Without External Engineering Networks
B16: BIN: 110740016192
B17: info@ccgt.kz | S17: *MANUFACTURER'S NAME / НАЗВАНИЕ ПРОИЗВОДИТЕЛЯ
S18: Doosan Škoda Power a.s.
A19: 3. Notify party / Уведомляемая сторона | S19: *MANUFACTURE YEAR / ГОД ИЗГОТОВЛЕНИЯ
B20: Wise Logistics | S20: 2024
B21: ATTAN: MS. Aliya | S21: *COUNTRY OF ORIGIN / СТРАНА ПРОИСХОЖДЕНИЯ
B22: (E): a.kipshakbayeva@wiselogistics.kz | S22: Germany
B23: (T): +7 701 512 19 69 | S23: *INCOTERMS / УСЛОВИЯ ПОСТАВКИ СОГЛАСНО ИНКОТЕРМС
S24: DAP Main site
S25: * CONTRACT NO. / НОМЕР КОНТРАКТ
A26: 4. Port of Loading / Порт погрузки | I26: 5. Carrier / Перевозчик | S26: 0123-ПГУТ-8Д date 14.03.2023
B27: Hamburg, Germany | J27: MV. DA JI
A29: 6. Port of Unloading / Порт разгрузки | I29: 7. Final Destination / Конечный пункт назначения | R29: 14. Mark and Numbers of PKGS / Маркировка и количество упаковок
B31: Tianjin, China | I31: Turkestan region, Sairam district | S31: PKG No. | X31: : | Y31: PGU-DE-0175-STG-OPS-001 ~ 017
S32: Q-ty of Package | X32: : | Y32: =COUNT('Summary PL'!A14:A30) -> 17 | AC32: PKGS
A33: 8. Voyage No / Рейс № | I33: 9. Sailing on or about / Дата или ожидаемая дата | S33: Net Weight (kg) | X33: : | Y33: ='Summary PL'!L31 -> 8993 | AC33: KG
S34: Gross Weight (kg) | X34: : | Y34: ='Summary PL'!M31 -> 11259 | AC34: KG
J35: 45720 | S35: Dimension (m3) | X35: : | Y35: ='Summary PL'!K31 -> 48.725534 | AC35: m3
A37: 10. Customs Place / Место таможенного оформления
B38: Later
A40: 15. Description of Goods / Описание товара | R40: 16. HS CODE / | W40: 17. Quantity / | AA40: 18. Total Price (USD)
R41: Код ТН ВЭД | W41: Количество | AA41: Общая сумма (Дол. США)
B42: =+PL!B42 -> STG_Control system Unit 1 | R42: 8502 39 2000 | W42: 1 | AC42: =CI_BD!I26 -> 606914.81 | AD42: Item 3.8
B43: Система управления | W43: / комплект
I45: Total (DAP Value) | AA45: =AC42 -> 606914.81
S53: Signed by
...

Sheet CI_BD
J1: HEAD OFFICE & CHANGWON PLANT
J2: 22, DoosanVolvo-ro, Seongsan-gu, Changwon-Si,
J3: Gyeongsangnam-do, Korea
J4: (P.O.BOX 77, Changwon, Korea)
J5: TEL:(055)278-6114,7114 FAX:(055)264-5551/2
A6: PROFORMA INVOICE (Break-down) ПРОФОРМА-ИНВОЙС (Разбивка)
A7: Invoice № : | B7: =CI!V8 -> PGU-DE-0175
A8: № | B8: № Package | C8: Description of Goods Specification | D8: Material | E8: HS CODE | F8: Quantity | G8: Unit | H8: U/Price (USD) | I8: Amount (USD) | J8: Country of Origin | K8: Remark
A9: 1 | B9: PGU-DE-0175-STG-OPS-001 | C9: Cables/ Кабели | F9: 1 | G9: EA / ШТ. | H9: 34756.05 | I9: =F9*H9 -> 34756.05
A10: 2 | B10: PGU-DE-0175-STG-OPS-002 | C10: Cables/ Кабели | F10: 1 | G10: EA / ШТ. | H10: 13227.54 | I10: =F10*H10 -> 13227.54
A11: 3 | B11: PGU-DE-0175-STG-OPS-003 | C11: Cables/ Кабели | F11: 1 | G11: EA / ШТ. | H11: 37927.96 | I11: =F11*H11 -> 37927.96
A12: 4 | B12: PGU-DE-0175-STG-OPS-004 | C12: Cables/ Кабели | F12: 1 | G12: EA / ШТ. | H12: 28749.66 | I12: =F12*H12 -> 28749.66
A13: 5 | B13: PGU-DE-0175-STG-OPS-005 | C13: Cables/ Кабели | F13: 1 | G13: EA / ШТ. | H13: 37185.6 | I13: =F13*H13 -> 37185.6
A14: 6 | B14: PGU-DE-0175-STG-OPS-006 | C14: Cables/ Кабели | F14: 1 | G14: EA / ШТ. | H14: 37253.08 | I14: =F14*H14 -> 37253.08
A15: 7 | B15: PGU-DE-0175-STG-OPS-007 | C15: Cables/ Кабели | F15: 1 | G15: EA / ШТ. | H15: 37792.98 | I15: =F15*H15 -> 37792.98
A16: 8 | B16: PGU-DE-0175-STG-OPS-008 | C16: Cables/ Кабели | F16: 1 | G16: EA / ШТ. | H16: 37253.08 | I16: =F16*H16 -> 37253.08
A17: 9 | B17: PGU-DE-0175-STG-OPS-009 | C17: Cables/ Кабели | F17: 1 | G17: EA / ШТ. | H17: 37523.03 | I17: =F17*H17 -> 37523.03
A18: 10 | B18: PGU-DE-0175-STG-OPS-010 | C18: Cables/ Кабели | F18: 1 | G18: EA / ШТ. | H18: 13160.06 | I18: =F18*H18 -> 13160.06
A19: 11 | B19: PGU-DE-0175-STG-OPS-011 | C19: Optical cable/ Оптический кабель | F19: 1 | G19: EA / ШТ. | H19: 26320.11 | I19: =F19*H19 -> 26320.11
A20: 12 | B20: PGU-DE-0175-STG-OPS-012 | C20: Field instrumentation and cables/ Полевые приборы и кабели | F20: 1 | G20: EA / ШТ. | H20: 20381.22 | I20: =F20*H20 -> 20381.22
... A25: 17 | B25: PGU-DE-0175-STG-OPS-017 | C25: Cable traces and structures equipment/ оборудование для кабельных трасс и конструкций | F25: 1 | G25: EA / ШТ. | H25: 94954.87 | I25: =F25*H25 -> 94954.87
B26: TOTAL | I26: =SUM(I9:I25) -> 606914.81

Sheet PL
W1: HEAD OFFICE & CHANGWON PLANT
W2: 22, DoosanVolvo-ro, Seongsan-gu, Changwon-Si,
W3: Gyeongsangnam-do, Korea
W4: (P.O.BOX 77, Changwon, Korea)
W5: TEL:(055)278-6114,7114 FAX:(055)264-5551/2
A6: PACKING LIST УПАКОВОЧНЫЙ ЛИСТ
A8: 1. Shipper / Грузоотправитель | R8: 11. Invoice № : | V8: =CI!V8 -> PGU-DE-0175
B9: Doosan Enerbility Co., Ltd (DOOSAN) | R9: Инвойс №
B10: 22, DoosanVolvo-ro, Seongsan-gu, Changwon-si, Gyeongsangnam-do | R10: 12. Date : | V10: =CI!V10 -> 45720
B11: Republic of Korea | R11: Дата
A12: 2. Consignee / Грузополучатель | R12: 13. Remarks / Примечания
B13: CCGT Turkestan LLP
B14: Republic of Kazakhstan, Turkestan region, Sairam district, | S14: *Project Name / Название Проекта
B15: Aksukent rural district, Aksu village, Zhibek Zholy street, building 55 | S15: Construction of a 1000 MW CCGT Power Plant in the Sairam District of Turkistan Region, Main Site. Without External Engineering Networks
B16: BIN: 110740016192
B17: info@ccgt.kz | S17: *MANUFACTURER'S NAME / НАЗВАНИЕ ПРОИЗВОДИТЕЛЯ
S18: Doosan Škoda Power a.s.
A19: 3. Notify party / Уведомляемая сторона | S19: *MANUFACTURE YEAR / ГОД ИЗГОТОВЛЕНИЯ
B20: Wise Logistics | S20: 2024
B21: ATTAN: MS. Aliya | S21: *COUNTRY OF ORIGIN / СТРАНА ПРОИСХОЖДЕНИЯ
B22: (E): a.kipshakbayeva@wiselogistics.kz | S22: Germany
B23: (T): +7 701 512 19 69 | S23: *INCOTERMS / УСЛОВИЯ ПОСТАВКИ СОГЛАСНО ИНКОТЕРМС
S24: DAP Main site
S25: * CONTRACT NO. / НОМЕР КОНТРАКТ
A26: 4. Port of Loading / Порт погрузки | I26: 5. Carrier / Перевозчик | S26: 0123-ПГУТ-8Д date 14.03.2023
B27: Hamburg, Germany | K27: =CI!J27 -> MV. DA JI
A29: 6. Port of Unloading / Порт разгрузки | I29: 7. Final Destination / Конечный пункт назначения | R29: 14. Mark and Numbers of PKGS / Маркировка и количество упаковок
B31: =CI!B31 -> Tianjin, China | I31: =CI!I31 -> Turkestan region, Sairam district | S31: PKG No. | X31: : | Y31: =CI!Y31 -> PGU-DE-0175-STG-OPS-001 ~ 017
S32: Q-ty of Package | X32: : | Y32: =COUNT('Summary PL'!A14:A30) -> 17 | AC32: PKGS
A33: 8. Voyage No / Рейс № | I33: 9. Sailing on or about / Дата или ожидаемая дата | S33: Net Weight (kg) | X33: : | Y33: =U45 -> 8993 | AC33: KG
S34: Gross Weight (kg) | X34: : | Y34: =Y45 -> 11259 | AC34: KG
J35: =V10 -> 45720 | S35: Dimension (m3) | X35: : | Y35: =AC45 -> 48.725534 | AC35: m3
A37: 10. Customs Place / Место таможенного оформления
A40: 15. Description of Goods / Описание товара | R40: 16. Q-ty | U40: 17. Net Weight | Y40: 18. Gross Weight | AC40: 19. Measurement
R41: (EA) | U41: (kg) | Y41: (kg) | AC41: (CBM)
B42: STG_Control system Unit 1 | R42: =CI!W42 -> 1 | U42: =+'Summary PL'!L31 -> 8993 | Y42: =+'Summary PL'!M31 -> 11259 | AC42: =+'Summary PL'!K31 -> 48.725534
B43: =CI!B43 -> Система управления | R43: =CI!W43 -> / комплект
U45: =SUM(U42:X43) -> 8993 | Y45: =SUM(Y42:AB43) -> 11259 | AC45: =SUM(AC42:AC43) -> 48.725534
S53: Signed by
A54: Doosan Enerbility Co., Ltd
...

Sheet Summary PL
O1: HEAD OFFICE & CHANGWON PLANT | Q1: Note> | R1: Storage Classification "A" : | S1: Indoor with Air-conditioning
O2: 22, DoosanVolvo-ro, Seongsan-gu, Changwon-Si, | R2: Storage Classification "B" : | S2: Indoor without Air-conditioning
O3: Gyeongsangnam-do, Korea | R3: Storage Classification "C" : | S3: Outdoor with Waterproofing
O4: (P.O.BOX 77, Changwon, Korea) | R4: Storage Classification "D" : | S4: Outdoor without Waterproofing
O5: TEL:(055)278-6114,7114 FAX:(055)264-5551/2
A6: SUMMARY PACKING LIST CВОДНЫЙ УПАКОВОЧНЫЙ ЛИСТ
A7: Project Name: | B7: Construction of a 1000 MW CCGT Power Plant in the Sairam District of the Turkistan Region
B8: Main Site. Without External Engineering Networks
A9: Invoice №: | B9: =PL!V8 -> PGU-DE-0175
A10: Name of Consignee: | B10: =PL!B13 -> CCGT Turkestan LLP
A11: Consignee address: | B11: =PL!B14&PL!B15 -> Republic of Kazakhstan, Turkestan region, Sairam district, Aksukent rural district, Aksu village, Zhibek Zholy street, building 55
A12: № | B12: CNTR No. / Seal No. / № контейнера / № пломбы | C12: Package No. / № упаковки | D12: Description / Описание | E12: Packing Style / Вид упаковки | F12: Quantity / Количество | H12: Shipping Dimension / Отгрузочные параметры | L12: Net Weight (kg) / Вес нетто (кг) | M12: Gross Weight (kg) / Вес брутто (кг) | N12: Hazardous Material (UN Number) | O12: Storage Class / Класс хранения | P12: Stackable / Штабелируемый
F13: Q'ty / Количество | G13: Unit / Ед.изм. | H13: L (cm) / Д (см) | I13: W (cm) / Ш (см) | J13: H (cm) / В (см) | K13: CBM (m3) / Объем (м3)
A14: 1 | C14: PGU-DE-0175-STG-OPS-001 | D14: Cables/ Кабели | E14: Drum | F14: 1 | G14: EA / ШТ. | H14: 130 | I14: 90 | J14: 130 | K14: =+H14*I14*J14/100^3 -> 1.521 | L14: 515 | M14: 596 | O14: D | P14: N
A15: 2 | C15: PGU-DE-0175-STG-OPS-002 | D15: Cables/ Кабели | E15: Drum | F15: 1 | G15: EA / ШТ. | H15: 130 | I15: 90 | J15: 130 | K15: =+H15*I15*J15/100^3 -> 1.521 | L15: 196 | M15: 277 | O15: D | P15: N
A16: 3 | C16: PGU-DE-0175-STG-OPS-003 | D16: Cables/ Кабели | E16: Drum | F16: 1 | G16: EA / ШТ. | H16: 130 | I16: 90 | J16: 130 | K16: =+H16*I16*J16/100^3 -> 1.521 | L16: 562 | M16: 643 | O16: D | P16: N
A17: 4 | C17: PGU-DE-0175-STG-OPS-004 | D17: Cables/ Кабели | E17: Drum | F17: 1 | G17: EA / ШТ. | H17: 130 | I17: 90 | J17: 130 | K17: =+H17*I17*J17/100^3 -> 1.521 | L17: 426 | M17: 507 | O17: D | P17: N
A18: 5 | C18: PGU-DE-0175-STG-OPS-005 | D18: Cables/ Кабели | E18: Drum | F18: 1 | G18: EA / ШТ. | H18: 130 | I18: 90 | J18: 130 | K18: =+H18*I18*J18/100^3 -> 1.521 | L18: 551 | M18: 632 | O18: D | P18: N
A19: 6 | C19: PGU-DE-0175-STG-OPS-006 | D19: Cables/ Кабели | E19: Drum | F19: 1 | G19: EA / ШТ. | H19: 130 | I19: 90 | J19: 130 | K19: =+H19*I19*J19/100^3 -> 1.521 | L19: 552 | M19: 633 | O19: D | P19: N
A20: 7 | C20: PGU-DE-0175-STG-OPS-007 | D20: Cables/ Кабели | E20: Drum | F20: 1 | G20: EA / ШТ. | H20: 130 | I20: 90 | J20: 130 | K20: =+H20*I20*J20/100^3 -> 1.521 | L20: 560 | M20: 641 | O20: D | P20: N
A21: 8 | C21: PGU-DE-0175-STG-OPS-008 | D21: Cables/ Кабели | E21: Drum | F21: 1 | G21: EA / ШТ. | H21: 130 | I21: 90 | J21: 130 | K21: =+H21*I21*J21/100^3 -> 1.521 | L21: 552 | M21: 633 | O21: D | P21: N
A22: 9 | C22: PGU-DE-0175-STG-OPS-009 | D22: Cables/ Кабели | E22: Drum | F22: 1 | G22: EA / ШТ. | H22: 130 | I22: 90 | J22: 130 | K22: =+H22*I22*J22/100^3 -> 1.521 | L22: 556 | M22: 637 | O22: D | P22: N
A23: 10 | C23: PGU-DE-0175-STG-OPS-010 | D23: Cables/ Кабели | E23: Drum | F23: 1 | G23: EA / ШТ. | H23: 130 | I23: 90 | J23: 130 | K23: =+H23*I23*J23/100^3 -> 1.521 | L23: 195 | M23: 276 | O23: D | P23: N
A24: 11 | C24: PGU-DE-0175-STG-OPS-011 | D24: Optical cable/ Оптический кабель | E24: Drum | F24: 1 | G24: EA / ШТ. | H24: 130 | I24: 90 | J24: 130 | K24: =+H24*I24*J24/100^3 -> 1.521 | L24: 390 | M24: 514 | O24: D | P24: N
A25: 12 | C25: PGU-DE-0175-STG-OPS-012 | D25: Field instrumentation and cables/ Полевые приборы и кабели | E25: Wooden box | F25: 1 | G25: EA / ШТ. | H25: 309 | I25: 169 | J25: 126 | K25: =+H25*I25*J25/100^3 -> 6.579846 | L25: 302 | M25: 555 | O25: A | P25: N
... A30: 17 | C30: PGU-DE-0175-STG-OPS-017 | D30: Cable traces and structures equipment/ оборудование для кабельных трасс и конструкций | E30: Wooden box | F30: 1 | G30: EA / ШТ. | H30: 339 | I30: 189 | J30: 156 | K30: =+H30*I30*J30/100^3 -> 9.995076 | L30: 1407 | M30: 1740 | O30: C | P30: N
A31: TOTAL / ИТОГО | K31: =SUM(K14:K30) -> 48.725534 | L31: =SUM(L14:L30) -> 8993 | M31: =SUM(M14:M30) -> 11259

Sheet Detail PL
P1: HEAD OFFICE & CHANGWON PLANT
P2: 22, DoosanVolvo-ro, Seongsan-gu, Changwon-Si, | R2: Note> | S2: Storage Classification "A" : | T2: Indoor with Air-conditioning
P3: Gyeongsangnam-do, Korea | S3: Storage Classification "B" : | T3: Indoor without Air-conditioning
P4: (P.O.BOX 77, Changwon, Korea) | S4: Storage Classification "C" : | T4: Outdoor with Waterproofing
P5: TEL:(055)278-6114,7114 FAX:(055)264-5551/2 | S5: Storage Classification "D" : | T5: Outdoor without Waterproofing
A6: DETAILED PACKING LIST ПОДРОБНЫЙ УПАКОВОЧНЫЙ ЛИСТ
A7: Project Name: | B7: Construction of a 1000 MW CCGT Power Plant in the Sairam District of the Turkistan Region
B8: Main Site. Without External Engineering Networks
A9: Invoice №: | B9: =PL!V8 -> PGU-DE-0175
A10: Name of Consignee: | B10: =PL!B13 -> CCGT Turkestan LLP
A11: Consignee address: | B11: ='Summary PL'!B11 -> Republic of Kazakhstan, Turkestan region, Sairam district, Aksukent rural district, Aksu village, Zhibek Zholy street, building 55
A12: № | B12: Package No./ Номер упаковки | C12: Description / Описание | D12: HS Code / Код ТН ВЭД | E12: Quantity / Количество | G12: Shipping Dimension / Отгрузочные параметры | K12: Net Weight (kg) / Вес нетто (кг) | L12: Gross Weight (kg) / Вес брутто (кг) | M12: Drawing No. / № чертежа | N12: Tag No. / № Тег | O12: Unit Price (US$) / Цена за единицу | P12: Total Price (US$) / Общая цена | Q12: Remark / Примечания
E13: Q'ty / Кол-во | F13: Unit / Ед. изм. | G13: L (cm) / Д (см) | H13: W (cm) / Ш (см) | I13: H (cm) / В (см) | J13: CBM (m3) / Объем (м3)
A14: 1 | B14: PGU-DE-0175-STG-OPS-001 | C14: Cables | E14: 1 | F14: EA/ШТ.
G15: ='Summary PL'!H14 -> 130 | H15: ='Summary PL'!I14 -> 90 | I15: ='Summary PL'!J14 -> 130 | J15: =+G15*H15*I15/100^3 -> 1.521 | K15: ='Summary PL'!L14 -> 515 | L15: ='Summary PL'!M14 -> 596
A16: 2 | B16: PGU-DE-0175-STG-OPS-002 | C16: Cables | E16: 1 | F16: EA/ШТ.
G17: ='Summary PL'!H15 -> 130 | H17: ='Summary PL'!I15 -> 90 | I17: ='Summary PL'!J15 -> 130 | J17: =+G17*H17*I17/100^3 -> 1.521 | K17: ='Summary PL'!L15 -> 196 | L17: ='Summary PL'!M15 -> 277
A18: 3 | B18: PGU-DE-0175-STG-OPS-003 | C18: Cables | E18: 1 | F18: EA/ШТ.
G19: ='Summary PL'!H16 -> 130 | H19: ='Summary PL'!I16 -> 90 | I19: ='Summary PL'!J16 -> 130 | J19: =+G19*H19*I19/100^3 -> 1.521 | K19: ='Summary PL'!L16 -> 562 | L19: ='Summary PL'!M16 -> 643
A20: 4 | B20: PGU-DE-0175-STG-OPS-004 | C20: Cables | E20: 1 | F20: EA/ШТ.
G21: ='Summary PL'!H17 -> 130 | H21: ='Summary PL'!I17 -> 90 | I21: ='Summary PL'!J17 -> 130 | J21: =+G21*H21*I21/100^3 -> 1.521 | K21: ='Summary PL'!L17 -> 426 | L21: ='Summary PL'!M17 -> 507
A22: 5 | B22: PGU-DE-0175-STG-OPS-005 | C22: Cables | E22: 1 | F22: EA/ШТ.
G23: ='Summary PL'!H18 -> 130 | H23: ='Summary PL'!I18 -> 90 | I23: ='Summary PL'!J18 -> 130 | J23: =+G23*H23*I23/100^3 -> 1.521 | K23: ='Summary PL'!L18 -> 551 | L23: ='Summary PL'!M18 -> 632
A24: 6 | B24: PGU-DE-0175-STG-OPS-006 | C24: Cables | E24: 1 | F24: EA/ШТ.
G25: ='Summary PL'!H19 -> 130 | H25: ='Summary PL'!I19 -> 90 | I25: ='Summary PL'!J19 -> 130 | J25: =+G25*H25*I25/100^3 -> 1.521 | K25: ='Summary PL'!L19 -> 552 | L25: ='Summary PL'!M19 -> 633
A26: 7 | B26: PGU-DE-0175-STG-OPS-007 | C26: Cables | E26: 1 | F26: EA/ШТ.
G27: ='Summary PL'!H20 -> 130 | H27: ='Summary PL'!I20 -> 90 | I27: ='Summary PL'!J20 -> 130 | J27: =+G27*H27*I27/100^3 -> 1.521 | K27: ='Summary PL'!L20 -> 560 | L27: ='Summary PL'!M20 -> 641
A28: 8 | B28: PGU-DE-0175-STG-OPS-008 | C28: Cables | E28: 1 | F28: EA/ШТ.
G29: ='Summary PL'!H21 -> 130 | H29: ='Summary PL'!I21 -> 90 | I29: ='Summary PL'!J21 -> 130 | J29: =+G29*H29*I29/100^3 -> 1.521 | K29: ='Summary PL'!L21 -> 552 | L29: ='Summary PL'!M21 -> 633
A30: 9 | B30: PGU-DE-0175-STG-OPS-009 | C30: Cables | E30: 1 | F30: EA/ШТ.
G31: ='Summary PL'!H22 -> 130 | H31: ='Summary PL'!I22 -> 90 | I31: ='Summary PL'!J22 -> 130 | J31: =+G31*H31*I31/100^3 -> 1.521 | K31: ='Summary PL'!L22 -> 556 | L31: ='Summary PL'!M22 -> 637
A32: 10 | B32: PGU-DE-0175-STG-OPS-010 | C32: Cables | E32: 1 | F32: EA/ШТ.
G33: ='Summary PL'!H23 -> 130 | H33: ='Summary PL'!I23 -> 90 | I33: ='Summary PL'!J23 -> 130 | J33: =+G33*H33*I33/100^3 -> 1.521 | K33: ='Summary PL'!L23 -> 195 | L33: ='Summary PL'!M23 -> 276
A34: 11 | B34: PGU-DE-0175-STG-OPS-011 | C34: Optical cable | E34: 1 | F34: EA/ШТ.
G35: ='Summary PL'!H24 -> 130 | H35: ='Summary PL'!I24 -> 90 | I35: ='Summary PL'!J24 -> 130 | J35: =+G35*H35*I35/100^3 -> 1.521 | K35: ='Summary PL'!L24 -> 390 | L35: ='Summary PL'!M24 -> 514
A36: 12 | B36: PGU-DE-0175-STG-OPS-012 | C36: Cable KX-1-1-F-2 x 2 x 0,5 mm2 | E36: 60 | F36: m
B37: PGU-DE-0175-STG-OPS-012 | C37: Cable Ethernet 6XV1878-2F | E37: 170 | F37: m
B38: PGU-DE-0175-STG-OPS-012 | C38: Ethernet connectors 6GK1901-1BB12-2AB0 | E38: 10 | F38: pc
B39: PGU-DE-0175-STG-OPS-012 | C39: Pressure transmitters Sitrans P320 | E39: 20 | F39: pc
B40: PGU-DE-0175-STG-OPS-012 | C40: Pressure switches PCS | E40: 4 | F40: pc
...

Sheet Description
A1: Technical Description
A2: № | B2: Name | C2: Model-Part No. | D2: Kind of material | E2: Size/specification/ Usage | F2: Photo | G2: Manufacturer / Origin
A3: 1
A4: 2
A5: 3
A6: 4
A7: 5
A8: 6
A9: 7

Sheet Marking
A1: SHIPPING MARK ГРУЗОВАЯ МАРКИРОВКА
A2: ● NAME OF THE PROJECT | F2: : | G2: Construction of a 1000 MW CCGT Power Plant in the Sairam District of the
A3: НАЗВАНИЕ ПРОЕКТА | G3: Turkistan Region, Main Site. Without External Engineering Networks
A5: ● CONSIGNEE | F5: : | G5: ='Detail PL'!B10 -> CCGT Turkestan LLP
A6: ГРУЗОПОЛУЧАТЕЛЬ
A8: ● Shipper/Exporter | F8: : Doosan Enerbility Co., LTD
A9: Грузоотправитель/Экспортер | F9: 22, Doosan Volvo-ro, Sengsan-gu, Changwon, Gyeongnam, South Korea
A11: ● Number of Invoice | F11: : | G11: =CI!V8 -> PGU-DE-0175
A12: № инвойса
A14: ● CARGO DESCRIPTION | F14: : | G14: ='Summary PL'!D14 -> Cables/ Кабели
A15: ОПИСАНИЕ ГРУЗА
A17: ● PACKAGE NO. | F17: : | G17: ='Summary PL'!C14 -> PGU-DE-0175-STG-OPS-001
A18: УПАКОВОЧНЫЙ НОМЕР
A20: ● NET WEIGHT | F20: : | G20: ='Summary PL'!L14 -> 515 | H20: Kg
A21: ВЕС НЕТТО
A23: ● GROSS WEIGHT | F23: : | G23: ='Summary PL'!M14 -> 596 | H23: Kg
A24: ВЕС БРУТТО
A26: ● CBM(m3) | F26: : | G26: ='Summary PL'!K14 -> 1.521 | H26: m3
A27: РАЗМЕРЫ
A28: ● Port of Discharge | F28: : | G28: Tianjin Port, China
A29: Порт разгрузки
A31: ● FINAL DESTINATION | F31: : | G31: Turkestan Oblast, Sairam district, Karamurt rural district, quarter 171, Republic of Kazakhstan
A32: КОНЕЧНЫЙ ПУНКТ НАЗНАЧЕНИЯ
E33: Doosan Enerbility
A35: SHIPPING MARK ГРУЗОВАЯ МАРКИРОВКА
A36: ● NAME OF THE PROJECT | F36: : | G36: Construction of a 1000 MW CCGT Power Plant in the Sairam District of the
A37: НАЗВАНИЕ ПРОЕКТА | G37: Turkistan Region, Main Site. Without External Engineering Networks
A39: ● CONSIGNEE | F39: : | G39: ='Detail PL'!B10 -> CCGT Turkestan LLP
A40: ГРУЗОПОЛУЧАТЕЛЬ
A42: ● Shipper/Exporter | F42: : Doosan Enerbility Co., LTD
A43: Грузоотправитель/Экспортер | F43: 22, Doosan Volvo-ro, Sengsan-gu, Changwon, Gyeongnam, South Korea
A45: ● Number of Invoice | F45: : | G45: =CI!V8 -> PGU-DE-0175
A46: № инвойса
A48: ● CARGO DESCRIPTION | F48: : | G48: ='Summary PL'!D15 -> Cables/ Кабели
A49: ОПИСАНИЕ ГРУЗА
A51: ● PACKAGE NO. | F51: : | G51: ='Summary PL'!C15 -> PGU-DE-0175-STG-OPS-002
A52: УПАКОВОЧНЫЙ НОМЕР
A54: ● NET WEIGHT | F54: : | G54: ='Summary PL'!L15 -> 196 | H54: Kg
A55: ВЕС НЕТТО
A57: ● GROSS WEIGHT | F57: : | G57: ='Summary PL'!M15 -> 277 | H57: Kg
...
