Workbook

Sheet CI
W1: HEAD OFFICE & CHANGWON PLANT
W2: 22, DoosanVolvo-ro, Seongsan-gu, Changwon-Si,
W3: Gyeongsangnam-do, Korea
W4: (P.O.BOX 77, Changwon, Korea)
W5: TEL:(055)278-6114,7114 FAX:(055)264-5551/2
A6: PROFORMA INVOICE ПРОФОРМА ИНВОЙС
A8: 1. Shipper / Грузоотправитель | R8: 10. Invoice № : | V8: PGU-DE-0581
B9: Doosan Enerbility Co., Ltd (DOOSAN) | R9: Инвойс №
B10: 22, DoosanVolvo-ro, Seongsan-gu, Changwon-si, Gyeongsangnam-do | R10: Date : | V10: 46157
B11: Republic of Korea | R11: Дата
A12: 2. Consignee / Грузополучатель | R12: 13. Remarks / Примечания
B13: Branch of JSC "Doosan Enerbility" in the Turkestan region
B14: 321 Tauke Khan Avenue, Turkestan region, Turkestan, Kazakhstan, 161200 | S14: *Project Name / Название Проекта
B15: BIN: 230741006561 | S15: Construction of a 1000 MW CCGT Power Plant in the Sairam District of
S16: Turkistan Region, Main Site. Without External Engineering Networks
S17: *MANUFACTURER'S NAME / НАЗВАНИЕ ПРОИЗВОДИТЕЛЯ
A18: 3. Notify party / Уведомляемая сторона | S18: WONLEE Solutions
B19: Wise Logistics | S19: *MANUFACTURE YEAR / ГОД ИЗГОТОВЛЕНИЯ
B20: ATTAN: MS. Aliya | S20: 2026
B21: (E): a.kipshakbayeva@wiselogistics.kz | S21: *COUNTRY OF ORIGIN / СТРАНА ПРОИСХОЖДЕНИЯ
B22: (T): +7 701 512 19 69 | S22: Korea
S23: *INCOTERMS / УСЛОВИЯ ПОСТАВКИ СОГЛАСНО ИНКОТЕРМС
S24: DAP Sairam district
S25: * CONTRACT NO. / НОМЕР КОНТРАКТ
A26: 4. Port of Loading / Порт погрузки | I26: 5. Carrier / Перевозчик | S26: 0123-ПГУТ-8Д date 14.03.2023
B27: Busan, Korea | J27: HEUNG-A JANICE
A29: 6. Port of Unloading / Порт разгрузки | I29: 7. Final Destination / Конечный пункт назначения | R29: 14. Mark and Numbers of PKGS / Маркировка и количество упаковок
B31: Qingdao, China | I31: Turkestan Oblast, Sairam district | S31: PKG No. | X31: : | Y31: PGU-DE-0581-PRP-FC-001~006
S32: Q-ty of Package | X32: : | Y32: =COUNT('Summary PL'!A14:A19) -> 6 | AC32: PKGS
A33: 8. Voyage No / Рейс № | I33: 9. Sailing on or about / Дата или ожидаемая дата | S33: Net Weight (kg) | X33: : | Y33: ='Summary PL'!L20 -> 2079 | AC33: KG
S34: Gross Weight (kg) | X34: : | Y34: ='Summary PL'!M20 -> 3130 | AC34: KG
B35: 2626W | J35: 46213 | S35: Dimension (m3) | X35: : | Y35: ='Summary PL'!K20 -> 7.726 | AC35: m3
A37: 10. Customs Place / Место таможенного оформления
A40: 15. Description of Goods / Описание товара | R40: 16. HS CODE / | W40: 17. Quantity / | AA40: 18. Total Price (USD)
R41: Код ТН ВЭД | W41: Количество | AA41: Общая сумма (Дол. США)
B42: =PL!B42 -> Fiber Optic Cable | R42: 8544.70-0000 | W42: 1 SET | AC42: =CI_BD!H15 -> 236916.38 | AD42: CD - Eletrical System
B43: Силовые кабели и кабели управления | W43: / комплект
I45: Total (DAP Value) | AA45: =SUM(AC42:AC44) -> 236916.38
S52: Signed by
A53: Doosan Enerbility Co., Ltd
...

Sheet CI_BD
I1: HEAD OFFICE & CHANGWON PLANT
I2: 22, DoosanVolvo-ro, Seongsan-gu, Changwon-Si,
I3: Gyeongsangnam-do, Korea
I4: (P.O.BOX 77, Changwon, Korea)
I5: TEL:(055)278-6114,7114 FAX:(055)264-5551/2
A6: Invoice (Break-down)
A7: Invoice № : | B7: =CI!V8 -> PGU-DE-0581
A8: № | B8: № Package | C8: Description of Goods Specification | D8: HS CODE | E8: Quantity | F8: Unit | G8: U/Price (USD) | H8: Amount (USD) | I8: Country of Origin | J8: Remark
A9: 1 | B9: PGU-DE-0581-PRP-FC-001 | C9: FO Cable | D9: 8544.70-0000 | E9: 1 | F9: EA | G9: 31790.7 | H9: 31790.7 | I9: Korea
A10: 2 | B10: PGU-DE-0581-PRP-FC-002 | C10: FO Cable | D10: 8544.70-0001 | E10: 1 | F10: EA | G10: 35121.15 | H10: 35121.15 | I10: Korea
A11: 3 | B11: PGU-DE-0581-PRP-FC-003 | C11: FO Cable | D11: 8544.70-0002 | E11: 1 | F11: EA | G11: 42614.67 | H11: 42614.67 | I11: Korea
A12: 4 | B12: PGU-DE-0581-PRP-FC-004 | C12: FO Cable | D12: 8544.70-0003 | E12: 1 | F12: EA | G12: 42614.67 | H12: 42614.67 | I12: Korea
A13: 5 | B13: PGU-DE-0581-PRP-FC-005 | C13: FO Cable | D13: 8544.70-0004 | E13: 1 | F13: EA | G13: 31487.93 | H13: 31487.93 | I13: Korea
A14: 6 | B14: PGU-DE-0581-PRP-FC-006 | C14: FO Cable | D14: 8544.70-0005 | E14: 1 | F14: EA | G14: 53287.26 | H14: 53287.26 | I14: Korea
C15: TOTAL | H15: =SUM(H9:H14) -> 236916.38

Sheet PL
W1: HEAD OFFICE & CHANGWON PLANT
W2: 22, DoosanVolvo-ro, Seongsan-gu, Changwon-Si,
W3: Gyeongsangnam-do, Korea
W4: (P.O.BOX 77, Changwon, Korea)
W5: TEL:(055)278-6114,7114 FAX:(055)264-5551/2
A6: PACKING LIST УПАКОВОЧНЫЙ ЛИСТ
A8: 1. Shipper / Грузоотправитель | R8: 11. Invoice № : | V8: PGU-DE-0581
B9: Doosan Enerbility Co., Ltd (DOOSAN) | R9: Инвойс №
B10: 22, DoosanVolvo-ro, Seongsan-gu, Changwon-si, Gyeongsangnam-do | R10: 12. Date : | V10: 46157
B11: Republic of Korea | R11: Дата
A12: 2. Consignee / Грузополучатель | R12: 13. Remarks / Примечания
B13: Branch of JSC "Doosan Enerbility" in the Turkestan region
B14: 321 Tauke Khan Avenue, Turkestan region, Turkestan, Kazakhstan, 161200 | S14: *Project Name / Название Проекта
B15: BIN: 230741006561 | S15: Construction of a 1000 MW CCGT Power Plant in the Sairam District of
S16: Turkistan Region, Main Site. Without External Engineering Networks
S17: *MANUFACTURER'S NAME / НАЗВАНИЕ ПРОИЗВОДИТЕЛЯ
A18: 3. Notify party / Уведомляемая сторона | S18: WONLEE Solutions
B19: Wise Logistics | S19: *MANUFACTURE YEAR / ГОД ИЗГОТОВЛЕНИЯ
B20: ATTAN: MS. Aliya | S20: 2026
B21: (E): a.kipshakbayeva@wiselogistics.kz | S21: *COUNTRY OF ORIGIN / СТРАНА ПРОИСХОЖДЕНИЯ
B22: (T): +7 701 512 19 69 | S22: Korea
S23: *INCOTERMS / УСЛОВИЯ ПОСТАВКИ СОГЛАСНО ИНКОТЕРМС
S24: DAP Sairam district
S25: * CONTRACT NO. / НОМЕР КОНТРАКТ
A26: 4. Port of Loading / Порт погрузки | I26: 5. Carrier / Перевозчик | S26: 0123-ПГУТ-8Д date 14.03.2023
B27: Busan, Korea | J27: HEUNG-A JANICE
A29: 6. Port of Unloading / Порт разгрузки | I29: 7. Final Destination / Конечный пункт назначения | R29: 14. Mark and Numbers of PKGS / Маркировка и количество упаковок
B31: Qingdao, China | I31: Turkestan Oblast, Sairam district | S31: PKG No. | X31: : | Y31: PGU-DE-0581-PRP-FC-001~006
S32: Q-ty of Package | X32: : | Y32: =COUNT('Summary PL'!A14:A19) -> 6 | AC32: PKGS
A33: 8. Voyage No / Рейс № | I33: 9. Sailing on or about / Дата или ожидаемая дата | S33: Net Weight (kg) | X33: : | Y33: ='Summary PL'!L20 -> 2079 | AC33: KG
S34: Gross Weight (kg) | X34: : | Y34: ='Summary PL'!M20 -> 3130 | AC34: KG
B35: 2626W | J35: 46213 | S35: Dimension (m3) | X35: : | Y35: ='Summary PL'!K20 -> 7.726 | AC35: m3
A37: 10. Customs Place / Место таможенного оформления
A40: 15. Description of Goods / Описание товара | R40: 16. Q-ty | U40: 17. Net Weight | Y40: 18. Gross Weight | AC40: 19. Measurement
R41: (EA) | U41: (kg) | Y41: (kg) | AC41: (CBM)
B42: Fiber Optic Cable | R42: 1 SET | U42: ='Summary PL'!L20 -> 2079 | Y42: ='Summary PL'!M20 -> 3130 | AC42: ='Summary PL'!K20 -> 7.726
B43: =CI!B43 -> Силовые кабели и кабели управления | R43: / комплект
U45: =SUM(U42:X43) -> 2079 | Y45: =SUM(Y42:AB43) -> 3130 | AC45: =SUM(AC42:AC43) -> 7.726
S53: Signed by
A54: Doosan Enerbility Co., Ltd
...

Sheet Summary PL
O1: HEAD OFFICE & CHANGWON PLANT | R1: Storage Classification "A" : | S1: Indoor with Air-conditioning
O2: 22, DoosanVolvo-ro, Seongsan-gu, Changwon-Si, | Q2: Note> | R2: Storage Classification "B" : | S2: Indoor without Air-conditioning
O3: Gyeongsangnam-do, Korea | R3: Storage Classification "C" : | S3: Outdoor with Waterproofing
O4: (P.O.BOX 77, Changwon, Korea) | R4: Storage Classification "D" : | S4: Outdoor without Waterproofing
O5: TEL:(055)278-6114,7114 FAX:(055)264-5551/2
A6: SUMMARY PACKING LIST CВОДНЫЙ УПАКОВОЧНЫЙ ЛИСТ
A7: Project Name: | B7: Construction of a 1000 MW CCGT Power Plant in the Sairam District of the Turkistan Region
B8: Main Site. Without External Engineering Networks
A9: Invoice №: | B9: =PL!V8 -> PGU-DE-0581
A10: Name of Consignee: | B10: CCGT Turkestan LLP
A11: Consignee address: | B11: Republic of Kazakhstan, Turkistan Region, Sairam District, Karamurt Rural District, Quarter 171
A12: № | B12: CNTR No. / Seal No. / № контейнера / № пломбы | C12: Package No. / № упаковки | D12: Description / Описание | E12: Packing Style / Вид упаковки | F12: Quantity / Количество | H12: Shipping Dimension / Отгрузочные параметры | L12: Net Weight (kg) / Вес нетто (кг) | M12: Gross Weight (kg) / Вес брутто (кг) | N12: Hazardous Material (UN Number) | O12: Storage Class / Класс хранения | P12: Stackable / Штабелируемый
F13: Q'ty / Количество | G13: Unit / Ед.изм. | H13: L (cm) / Д (см) | I13: W (cm) / Ш (см) | J13: H (cm) / В (см) | K13: CBM (m3) / Объем (м3)
A14: 1 | C14: PGU-DE-0581-PRP-FC-001 | D14: FO Cable, MM Armoured (24C)-2000M | E14: Wooden | F14: 1 | G14: EA | H14: 125 | I14: 75 | J14: 125 | K14: =ROUND(J14*I14*H14/1000000,3) -> 1.172 | L14: ='Detail PL'!K15 -> 261 | M14: 420 | N14: N | O14: B | P14: N
A15: 2 | C15: PGU-DE-0581-PRP-FC-002 | D15: FO Cable, MM Armoured (4C)-2300M | E15: Wooden | F15: 1 | G15: EA | H15: 125 | I15: 75 | J15: 125 | K15: =ROUND(J15*I15*H15/1000000,3) -> 1.172 | L15: ='Detail PL'!K17 -> 296 | M15: 464 | N15: N | O15: B | P15: N
A16: 3 | C16: PGU-DE-0581-PRP-FC-003 | D16: FO Cable, MM Armoured (8C)-3000M | E16: Wooden | F16: 1 | G16: EA | H16: 132 | I16: 75 | J16: 132 | K16: =ROUND(J16*I16*H16/1000000,3) -> 1.307 | L16: ='Detail PL'!K19 -> 387 | M16: 563 | N16: N | O16: B | P16: N
A17: 4 | C17: PGU-DE-0581-PRP-FC-004 | D17: FO Cable, MM Armoured (8C)-3000M | E17: Wooden | F17: 1 | G17: EA | H17: 132 | I17: 75 | J17: 132 | K17: =ROUND(J17*I17*H17/1000000,3) -> 1.307 | L17: ='Detail PL'!K21 -> 387 | M17: 563 | N17: N | O17: B | P17: N
A18: 5 | C18: PGU-DE-0581-PRP-FC-005 | D18: FO Cable, SM Armoured (4C)-2000M | E18: Wooden | F18: 1 | G18: EA | H18: 120 | I18: 75 | J18: 120 | K18: =ROUND(J18*I18*H18/1000000,3) -> 1.08 | L18: ='Detail PL'!K23 -> 257 | M18: 416 | N18: N | O18: B | P18: N
A19: 6 | C19: PGU-DE-0581-PRP-FC-006 | D19: FO Cable, SM Armoured (8C)-3800M | E19: Wooden | F19: 1 | G19: EA | H19: 150 | I19: 75 | J19: 150 | K19: =ROUND(J19*I19*H19/1000000,3) -> 1.688 | L19: ='Detail PL'!K25 -> 491 | M19: 704 | N19: N | O19: B | P19: N
A20: TOTAL / ИТОГО | F20: =SUM(F14:F19) -> 6 | K20: =SUM(K14:K19) -> 7.726 | L20: =SUM(L14:L19) -> 2079 | M20: =SUM(M14:M19) -> 3130

Sheet Detail PL
P1: HEAD OFFICE & CHANGWON PLANT
P2: 22, DoosanVolvo-ro, Seongsan-gu, Changwon-Si, | R2: Note> | S2: Storage Classification "A" : | T2: Indoor with Air-conditioning
P3: Gyeongsangnam-do, Korea | S3: Storage Classification "B" : | T3: Indoor without Air-conditioning
P4: (P.O.BOX 77, Changwon, Korea) | S4: Storage Classification "C" : | T4: Outdoor with Waterproofing
P5: TEL:(055)278-6114,7114 FAX:(055)264-5551/2 | S5: Storage Classification "D" : | T5: Outdoor without Waterproofing
A6: DETAILED PACKING LIST ПОДРОБНЫЙ УПАКОВОЧНЫЙ ЛИСТ
A7: Project Name: | B7: Construction of a 1000 MW CCGT Power Plant in the Sairam District of the Turkistan Region
B8: Main Site. Without External Engineering Networks
A9: Invoice №: | B9: PGU-DE-0581
A10: Name of Consignee: | B10: CCGT Turkestan LLP
A11: Consignee address: | B11: Republic of Kazakhstan, Turkistan Region, Sairam District, Karamurt Rural District, Quarter 171
A12: № | B12: Package No./ Номер упаковки | C12: Description / Описание | D12: HS Code / Код ТН ВЭД | E12: Quantity / Количество | G12: Shipping Dimension / Отгрузочные параметры | K12: Net Weight (kg) / Вес нетто (кг) | L12: Gross Weight (kg) / Вес брутто (кг) | M12: Drawing No. / № чертежа | N12: Tag No. / № Тег | O12: Unit Price (US$) / Цена за единицу | P12: Total Price (US$) / Общая цена | Q12: Remark / Примечания
E13: Q'ty / Кол-во | F13: Unit / Ед. изм. | G13: L (cm) / Д (см) | H13: W (cm) / Ш (см) | I13: H (cm) / В (см) | J13: CBM (m3) / Объем (м3)
A14: 1 | B14: ='Summary PL'!C14 -> PGU-DE-0581-PRP-FC-001 | C14: FO Cable, MM Armoured (24C)-2000M | D14: 8544.70.0000 | E14: 1 | F14: BOX | G14: 125 | H14: 75 | I14: 125
G15: =SUM(G14) -> 125 | H15: =SUM(H14) -> 75 | I15: =SUM(I14) -> 125 | J15: =ROUND(I15*H15*G15/1000000,3) -> 1.172 | K15: 261 | L15: 420
A16: 2 | B16: ='Summary PL'!C15 -> PGU-DE-0581-PRP-FC-002 | C16: FO Cable, MM Armoured (4C)-2300M | D16: 8544.70.0000 | E16: 1 | F16: BOX | G16: 125 | H16: 75 | I16: 125
G17: =SUM(G16) -> 125 | H17: =SUM(H16) -> 75 | I17: =SUM(I16) -> 125 | J17: =ROUND(I17*H17*G17/1000000,3) -> 1.172 | K17: 296 | L17: 464
A18: 3 | B18: ='Summary PL'!C16 -> PGU-DE-0581-PRP-FC-003 | C18: FO Cable, MM Armoured (8C)-3000M | D18: 8544.70.0000 | E18: 1 | F18: BOX | G18: 132 | H18: 75 | I18: 132
G19: =SUM(G18) -> 132 | H19: =SUM(H18) -> 75 | I19: =SUM(I18) -> 132 | J19: =ROUND(I19*H19*G19/1000000,3) -> 1.307 | K19: 387 | L19: 563
A20: 4 | B20: ='Summary PL'!C17 -> PGU-DE-0581-PRP-FC-004 | C20: FO Cable, MM Armoured (8C)-3000M | D20: 8544.70.0000 | E20: 1 | F20: BOX | G20: 132 | H20: 75 | I20: 132
G21: =SUM(G20) -> 132 | H21: =SUM(H20) -> 75 | I21: =SUM(I20) -> 132 | J21: =ROUND(I21*H21*G21/1000000,3) -> 1.307 | K21: 387 | L21: 563
A22: 5 | B22: ='Summary PL'!C18 -> PGU-DE-0581-PRP-FC-005 | C22: FO Cable, SM Armoured (4C)-2000M | D22: 8544.70.0000 | E22: 1 | F22: BOX | G22: 120 | H22: 75 | I22: 120
G23: =SUM(G22) -> 120 | H23: =SUM(H22) -> 75 | I23: =SUM(I22) -> 120 | J23: =ROUND(I23*H23*G23/1000000,3) -> 1.08 | K23: 257 | L23: 416
A24: 6 | B24: ='Summary PL'!C19 -> PGU-DE-0581-PRP-FC-006 | C24: FO Cable, SM Armoured (8C)-3800M | D24: 8544.70.0000 | E24: 1 | F24: BOX | G24: 150 | H24: 75 | I24: 150
G25: =SUM(G24) -> 150 | H25: =SUM(H24) -> 75 | I25: =SUM(I24) -> 150 | J25: =ROUND(I25*H25*G25/1000000,3) -> 1.688 | K25: 491 | L25: 704
A26: TOTAL/ ИТОГО | J26: =SUM(J14:J25) -> 7.726 | K26: =SUM(K14:K25) -> 2079 | L26: =SUM(L14:L25) -> 3130

Sheet Marking
A1: SHIPPING MARK ГРУЗОВАЯ МАРКИРОВКА
A2: ● NAME OF THE PROJECT | F2: : | G2: Construction of a 1000 MW CCGT Power Plant in the Sairam District of the
A3: НАЗВАНИЕ ПРОЕКТА | G3: Turkistan Region, Main Site. Without External Engineering Networks
A5: ● CONSIGNEE | F5: : | G5: Branch of JSC "Doosan Enerbility" in the Turkistan region
A6: ГРУЗОПОЛУЧАТЕЛЬ
A8: ● Shipper/Exporter | F8: : Doosan Enerbility Co., LTD
A9: Грузоотправитель/Экспортер | F9: 22, Doosan Volvo-ro, Sengsan-gu, Changwon, Gyeongnam, South Korea
A11: ● Number of Invoice | F11: : | G11: =CI!$V$8 -> PGU-DE-0581
A12: № инвойса
A14: ● CARGO DESCRIPTION | F14: : | G14: ='Summary PL'!D14 -> FO Cable, MM Armoured (24C)-2000M
A15: ОПИСАНИЕ ГРУЗА
A17: ● PACKAGE NO. | F17: : | G17: ='Summary PL'!C14 -> PGU-DE-0581-PRP-FC-001
A18: УПАКОВОЧНЫЙ НОМЕР
A20: ● NET WEIGHT | F20: : | G20: ='Detail PL'!K15 -> 261 | H20: Kg
A21: ВЕС НЕТТО
A23: ● GROSS WEIGHT | F23: : | G23: ='Summary PL'!M14 -> 420 | H23: Kg
A24: ВЕС БРУТТО
A26: ● CBM(m3) | F26: : | G26: ='Summary PL'!K14 -> 1.172 | H26: m3
A27: РАЗМЕРЫ
A29: ● FINAL DESTINATION | F29: : | G29: Turkestan Oblast, Sairam district, Karamurt rural district, quarter 171, Republic of Kazakhstan
A30: КОНЕЧНЫЙ ПУНКТ НАЗНАЧЕНИЯ
E31: Doosan Enerbility
A35: SHIPPING MARK ГРУЗОВАЯ МАРКИРОВКА
A36: ● NAME OF THE PROJECT | F36: : | G36: Construction of a 1000 MW CCGT Power Plant in the Sairam District of the
A37: НАЗВАНИЕ ПРОЕКТА | G37: Turkistan Region, Main Site. Without External Engineering Networks
A39: ● CONSIGNEE | F39: : | G39: Branch of JSC "Doosan Enerbility" in the Turkistan region
A40: ГРУЗОПОЛУЧАТЕЛЬ
A42: ● Shipper/Exporter | F42: : Doosan Enerbility Co., LTD
A43: Грузоотправитель/Экспортер | F43: 22, Doosan Volvo-ro, Sengsan-gu, Changwon, Gyeongnam, South Korea
A45: ● Number of Invoice | F45: : | G45: =CI!$V$8 -> PGU-DE-0581
A46: № инвойса
A48: ● CARGO DESCRIPTION | F48: : | G48: ='Summary PL'!D15 -> FO Cable, MM Armoured (4C)-2300M
A49: ОПИСАНИЕ ГРУЗА
A51: ● PACKAGE NO. | F51: : | G51: ='Summary PL'!C15 -> PGU-DE-0581-PRP-FC-002
A52: УПАКОВОЧНЫЙ НОМЕР
A54: ● NET WEIGHT | F54: : | G54: ='Detail PL'!K17 -> 296 | H54: Kg
A55: ВЕС НЕТТО
A57: ● GROSS WEIGHT | F57: : | G57: ='Summary PL'!M15 -> 464 | H57: Kg
A58: ВЕС БРУТТО
A60: ● CBM(m3) | F60: : | G60: ='Summary PL'!K15 -> 1.172 | H60: m3
...
