Workbook

Sheet CI
W1: HEAD OFFICE & CHANGWON PLANT
W2: 22, DoosanVolvo-ro, Seongsan-gu, Changwon-Si,
W3: Gyeongsangnam-do, Korea
W4: (P.O.BOX 77, Changwon, Korea)
W5: TEL:(055)278-6114,7114 FAX:(055)264-5551/2
A6: PROFORMA INVOICE ПРОФОРМА ИНВОЙС
A8: 1. Shipper / Грузоотправитель | R8: 11. Invoice № : | V8: PGU-DE-0257
B9: Doosan Enerbility Co., Ltd (DOOSAN) | R9: Инвойс №
B10: 22, DoosanVolvo-ro, Seongsan-gu, Changwon-si, Gyeongsangnam-do, | R10: 12. Date : | V10: 45770
B11: Republic of Korea | R11: Дата
A12: 2. Consignee / Грузополучатель | R12: 13. Remarks / Примечания
B13: CCGT Turkestan LLP
B14: Republic of Kazakhstan, Turkestan region, Sairam district, | S14: *Project Name / Название Проекта
B15: Aksukent rural district, Aksu village, Zhibek Zholy street, building 55 | S15: Construction of a 1000 MW CCGT Power Plant in the Sairam District of
B16: BIN: 110740016192 | S16: Turkistan Region, Main Site. Without External Engineering Networks
B17: info@ccgt.kz | S17: *MANUFACTURER'S NAME / НАЗВАНИЕ ПРОИЗВОДИТЕЛЯ
S18: Doosan Škoda Power a.s.
A19: 3. Notify party / Уведомляемая сторона | S19: *MANUFACTURE YEAR / ГОД ИЗГОТОВЛЕНИЯ
B20: Wise Logistics | S20: 2024
B21: ATTAN: MS. Aliya | S21: *COUNTRY OF ORIGIN / СТРАНА ПРОИСХОЖДЕНИЯ
B22: (E): a.kipshakbayeva@wiselogistics.kz | S22: Germany
B23: (T): +7 701 512 19 69 | S23: *INCOTERMS / УСЛОВИЯ ПОСТАВКИ СОГЛАСНО ИНКОТЕРМС
S24: DAP Main site
S25: * CONTRACT NO. / НОМЕР КОНТРАКТ
A26: 4. Port of Loading / Порт погрузки | I26: 5. Carrier / Перевозчик | S26: 0123-ПГУТ-8Д date 14.03.2023
B27: Hamburg, Germany | J27: MV DA QING
A29: 6. Port of Unloading / Порт разгрузки | I29: 7. Final Destination / Конечный пункт назначения | R29: 14. Mark and Numbers of PKGS / Маркировка и количество упаковок
B31: Tianjin, China | I31: Turkestan region, Sairam district | S31: PKG No. | X31: : | Y31: PGU-DE-0257-STG-CON-001 ~ 019
S32: Q-ty of Package | X32: : | Y32: =COUNT('Summary PL'!A14:A32) -> 19 | AC32: PKGS
A33: 8. Voyage No / Рейс № | I33: 9. Sailing on or about / Дата или ожидаемая дата | S33: Net Weight (kg) | X33: : | Y33: ='Summary PL'!L33 -> 9082 | AC33: KG
S34: Gross Weight (kg) | X34: : | Y34: ='Summary PL'!M33 -> 11264 | AC34: KG
J35: =V10 -> 45770 | S35: Dimension (m3) | X35: : | Y35: ='Summary PL'!K33 -> 48.920486 | AC35: m3
A37: 10. Customs Place / Место таможенного оформления
A40: 15. Description of Goods / Описание товара | R40: 16. HS CODE / | W40: 17. Quantity / | AA40: 18. Total Price (USD)
R41: Код ТН ВЭД | W41: Количество | AA41: Общая сумма (Дол. США)
B42: STG_Control system Unit 2 | R42: 8502 39 2000 | W42: 1 | AC42: =CI_BD!I28 -> 501228
B43: Система управления | W43: / комплект
I45: Total (DAP Value) | AA45: =AC42 -> 501228
S53: Signed by
A54: Doosan Enerbility Co., Ltd
...

Sheet CI_BD
J1: HEAD OFFICE & CHANGWON PLANT
J2: 22, DoosanVolvo-ro, Seongsan-gu, Changwon-Si,
J3: Gyeongsangnam-do, Korea
J4: (P.O.BOX 77, Changwon, Korea)
J5: TEL:(055)278-6114,7114 FAX:(055)264-5551/2
A6: PROFORMA INVOICE (Break-down) ПРОФОРМА-ИНВОЙС (Разбивка)
A7: Invoice № : | B7: =CI!V8 -> PGU-DE-0257
A8: № | B8: № Package | C8: Description of Goods Specification | D8: Material | E8: HS CODE | F8: Quantity | G8: Unit | H8: U/Price (USD) | I8: Amount (USD) | J8: Country of Origin | K8: Remark
A9: 1 | B9: PGU-DE-0257-STG-CON-001 | C9: Cables | F9: 1 | G9: EA / ШТ. | H9: 27925.72 | I9: =F9*H9 -> 27925.72
A10: 2 | B10: PGU-DE-0257-STG-CON-002 | C10: Cables | F10: 1 | G10: EA / ШТ. | H10: 11589.72 | I10: =F10*H10 -> 11589.72
A11: 3 | B11: PGU-DE-0257-STG-CON-003 | C11: Cables | F11: 1 | G11: EA / ШТ. | H11: 31016.31 | I11: =F11*H11 -> 31016.31
A12: 4 | B12: PGU-DE-0257-STG-CON-004 | C12: Cables | F12: 1 | G12: EA / ШТ. | H12: 23786.53 | I12: =F12*H12 -> 23786.53
A13: 5 | B13: PGU-DE-0257-STG-CON-005 | C13: Cables | F13: 1 | G13: EA / ШТ. | H13: 30464.42 | I13: =F13*H13 -> 30464.42
A14: 6 | B14: PGU-DE-0257-STG-CON-006 | C14: Cables | F14: 1 | G14: EA / ШТ. | H14: 30464.42 | I14: =F14*H14 -> 30464.42
A15: 7 | B15: PGU-DE-0257-STG-CON-007 | C15: Cables | F15: 1 | G15: EA / ШТ. | H15: 30188.47 | I15: =F15*H15 -> 30188.47
A16: 8 | B16: PGU-DE-0257-STG-CON-008 | C16: Cables | F16: 1 | G16: EA / ШТ. | H16: 30464.42 | I16: =F16*H16 -> 30464.42
A17: 9 | B17: PGU-DE-0257-STG-CON-009 | C17: Cables | F17: 1 | G17: EA / ШТ. | H17: 30409.23 | I17: =F17*H17 -> 30409.23
A18: 10 | B18: PGU-DE-0257-STG-CON-010 | C18: Cables | F18: 1 | G18: EA / ШТ. | H18: 3532.11 | I18: =F18*H18 -> 3532.11
A19: 11 | B19: PGU-DE-0257-STG-CON-011 | C19: Cables | F19: 1 | G19: EA / ШТ. | H19: 2428.32 | I19: =F19*H19 -> 2428.32
A20: 12 | B20: PGU-DE-0257-STG-CON-012 | C20: Cables | F20: 1 | G20: EA / ШТ. | H20: 5187.78 | I20: =F20*H20 -> 5187.78
... A27: 19 | B27: PGU-DE-0257-STG-CON-019 | C27: Cable traces and structures equipment | F27: 1 | G27: EA / ШТ. | H27: 81790.34 | I27: =F27*H27 -> 81790.34
B28: TOTAL | I28: =SUM(I9:I27) -> 501228

Sheet PL
W1: HEAD OFFICE & CHANGWON PLANT
W2: 22, DoosanVolvo-ro, Seongsan-gu, Changwon-Si,
W3: Gyeongsangnam-do, Korea
W4: (P.O.BOX 77, Changwon, Korea)
W5: TEL:(055)278-6114,7114 FAX:(055)264-5551/2
A6: PACKING LIST УПАКОВОЧНЫЙ ЛИСТ
A8: 1. Shipper / Грузоотправитель | R8: 11. Invoice № : | V8: =CI!V8 -> PGU-DE-0257
B9: Doosan Enerbility Co., Ltd (DOOSAN) | R9: Инвойс №
B10: 22, DoosanVolvo-ro, Seongsan-gu, Changwon-si, Gyeongsangnam-do, | R10: 12. Date : | V10: =CI!V10 -> 45770
B11: Republic of Korea | R11: Дата
A12: 2. Consignee / Грузополучатель | R12: 13. Remarks / Примечания
B13: CCGT Turkestan LLP
B14: Republic of Kazakhstan, Turkestan region, Sairam district, | S14: *Project Name / Название Проекта
B15: Aksukent rural district, Aksu village, Zhibek Zholy street, building 55 | S15: Construction of a 1000 MW CCGT Power Plant in the Sairam District of Turkistan Region, Main Site. Without External Engineering Networks
B16: BIN: 110740016192
B17: info@ccgt.kz | S17: *MANUFACTURER'S NAME / НАЗВАНИЕ ПРОИЗВОДИТЕЛЯ
S18: Doosan Škoda Power a.s.
A19: 3. Notify party / Уведомляемая сторона | S19: *MANUFACTURE YEAR / ГОД ИЗГОТОВЛЕНИЯ
B20: Wise Logistics | S20: 2024
B21: ATTAN: MS. Aliya | S21: *COUNTRY OF ORIGIN / СТРАНА ПРОИСХОЖДЕНИЯ
B22: (E): a.kipshakbayeva@wiselogistics.kz | S22: Germany
B23: (T): +7 701 512 19 69 | S23: *INCOTERMS / УСЛОВИЯ ПОСТАВКИ СОГЛАСНО ИНКОТЕРМС
S24: DAP Main site
S25: * CONTRACT NO. / НОМЕР КОНТРАКТ
A26: 4. Port of Loading / Порт погрузки | I26: 5. Carrier / Перевозчик | S26: 0123-ПГУТ-8Д date 14.03.2023
B27: Hamburg, Germany | J27: =CI!J27 -> MV DA QING
A29: 6. Port of Unloading / Порт разгрузки | I29: 7. Final Destination / Конечный пункт назначения | R29: 14. Mark and Numbers of PKGS / Маркировка и количество упаковок
B31: =CI!B31 -> Tianjin, China | I31: Turkestan region, Sairam district | S31: PKG No. | X31: : | Y31: =CI!Y31 -> PGU-DE-0257-STG-CON-001 ~ 019
S32: Q-ty of Package | X32: : | Y32: =COUNT('Summary PL'!A14:A32) -> 19 | AC32: PKGS
A33: 8. Voyage No / Рейс № | I33: 9. Sailing on or about / Дата или ожидаемая дата | S33: Net Weight (kg) | X33: : | Y33: =U45 -> 9082 | AC33: KG
S34: Gross Weight (kg) | X34: : | Y34: =Y45 -> 11264 | AC34: KG
J35: 45770 | S35: Dimension (m3) | X35: : | Y35: =AC45 -> 48.920486 | AC35: m3
A37: 10. Customs Place / Место таможенного оформления
A40: 15. Description of Goods / Описание товара | R40: 16. Q-ty | U40: 17. Net Weight | Y40: 18. Gross Weight | AC40: 19. Measurement
R41: (EA) | U41: (kg) | Y41: (kg) | AC41: (CBM)
B42: STG_Control system Unit 2 | R42: =CI!W42 -> 1 | U42: =+'Summary PL'!L33 -> 9082 | Y42: =+'Summary PL'!M33 -> 11264 | AC42: =+'Summary PL'!K33 -> 48.920486
B43: =CI!B43 -> Система управления | R43: / комплект
U45: =SUM(U42:X44) -> 9082 | Y45: =SUM(Y42:AB44) -> 11264 | AC45: =SUM(AC42:AC44) -> 48.920486
S53: Signed by
A54: Doosan Enerbility Co., Ltd
...

Sheet Summary PL
O1: HEAD OFFICE & CHANGWON PLANT | Q1: Note> | R1: Storage Classification "A" : | S1: Indoor with Air-conditioning
O2: 22, DoosanVolvo-ro, Seongsan-gu, Changwon-Si, | R2: Storage Classification "B" : | S2: Indoor without Air-conditioning
O3: Gyeongsangnam-do, Korea | R3: Storage Classification "C" : | S3: Outdoor with Waterproofing
O4: (P.O.BOX 77, Changwon, Korea) | R4: Storage Classification "D" : | S4: Outdoor without Waterproofing
O5: TEL:(055)278-6114,7114 FAX:(055)264-5551/2
A6: SUMMARY PACKING LIST CВОДНЫЙ УПАКОВОЧНЫЙ ЛИСТ
A7: Project Name: | B7: Construction of a 1000 MW CCGT Power Plant in the Sairam District of the Turkistan Region
B8: Main Site. Without External Engineering Networks
A9: Invoice №: | B9: =PL!V8 -> PGU-DE-0257
A10: Name of Consignee: | B10: =PL!B13 -> CCGT Turkestan LLP
A11: Consignee address: | B11: =PL!B14&PL!B15 -> Republic of Kazakhstan, Turkestan region, Sairam district, Aksukent rural district, Aksu village, Zhibek Zholy street, building 55
A12: № | B12: CNTR No. / Seal No. / № контейнера / № пломбы | C12: Package No. / № упаковки | D12: Description / Описание | E12: Packing Style / Вид упаковки | F12: Quantity / Количество | H12: Shipping Dimension / Отгрузочные параметры | L12: Net Weight (kg) / Вес нетто (кг) | M12: Gross Weight (kg) / Вес брутто (кг) | N12: Hazardous Material (UN Number) | O12: Storage Class / Класс хранения | P12: Stackable / Штабелируемый
F13: Q'ty / Количество | G13: Unit / Ед.изм. | H13: L (cm) / Д (см) | I13: W (cm) / Ш (см) | J13: H (cm) / В (см) | K13: CBM (m3) / Объем (м3)
A14: 1 | C14: PGU-DE-0257-STG-CON-001 | D14: Cables / Кабели | E14: Drum | F14: 1 | G14: EA / ШТ. | H14: 130 | I14: 90 | J14: 130 | K14: =+H14*I14*J14/100^3 -> 1.521 | L14: 506 | M14: 577 | O14: D | P14: N
A15: 2 | C15: PGU-DE-0257-STG-CON-002 | D15: Cables / Кабели | E15: Drum | F15: 1 | G15: EA / ШТ. | H15: 130 | I15: 90 | J15: 130 | K15: =+H15*I15*J15/100^3 -> 1.521 | L15: 210 | M15: 281 | O15: D | P15: N
A16: 3 | C16: PGU-DE-0257-STG-CON-003 | D16: Cables / Кабели | E16: Drum | F16: 1 | G16: EA / ШТ. | H16: 130 | I16: 90 | J16: 130 | K16: =+H16*I16*J16/100^3 -> 1.521 | L16: 562 | M16: 633 | O16: D | P16: N
A17: 4 | C17: PGU-DE-0257-STG-CON-004 | D17: Cables / Кабели | E17: Drum | F17: 1 | G17: EA / ШТ. | H17: 130 | I17: 90 | J17: 130 | K17: =+H17*I17*J17/100^3 -> 1.521 | L17: 431 | M17: 502 | O17: D | P17: N
A18: 5 | C18: PGU-DE-0257-STG-CON-005 | D18: Cables / Кабели | E18: Drum | F18: 1 | G18: EA / ШТ. | H18: 130 | I18: 90 | J18: 130 | K18: =+H18*I18*J18/100^3 -> 1.521 | L18: 552 | M18: 623 | O18: D | P18: N
A19: 6 | C19: PGU-DE-0257-STG-CON-006 | D19: Cables / Кабели | E19: Drum | F19: 1 | G19: EA / ШТ. | H19: 130 | I19: 90 | J19: 130 | K19: =+H19*I19*J19/100^3 -> 1.521 | L19: 552 | M19: 623 | O19: D | P19: N
A20: 7 | C20: PGU-DE-0257-STG-CON-007 | D20: Cables / Кабели | E20: Drum | F20: 1 | G20: EA / ШТ. | H20: 130 | I20: 90 | J20: 130 | K20: =+H20*I20*J20/100^3 -> 1.521 | L20: 547 | M20: 618 | O20: D | P20: N
A21: 8 | C21: PGU-DE-0257-STG-CON-008 | D21: Cables / Кабели | E21: Drum | F21: 1 | G21: EA / ШТ. | H21: 130 | I21: 90 | J21: 130 | K21: =+H21*I21*J21/100^3 -> 1.521 | L21: 552 | M21: 623 | O21: D | P21: N
A22: 9 | C22: PGU-DE-0257-STG-CON-009 | D22: Cables / Кабели | E22: Drum | F22: 1 | G22: EA / ШТ. | H22: 130 | I22: 90 | J22: 130 | K22: =+H22*I22*J22/100^3 -> 1.521 | L22: 551 | M22: 622 | O22: D | P22: N
A23: 10 | C23: PGU-DE-0257-STG-CON-010 | D23: Cables / Кабели | E23: Drum | F23: 1 | G23: EA / ШТ. | H23: 90 | I23: 70 | J23: 90 | K23: =+H23*I23*J23/100^3 -> 0.567 | L23: 64 | M23: 99 | O23: D | P23: N
A24: 11 | C24: PGU-DE-0257-STG-CON-011 | D24: Cables / Кабели | E24: Drum | F24: 1 | G24: EA / ШТ. | H24: 90 | I24: 70 | J24: 90 | K24: =+H24*I24*J24/100^3 -> 0.567 | L24: 44 | M24: 79 | O24: D | P24: N
A25: 12 | C25: PGU-DE-0257-STG-CON-012 | D25: Cables / Кабели | E25: Drum | F25: 1 | G25: EA / ШТ. | H25: 90 | I25: 70 | J25: 90 | K25: =+H25*I25*J25/100^3 -> 0.567 | L25: 94 | M25: 129 | O25: D | P25: N
... A32: 19 | C32: PGU-DE-0257-STG-CON-019 | D32: Cable traces and structures equipment / Оборудование для кабельных трасс и конструкций | E32: Wooden box | F32: 1 | G32: EA / ШТ. | H32: 339 | I32: 189 | J32: 156 | K32: =+H32*I32*J32/100^3 -> 9.995076 | L32: 1482 | M32: 1820 | O32: C | P32: N
A33: TOTAL / ИТОГО | K33: =SUM(K14:K32) -> 48.920486 | L33: =SUM(L14:L32) -> 9082 | M33: =SUM(M14:M32) -> 11264

Sheet Detail PL
P1: HEAD OFFICE & CHANGWON PLANT
P2: 22, DoosanVolvo-ro, Seongsan-gu, Changwon-Si,
P3: Gyeongsangnam-do, Korea
P4: (P.O.BOX 77, Changwon, Korea)
P5: TEL:(055)278-6114,7114 FAX:(055)264-5551/2
A6: DETAILED PACKING LIST ПОДРОБНЫЙ УПАКОВОЧНЫЙ ЛИСТ
A7: Project Name: | B7: Construction of a 1000 MW CCGT Power Plant in the Sairam District of the Turkistan Region
B8: Main Site. Without External Engineering Networks
A9: Invoice №: | B9: =PL!V8 -> PGU-DE-0257
A10: Name of Consignee: | B10: =PL!B13 -> CCGT Turkestan LLP
A11: Consignee address: | B11: ='Summary PL'!B11 -> Republic of Kazakhstan, Turkestan region, Sairam district, Aksukent rural district, Aksu village, Zhibek Zholy street, building 55
A12: № | B12: Package No./ Номер упаковки | C12: Description / Описание | D12: HS Code / Код ТН ВЭД | E12: Quantity / Количество | G12: Shipping Dimension / Отгрузочные параметры | K12: Net Weight (kg) / Вес нетто (кг) | L12: Gross Weight (kg) / Вес брутто (кг) | M12: Drawing No. / № чертежа | N12: Tag No. / № Тег | O12: Unit Price (US$) / Цена за единицу | P12: Total Price (US$) / Общая цена | Q12: Remark / Примечания
E13: Q'ty / Кол-во | F13: Unit / Ед. изм. | G13: L (cm) / Д (см) | H13: W (cm) / Ш (см) | I13: H (cm) / В (см) | J13: CBM (m3) / Объем (м3)
A14: 1 | B14: PGU-DE-0257-STG-CON-001 | C14: Cables 2x2x1 | E14: 1 | F14: EA/ШТ. | M14: CCP-W-B113-03-ME-E10-0075 | N14: PI-I-5026
G15: 130 | H15: 90 | I15: 130 | J15: =+G15*H15*I15/100^3 -> 1.521 | K15: 506 | L15: 577
A16: 2 | B16: PGU-DE-0257-STG-CON-002 | C16: Cables 2x2x1 | E16: 1 | F16: EA/ШТ. | M16: CCP-W-B113-03-ME-E10-0075 | N16: PI-I-5023
G17: 130 | H17: 90 | I17: 130 | J17: =+G17*H17*I17/100^3 -> 1.521 | K17: 210 | L17: 281
A18: 3 | B18: PGU-DE-0257-STG-CON-003 | C18: Cables 5x2x1 | E18: 1 | F18: EA/ШТ. | M18: CCP-W-B113-03-ME-E10-0075 | N18: PI-I-5021
G19: 130 | H19: 90 | I19: 130 | J19: =+G19*H19*I19/100^3 -> 1.521 | K19: 562 | L19: 633
A20: 4 | B20: PGU-DE-0257-STG-CON-004 | C20: Cables 5x2x1 | E20: 1 | F20: EA/ШТ. | M20: CCP-W-B113-03-ME-E10-0075 | N20: PI-I-5027
G21: 130 | H21: 90 | I21: 130 | J21: =+G21*H21*I21/100^3 -> 1.521 | K21: 431 | L21: 502
A22: 5 | B22: PGU-DE-0257-STG-CON-005 | C22: Cables 10x2x1 | E22: 1 | F22: EA/ШТ. | M22: CCP-W-B113-03-ME-E10-0075 | N22: PI-I-5022
G23: 130 | H23: 90 | I23: 130 | J23: =+G23*H23*I23/100^3 -> 1.521 | K23: 552 | L23: 623
A24: 6 | B24: PGU-DE-0257-STG-CON-006 | C24: Cables 10x2x1 | E24: 1 | F24: EA/ШТ. | M24: CCP-W-B113-03-ME-E10-0075 | N24: PI-I-5028
G25: 130 | H25: 90 | I25: 130 | J25: =+G25*H25*I25/100^3 -> 1.521 | K25: 552 | L25: 623
A26: 7 | B26: PGU-DE-0257-STG-CON-007 | C26: Cables 10x2x1 | E26: 1 | F26: EA/ШТ.
G27: 130 | H27: 90 | I27: 130 | J27: =+G27*H27*I27/100^3 -> 1.521 | K27: 547 | L27: 618
A28: 8 | B28: PGU-DE-0257-STG-CON-008 | C28: Cables 10x2x1 | E28: 1 | F28: EA/ШТ.
G29: 130 | H29: 90 | I29: 130 | J29: =+G29*H29*I29/100^3 -> 1.521 | K29: 552 | L29: 623
A30: 9 | B30: PGU-DE-0257-STG-CON-009 | C30: Cables 10x2x1 | E30: 1 | F30: EA/ШТ.
G31: 130 | H31: 90 | I31: 130 | J31: =+G31*H31*I31/100^3 -> 1.521 | K31: 551 | L31: 622
A32: 10 | B32: PGU-DE-0257-STG-CON-010 | C32: Cables 1x2x2,5 | E32: 1 | F32: EA/ШТ.
G33: 90 | H33: 70 | I33: 90 | J33: =+G33*H33*I33/100^3 -> 0.567 | K33: 64 | L33: 99
A34: 11 | B34: PGU-DE-0257-STG-CON-011 | C34: Cables 1x2x2,5 | E34: 1 | F34: EA/ШТ.
G35: 90 | H35: 70 | I35: 90 | J35: =+G35*H35*I35/100^3 -> 0.567 | K35: 44 | L35: 79
A36: 12 | B36: PGU-DE-0257-STG-CON-012 | C36: Cables 1x2x2,5 | E36: 1 | F36: EA/ШТ.
G37: 90 | H37: 70 | I37: 90 | J37: =+G37*H37*I37/100^3 -> 0.567 | K37: 94 | L37: 129
A38: 13 | B38: PGU-DE-0257-STG-CON-013 | C38: Optical cable | E38: 1 | F38: EA/ШТ.
G39: 130 | H39: 90 | I39: 130 | J39: =+G39*H39*I39/100^3 -> 1.521 | K39: 385 | L39: 485
A40: 14 | B40: PGU-DE-0257-STG-CON-014 | C40: Cable KX-1-1-F-2 x 2 x 0,5 mm2 | E40: 60 | F40: m
...

Sheet Description
A1: Technical Description
A2: № | B2: Name | C2: Model-Part No. | D2: Kind of material | E2: Size/specification/ Usage | F2: Photo | G2: Manufacturer / Origin
A3: 1
A4: 2
A5: 3
A6: 4
A7: 5
A8: 6
A9: 7

Sheet Marking
A1: SHIPPING MARK ГРУЗОВАЯ МАРКИРОВКА
A2: ● NAME OF THE PROJECT | F2: : | G2: Construction of a 1000 MW CCGT Power Plant in the Sairam District of the
A3: НАЗВАНИЕ ПРОЕКТА | G3: Turkistan Region, Main Site. Without External Engineering Networks
A5: ● CONSIGNEE | F5: : | G5: ='Detail PL'!B10 -> CCGT Turkestan LLP
A6: ГРУЗОПОЛУЧАТЕЛЬ
A8: ● Shipper/Exporter | F8: : Doosan Enerbility Co., LTD
A9: Грузоотправитель/Экспортер | F9: 22, Doosan Volvo-ro, Sengsan-gu, Changwon, Gyeongnam, South Korea
A11: ● Number of Invoice | F11: : | G11: =CI!V8 -> PGU-DE-0257
A12: № инвойса
A14: ● CARGO DESCRIPTION | F14: : | G14: ='Summary PL'!D14 -> Cables / Кабели
A15: ОПИСАНИЕ ГРУЗА
A17: ● PACKAGE NO. | F17: : | G17: ='Summary PL'!C14 -> PGU-DE-0257-STG-CON-001
A18: УПАКОВОЧНЫЙ НОМЕР
A20: ● NET WEIGHT | F20: : | G20: ='Summary PL'!L14 -> 506 | H20: Kg
A21: ВЕС НЕТТО
A23: ● GROSS WEIGHT | F23: : | G23: ='Summary PL'!M14 -> 577 | H23: Kg
A24: ВЕС БРУТТО
A26: ● CBM(m3) | F26: : | G26: ='Summary PL'!K14 -> 1.521 | H26: m3
A27: РАЗМЕРЫ
A28: ● Port of Discharge | F28: : | G28: Tianjin Port, China
A29: Порт разгрузки
A31: ● FINAL DESTINATION | F31: : | G31: Turkestan Oblast, Sairam district, Karamurt rural district, quarter 171, Republic of Kazakhstan
A32: КОНЕЧНЫЙ ПУНКТ НАЗНАЧЕНИЯ
E33: Doosan Enerbility
A35: SHIPPING MARK ГРУЗОВАЯ МАРКИРОВКА
A36: ● NAME OF THE PROJECT | F36: : | G36: Construction of a 1000 MW CCGT Power Plant in the Sairam District of the
A37: НАЗВАНИЕ ПРОЕКТА | G37: Turkistan Region, Main Site. Without External Engineering Networks
A39: ● CONSIGNEE | F39: : | G39: ='Detail PL'!B10 -> CCGT Turkestan LLP
A40: ГРУЗОПОЛУЧАТЕЛЬ
A42: ● Shipper/Exporter | F42: : Doosan Enerbility Co., LTD
A43: Грузоотправитель/Экспортер | F43: 22, Doosan Volvo-ro, Sengsan-gu, Changwon, Gyeongnam, South Korea
A45: ● Number of Invoice | F45: : | G45: =CI!V8 -> PGU-DE-0257
A46: № инвойса
A48: ● CARGO DESCRIPTION | F48: : | G48: ='Summary PL'!D15 -> Cables / Кабели
A49: ОПИСАНИЕ ГРУЗА
A51: ● PACKAGE NO. | F51: : | G51: ='Summary PL'!C15 -> PGU-DE-0257-STG-CON-002
A52: УПАКОВОЧНЫЙ НОМЕР
A54: ● NET WEIGHT | F54: : | G54: ='Summary PL'!L15 -> 210 | H54: Kg
A55: ВЕС НЕТТО
A57: ● GROSS WEIGHT | F57: : | G57: ='Summary PL'!M15 -> 281 | H57: Kg
...
