Workbook
Name AnnullaInseriscidata: #REF!
Name AnnullaInseriscidata: #REF!
Name InserisciData: #REF!
Name InserisciData: #REF!

Sheet CI
W1: HEAD OFFICE & CHANGWON PLANT
W2: 22, DoosanVolvo-ro, Seongsan-gu, Changwon-Si,
W3: Gyeongsangnam-do, Korea
W4: (P.O.BOX 77, Changwon, Korea)
W5: TEL:(055)278-6114,7114 FAX:(055)264-5551/2
A6: INVOICE ИНВОЙС
A8: 1. Shipper / Грузоотправитель | R8: 11. Invoice № : | V8: PGU-DE-0560
B9: Doosan Enerbility Co., Ltd (DOOSAN) | R9: Инвойс №
B10: 22, DoosanVolvo-ro, Seongsan-gu, Changwon-si, Gyeongsangnam-do, | R10: 12. Date : | V10: 46107
B11: Republic of Korea | R11: Дата
A12: 2. Consignee / Грузополучатель | R12: 13. Remarks / Примечания
B13: Branch of JSC "Doosan Enerbility" in the Turkestan region
B14: 321 Tauke Khan Avenue, Turkestan region, Turkestan, Kazakhstan, 161200 | S14: *Project Name / Название Проекта
B15: BIN: 230741006561 | S15: Construction of a 1000 MW CCGT Power Plant in the Sairam District of
S16: Turkistan Region, Main Site. Without External Engineering Networks
S17: *MANUFACTURER'S NAME / НАЗВАНИЕ ПРОИЗВОДИТЕЛЯ
S18: DTS
A19: 3. Notify party / Уведомляемая сторона | S19: *MANUFACTURE YEAR / ГОД ИЗГОТОВЛЕНИЯ
B20: Wise Logistics | S20: 2026
B21: ATTAN: MS. Aliya | S21: *COUNTRY OF ORIGIN / СТРАНА ПРОИСХОЖДЕНИЯ
B22: (E): a.kipshakbayeva@wiselogistics.kz | S22: Republic of Korea
B23: (T): +7 701 512 19 69 | S23: *INCOTERMS / УСЛОВИЯ ПОСТАВКИ СОГЛАСНО ИНКОТЕРМС
S24: DAP Sairam district
S25: * CONTRACT NO. / НОМЕР КОНТРАКТ
A26: 4. Port of Loading / Порт погрузки | I26: 5. Carrier / Перевозчик | S26: 0123-ПГУТ-8Д date 14.03.2023
B27: Busan, Korea | J27: Later
A29: 6. Port of Unloading / Порт разгрузки | I29: 7. Final Destination / Конечный пункт назначения | R29: 14. Mark and Numbers of PKGS / Маркировка и количество упаковок
B31: Lianyungang, China | I31: Turkestan region, Sairam district | S31: PKG No. | X31: : | Y31: PGU-DE-0560-FFC-CAB-001
S32: Q-ty of Package | X32: : | Y32: =COUNT('Summary PL'!A14:A14) -> 1 | AC32: PKGS
A33: 8. Voyage No / Рейс № | I33: 9. Sailing on or about / Дата или ожидаемая дата | S33: Net Weight (kg) | X33: : | Y33: ='Summary PL'!L15 -> 1260 | AC33: KG
S34: Gross Weight (kg) | X34: : | Y34: ='Summary PL'!M15 -> 1410 | AC34: KG
B35: FU TU LIAN XING 2630W | J35: 46135 | S35: Dimension (m3) | X35: : | Y35: ='Summary PL'!K15 -> 3.46 | AC35: m3
A37: 10. Customs Place / Место таможенного оформления
A40: 15. Description of Goods / Описание товара | R40: 16. HS CODE / | W40: 17. Quantity / | AA40: 18. Total Price (USD)
R41: Код ТН ВЭД | W41: Количество | AA41: Общая сумма (Дол. США)
B42: Cable | R42: =CI_BD!D9 -> 8544.49-2012 | W42: 1 | AC42: =CI_BD!H10 -> 106608.24 | AD42: ★ CD - Electrical System
B43: =PL!B43 -> Силовые кабели и кабели управления | W43: / комплект
I45: Total (DAP Value) | AA45: =AC42 -> 106608.24
S53: Signed by
A54: Doosan Enerbility Co., Ltd
...

Sheet CI_BD
I1: HEAD OFFICE & CHANGWON PLANT
I2: 22, DoosanVolvo-ro, Seongsan-gu, Changwon-Si,
I3: Gyeongsangnam-do, Korea
I4: (P.O.BOX 77, Changwon, Korea)
I5: TEL:(055)278-6114,7114 FAX:(055)264-5551/2
A6: INVOICE (Break-down)
A7: Invoice № : | B7: =CI!V8 -> PGU-DE-0560
A8: № | B8: № Package | C8: Description of Goods Specification | D8: HS CODE | E8: Quantity | F8: Unit | G8: U/Price (USD) | H8: Amount (USD) | I8: Country of Origin | J8: Remark
A9: 1 | B9: ='Summary PL'!C14 -> PGU-DE-0560-FFC-CAB-001 | C9: Power Cable | D9: 8544.49-2012 | E9: 1 | F9: SET | G9: 106608.24 | H9: =E9*G9 -> 106608.24
C10: TOTAL | H10: =SUM(H9:H9) -> 106608.24

Sheet PL
W1: HEAD OFFICE & CHANGWON PLANT
W2: 22, DoosanVolvo-ro, Seongsan-gu, Changwon-Si,
W3: Gyeongsangnam-do, Korea
W4: (P.O.BOX 77, Changwon, Korea)
W5: TEL:(055)278-6114,7114 FAX:(055)264-5551/2
A6: PACKING LIST УПАКОВОЧНЫЙ ЛИСТ
A8: 1. Shipper / Грузоотправитель | R8: 11. Invoice № : | V8: PGU-DE-0560
B9: Doosan Enerbility Co., Ltd (DOOSAN) | R9: Инвойс №
B10: 22, DoosanVolvo-ro, Seongsan-gu, Changwon-si, Gyeongsangnam-do, | R10: 12. Date : | V10: 46107
B11: Republic of Korea | R11: Дата
A12: 2. Consignee / Грузополучатель | R12: 13. Remarks / Примечания
B13: Branch of JSC "Doosan Enerbility" in the Turkestan region
B14: 321 Tauke Khan Avenue, Turkestan region, Turkestan, Kazakhstan, 161200 | S14: *Project Name / Название Проекта
B15: BIN: 230741006561 | S15: Construction of a 1000 MW CCGT Power Plant in the Sairam District of
S16: Turkistan Region, Main Site. Without External Engineering Networks
S17: *MANUFACTURER'S NAME / НАЗВАНИЕ ПРОИЗВОДИТЕЛЯ
A18: 3. Notify party / Уведомляемая сторона | S18: DTS
B19: Wise Logistics | S19: *MANUFACTURE YEAR / ГОД ИЗГОТОВЛЕНИЯ
B20: ATTAN: MS. Aliya | S20: 2026
B21: (E): a.kipshakbayeva@wiselogistics.kz | S21: *COUNTRY OF ORIGIN / СТРАНА ПРОИСХОЖДЕНИЯ
B22: (T): +7 701 512 19 69 | S22: Republic of Korea
S23: *INCOTERMS / УСЛОВИЯ ПОСТАВКИ СОГЛАСНО ИНКОТЕРМС
S24: DAP Sairam district
S25: * CONTRACT NO. / НОМЕР КОНТРАКТ
A26: 4. Port of Loading / Порт погрузки | I26: 5. Carrier / Перевозчик | S26: 0123-ПГУТ-8Д date 14.03.2023
B27: Busan, Korea | J27: Later
A29: 6. Port of Unloading / Порт разгрузки | I29: 7. Final Destination / Конечный пункт назначения | R29: 14. Mark and Numbers of PKGS / Маркировка и количество упаковок
AD30: Turkestan region, Sairam district, Karamurt rural district, quarter 171
B31: Lianyungang, China | I31: Turkestan region, Sairam district | S31: PKG No. | X31: : | Y31: PGU-DE-0560-FFC-CAB-001
S32: Q-ty of Package | X32: : | Y32: 1 | AC32: PKGS
A33: 8. Voyage No / Рейс № | I33: 9. Sailing on or about / Дата или ожидаемая дата | S33: Net Weight (kg) | X33: : | Y33: ='Summary PL'!L15 -> 1260 | AC33: KG
S34: Gross Weight (kg) | X34: : | Y34: ='Summary PL'!M15 -> 1410 | AC34: KG
B35: FU TU LIAN XING 2630W | J35: 46135 | S35: Dimension (m3) | X35: : | Y35: ='Summary PL'!K15 -> 3.46 | AC35: m3
A37: 10. Customs Place / Место таможенного оформления
A40: 15. Description of Goods / Описание товара | R40: 16. Q-ty | U40: 17. Net Weight | Y40: 18. Gross Weight | AC40: 19. Measurement
R41: (EA) | U41: (kg) | Y41: (kg) | AC41: (CBM)
B42: =CI!B42 -> Cable | R42: =CI!W42 -> 1 | U42: ='Summary PL'!L15 -> 1260 | Y42: ='Summary PL'!M15 -> 1410 | AC42: ='Summary PL'!K15 -> 3.46
B43: Силовые кабели и кабели управления | R43: / комплект | AD43: ★ CD - Electrical System
U45: =SUM(U42:X43) -> 1260 | Y45: =SUM(Y42:AB43) -> 1410 | AC45: =SUM(AC42:AC43) -> 3.46
S53: Signed by
...

Sheet Summary PL
O1: HEAD OFFICE & CHANGWON PLANT | Q1: Note> | R1: Storage Classification "A" : | S1: Indoor with Air-conditioning
O2: 22, DoosanVolvo-ro, Seongsan-gu, Changwon-Si, | R2: Storage Classification "B" : | S2: Indoor without Air-conditioning
O3: Gyeongsangnam-do, Korea | R3: Storage Classification "C" : | S3: Outdoor with Waterproofing
O4: (P.O.BOX 77, Changwon, Korea) | R4: Storage Classification "D" : | S4: Outdoor without Waterproofing
O5: TEL:(055)278-6114,7114 FAX:(055)264-5551/2
A6: SUMMARY PACKING LIST CВОДНЫЙ УПАКОВОЧНЫЙ ЛИСТ
A7: Project Name: | B7: Construction of a 1000 MW CCGT Power Plant in the Sairam District of the Turkistan Region
B8: Main Site. Without External Engineering Networks
A9: Invoice №: | B9: =CI!V8 -> PGU-DE-0560
A10: Name of Consignee: | B10: Branch of JSC "Doosan Enerbility" in the Turkestan region
A11: Consignee address: | B11: 321 Tauke Khan Avenue, Turkestan region, Turkestan, Kazakhstan, 161200
A12: № | B12: CNTR No. / Seal No. / № контейнера / № пломбы | C12: Package No. / № упаковки | D12: Description / Описание | E12: Packing Style / Вид упаковки | F12: Quantity / Количество | H12: Shipping Dimension / Отгрузочные параметры | L12: Net Weight (kg) / Вес нетто (кг) | M12: Gross Weight (kg) / Вес брутто (кг) | N12: Hazardous Material (UN Number) | O12: Storage Class / Класс хранения | P12: Stackable / Штабелируемый
F13: Q'ty / Количество | G13: Unit / Ед.изм. | H13: L (cm) / Д (см) | I13: W (cm) / Ш (см) | J13: H (cm) / В (см) | K13: CBM (m3) / Объем (м3)
A14: 1 | C14: PGU-DE-0560-FFC-CAB-001 | D14: Power Cable / Силовой кабель | E14: Wooden Box | F14: 1 | G14: SET | H14: 135 | I14: 135 | J14: 190 | K14: =ROUND(J14*I14*H14/1000000,2) -> 3.46 | L14: 1260 | M14: =L14+150 -> 1410 | N14: N | O14: B | P14: N
A15: TOTAL / ИТОГО | F15: 1 | G15: SET | K15: =SUM(K14:K14) -> 3.46 | L15: =SUM(L14:L14) -> 1260 | M15: =SUM(M14:M14) -> 1410

Sheet Detail PL
P1: HEAD OFFICE & CHANGWON PLANT
P2: 22, DoosanVolvo-ro, Seongsan-gu, Changwon-Si, | R2: Note> | S2: Storage Classification "A" : | T2: Indoor with Air-conditioning
P3: Gyeongsangnam-do, Korea | S3: Storage Classification "B" : | T3: Indoor without Air-conditioning
P4: (P.O.BOX 77, Changwon, Korea) | S4: Storage Classification "C" : | T4: Outdoor with Waterproofing
P5: TEL:(055)278-6114,7114 FAX:(055)264-5551/2 | S5: Storage Classification "D" : | T5: Outdoor without Waterproofing
A6: DETAILED PACKING LIST ПОДРОБНЫЙ УПАКОВОЧНЫЙ ЛИСТ
A7: Project Name: | B7: Construction of a 1000 MW CCGT Power Plant in the Sairam District of the Turkistan Region
B8: Main Site. Without External Engineering Networks
A9: Invoice №: | B9: =CI!V8 -> PGU-DE-0560
A10: Name of Consignee: | B10: Branch of JSC "Doosan Enerbility" in the Turkestan region
A11: Consignee address: | B11: 321 Tauke Khan Avenue, Turkestan region, Turkestan, Kazakhstan, 161200
A12: № | B12: Package No./ Номер упаковки | C12: Description / Описание | D12: HS Code / Код ТН ВЭД | E12: Quantity / Количество | G12: Shipping Dimension / Отгрузочные параметры | K12: Net Weight (kg) / Вес нетто (кг) | L12: Gross Weight (kg) / Вес брутто (кг) | M12: Drawing No. / № чертежа | N12: Tag No. / № Тег | O12: Unit Price (US$) / Цена за единицу | P12: Total Price (US$) / Общая цена | Q12: Remark / Примечания
E13: Q'ty / Кол-во | F13: Unit / Ед. изм. | G13: L (cm) / Д (см) | H13: W (cm) / Ш (см) | I13: H (cm) / В (см) | J13: CBM (m3) / Объем (м3)
A14: 1 | B14: ='Summary PL'!C14 -> PGU-DE-0560-FFC-CAB-001 | C14: Cable 0.6/1KV CU/XLPE/LSZH 2Cx4SQ Common | D14: 8544.49-2012 | E14: 1 | F14: EA/ШТ. | K14: 670 | M14: CCP-W-B182-09-ME-H05-0002 | N14: refer to document
A15: 2 | B15: =B14 -> PGU-DE-0560-FFC-CAB-001 | C15: Cable 0.6/1KV CU/XLPE/LSZH 2Cx4SQ Common | D15: 8544.49-2012 | E15: 1 | F15: EA/ШТ. | K15: 590 | M15: CCP-W-B182-09-ME-H05-0002 | N15: refer to document
G16: 135 | H16: 135 | I16: 190 | J16: =+G16*H16*I16/100^3 -> 3.46275 | K16: =K14+K15 -> 1260 | L16: =K16+150 -> 1410
A17: TOTAL/ ИТОГО | J17: =SUM(J14:J16) -> 3.46275 | K17: =K16 -> 1260 | L17: =L16 -> 1410 | P17: =SUM(P14:P16) -> 0

Sheet Marking
A3: SHIPPING MARK ГРУЗОВАЯ МАРКИРОВКА
A4: ● NAME OF THE PROJECT | F4: : | G4: Construction of a 1000 MW CCGT Power Plant in the Sairam District of the Turkistan Region, Main Site. Without External Engineering Networks
A5: НАЗВАНИЕ ПРОЕКТА
A7: ● CONSIGNEE | F7: : | G7: Branch of JSC "Doosan Enerbility" in the Turkistan region
A8: ГРУЗОПОЛУЧАТЕЛЬ
A10: ● Shipper/Exporter | F10: : Doosan Enerbility Co., LTD
A11: Грузоотправитель/Экспортер | F11: 22, Doosan Volvo-ro, Sengsan-gu, Changwon, Gyeongnam, South Korea
A13: ● Number of Invoice | F13: : | G13: ='Summary PL'!$B$9 -> PGU-DE-0560
A14: № инвойса
A16: ● CARGO DESCRIPTION | F16: : | G16: ='Summary PL'!D14 -> Power Cable / Силовой кабель
A17: ОПИСАНИЕ ГРУЗА
A19: ● PACKAGE NO. | F19: : | G19: ='Summary PL'!C14 -> PGU-DE-0560-FFC-CAB-001
A20: УПАКОВОЧНЫЙ НОМЕР
A22: ● NET WEIGHT | F22: : | G22: ='Summary PL'!L14 -> 1260 | H22: Kg
A23: ВЕС НЕТТО
A25: ● GROSS WEIGHT | F25: : | G25: ='Summary PL'!M14 -> 1410 | H25: Kg
A26: ВЕС БРУТТО
A28: ● CBM(m3) | F28: : | G28: ='Summary PL'!K14 -> 3.46 | H28: m3
A29: РАЗМЕРЫ
A32: ● FINAL DESTINATION | F32: : | G32: Turkestan region, Sairam district, Karamurt rural district, quarter 171, Republic of Kazakhstan
A33: КОНЕЧНЫЙ ПУНКТ НАЗНАЧЕНИЯ
E36: Doosan Enerbility
