Workbook
Name AnnullaInseriscidata: #REF!
Name AnnullaInseriscidata: #REF!
Name InserisciData: #REF!
Name InserisciData: #REF!

Sheet CI
W1: HEAD OFFICE & CHANGWON PLANT
W2: 22, DoosanVolvo-ro, Seongsan-gu, Changwon-Si,
W3: Gyeongsangnam-do, Korea
W4: (P.O.BOX 77, Changwon, Korea)
W5: TEL:(055)278-6114,7114 FAX:(055)264-5551/2
A6: PROFORMA INVOICE ПРОФОРМА ИНВОЙС
A8: 1. Shipper / Грузоотправитель | R8: 11. Invoice № : | V8: PGU-DE-0311
B9: Doosan Enerbility Co., Ltd (DOOSAN) | R9: Инвойс №
B10: 22, DoosanVolvo-ro, Seongsan-gu, Changwon-si, Gyeongsangnam-do | R10: 12. Date : | V10: 45693
B11: Republic of Korea | R11: Дата
A12: 2. Consignee / Грузополучатель | R12: 13. Remarks / Примечания
B13: Branch of JSC "Doosan Enerbility" in the Turkestan region
B14: 321 Tauke Khan Avenue, Turkestan region, Turkestan, Kazakhstan, 161200 | S14: *Project Name / Название Проекта
B15: BIN: 230741006561 | S15: Construction of a 1000 MW CCGT Power Plant in the Sairam District of Turkistan Region, Main Site. Without External Engineering Networks
S17: *MANUFACTURER'S NAME / НАЗВАНИЕ ПРОИЗВОДИТЕЛЯ
A18: 3. Notify party / Уведомляемая сторона | S18: Siemens-energy
B19: Wise Logistics | S19: *MANUFACTURE YEAR / ГОД ИЗГОТОВЛЕНИЯ
B20: ATTAN: MS. Aliya | S20: 2024
B21: (E): a.kipshakbayeva@wiselogistics.kz | S21: *COUNTRY OF ORIGIN / СТРАНА ПРОИСХОЖДЕНИЯ
B22: (T): +7 701 512 19 69 | S22: Korea
S23: *INCOTERMS / УСЛОВИЯ ПОСТАВКИ СОГЛАСНО ИНКОТЕРМС
S24: DDP Turkistan
A25: 4. Port of Loading / Порт погрузки | I25: 5. Carrier / Перевозчик
B26: Busan, Korea | J26: Later
A28: 6. Port of Unloading / Порт разгрузки | I28: 7. Final Destination / Конечный пункт назначения | R28: 14. Mark and Numbers of PKGS / Маркировка и количество упаковок
B30: Later | I30: Turkestan Oblast, Sairam district | S30: PKG No. | X30: : | Y30: PGU-DE-0311-DCS-INS-001~037
S31: Q-ty of Package | X31: : | Y31: =COUNT('Summary PL'!A14:A50) -> 37 | AC31: PKGS
A32: 8. Voyage No / Рейс № | I32: 9. Sailing on or about / Дата или ожидаемая дата | S32: Net Weight (kg) | X32: : | Y32: ='Summary PL'!L51 -> 6102 | AC32: KG
S33: Gross Weight (kg) | X33: : | Y33: ='Summary PL'!M51 -> 8009 | AC33: KG
B34: Later | J34: 45917 | S34: Dimension (m3) | X34: : | Y34: ='Summary PL'!K51 -> 18.302 | AC34: m3
A36: 10. Customs Place / Место таможенного оформления
A39: 15. Description of Goods / Описание товара | R39: 16. HS CODE / | W39: 17. Quantity / | AA39: 18. Total Price (USD)
R40: Код ТН ВЭД | W40: Количество | AA40: Общая сумма (Дол. США)
B41: DCS_Installation Material | R41: 8544.20-0000 | W41: 1 SET | AC41: =CI_BD!H46 -> 490515.56 | AD41: BOM 9.1 - Распределённая автоматизированная система управления
B42: Распределённая автоматизированная система управления
I44: Total (DDP Value) | AA44: =SUM(AC41:AC43) -> 490515.56
S52: Signed by
A53: Doosan Enerbility Co., Ltd
A54: 155, Jeongjail-ro, Bundang-gu, Seongnam-si, Gyeonggi-do, Korea
A55: Tel. +82 31 5179 2045 | V55: Gihun Bek / Project Director
...

Sheet CI_BD
I1: HEAD OFFICE & CHANGWON PLANT
I2: 22, DoosanVolvo-ro, Seongsan-gu, Changwon-Si,
I3: Gyeongsangnam-do, Korea
I4: (P.O.BOX 77, Changwon, Korea)
I5: TEL:(055)278-6114,7114 FAX:(055)264-5551/2
A6: INVOICE (Break-down)
A7: Invoice № : | B7: =CI!V8 -> PGU-DE-0311
A8: № | B8: № Package | C8: Description of Goods Specification | D8: HS CODE | E8: Quantity | F8: Unit | G8: U/Price (USD) | H8: Amount (USD) | I8: Country of Origin | J8: Remark
A9: 1 | B9: PGU-DE-0311-DCS-INS-001 | C9: Power cable | E9: 1 | F9: EA / ШТ. | G9: 36977.57 | H9: =E9*G9 -> 36977.57 | I9: Korea
A10: 2 | B10: PGU-DE-0311-DCS-INS-002 | C10: FO Cable Drum | E10: 1 | F10: EA / ШТ. | G10: 12700.99 | H10: =E10*G10 -> 12700.99 | I10: Korea
A11: 3 | B11: PGU-DE-0311-DCS-INS-003 | C11: FO Cable Drum | E11: 1 | F11: EA / ШТ. | G11: 12459.83 | H11: =E11*G11 -> 12459.83 | I11: Korea
A12: 4 | B12: PGU-DE-0311-DCS-INS-004 | C12: FO Cable Drum | E12: 1 | F12: EA / ШТ. | G12: 12861.76 | H12: =E12*G12 -> 12861.76 | I12: Korea
A13: 5 | B13: PGU-DE-0311-DCS-INS-005 | C13: FO Cable Drum | E13: 1 | F13: EA / ШТ. | G13: 12459.83 | H13: =E13*G13 -> 12459.83 | I13: Korea
A14: 6 | B14: PGU-DE-0311-DCS-INS-006 | C14: FO Cable Drum | E14: 1 | F14: EA / ШТ. | G14: 12459.83 | H14: =E14*G14 -> 12459.83 | I14: Korea
A15: 7 | B15: PGU-DE-0311-DCS-INS-007 | C15: FO Cable Drum | E15: 1 | F15: EA / ШТ. | G15: 12700.99 | H15: =E15*G15 -> 12700.99 | I15: Korea
A16: 8 | B16: PGU-DE-0311-DCS-INS-008 | C16: FO Cable Drum | E16: 1 | F16: EA / ШТ. | G16: 12379.45 | H16: =E16*G16 -> 12379.45 | I16: Korea
A17: 9 | B17: PGU-DE-0311-DCS-INS-009 | C17: FO Cable Drum | E17: 1 | F17: EA / ШТ. | G17: 12540.22 | H17: =E17*G17 -> 12540.22 | I17: Korea
A18: 10 | B18: PGU-DE-0311-DCS-INS-010 | C18: FO Cable Drum | E18: 1 | F18: EA / ШТ. | G18: 12379.45 | H18: =E18*G18 -> 12379.45 | I18: Korea
A19: 11 | B19: PGU-DE-0311-DCS-INS-011 | C19: FO Cable Drum | E19: 1 | F19: EA / ШТ. | G19: 12540.22 | H19: =E19*G19 -> 12540.22 | I19: Korea
A20: 12 | B20: PGU-DE-0311-DCS-INS-012 | C20: FO Cable Drum | E20: 1 | F20: EA / ШТ. | G20: 12299.06 | H20: =E20*G20 -> 12299.06 | I20: Korea
... A45: 37 | B45: PGU-DE-0311-DCS-INS-037 | C45: FO Cable Drum | E45: 1 | F45: EA / ШТ. | G45: 12299.15 | H45: =E45*G45 -> 12299.15 | I45: Korea
C46: TOTAL | H46: =SUM(H9:H45) -> 490515.56

Sheet PL
W1: HEAD OFFICE & CHANGWON PLANT
W2: 22, DoosanVolvo-ro, Seongsan-gu, Changwon-Si,
W3: Gyeongsangnam-do, Korea
W4: (P.O.BOX 77, Changwon, Korea)
W5: TEL:(055)278-6114,7114 FAX:(055)264-5551/2
A6: PACKING LIST УПАКОВОЧНЫЙ ЛИСТ
A8: 1. Shipper / Грузоотправитель | R8: 11. Invoice № : | V8: =CI!V8 -> PGU-DE-0311
B9: Doosan Enerbility Co., Ltd (DOOSAN) | R9: Инвойс №
B10: 22, DoosanVolvo-ro, Seongsan-gu, Changwon-si, Gyeongsangnam-do, | R10: 12. Date : | V10: =CI!V10 -> 45693
B11: Republic of Korea | R11: Дата
A12: 2. Consignee / Грузополучатель | R12: 13. Remarks / Примечания
B13: Branch of JSC "Doosan Enerbility" in the Turkestan region
B14: 321 Tauke Khan Avenue, Turkestan region, Turkestan, Kazakhstan, 161200 | S14: *Project Name / Название Проекта
B15: BIN: 230741006561 | S15: Construction of a 1000 MW CCGT Power Plant in the Sairam District of
S16: Turkistan Region, Main Site. Without External Engineering Networks
S17: *MANUFACTURER'S NAME / НАЗВАНИЕ ПРОИЗВОДИТЕЛЯ
A18: 3. Notify party / Уведомляемая сторона | S18: Siemens-energy
B19: =CI!B19 -> Wise Logistics | S19: *MANUFACTURE YEAR / ГОД ИЗГОТОВЛЕНИЯ
B20: =CI!B20 -> ATTAN: MS. Aliya | S20: 2024
B21: =CI!B21 -> (E): a.kipshakbayeva@wiselogistics.kz | S21: *COUNTRY OF ORIGIN / СТРАНА ПРОИСХОЖДЕНИЯ
B22: =CI!B22 -> (T): +7 701 512 19 69 | S22: Korea
S23: *INCOTERMS / УСЛОВИЯ ПОСТАВКИ СОГЛАСНО ИНКОТЕРМС
S24: DDP Turkistan
A25: 4. Port of Loading / Порт погрузки | I25: 5. Carrier / Перевозчик
B26: Busan, Korea | J26: Later
A28: 6. Port of Unloading / Порт разгрузки | I28: 7. Final Destination / Конечный пункт назначения | R28: 14. Mark and Numbers of PKGS / Маркировка и количество упаковок
B30: Later | I30: Turkestan Oblast, Sairam district | S30: PKG No. | X30: : | Y30: PGU-DE-0311-DCS-INS-001~037
S31: Q-ty of Package | X31: : | Y31: =COUNT('Summary PL'!A14:A50) -> 37 | AC31: PKGS
A32: 8. Voyage No / Рейс № | I32: 9. Sailing on or about / Дата или ожидаемая дата | S32: Net Weight (kg) | X32: : | Y32: ='Summary PL'!L51 -> 6102 | AC32: KG
B33: Later | S33: Gross Weight (kg) | X33: : | Y33: ='Summary PL'!M51 -> 8009 | AC33: KG
J34: 45917 | S34: Dimension (m3) | X34: : | Y34: ='Summary PL'!K51 -> 18.302 | AC34: m3
A36: 10. Customs Place / Место таможенного оформления
A39: 15. Description of Goods / Описание товара | R39: 16. Q-ty | U39: 17. Net Weight | Y39: 18. Gross Weight | AC39: 19. Measurement
R40: (EA) | U40: (kg) | Y40: (kg) | AC40: (CBM)
B41: =CI!B41 -> DCS_Installation Material | R41: 1 | U41: ='Summary PL'!L51 -> 6102 | Y41: ='Summary PL'!M51 -> 8009 | AC41: ='Summary PL'!K51 -> 18.302
B42: Распределённая автоматизированная система управления
U44: ='Summary PL'!L51 -> 6102 | Y44: ='Summary PL'!M51 -> 8009 | AC44: ='Summary PL'!K51 -> 18.302
S52: Signed by
A53: Doosan Enerbility Co., Ltd
A54: 155, Jeongjail-ro, Bundang-gu, Seongnam-si, Gyeonggi-do, Korea
...

Sheet Summary PL
O1: HEAD OFFICE & CHANGWON PLANT | Q1: Note> | R1: Storage Classification "A" : | S1: Indoor with Air-conditioning
O2: 22, DoosanVolvo-ro, Seongsan-gu, Changwon-Si, | R2: Storage Classification "B" : | S2: Indoor without Air-conditioning
O3: Gyeongsangnam-do, Korea | R3: Storage Classification "C" : | S3: Outdoor with Waterproofing
O4: (P.O.BOX 77, Changwon, Korea) | R4: Storage Classification "D" : | S4: Outdoor without Waterproofing
O5: TEL:(055)278-6114,7114 FAX:(055)264-5551/2
A6: SUMMARY PACKING LIST CВОДНЫЙ УПАКОВОЧНЫЙ ЛИСТ
A7: Project Name: | B7: Construction of a 1000 MW CCGT Power Plant in the Sairam District of the Turkistan Region
B8: Main Site. Without External Engineering Networks
A9: Invoice №: | B9: =CI!V8 -> PGU-DE-0311
A10: Name of Consignee: | B10: =PL!B13 -> Branch of JSC "Doosan Enerbility" in the Turkestan region
A11: Consignee address: | B11: =PL!B14 -> 321 Tauke Khan Avenue, Turkestan region, Turkestan, Kazakhstan, 161200
A12: № | B12: CNTR No. / Seal No. / № контейнера / № пломбы | C12: Package No. / № упаковки | D12: Description / Описание | E12: Packing Style / Вид упаковки | F12: Quantity / Количество | H12: Shipping Dimension / Отгрузочные параметры | L12: Net Weight (kg) / Вес нетто (кг) | M12: Gross Weight (kg) / Вес брутто (кг) | N12: Hazardous Material (UN Number) | O12: Storage Class / Класс хранения | P12: Stackable / Штабелируемый
F13: Q'ty / Количество | G13: Unit / Ед.изм. | H13: L (cm) / Д (см) | I13: W (cm) / Ш (см) | J13: H (cm) / В (см) | K13: CBM (m3) / Объем (м3)
A14: 1 | C14: PGU-DE-0311-DCS-INS-001 | D14: Power cable | E14: Drum | F14: 1 | G14: EA / ШТ. | H14: 125 | I14: 106 | J14: 107 | K14: =ROUND(J14*I14*H14/1000000,3) -> 1.418 | L14: 460 | M14: 517 | N14: N/A | O14: B | P14: N
A15: 2 | C15: PGU-DE-0311-DCS-INS-002 | D15: FO Cable Drum | E15: Drum | F15: 1 | G15: EA / ШТ. | H15: 95 | I15: 52 | J15: 95 | K15: =ROUND(J15*I15*H15/1000000,3) -> 0.469 | L15: 158 | M15: 211 | N15: N/A | O15: B | P15: N
A16: 3 | C16: PGU-DE-0311-DCS-INS-003 | D16: FO Cable Drum | E16: Drum | F16: 1 | G16: EA / ШТ. | H16: 95 | I16: 52 | J16: 95 | K16: =ROUND(J16*I16*H16/1000000,3) -> 0.469 | L16: 155 | M16: 207 | N16: N/A | O16: B | P16: N
A17: 4 | C17: PGU-DE-0311-DCS-INS-004 | D17: FO Cable Drum | E17: Drum | F17: 1 | G17: EA / ШТ. | H17: 95 | I17: 52 | J17: 95 | K17: =ROUND(J17*I17*H17/1000000,3) -> 0.469 | L17: 160 | M17: 213 | N17: N/A | O17: B | P17: N
A18: 5 | C18: PGU-DE-0311-DCS-INS-005 | D18: FO Cable Drum | E18: Drum | F18: 1 | G18: EA / ШТ. | H18: 95 | I18: 52 | J18: 95 | K18: =ROUND(J18*I18*H18/1000000,3) -> 0.469 | L18: 155 | M18: 208 | N18: N/A | O18: B | P18: N
A19: 6 | C19: PGU-DE-0311-DCS-INS-006 | D19: FO Cable Drum | E19: Drum | F19: 1 | G19: EA / ШТ. | H19: 95 | I19: 52 | J19: 95 | K19: =ROUND(J19*I19*H19/1000000,3) -> 0.469 | L19: 155 | M19: 209 | N19: N/A | O19: B | P19: N
A20: 7 | C20: PGU-DE-0311-DCS-INS-007 | D20: FO Cable Drum | E20: Drum | F20: 1 | G20: EA / ШТ. | H20: 95 | I20: 52 | J20: 95 | K20: =ROUND(J20*I20*H20/1000000,3) -> 0.469 | L20: 158 | M20: 211 | N20: N/A | O20: B | P20: N
A21: 8 | C21: PGU-DE-0311-DCS-INS-008 | D21: FO Cable Drum | E21: Drum | F21: 1 | G21: EA / ШТ. | H21: 95 | I21: 52 | J21: 95 | K21: =ROUND(J21*I21*H21/1000000,3) -> 0.469 | L21: 154 | M21: 207 | N21: N/A | O21: B | P21: N
A22: 9 | C22: PGU-DE-0311-DCS-INS-009 | D22: FO Cable Drum | E22: Drum | F22: 1 | G22: EA / ШТ. | H22: 95 | I22: 52 | J22: 95 | K22: =ROUND(J22*I22*H22/1000000,3) -> 0.469 | L22: 156 | M22: 209 | N22: N/A | O22: B | P22: N
A23: 10 | C23: PGU-DE-0311-DCS-INS-010 | D23: FO Cable Drum | E23: Drum | F23: 1 | G23: EA / ШТ. | H23: 95 | I23: 52 | J23: 95 | K23: =ROUND(J23*I23*H23/1000000,3) -> 0.469 | L23: 154 | M23: 207 | N23: N/A | O23: B | P23: N
A24: 11 | C24: PGU-DE-0311-DCS-INS-011 | D24: FO Cable Drum | E24: Drum | F24: 1 | G24: EA / ШТ. | H24: 95 | I24: 52 | J24: 95 | K24: =ROUND(J24*I24*H24/1000000,3) -> 0.469 | L24: 156 | M24: 209 | N24: N/A | O24: B | P24: N
A25: 12 | C25: PGU-DE-0311-DCS-INS-012 | D25: FO Cable Drum | E25: Drum | F25: 1 | G25: EA / ШТ. | H25: 95 | I25: 52 | J25: 95 | K25: =ROUND(J25*I25*H25/1000000,3) -> 0.469 | L25: 153 | M25: 206 | N25: N/A | O25: B | P25: N
... A50: 37 | C50: PGU-DE-0311-DCS-INS-037 | D50: FO Cable Drum | E50: Drum | F50: 1 | G50: EA / ШТ. | H50: 95 | I50: 52 | J50: 95 | K50: =ROUND(J50*I50*H50/1000000,3) -> 0.469 | L50: 153 | M50: 207 | N50: N/A | O50: B | P50: N
A51: TOTAL / ИТОГО | K51: =SUM(K14:K50) -> 18.302 | L51: =SUM(L14:L50) -> 6102 | M51: =SUM(M14:M50) -> 8009

Sheet Detail PL
P1: HEAD OFFICE & CHANGWON PLANT
P2: 22, DoosanVolvo-ro, Seongsan-gu, Changwon-Si, | R2: Note> | S2: Storage Classification "A" : | T2: Indoor with Air-conditioning
P3: Gyeongsangnam-do, Korea | S3: Storage Classification "B" : | T3: Indoor without Air-conditioning
P4: (P.O.BOX 77, Changwon, Korea) | S4: Storage Classification "C" : | T4: Outdoor with Waterproofing
P5: TEL:(055)278-6114,7114 FAX:(055)264-5551/2 | S5: Storage Classification "D" : | T5: Outdoor without Waterproofing
A6: DETAILED PACKING LIST ПОДРОБНЫЙ УПАКОВОЧНЫЙ ЛИСТ
A7: Project Name: | B7: Construction of a 1000 MW CCGT Power Plant in the Sairam District of the Turkistan Region
B8: Main Site. Without External Engineering Networks
A9: Invoice №: | B9: =PL!V8 -> PGU-DE-0311
A10: Name of Consignee: | B10: ='Summary PL'!B10 -> Branch of JSC "Doosan Enerbility" in the Turkestan region
A11: Consignee address: | B11: ='Summary PL'!B11 -> 321 Tauke Khan Avenue, Turkestan region, Turkestan, Kazakhstan, 161200
A12: № | B12: Package No./ Номер упаковки | C12: Description / Описание | D12: HS Code / Код ТН ВЭД | E12: Quantity / Количество | G12: Shipping Dimension / Отгрузочные параметры | K12: Net Weight (kg) / Вес нетто (кг) | L12: Gross Weight (kg) / Вес брутто (кг) | M12: Drawing No. / № чертежа | N12: Tag No. / № Тег | O12: Unit Price (US$) / Цена за единицу | P12: Total Price (US$) / Общая цена | Q12: Remark / Примечания
E13: Q'ty / Кол-во | F13: Unit / Ед. изм. | G13: L (cm) / Д (см) | H13: W (cm) / Ш (см) | I13: H (cm) / В (см) | J13: CBM (m3) / Объем (м3)
A14: 1 | B14: PGU-DE-0311-DCS-INS-001 | C14: Power cable - CLASSIC 100 450/750V 3G4-10210 115060721 (4 nos. each have 500 mtr.) Mtr.2000 | E14: 1 | F14: EA/ШТ.
G15: ='Summary PL'!H14 -> 125 | H15: ='Summary PL'!I14 -> 106 | I15: ='Summary PL'!J14 -> 107 | J15: =ROUND(I15*H15*G15/1000000,2) -> 1.42 | K15: 460 | L15: 517
A16: 1 | B16: PGU-DE-0311-DCS-INS-002 | C16: FO Cable drum - Cable No.25005190 Mtr.2100 | E16: 1 | F16: EA/ШТ.
G17: ='Summary PL'!H15 -> 95 | H17: ='Summary PL'!I15 -> 52 | I17: ='Summary PL'!J15 -> 95 | J17: =ROUND(I17*H17*G17/1000000,3) -> 0.469 | K17: 158 | L17: 211
A18: 1 | B18: PGU-DE-0311-DCS-INS-003 | C18: FO Cable drum - Cable No.25005191 Mtr.2100 | E18: 1 | F18: EA/ШТ.
G19: ='Summary PL'!H16 -> 95 | H19: ='Summary PL'!I16 -> 52 | I19: ='Summary PL'!J16 -> 95 | J19: =ROUND(I19*H19*G19/1000000,3) -> 0.469 | K19: 155 | L19: 207
A20: 1 | B20: PGU-DE-0311-DCS-INS-004 | C20: FO Cable drum - Cable No.25005192 Mtr.2100 | E20: 1 | F20: EA/ШТ.
G21: ='Summary PL'!H17 -> 95 | H21: ='Summary PL'!I17 -> 52 | I21: ='Summary PL'!J17 -> 95 | J21: =ROUND(I21*H21*G21/1000000,3) -> 0.469 | K21: 160 | L21: 213
A22: 1 | B22: PGU-DE-0311-DCS-INS-005 | C22: FO Cable drum - Cable No.25005193Mtr.2100 | E22: 1 | F22: EA/ШТ.
G23: ='Summary PL'!H19 -> 95 | H23: ='Summary PL'!I19 -> 52 | I23: ='Summary PL'!J19 -> 95 | J23: =ROUND(I23*H23*G23/1000000,3) -> 0.469 | K23: 155 | L23: 208
A24: 1 | B24: PGU-DE-0311-DCS-INS-006 | C24: FO Cable drum - Cable No.25005194Mtr.2100 | E24: 1 | F24: EA/ШТ.
G25: 95 | H25: 52 | I25: 95 | J25: =ROUND(I25*H25*G25/1000000,3) -> 0.469 | K25: 155 | L25: 209
A26: 1 | B26: PGU-DE-0311-DCS-INS-007 | C26: FO Cable drum - Cable No.25005195Mtr.2100 | E26: 1 | F26: EA/ШТ.
G27: 95 | H27: 52 | I27: 95 | J27: =ROUND(I27*H27*G27/1000000,3) -> 0.469 | K27: 158 | L27: 211
A28: 1 | B28: PGU-DE-0311-DCS-INS-008 | C28: FO Cable drum - Cable No.25005196Mtr.2052 | E28: 1 | F28: EA/ШТ.
G29: 95 | H29: 52 | I29: 95 | J29: =ROUND(I29*H29*G29/1000000,3) -> 0.469 | K29: 154 | L29: 207
A30: 1 | B30: PGU-DE-0311-DCS-INS-009 | C30: FO Cable drum - Cable No.25005197Mtr.2079 | E30: 1 | F30: EA/ШТ.
G31: 95 | H31: 52 | I31: 95 | J31: =ROUND(I31*H31*G31/1000000,3) -> 0.469 | K31: 156 | L31: 209
A32: 1 | B32: PGU-DE-0311-DCS-INS-010 | C32: FO Cable drum - Cable No.25005198Mtr.2049 | E32: 1 | F32: EA/ШТ.
G33: 95 | H33: 52 | I33: 95 | J33: =ROUND(I33*H33*G33/1000000,3) -> 0.469 | K33: 154 | L33: 207
A34: 1 | B34: PGU-DE-0311-DCS-INS-011 | C34: FO Cable drum - Cable No.25005199Mtr.2074 | E34: 1 | F34: EA/ШТ.
G35: 95 | H35: 52 | I35: 95 | J35: =ROUND(I35*H35*G35/1000000,3) -> 0.469 | K35: 156 | L35: 209
A36: 1 | B36: PGU-DE-0311-DCS-INS-012 | C36: FO Cable drum - Cable No.25005200Mtr.2065 | E36: 1 | F36: EA/ШТ.
G37: 95 | H37: 52 | I37: 95 | J37: =ROUND(I37*H37*G37/1000000,3) -> 0.469 | K37: 153 | L37: 206
A38: 1 | B38: PGU-DE-0311-DCS-INS-013 | C38: FO Cable drum - Cable No.25005201Mtr.2100 | E38: 1 | F38: EA/ШТ.
G39: 95 | H39: 52 | I39: 95 | J39: =ROUND(I39*H39*G39/1000000,3) -> 0.469 | K39: 158 | L39: 211
A40: 1 | B40: PGU-DE-0311-DCS-INS-014 | C40: FO Cable drum - Cable No.25005202Mtr.2100 | E40: 1 | F40: EA/ШТ.
...

Sheet PGU-DE-0311-DCS-INS-001
A1: SHIPPING MARK ГРУЗОВАЯ МАРКИРОВКА | P1: SHIPPING MARK ГРУЗОВАЯ МАРКИРОВКА
A2: ● NAME OF THE PROJECT | F2: : | G2: Construction of a 1000 MW CCGT Power Plant in the Sairam District of the | P2: ● NAME OF THE PROJECT | U2: : | V2: Construction of a 1000 MW CCGT Power Plant in the Sairam District of the
A3: НАЗВАНИЕ ПРОЕКТА | G3: Turkistan Region, Main Site. Without External Engineering Networks | P3: НАЗВАНИЕ ПРОЕКТА | V3: Turkistan Region, Main Site. Without External Engineering Networks
A5: ● CONSIGNEE | F5: : | G5: =CI!B13 -> Branch of JSC "Doosan Enerbility" in the Turkestan region | P5: ● CONSIGNEE | U5: : | V5: =G5 -> Branch of JSC "Doosan Enerbility" in the Turkestan region
A6: ГРУЗОПОЛУЧАТЕЛЬ | P6: ГРУЗОПОЛУЧАТЕЛЬ
A8: ● Shipper/Exporter | F8: : Doosan Enerbility Co., LTD | P8: ● Shipper/Exporter | U8: : Doosan Enerbility Co., LTD
A9: Грузоотправитель/Экспортер | F9: 22, Doosan Volvo-ro, Sengsan-gu, Changwon, Gyeongnam, South Korea | P9: Грузоотправитель/Экспортер | U9: 22, Doosan Volvo-ro, Sengsan-gu, Changwon, Gyeongnam, South Korea
A11: ● Number of Invoice | F11: : | G11: =CI!V8 -> PGU-DE-0311 | P11: ● Number of Invoice | U11: : | V11: =CI!V8 -> PGU-DE-0311
A12: № инвойса | P12: № инвойса
A14: ● CARGO DESCRIPTION | F14: : | G14: ='Summary PL'!D14 -> Power cable | P14: ● CARGO DESCRIPTION | U14: : | V14: =G14 -> Power cable
A15: ОПИСАНИЕ ГРУЗА | P15: ОПИСАНИЕ ГРУЗА
A17: ● PACKAGE NO. | F17: : | G17: ='Summary PL'!C14 -> PGU-DE-0311-DCS-INS-001 | P17: ● PACKAGE NO. | U17: : | V17: =G17 -> PGU-DE-0311-DCS-INS-001
A18: УПАКОВОЧНЫЙ НОМЕР | P18: УПАКОВОЧНЫЙ НОМЕР
A20: ● NET WEIGHT | F20: : | G20: ='Summary PL'!L14 -> 460 | H20: Kg | P20: ● NET WEIGHT | U20: : | V20: =G20 -> 460 | W20: Kg
A21: ВЕС НЕТТО | P21: ВЕС НЕТТО
A23: ● GROSS WEIGHT | F23: : | G23: ='Summary PL'!M14 -> 517 | H23: Kg | P23: ● GROSS WEIGHT | U23: : | V23: =G23 -> 517 | W23: Kg
A24: ВЕС БРУТТО | P24: ВЕС БРУТТО
A26: ● CBM(m3) | F26: : | G26: ='Summary PL'!K14 -> 1.418 | H26: m3 | P26: ● CBM(m3) | U26: : | V26: =G26 -> 1.418 | W26: m3
A27: РАЗМЕРЫ | P27: РАЗМЕРЫ
A29: ● FINAL DESTINATION | F29: : | G29: Turkestan Oblast, Sairam district, Karamurt rural district, quarter 171, Republic of Kazakhstan | P29: ● FINAL DESTINATION | U29: : | V29: =G29 -> Turkestan Oblast, Sairam district, Karamurt rural district, quarter 171, Republic of Kazakhstan
A30: КОНЕЧНЫЙ ПУНКТ НАЗНАЧЕНИЯ | P30: КОНЕЧНЫЙ ПУНКТ НАЗНАЧЕНИЯ
E31: Doosan Enerbility | T31: Doosan Enerbility

Sheet PGU-DE-0311-DCS-INS-002
A1: SHIPPING MARK ГРУЗОВАЯ МАРКИРОВКА | P1: SHIPPING MARK ГРУЗОВАЯ МАРКИРОВКА
A2: ● NAME OF THE PROJECT | F2: : | G2: Construction of a 1000 MW CCGT Power Plant in the Sairam District of the | P2: ● NAME OF THE PROJECT | U2: : | V2: Construction of a 1000 MW CCGT Power Plant in the Sairam District of the
A3: НАЗВАНИЕ ПРОЕКТА | G3: Turkistan Region, Main Site. Without External Engineering Networks | P3: НАЗВАНИЕ ПРОЕКТА | V3: Turkistan Region, Main Site. Without External Engineering Networks
A5: ● CONSIGNEE | F5: : | G5: =CI!B13 -> Branch of JSC "Doosan Enerbility" in the Turkestan region | P5: ● CONSIGNEE | U5: : | V5: =G5 -> Branch of JSC "Doosan Enerbility" in the Turkestan region
A6: ГРУЗОПОЛУЧАТЕЛЬ | P6: ГРУЗОПОЛУЧАТЕЛЬ
A8: ● Shipper/Exporter | F8: : Doosan Enerbility Co., LTD | P8: ● Shipper/Exporter | U8: : Doosan Enerbility Co., LTD
A9: Грузоотправитель/Экспортер | F9: 22, Doosan Volvo-ro, Sengsan-gu, Changwon, Gyeongnam, South Korea | P9: Грузоотправитель/Экспортер | U9: 22, Doosan Volvo-ro, Sengsan-gu, Changwon, Gyeongnam, South Korea
A11: ● Number of Invoice | F11: : | G11: =CI!V8 -> PGU-DE-0311 | P11: ● Number of Invoice | U11: : | V11: =CI!V8 -> PGU-DE-0311
A12: № инвойса | P12: № инвойса
A14: ● CARGO DESCRIPTION | F14: : | G14: ='Summary PL'!D15 -> FO Cable Drum | P14: ● CARGO DESCRIPTION | U14: : | V14: =G14 -> FO Cable Drum
A15: ОПИСАНИЕ ГРУЗА | P15: ОПИСАНИЕ ГРУЗА
A17: ● PACKAGE NO. | F17: : | G17: ='Summary PL'!C18 -> PGU-DE-0311-DCS-INS-005 | P17: ● PACKAGE NO. | U17: : | V17: =G17 -> PGU-DE-0311-DCS-INS-005
A18: УПАКОВОЧНЫЙ НОМЕР | P18: УПАКОВОЧНЫЙ НОМЕР
A20: ● NET WEIGHT | F20: : | G20: ='Summary PL'!L15 -> 158 | H20: Kg | P20: ● NET WEIGHT | U20: : | V20: =G20 -> 158 | W20: Kg
A21: ВЕС НЕТТО | P21: ВЕС НЕТТО
A23: ● GROSS WEIGHT | F23: : | G23: ='Summary PL'!M15 -> 211 | H23: Kg | P23: ● GROSS WEIGHT | U23: : | V23: =G23 -> 211 | W23: Kg
A24: ВЕС БРУТТО | P24: ВЕС БРУТТО
A26: ● CBM(m3) | F26: : | G26: ='Summary PL'!K15 -> 0.469 | H26: m3 | P26: ● CBM(m3) | U26: : | V26: =G26 -> 0.469 | W26: m3
A27: РАЗМЕРЫ | P27: РАЗМЕРЫ
A29: ● FINAL DESTINATION | F29: : | G29: Turkestan Oblast, Sairam district, Karamurt rural district, quarter 171, Republic of Kazakhstan | P29: ● FINAL DESTINATION | U29: : | V29: =G29 -> Turkestan Oblast, Sairam district, Karamurt rural district, quarter 171, Republic of Kazakhstan
A30: КОНЕЧНЫЙ ПУНКТ НАЗНАЧЕНИЯ | P30: КОНЕЧНЫЙ ПУНКТ НАЗНАЧЕНИЯ
E31: Doosan Enerbility | T31: Doosan Enerbility

Sheet PGU-DE-0311-DCS-INS-003
A1: SHIPPING MARK ГРУЗОВАЯ МАРКИРОВКА | P1: SHIPPING MARK ГРУЗОВАЯ МАРКИРОВКА
A2: ● NAME OF THE PROJECT | F2: : | G2: Construction of a 1000 MW CCGT Power Plant in the Sairam District of the | P2: ● NAME OF THE PROJECT | U2: : | V2: Construction of a 1000 MW CCGT Power Plant in the Sairam District of the
A3: НАЗВАНИЕ ПРОЕКТА | G3: Turkistan Region, Main Site. Without External Engineering Networks | P3: НАЗВАНИЕ ПРОЕКТА | V3: Turkistan Region, Main Site. Without External Engineering Networks
A5: ● CONSIGNEE | F5: : | G5: =CI!B13 -> Branch of JSC "Doosan Enerbility" in the Turkestan region | P5: ● CONSIGNEE | U5: : | V5: =G5 -> Branch of JSC "Doosan Enerbility" in the Turkestan region
A6: ГРУЗОПОЛУЧАТЕЛЬ | P6: ГРУЗОПОЛУЧАТЕЛЬ
A8: ● Shipper/Exporter | F8: : Doosan Enerbility Co., LTD | P8: ● Shipper/Exporter | U8: : Doosan Enerbility Co., LTD
A9: Грузоотправитель/Экспортер | F9: 22, Doosan Volvo-ro, Sengsan-gu, Changwon, Gyeongnam, South Korea | P9: Грузоотправитель/Экспортер | U9: 22, Doosan Volvo-ro, Sengsan-gu, Changwon, Gyeongnam, South Korea
A11: ● Number of Invoice | F11: : | G11: =CI!V8 -> PGU-DE-0311 | P11: ● Number of Invoice | U11: : | V11: =CI!V8 -> PGU-DE-0311
A12: № инвойса | P12: № инвойса
A14: ● CARGO DESCRIPTION | F14: : | G14: ='Summary PL'!D16 -> FO Cable Drum | P14: ● CARGO DESCRIPTION | U14: : | V14: =G14 -> FO Cable Drum
A15: ОПИСАНИЕ ГРУЗА | P15: ОПИСАНИЕ ГРУЗА
A17: ● PACKAGE NO. | F17: : | G17: ='Summary PL'!C16 -> PGU-DE-0311-DCS-INS-003 | P17: ● PACKAGE NO. | U17: : | V17: =G17 -> PGU-DE-0311-DCS-INS-003
A18: УПАКОВОЧНЫЙ НОМЕР | P18: УПАКОВОЧНЫЙ НОМЕР
A20: ● NET WEIGHT | F20: : | G20: ='Summary PL'!L16 -> 155 | H20: Kg | P20: ● NET WEIGHT | U20: : | V20: =G20 -> 155 | W20: Kg
A21: ВЕС НЕТТО | P21: ВЕС НЕТТО
A23: ● GROSS WEIGHT | F23: : | G23: ='Summary PL'!M16 -> 207 | H23: Kg | P23: ● GROSS WEIGHT | U23: : | V23: =G23 -> 207 | W23: Kg
A24: ВЕС БРУТТО | P24: ВЕС БРУТТО
A26: ● CBM(m3) | F26: : | G26: ='Summary PL'!K16 -> 0.469 | H26: m3 | P26: ● CBM(m3) | U26: : | V26: =G26 -> 0.469 | W26: m3
A27: РАЗМЕРЫ | P27: РАЗМЕРЫ
A29: ● FINAL DESTINATION | F29: : | G29: Turkestan Oblast, Sairam district, Karamurt rural district, quarter 171, Republic of Kazakhstan | P29: ● FINAL DESTINATION | U29: : | V29: =G29 -> Turkestan Oblast, Sairam district, Karamurt rural district, quarter 171, Republic of Kazakhstan
A30: КОНЕЧНЫЙ ПУНКТ НАЗНАЧЕНИЯ | P30: КОНЕЧНЫЙ ПУНКТ НАЗНАЧЕНИЯ
E31: Doosan Enerbility | T31: Doosan Enerbility

Sheet PGU-DE-0311-DCS-INS-004
A1: SHIPPING MARK ГРУЗОВАЯ МАРКИРОВКА | P1: SHIPPING MARK ГРУЗОВАЯ МАРКИРОВКА
A2: ● NAME OF THE PROJECT | F2: : | G2: Construction of a 1000 MW CCGT Power Plant in the Sairam District of the | P2: ● NAME OF THE PROJECT | U2: : | V2: Construction of a 1000 MW CCGT Power Plant in the Sairam District of the
A3: НАЗВАНИЕ ПРОЕКТА | G3: Turkistan Region, Main Site. Without External Engineering Networks | P3: НАЗВАНИЕ ПРОЕКТА | V3: Turkistan Region, Main Site. Without External Engineering Networks
A5: ● CONSIGNEE | F5: : | G5: =CI!B13 -> Branch of JSC "Doosan Enerbility" in the Turkestan region | P5: ● CONSIGNEE | U5: : | V5: =G5 -> Branch of JSC "Doosan Enerbility" in the Turkestan region
A6: ГРУЗОПОЛУЧАТЕЛЬ | P6: ГРУЗОПОЛУЧАТЕЛЬ
A8: ● Shipper/Exporter | F8: : Doosan Enerbility Co., LTD | P8: ● Shipper/Exporter | U8: : Doosan Enerbility Co., LTD
A9: Грузоотправитель/Экспортер | F9: 22, Doosan Volvo-ro, Sengsan-gu, Changwon, Gyeongnam, South Korea | P9: Грузоотправитель/Экспортер | U9: 22, Doosan Volvo-ro, Sengsan-gu, Changwon, Gyeongnam, South Korea
A11: ● Number of Invoice | F11: : | G11: =CI!V8 -> PGU-DE-0311 | P11: ● Number of Invoice | U11: : | V11: =CI!V8 -> PGU-DE-0311
A12: № инвойса | P12: № инвойса
A14: ● CARGO DESCRIPTION | F14: : | G14: ='Summary PL'!D17 -> FO Cable Drum | P14: ● CARGO DESCRIPTION | U14: : | V14: =G14 -> FO Cable Drum
A15: ОПИСАНИЕ ГРУЗА | P15: ОПИСАНИЕ ГРУЗА
A17: ● PACKAGE NO. | F17: : | G17: ='Summary PL'!C17 -> PGU-DE-0311-DCS-INS-004 | P17: ● PACKAGE NO. | U17: : | V17: =G17 -> PGU-DE-0311-DCS-INS-004
A18: УПАКОВОЧНЫЙ НОМЕР | P18: УПАКОВОЧНЫЙ НОМЕР
A20: ● NET WEIGHT | F20: : | G20: ='Summary PL'!L17 -> 160 | H20: Kg | P20: ● NET WEIGHT | U20: : | V20: =G20 -> 160 | W20: Kg
A21: ВЕС НЕТТО | P21: ВЕС НЕТТО
A23: ● GROSS WEIGHT | F23: : | G23: ='Summary PL'!M17 -> 213 | H23: Kg | P23: ● GROSS WEIGHT | U23: : | V23: =G23 -> 213 | W23: Kg
A24: ВЕС БРУТТО | P24: ВЕС БРУТТО
A26: ● CBM(m3) | F26: : | G26: ='Summary PL'!K17 -> 0.469 | H26: m3 | P26: ● CBM(m3) | U26: : | V26: =G26 -> 0.469 | W26: m3
A27: РАЗМЕРЫ | P27: РАЗМЕРЫ
A29: ● FINAL DESTINATION | F29: : | G29: Turkestan Oblast, Sairam district, Karamurt rural district, quarter 171, Republic of Kazakhstan | P29: ● FINAL DESTINATION | U29: : | V29: =G29 -> Turkestan Oblast, Sairam district, Karamurt rural district, quarter 171, Republic of Kazakhstan
A30: КОНЕЧНЫЙ ПУНКТ НАЗНАЧЕНИЯ | P30: КОНЕЧНЫЙ ПУНКТ НАЗНАЧЕНИЯ
E31: Doosan Enerbility | T31: Doosan Enerbility

Sheet PGU-DE-0311-DCS-INS-005
A1: SHIPPING MARK ГРУЗОВАЯ МАРКИРОВКА | P1: SHIPPING MARK ГРУЗОВАЯ МАРКИРОВКА
A2: ● NAME OF THE PROJECT | F2: : | G2: Construction of a 1000 MW CCGT Power Plant in the Sairam District of the | P2: ● NAME OF THE PROJECT | U2: : | V2: Construction of a 1000 MW CCGT Power Plant in the Sairam District of the
A3: НАЗВАНИЕ ПРОЕКТА | G3: Turkistan Region, Main Site. Without External Engineering Networks | P3: НАЗВАНИЕ ПРОЕКТА | V3: Turkistan Region, Main Site. Without External Engineering Networks
A5: ● CONSIGNEE | F5: : | G5: =CI!B13 -> Branch of JSC "Doosan Enerbility" in the Turkestan region | P5: ● CONSIGNEE | U5: : | V5: =G5 -> Branch of JSC "Doosan Enerbility" in the Turkestan region
A6: ГРУЗОПОЛУЧАТЕЛЬ | P6: ГРУЗОПОЛУЧАТЕЛЬ
A8: ● Shipper/Exporter | F8: : Doosan Enerbility Co., LTD | P8: ● Shipper/Exporter | U8: : Doosan Enerbility Co., LTD
A9: Грузоотправитель/Экспортер | F9: 22, Doosan Volvo-ro, Sengsan-gu, Changwon, Gyeongnam, South Korea | P9: Грузоотправитель/Экспортер | U9: 22, Doosan Volvo-ro, Sengsan-gu, Changwon, Gyeongnam, South Korea
A11: ● Number of Invoice | F11: : | G11: =CI!V8 -> PGU-DE-0311 | P11: ● Number of Invoice | U11: : | V11: =CI!V8 -> PGU-DE-0311
A12: № инвойса | P12: № инвойса
A14: ● CARGO DESCRIPTION | F14: : | G14: ='Summary PL'!D18 -> FO Cable Drum | P14: ● CARGO DESCRIPTION | U14: : | V14: =G14 -> FO Cable Drum
A15: ОПИСАНИЕ ГРУЗА | P15: ОПИСАНИЕ ГРУЗА
A17: ● PACKAGE NO. | F17: : | G17: ='Summary PL'!C18 -> PGU-DE-0311-DCS-INS-005 | P17: ● PACKAGE NO. | U17: : | V17: =G17 -> PGU-DE-0311-DCS-INS-005
A18: УПАКОВОЧНЫЙ НОМЕР | P18: УПАКОВОЧНЫЙ НОМЕР
A20: ● NET WEIGHT | F20: : | G20: ='Summary PL'!L18 -> 155 | H20: Kg | P20: ● NET WEIGHT | U20: : | V20: =G20 -> 155 | W20: Kg
A21: ВЕС НЕТТО | P21: ВЕС НЕТТО
A23: ● GROSS WEIGHT | F23: : | G23: ='Summary PL'!M18 -> 208 | H23: Kg | P23: ● GROSS WEIGHT | U23: : | V23: =G23 -> 208 | W23: Kg
A24: ВЕС БРУТТО | P24: ВЕС БРУТТО
A26: ● CBM(m3) | F26: : | G26: ='Summary PL'!K18 -> 0.469 | H26: m3 | P26: ● CBM(m3) | U26: : | V26: =G26 -> 0.469 | W26: m3
A27: РАЗМЕРЫ | P27: РАЗМЕРЫ
A29: ● FINAL DESTINATION | F29: : | G29: Turkestan Oblast, Sairam district, Karamurt rural district, quarter 171, Republic of Kazakhstan | P29: ● FINAL DESTINATION | U29: : | V29: =G29 -> Turkestan Oblast, Sairam district, Karamurt rural district, quarter 171, Republic of Kazakhstan
A30: КОНЕЧНЫЙ ПУНКТ НАЗНАЧЕНИЯ | P30: КОНЕЧНЫЙ ПУНКТ НАЗНАЧЕНИЯ
E31: Doosan Enerbility | T31: Doosan Enerbility

Sheet PGU-DE-0311-DCS-INS-006
A1: SHIPPING MARK ГРУЗОВАЯ МАРКИРОВКА | P1: SHIPPING MARK ГРУЗОВАЯ МАРКИРОВКА
A2: ● NAME OF THE PROJECT | F2: : | G2: Construction of a 1000 MW CCGT Power Plant in the Sairam District of the | P2: ● NAME OF THE PROJECT | U2: : | V2: Construction of a 1000 MW CCGT Power Plant in the Sairam District of the
A3: НАЗВАНИЕ ПРОЕКТА | G3: Turkistan Region, Main Site. Without External Engineering Networks | P3: НАЗВАНИЕ ПРОЕКТА | V3: Turkistan Region, Main Site. Without External Engineering Networks
A5: ● CONSIGNEE | F5: : | G5: =CI!B13 -> Branch of JSC "Doosan Enerbility" in the Turkestan region | P5: ● CONSIGNEE | U5: : | V5: =G5 -> Branch of JSC "Doosan Enerbility" in the Turkestan region
A6: ГРУЗОПОЛУЧАТЕЛЬ | P6: ГРУЗОПОЛУЧАТЕЛЬ
A8: ● Shipper/Exporter | F8: : Doosan Enerbility Co., LTD | P8: ● Shipper/Exporter | U8: : Doosan Enerbility Co., LTD
A9: Грузоотправитель/Экспортер | F9: 22, Doosan Volvo-ro, Sengsan-gu, Changwon, Gyeongnam, South Korea | P9: Грузоотправитель/Экспортер | U9: 22, Doosan Volvo-ro, Sengsan-gu, Changwon, Gyeongnam, South Korea
A11: ● Number of Invoice | F11: : | G11: =CI!V8 -> PGU-DE-0311 | P11: ● Number of Invoice | U11: : | V11: =CI!V8 -> PGU-DE-0311
A12: № инвойса | P12: № инвойса
A14: ● CARGO DESCRIPTION | F14: : | G14: ='Summary PL'!D19 -> FO Cable Drum | P14: ● CARGO DESCRIPTION | U14: : | V14: =G14 -> FO Cable Drum
A15: ОПИСАНИЕ ГРУЗА | P15: ОПИСАНИЕ ГРУЗА
A17: ● PACKAGE NO. | F17: : | G17: ='Summary PL'!C19 -> PGU-DE-0311-DCS-INS-006 | P17: ● PACKAGE NO. | U17: : | V17: =G17 -> PGU-DE-0311-DCS-INS-006
A18: УПАКОВОЧНЫЙ НОМЕР | P18: УПАКОВОЧНЫЙ НОМЕР
A20: ● NET WEIGHT | F20: : | G20: ='Summary PL'!L19 -> 155 | H20: Kg | P20: ● NET WEIGHT | U20: : | V20: =G20 -> 155 | W20: Kg
A21: ВЕС НЕТТО | P21: ВЕС НЕТТО
A23: ● GROSS WEIGHT | F23: : | G23: ='Summary PL'!M19 -> 209 | H23: Kg | P23: ● GROSS WEIGHT | U23: : | V23: =G23 -> 209 | W23: Kg
A24: ВЕС БРУТТО | P24: ВЕС БРУТТО
A26: ● CBM(m3) | F26: : | G26: ='Summary PL'!K19 -> 0.469 | H26: m3 | P26: ● CBM(m3) | U26: : | V26: =G26 -> 0.469 | W26: m3
A27: РАЗМЕРЫ | P27: РАЗМЕРЫ
A29: ● FINAL DESTINATION | F29: : | G29: Turkestan Oblast, Sairam district, Karamurt rural district, quarter 171, Republic of Kazakhstan | P29: ● FINAL DESTINATION | U29: : | V29: =G29 -> Turkestan Oblast, Sairam district, Karamurt rural district, quarter 171, Republic of Kazakhstan
A30: КОНЕЧНЫЙ ПУНКТ НАЗНАЧЕНИЯ | P30: КОНЕЧНЫЙ ПУНКТ НАЗНАЧЕНИЯ
E31: Doosan Enerbility | T31: Doosan Enerbility

Sheet PGU-DE-0311-DCS-INS-007
A1: SHIPPING MARK ГРУЗОВАЯ МАРКИРОВКА | P1: SHIPPING MARK ГРУЗОВАЯ МАРКИРОВКА
A2: ● NAME OF THE PROJECT | F2: : | G2: Construction of a 1000 MW CCGT Power Plant in the Sairam District of the | P2: ● NAME OF THE PROJECT | U2: : | V2: Construction of a 1000 MW CCGT Power Plant in the Sairam District of the
A3: НАЗВАНИЕ ПРОЕКТА | G3: Turkistan Region, Main Site. Without External Engineering Networks | P3: НАЗВАНИЕ ПРОЕКТА | V3: Turkistan Region, Main Site. Without External Engineering Networks
A5: ● CONSIGNEE | F5: : | G5: =CI!B13 -> Branch of JSC "Doosan Enerbility" in the Turkestan region | P5: ● CONSIGNEE | U5: : | V5: =G5 -> Branch of JSC "Doosan Enerbility" in the Turkestan region
A6: ГРУЗОПОЛУЧАТЕЛЬ | P6: ГРУЗОПОЛУЧАТЕЛЬ
A8: ● Shipper/Exporter | F8: : Doosan Enerbility Co., LTD | P8: ● Shipper/Exporter | U8: : Doosan Enerbility Co., LTD
A9: Грузоотправитель/Экспортер | F9: 22, Doosan Volvo-ro, Sengsan-gu, Changwon, Gyeongnam, South Korea | P9: Грузоотправитель/Экспортер | U9: 22, Doosan Volvo-ro, Sengsan-gu, Changwon, Gyeongnam, South Korea
A11: ● Number of Invoice | F11: : | G11: =CI!V8 -> PGU-DE-0311 | P11: ● Number of Invoice | U11: : | V11: =CI!V8 -> PGU-DE-0311
A12: № инвойса | P12: № инвойса
A14: ● CARGO DESCRIPTION | F14: : | G14: ='Summary PL'!D20 -> FO Cable Drum | P14: ● CARGO DESCRIPTION | U14: : | V14: =G14 -> FO Cable Drum
A15: ОПИСАНИЕ ГРУЗА | P15: ОПИСАНИЕ ГРУЗА
A17: ● PACKAGE NO. | F17: : | G17: ='Summary PL'!C20 -> PGU-DE-0311-DCS-INS-007 | P17: ● PACKAGE NO. | U17: : | V17: =G17 -> PGU-DE-0311-DCS-INS-007
A18: УПАКОВОЧНЫЙ НОМЕР | P18: УПАКОВОЧНЫЙ НОМЕР
A20: ● NET WEIGHT | F20: : | G20: ='Summary PL'!L20 -> 158 | H20: Kg | P20: ● NET WEIGHT | U20: : | V20: =G20 -> 158 | W20: Kg
A21: ВЕС НЕТТО | P21: ВЕС НЕТТО
A23: ● GROSS WEIGHT | F23: : | G23: ='Summary PL'!M20 -> 211 | H23: Kg | P23: ● GROSS WEIGHT | U23: : | V23: =G23 -> 211 | W23: Kg
A24: ВЕС БРУТТО | P24: ВЕС БРУТТО
A26: ● CBM(m3) | F26: : | G26: ='Summary PL'!K20 -> 0.469 | H26: m3 | P26: ● CBM(m3) | U26: : | V26: =G26 -> 0.469 | W26: m3
A27: РАЗМЕРЫ | P27: РАЗМЕРЫ
A29: ● FINAL DESTINATION | F29: : | G29: Turkestan Oblast, Sairam district, Karamurt rural district, quarter 171, Republic of Kazakhstan | P29: ● FINAL DESTINATION | U29: : | V29: =G29 -> Turkestan Oblast, Sairam district, Karamurt rural district, quarter 171, Republic of Kazakhstan
A30: КОНЕЧНЫЙ ПУНКТ НАЗНАЧЕНИЯ | P30: КОНЕЧНЫЙ ПУНКТ НАЗНАЧЕНИЯ
E31: Doosan Enerbility | T31: Doosan Enerbility

Sheet PGU-DE-0311-DCS-INS-008
A1: SHIPPING MARK ГРУЗОВАЯ МАРКИРОВКА | P1: SHIPPING MARK ГРУЗОВАЯ МАРКИРОВКА
A2: ● NAME OF THE PROJECT | F2: : | G2: Construction of a 1000 MW CCGT Power Plant in the Sairam District of the | P2: ● NAME OF THE PROJECT | U2: : | V2: Construction of a 1000 MW CCGT Power Plant in the Sairam District of the
A3: НАЗВАНИЕ ПРОЕКТА | G3: Turkistan Region, Main Site. Without External Engineering Networks | P3: НАЗВАНИЕ ПРОЕКТА | V3: Turkistan Region, Main Site. Without External Engineering Networks
A5: ● CONSIGNEE | F5: : | G5: =CI!B13 -> Branch of JSC "Doosan Enerbility" in the Turkestan region | P5: ● CONSIGNEE | U5: : | V5: =G5 -> Branch of JSC "Doosan Enerbility" in the Turkestan region
A6: ГРУЗОПОЛУЧАТЕЛЬ | P6: ГРУЗОПОЛУЧАТЕЛЬ
A8: ● Shipper/Exporter | F8: : Doosan Enerbility Co., LTD | P8: ● Shipper/Exporter | U8: : Doosan Enerbility Co., LTD
A9: Грузоотправитель/Экспортер | F9: 22, Doosan Volvo-ro, Sengsan-gu, Changwon, Gyeongnam, South Korea | P9: Грузоотправитель/Экспортер | U9: 22, Doosan Volvo-ro, Sengsan-gu, Changwon, Gyeongnam, South Korea
A11: ● Number of Invoice | F11: : | G11: =CI!V8 -> PGU-DE-0311 | P11: ● Number of Invoice | U11: : | V11: =CI!V8 -> PGU-DE-0311
A12: № инвойса | P12: № инвойса
A14: ● CARGO DESCRIPTION | F14: : | G14: ='Summary PL'!D21 -> FO Cable Drum | P14: ● CARGO DESCRIPTION | U14: : | V14: =G14 -> FO Cable Drum
A15: ОПИСАНИЕ ГРУЗА | P15: ОПИСАНИЕ ГРУЗА
A17: ● PACKAGE NO. | F17: : | G17: ='Summary PL'!C21 -> PGU-DE-0311-DCS-INS-008 | P17: ● PACKAGE NO. | U17: : | V17: =G17 -> PGU-DE-0311-DCS-INS-008
A18: УПАКОВОЧНЫЙ НОМЕР | P18: УПАКОВОЧНЫЙ НОМЕР
A20: ● NET WEIGHT | F20: : | G20: ='Summary PL'!L21 -> 154 | H20: Kg | P20: ● NET WEIGHT | U20: : | V20: =G20 -> 154 | W20: Kg
A21: ВЕС НЕТТО | P21: ВЕС НЕТТО
A23: ● GROSS WEIGHT | F23: : | G23: ='Summary PL'!M21 -> 207 | H23: Kg | P23: ● GROSS WEIGHT | U23: : | V23: =G23 -> 207 | W23: Kg
A24: ВЕС БРУТТО | P24: ВЕС БРУТТО
A26: ● CBM(m3) | F26: : | G26: ='Summary PL'!K21 -> 0.469 | H26: m3 | P26: ● CBM(m3) | U26: : | V26: =G26 -> 0.469 | W26: m3
A27: РАЗМЕРЫ | P27: РАЗМЕРЫ
A29: ● FINAL DESTINATION | F29: : | G29: Turkestan Oblast, Sairam district, Karamurt rural district, quarter 171, Republic of Kazakhstan | P29: ● FINAL DESTINATION | U29: : | V29: =G29 -> Turkestan Oblast, Sairam district, Karamurt rural district, quarter 171, Republic of Kazakhstan
A30: КОНЕЧНЫЙ ПУНКТ НАЗНАЧЕНИЯ | P30: КОНЕЧНЫЙ ПУНКТ НАЗНАЧЕНИЯ
E31: Doosan Enerbility | T31: Doosan Enerbility

Sheet PGU-DE-0311-DCS-INS-009
A1: SHIPPING MARK ГРУЗОВАЯ МАРКИРОВКА | P1: SHIPPING MARK ГРУЗОВАЯ МАРКИРОВКА
A2: ● NAME OF THE PROJECT | F2: : | G2: Construction of a 1000 MW CCGT Power Plant in the Sairam District of the | P2: ● NAME OF THE PROJECT | U2: : | V2: Construction of a 1000 MW CCGT Power Plant in the Sairam District of the
A3: НАЗВАНИЕ ПРОЕКТА | G3: Turkistan Region, Main Site. Without External Engineering Networks | P3: НАЗВАНИЕ ПРОЕКТА | V3: Turkistan Region, Main Site. Without External Engineering Networks
A5: ● CONSIGNEE | F5: : | G5: =CI!B13 -> Branch of JSC "Doosan Enerbility" in the Turkestan region | P5: ● CONSIGNEE | U5: : | V5: =G5 -> Branch of JSC "Doosan Enerbility" in the Turkestan region
A6: ГРУЗОПОЛУЧАТЕЛЬ | P6: ГРУЗОПОЛУЧАТЕЛЬ
A8: ● Shipper/Exporter | F8: : Doosan Enerbility Co., LTD | P8: ● Shipper/Exporter | U8: : Doosan Enerbility Co., LTD
A9: Грузоотправитель/Экспортер | F9: 22, Doosan Volvo-ro, Sengsan-gu, Changwon, Gyeongnam, South Korea | P9: Грузоотправитель/Экспортер | U9: 22, Doosan Volvo-ro, Sengsan-gu, Changwon, Gyeongnam, South Korea
A11: ● Number of Invoice | F11: : | G11: =CI!V8 -> PGU-DE-0311 | P11: ● Number of Invoice | U11: : | V11: =CI!V8 -> PGU-DE-0311
A12: № инвойса | P12: № инвойса
A14: ● CARGO DESCRIPTION | F14: : | G14: ='Summary PL'!D22 -> FO Cable Drum | P14: ● CARGO DESCRIPTION | U14: : | V14: =G14 -> FO Cable Drum
A15: ОПИСАНИЕ ГРУЗА | P15: ОПИСАНИЕ ГРУЗА
A17: ● PACKAGE NO. | F17: : | G17: ='Summary PL'!C22 -> PGU-DE-0311-DCS-INS-009 | P17: ● PACKAGE NO. | U17: : | V17: =G17 -> PGU-DE-0311-DCS-INS-009
A18: УПАКОВОЧНЫЙ НОМЕР | P18: УПАКОВОЧНЫЙ НОМЕР
A20: ● NET WEIGHT | F20: : | G20: ='Summary PL'!L22 -> 156 | H20: Kg | P20: ● NET WEIGHT | U20: : | V20: =G20 -> 156 | W20: Kg
A21: ВЕС НЕТТО | P21: ВЕС НЕТТО
A23: ● GROSS WEIGHT | F23: : | G23: ='Summary PL'!M22 -> 209 | H23: Kg | P23: ● GROSS WEIGHT | U23: : | V23: =G23 -> 209 | W23: Kg
A24: ВЕС БРУТТО | P24: ВЕС БРУТТО
A26: ● CBM(m3) | F26: : | G26: ='Summary PL'!K22 -> 0.469 | H26: m3 | P26: ● CBM(m3) | U26: : | V26: =G26 -> 0.469 | W26: m3
A27: РАЗМЕРЫ | P27: РАЗМЕРЫ
A29: ● FINAL DESTINATION | F29: : | G29: Turkestan Oblast, Sairam district, Karamurt rural district, quarter 171, Republic of Kazakhstan | P29: ● FINAL DESTINATION | U29: : | V29: =G29 -> Turkestan Oblast, Sairam district, Karamurt rural district, quarter 171, Republic of Kazakhstan
A30: КОНЕЧНЫЙ ПУНКТ НАЗНАЧЕНИЯ | P30: КОНЕЧНЫЙ ПУНКТ НАЗНАЧЕНИЯ
E31: Doosan Enerbility | T31: Doosan Enerbility

Sheet PGU-DE-0311-DCS-INS-010
A1: SHIPPING MARK ГРУЗОВАЯ МАРКИРОВКА | P1: SHIPPING MARK ГРУЗОВАЯ МАРКИРОВКА
A2: ● NAME OF THE PROJECT | F2: : | G2: Construction of a 1000 MW CCGT Power Plant in the Sairam District of the | P2: ● NAME OF THE PROJECT | U2: : | V2: Construction of a 1000 MW CCGT Power Plant in the Sairam District of the
A3: НАЗВАНИЕ ПРОЕКТА | G3: Turkistan Region, Main Site. Without External Engineering Networks | P3: НАЗВАНИЕ ПРОЕКТА | V3: Turkistan Region, Main Site. Without External Engineering Networks
A5: ● CONSIGNEE | F5: : | G5: =CI!B13 -> Branch of JSC "Doosan Enerbility" in the Turkestan region | P5: ● CONSIGNEE | U5: : | V5: =G5 -> Branch of JSC "Doosan Enerbility" in the Turkestan region
A6: ГРУЗОПОЛУЧАТЕЛЬ | P6: ГРУЗОПОЛУЧАТЕЛЬ
A8: ● Shipper/Exporter | F8: : Doosan Enerbility Co., LTD | P8: ● Shipper/Exporter | U8: : Doosan Enerbility Co., LTD
A9: Грузоотправитель/Экспортер | F9: 22, Doosan Volvo-ro, Sengsan-gu, Changwon, Gyeongnam, South Korea | P9: Грузоотправитель/Экспортер | U9: 22, Doosan Volvo-ro, Sengsan-gu, Changwon, Gyeongnam, South Korea
A11: ● Number of Invoice | F11: : | G11: =CI!V8 -> PGU-DE-0311 | P11: ● Number of Invoice | U11: : | V11: =CI!V8 -> PGU-DE-0311
A12: № инвойса | P12: № инвойса
A14: ● CARGO DESCRIPTION | F14: : | G14: ='Summary PL'!D23 -> FO Cable Drum | P14: ● CARGO DESCRIPTION | U14: : | V14: =G14 -> FO Cable Drum
A15: ОПИСАНИЕ ГРУЗА | P15: ОПИСАНИЕ ГРУЗА
A17: ● PACKAGE NO. | F17: : | G17: ='Summary PL'!C23 -> PGU-DE-0311-DCS-INS-010 | P17: ● PACKAGE NO. | U17: : | V17: =G17 -> PGU-DE-0311-DCS-INS-010
A18: УПАКОВОЧНЫЙ НОМЕР | P18: УПАКОВОЧНЫЙ НОМЕР
A20: ● NET WEIGHT | F20: : | G20: ='Summary PL'!L23 -> 154 | H20: Kg | P20: ● NET WEIGHT | U20: : | V20: =G20 -> 154 | W20: Kg
A21: ВЕС НЕТТО | P21: ВЕС НЕТТО
A23: ● GROSS WEIGHT | F23: : | G23: ='Summary PL'!M23 -> 207 | H23: Kg | P23: ● GROSS WEIGHT | U23: : | V23: =G23 -> 207 | W23: Kg
A24: ВЕС БРУТТО | P24: ВЕС БРУТТО
A26: ● CBM(m3) | F26: : | G26: ='Summary PL'!K23 -> 0.469 | H26: m3 | P26: ● CBM(m3) | U26: : | V26: =G26 -> 0.469 | W26: m3
A27: РАЗМЕРЫ | P27: РАЗМЕРЫ
A29: ● FINAL DESTINATION | F29: : | G29: Turkestan Oblast, Sairam district, Karamurt rural district, quarter 171, Republic of Kazakhstan | P29: ● FINAL DESTINATION | U29: : | V29: =G29 -> Turkestan Oblast, Sairam district, Karamurt rural district, quarter 171, Republic of Kazakhstan
A30: КОНЕЧНЫЙ ПУНКТ НАЗНАЧЕНИЯ | P30: КОНЕЧНЫЙ ПУНКТ НАЗНАЧЕНИЯ
E31: Doosan Enerbility | T31: Doosan Enerbility

Sheet PGU-DE-0311-DCS-INS-011
A1: SHIPPING MARK ГРУЗОВАЯ МАРКИРОВКА | P1: SHIPPING MARK ГРУЗОВАЯ МАРКИРОВКА
A2: ● NAME OF THE PROJECT | F2: : | G2: Construction of a 1000 MW CCGT Power Plant in the Sairam District of the | P2: ● NAME OF THE PROJECT | U2: : | V2: Construction of a 1000 MW CCGT Power Plant in the Sairam District of the
A3: НАЗВАНИЕ ПРОЕКТА | G3: Turkistan Region, Main Site. Without External Engineering Networks | P3: НАЗВАНИЕ ПРОЕКТА | V3: Turkistan Region, Main Site. Without External Engineering Networks
A5: ● CONSIGNEE | F5: : | G5: =CI!B13 -> Branch of JSC "Doosan Enerbility" in the Turkestan region | P5: ● CONSIGNEE | U5: : | V5: =G5 -> Branch of JSC "Doosan Enerbility" in the Turkestan region
A6: ГРУЗОПОЛУЧАТЕЛЬ | P6: ГРУЗОПОЛУЧАТЕЛЬ
A8: ● Shipper/Exporter | F8: : Doosan Enerbility Co., LTD | P8: ● Shipper/Exporter | U8: : Doosan Enerbility Co., LTD
A9: Грузоотправитель/Экспортер | F9: 22, Doosan Volvo-ro, Sengsan-gu, Changwon, Gyeongnam, South Korea | P9: Грузоотправитель/Экспортер | U9: 22, Doosan Volvo-ro, Sengsan-gu, Changwon, Gyeongnam, South Korea
A11: ● Number of Invoice | F11: : | G11: =CI!V8 -> PGU-DE-0311 | P11: ● Number of Invoice | U11: : | V11: =CI!V8 -> PGU-DE-0311
A12: № инвойса | P12: № инвойса
A14: ● CARGO DESCRIPTION | F14: : | G14: ='Summary PL'!D24 -> FO Cable Drum | P14: ● CARGO DESCRIPTION | U14: : | V14: =G14 -> FO Cable Drum
A15: ОПИСАНИЕ ГРУЗА | P15: ОПИСАНИЕ ГРУЗА
A17: ● PACKAGE NO. | F17: : | G17: ='Summary PL'!C24 -> PGU-DE-0311-DCS-INS-011 | P17: ● PACKAGE NO. | U17: : | V17: =G17 -> PGU-DE-0311-DCS-INS-011
A18: УПАКОВОЧНЫЙ НОМЕР | P18: УПАКОВОЧНЫЙ НОМЕР
A20: ● NET WEIGHT | F20: : | G20: ='Summary PL'!L24 -> 156 | H20: Kg | P20: ● NET WEIGHT | U20: : | V20: =G20 -> 156 | W20: Kg
A21: ВЕС НЕТТО | P21: ВЕС НЕТТО
A23: ● GROSS WEIGHT | F23: : | G23: ='Summary PL'!M24 -> 209 | H23: Kg | P23: ● GROSS WEIGHT | U23: : | V23: =G23 -> 209 | W23: Kg
A24: ВЕС БРУТТО | P24: ВЕС БРУТТО
A26: ● CBM(m3) | F26: : | G26: ='Summary PL'!K24 -> 0.469 | H26: m3 | P26: ● CBM(m3) | U26: : | V26: =G26 -> 0.469 | W26: m3
A27: РАЗМЕРЫ | P27: РАЗМЕРЫ
A29: ● FINAL DESTINATION | F29: : | G29: Turkestan Oblast, Sairam district, Karamurt rural district, quarter 171, Republic of Kazakhstan | P29: ● FINAL DESTINATION | U29: : | V29: =G29 -> Turkestan Oblast, Sairam district, Karamurt rural district, quarter 171, Republic of Kazakhstan
A30: КОНЕЧНЫЙ ПУНКТ НАЗНАЧЕНИЯ | P30: КОНЕЧНЫЙ ПУНКТ НАЗНАЧЕНИЯ
E31: Doosan Enerbility | T31: Doosan Enerbility

Sheet PGU-DE-0311-DCS-INS-012
A1: SHIPPING MARK ГРУЗОВАЯ МАРКИРОВКА | P1: SHIPPING MARK ГРУЗОВАЯ МАРКИРОВКА
A2: ● NAME OF THE PROJECT | F2: : | G2: Construction of a 1000 MW CCGT Power Plant in the Sairam District of the | P2: ● NAME OF THE PROJECT | U2: : | V2: Construction of a 1000 MW CCGT Power Plant in the Sairam District of the
A3: НАЗВАНИЕ ПРОЕКТА | G3: Turkistan Region, Main Site. Without External Engineering Networks | P3: НАЗВАНИЕ ПРОЕКТА | V3: Turkistan Region, Main Site. Without External Engineering Networks
A5: ● CONSIGNEE | F5: : | G5: =CI!B13 -> Branch of JSC "Doosan Enerbility" in the Turkestan region | P5: ● CONSIGNEE | U5: : | V5: =G5 -> Branch of JSC "Doosan Enerbility" in the Turkestan region
A6: ГРУЗОПОЛУЧАТЕЛЬ | P6: ГРУЗОПОЛУЧАТЕЛЬ
A8: ● Shipper/Exporter | F8: : Doosan Enerbility Co., LTD | P8: ● Shipper/Exporter | U8: : Doosan Enerbility Co., LTD
A9: Грузоотправитель/Экспортер | F9: 22, Doosan Volvo-ro, Sengsan-gu, Changwon, Gyeongnam, South Korea | P9: Грузоотправитель/Экспортер | U9: 22, Doosan Volvo-ro, Sengsan-gu, Changwon, Gyeongnam, South Korea
A11: ● Number of Invoice | F11: : | G11: =CI!V8 -> PGU-DE-0311 | P11: ● Number of Invoice | U11: : | V11: =CI!V8 -> PGU-DE-0311
A12: № инвойса | P12: № инвойса
A14: ● CARGO DESCRIPTION | F14: : | G14: ='Summary PL'!D25 -> FO Cable Drum | P14: ● CARGO DESCRIPTION | U14: : | V14: =G14 -> FO Cable Drum
A15: ОПИСАНИЕ ГРУЗА | P15: ОПИСАНИЕ ГРУЗА
A17: ● PACKAGE NO. | F17: : | G17: ='Summary PL'!C25 -> PGU-DE-0311-DCS-INS-012 | P17: ● PACKAGE NO. | U17: : | V17: =G17 -> PGU-DE-0311-DCS-INS-012
A18: УПАКОВОЧНЫЙ НОМЕР | P18: УПАКОВОЧНЫЙ НОМЕР
A20: ● NET WEIGHT | F20: : | G20: ='Summary PL'!L25 -> 153 | H20: Kg | P20: ● NET WEIGHT | U20: : | V20: =G20 -> 153 | W20: Kg
A21: ВЕС НЕТТО | P21: ВЕС НЕТТО
A23: ● GROSS WEIGHT | F23: : | G23: ='Summary PL'!M25 -> 206 | H23: Kg | P23: ● GROSS WEIGHT | U23: : | V23: =G23 -> 206 | W23: Kg
A24: ВЕС БРУТТО | P24: ВЕС БРУТТО
A26: ● CBM(m3) | F26: : | G26: ='Summary PL'!K25 -> 0.469 | H26: m3 | P26: ● CBM(m3) | U26: : | V26: =G26 -> 0.469 | W26: m3
A27: РАЗМЕРЫ | P27: РАЗМЕРЫ
A29: ● FINAL DESTINATION | F29: : | G29: Turkestan Oblast, Sairam district, Karamurt rural district, quarter 171, Republic of Kazakhstan | P29: ● FINAL DESTINATION | U29: : | V29: =G29 -> Turkestan Oblast, Sairam district, Karamurt rural district, quarter 171, Republic of Kazakhstan
A30: КОНЕЧНЫЙ ПУНКТ НАЗНАЧЕНИЯ | P30: КОНЕЧНЫЙ ПУНКТ НАЗНАЧЕНИЯ
E31: Doosan Enerbility | T31: Doosan Enerbility

Sheet PGU-DE-0311-INS-Cable-013
A1: SHIPPING MARK ГРУЗОВАЯ МАРКИРОВКА | P1: SHIPPING MARK ГРУЗОВАЯ МАРКИРОВКА
A2: ● NAME OF THE PROJECT | F2: : | G2: Construction of a 1000 MW CCGT Power Plant in the Sairam District of the | P2: ● NAME OF THE PROJECT | U2: : | V2: Construction of a 1000 MW CCGT Power Plant in the Sairam District of the
A3: НАЗВАНИЕ ПРОЕКТА | G3: Turkistan Region, Main Site. Without External Engineering Networks | P3: НАЗВАНИЕ ПРОЕКТА | V3: Turkistan Region, Main Site. Without External Engineering Networks
A5: ● CONSIGNEE | F5: : | G5: =CI!B13 -> Branch of JSC "Doosan Enerbility" in the Turkestan region | P5: ● CONSIGNEE | U5: : | V5: =G5 -> Branch of JSC "Doosan Enerbility" in the Turkestan region
A6: ГРУЗОПОЛУЧАТЕЛЬ | P6: ГРУЗОПОЛУЧАТЕЛЬ
A8: ● Shipper/Exporter | F8: : Doosan Enerbility Co., LTD | P8: ● Shipper/Exporter | U8: : Doosan Enerbility Co., LTD
A9: Грузоотправитель/Экспортер | F9: 22, Doosan Volvo-ro, Sengsan-gu, Changwon, Gyeongnam, South Korea | P9: Грузоотправитель/Экспортер | U9: 22, Doosan Volvo-ro, Sengsan-gu, Changwon, Gyeongnam, South Korea
A11: ● Number of Invoice | F11: : | G11: =CI!V8 -> PGU-DE-0311 | P11: ● Number of Invoice | U11: : | V11: =CI!V8 -> PGU-DE-0311
A12: № инвойса | P12: № инвойса
A14: ● CARGO DESCRIPTION | F14: : | G14: ='Summary PL'!D26 -> FO Cable Drum | P14: ● CARGO DESCRIPTION | U14: : | V14: =G14 -> FO Cable Drum
A15: ОПИСАНИЕ ГРУЗА | P15: ОПИСАНИЕ ГРУЗА
A17: ● PACKAGE NO. | F17: : | G17: ='Summary PL'!C26 -> PGU-DE-0311-DCS-INS-013 | P17: ● PACKAGE NO. | U17: : | V17: =G17 -> PGU-DE-0311-DCS-INS-013
A18: УПАКОВОЧНЫЙ НОМЕР | P18: УПАКОВОЧНЫЙ НОМЕР
A20: ● NET WEIGHT | F20: : | G20: ='Summary PL'!L26 -> 158 | H20: Kg | P20: ● NET WEIGHT | U20: : | V20: =G20 -> 158 | W20: Kg
A21: ВЕС НЕТТО | P21: ВЕС НЕТТО
A23: ● GROSS WEIGHT | F23: : | G23: ='Summary PL'!M26 -> 211 | H23: Kg | P23: ● GROSS WEIGHT | U23: : | V23: =G23 -> 211 | W23: Kg
A24: ВЕС БРУТТО | P24: ВЕС БРУТТО
A26: ● CBM(m3) | F26: : | G26: ='Summary PL'!K26 -> 0.469 | H26: m3 | P26: ● CBM(m3) | U26: : | V26: =G26 -> 0.469 | W26: m3
A27: РАЗМЕРЫ | P27: РАЗМЕРЫ
A29: ● FINAL DESTINATION | F29: : | G29: Turkestan Oblast, Sairam district, Karamurt rural district, quarter 171, Republic of Kazakhstan | P29: ● FINAL DESTINATION | U29: : | V29: =G29 -> Turkestan Oblast, Sairam district, Karamurt rural district, quarter 171, Republic of Kazakhstan
A30: КОНЕЧНЫЙ ПУНКТ НАЗНАЧЕНИЯ | P30: КОНЕЧНЫЙ ПУНКТ НАЗНАЧЕНИЯ
E31: Doosan Enerbility | T31: Doosan Enerbility

Sheet PGU-DE-0311-DCS-INS-014
A1: SHIPPING MARK ГРУЗОВАЯ МАРКИРОВКА | P1: SHIPPING MARK ГРУЗОВАЯ МАРКИРОВКА
A2: ● NAME OF THE PROJECT | F2: : | G2: Construction of a 1000 MW CCGT Power Plant in the Sairam District of the | P2: ● NAME OF THE PROJECT | U2: : | V2: Construction of a 1000 MW CCGT Power Plant in the Sairam District of the
A3: НАЗВАНИЕ ПРОЕКТА | G3: Turkistan Region, Main Site. Without External Engineering Networks | P3: НАЗВАНИЕ ПРОЕКТА | V3: Turkistan Region, Main Site. Without External Engineering Networks
A5: ● CONSIGNEE | F5: : | G5: =CI!B13 -> Branch of JSC "Doosan Enerbility" in the Turkestan region | P5: ● CONSIGNEE | U5: : | V5: =G5 -> Branch of JSC "Doosan Enerbility" in the Turkestan region
A6: ГРУЗОПОЛУЧАТЕЛЬ | P6: ГРУЗОПОЛУЧАТЕЛЬ
A8: ● Shipper/Exporter | F8: : Doosan Enerbility Co., LTD | P8: ● Shipper/Exporter | U8: : Doosan Enerbility Co., LTD
A9: Грузоотправитель/Экспортер | F9: 22, Doosan Volvo-ro, Sengsan-gu, Changwon, Gyeongnam, South Korea | P9: Грузоотправитель/Экспортер | U9: 22, Doosan Volvo-ro, Sengsan-gu, Changwon, Gyeongnam, South Korea
A11: ● Number of Invoice | F11: : | G11: =CI!V8 -> PGU-DE-0311 | P11: ● Number of Invoice | U11: : | V11: =CI!V8 -> PGU-DE-0311
A12: № инвойса | P12: № инвойса
A14: ● CARGO DESCRIPTION | F14: : | G14: ='Summary PL'!D27 -> FO Cable Drum | P14: ● CARGO DESCRIPTION | U14: : | V14: =G14 -> FO Cable Drum
A15: ОПИСАНИЕ ГРУЗА | P15: ОПИСАНИЕ ГРУЗА
A17: ● PACKAGE NO. | F17: : | G17: ='Summary PL'!C27 -> PGU-DE-0311-DCS-INS-014 | P17: ● PACKAGE NO. | U17: : | V17: =G17 -> PGU-DE-0311-DCS-INS-014
A18: УПАКОВОЧНЫЙ НОМЕР | P18: УПАКОВОЧНЫЙ НОМЕР
A20: ● NET WEIGHT | F20: : | G20: ='Summary PL'!L27 -> 160 | H20: Kg | P20: ● NET WEIGHT | U20: : | V20: =G20 -> 160 | W20: Kg
A21: ВЕС НЕТТО | P21: ВЕС НЕТТО
A23: ● GROSS WEIGHT | F23: : | G23: ='Summary PL'!M27 -> 213 | H23: Kg | P23: ● GROSS WEIGHT | U23: : | V23: =G23 -> 213 | W23: Kg
A24: ВЕС БРУТТО | P24: ВЕС БРУТТО
A26: ● CBM(m3) | F26: : | G26: ='Summary PL'!K27 -> 0.469 | H26: m3 | P26: ● CBM(m3) | U26: : | V26: =G26 -> 0.469 | W26: m3
A27: РАЗМЕРЫ | P27: РАЗМЕРЫ
A29: ● FINAL DESTINATION | F29: : | G29: Turkestan Oblast, Sairam district, Karamurt rural district, quarter 171, Republic of Kazakhstan | P29: ● FINAL DESTINATION | U29: : | V29: =G29 -> Turkestan Oblast, Sairam district, Karamurt rural district, quarter 171, Republic of Kazakhstan
A30: КОНЕЧНЫЙ ПУНКТ НАЗНАЧЕНИЯ | P30: КОНЕЧНЫЙ ПУНКТ НАЗНАЧЕНИЯ
E31: Doosan Enerbility | T31: Doosan Enerbility

Sheet PGU-DE-0311-DCS-INS-015
A1: SHIPPING MARK ГРУЗОВАЯ МАРКИРОВКА | P1: SHIPPING MARK ГРУЗОВАЯ МАРКИРОВКА
A2: ● NAME OF THE PROJECT | F2: : | G2: Construction of a 1000 MW CCGT Power Plant in the Sairam District of the | P2: ● NAME OF THE PROJECT | U2: : | V2: Construction of a 1000 MW CCGT Power Plant in the Sairam District of the
A3: НАЗВАНИЕ ПРОЕКТА | G3: Turkistan Region, Main Site. Without External Engineering Networks | P3: НАЗВАНИЕ ПРОЕКТА | V3: Turkistan Region, Main Site. Without External Engineering Networks
A5: ● CONSIGNEE | F5: : | G5: =CI!B13 -> Branch of JSC "Doosan Enerbility" in the Turkestan region | P5: ● CONSIGNEE | U5: : | V5: =G5 -> Branch of JSC "Doosan Enerbility" in the Turkestan region
A6: ГРУЗОПОЛУЧАТЕЛЬ | P6: ГРУЗОПОЛУЧАТЕЛЬ
A8: ● Shipper/Exporter | F8: : Doosan Enerbility Co., LTD | P8: ● Shipper/Exporter | U8: : Doosan Enerbility Co., LTD
A9: Грузоотправитель/Экспортер | F9: 22, Doosan Volvo-ro, Sengsan-gu, Changwon, Gyeongnam, South Korea | P9: Грузоотправитель/Экспортер | U9: 22, Doosan Volvo-ro, Sengsan-gu, Changwon, Gyeongnam, South Korea
A11: ● Number of Invoice | F11: : | G11: =CI!V8 -> PGU-DE-0311 | P11: ● Number of Invoice | U11: : | V11: =CI!V8 -> PGU-DE-0311
A12: № инвойса | P12: № инвойса
A14: ● CARGO DESCRIPTION | F14: : | G14: ='Summary PL'!D28 -> FO Cable Drum | P14: ● CARGO DESCRIPTION | U14: : | V14: =G14 -> FO Cable Drum
A15: ОПИСАНИЕ ГРУЗА | P15: ОПИСАНИЕ ГРУЗА
A17: ● PACKAGE NO. | F17: : | G17: ='Summary PL'!C28 -> PGU-DE-0311-DCS-INS-015 | P17: ● PACKAGE NO. | U17: : | V17: =G17 -> PGU-DE-0311-DCS-INS-015
A18: УПАКОВОЧНЫЙ НОМЕР | P18: УПАКОВОЧНЫЙ НОМЕР
A20: ● NET WEIGHT | F20: : | G20: ='Summary PL'!L28 -> 156 | H20: Kg | P20: ● NET WEIGHT | U20: : | V20: =G20 -> 156 | W20: Kg
A21: ВЕС НЕТТО | P21: ВЕС НЕТТО
A23: ● GROSS WEIGHT | F23: : | G23: ='Summary PL'!M28 -> 210 | H23: Kg | P23: ● GROSS WEIGHT | U23: : | V23: =G23 -> 210 | W23: Kg
A24: ВЕС БРУТТО | P24: ВЕС БРУТТО
A26: ● CBM(m3) | F26: : | G26: ='Summary PL'!K28 -> 0.469 | H26: m3 | P26: ● CBM(m3) | U26: : | V26: =G26 -> 0.469 | W26: m3
A27: РАЗМЕРЫ | P27: РАЗМЕРЫ
A29: ● FINAL DESTINATION | F29: : | G29: Turkestan Oblast, Sairam district, Karamurt rural district, quarter 171, Republic of Kazakhstan | P29: ● FINAL DESTINATION | U29: : | V29: =G29 -> Turkestan Oblast, Sairam district, Karamurt rural district, quarter 171, Republic of Kazakhstan
A30: КОНЕЧНЫЙ ПУНКТ НАЗНАЧЕНИЯ | P30: КОНЕЧНЫЙ ПУНКТ НАЗНАЧЕНИЯ
E31: Doosan Enerbility | T31: Doosan Enerbility

Sheet PGU-DE-0311-DCS-INS-016
A1: SHIPPING MARK ГРУЗОВАЯ МАРКИРОВКА | P1: SHIPPING MARK ГРУЗОВАЯ МАРКИРОВКА
A2: ● NAME OF THE PROJECT | F2: : | G2: Construction of a 1000 MW CCGT Power Plant in the Sairam District of the | P2: ● NAME OF THE PROJECT | U2: : | V2: Construction of a 1000 MW CCGT Power Plant in the Sairam District of the
A3: НАЗВАНИЕ ПРОЕКТА | G3: Turkistan Region, Main Site. Without External Engineering Networks | P3: НАЗВАНИЕ ПРОЕКТА | V3: Turkistan Region, Main Site. Without External Engineering Networks
A5: ● CONSIGNEE | F5: : | G5: =CI!B13 -> Branch of JSC "Doosan Enerbility" in the Turkestan region | P5: ● CONSIGNEE | U5: : | V5: =G5 -> Branch of JSC "Doosan Enerbility" in the Turkestan region
A6: ГРУЗОПОЛУЧАТЕЛЬ | P6: ГРУЗОПОЛУЧАТЕЛЬ
A8: ● Shipper/Exporter | F8: : Doosan Enerbility Co., LTD | P8: ● Shipper/Exporter | U8: : Doosan Enerbility Co., LTD
A9: Грузоотправитель/Экспортер | F9: 22, Doosan Volvo-ro, Sengsan-gu, Changwon, Gyeongnam, South Korea | P9: Грузоотправитель/Экспортер | U9: 22, Doosan Volvo-ro, Sengsan-gu, Changwon, Gyeongnam, South Korea
A11: ● Number of Invoice | F11: : | G11: =CI!V8 -> PGU-DE-0311 | P11: ● Number of Invoice | U11: : | V11: =CI!V8 -> PGU-DE-0311
A12: № инвойса | P12: № инвойса
A14: ● CARGO DESCRIPTION | F14: : | G14: ='Summary PL'!D29 -> FO Cable Drum | P14: ● CARGO DESCRIPTION | U14: : | V14: =G14 -> FO Cable Drum
A15: ОПИСАНИЕ ГРУЗА | P15: ОПИСАНИЕ ГРУЗА
A17: ● PACKAGE NO. | F17: : | G17: ='Summary PL'!C29 -> PGU-DE-0311-DCS-INS-016 | P17: ● PACKAGE NO. | U17: : | V17: =G17 -> PGU-DE-0311-DCS-INS-016
A18: УПАКОВОЧНЫЙ НОМЕР | P18: УПАКОВОЧНЫЙ НОМЕР
A20: ● NET WEIGHT | F20: : | G20: ='Summary PL'!L29 -> 158 | H20: Kg | P20: ● NET WEIGHT | U20: : | V20: =G20 -> 158 | W20: Kg
A21: ВЕС НЕТТО | P21: ВЕС НЕТТО
A23: ● GROSS WEIGHT | F23: : | G23: ='Summary PL'!M29 -> 210 | H23: Kg | P23: ● GROSS WEIGHT | U23: : | V23: =G23 -> 210 | W23: Kg
A24: ВЕС БРУТТО | P24: ВЕС БРУТТО
A26: ● CBM(m3) | F26: : | G26: ='Summary PL'!K29 -> 0.469 | H26: m3 | P26: ● CBM(m3) | U26: : | V26: =G26 -> 0.469 | W26: m3
A27: РАЗМЕРЫ | P27: РАЗМЕРЫ
A29: ● FINAL DESTINATION | F29: : | G29: Turkestan Oblast, Sairam district, Karamurt rural district, quarter 171, Republic of Kazakhstan | P29: ● FINAL DESTINATION | U29: : | V29: =G29 -> Turkestan Oblast, Sairam district, Karamurt rural district, quarter 171, Republic of Kazakhstan
A30: КОНЕЧНЫЙ ПУНКТ НАЗНАЧЕНИЯ | P30: КОНЕЧНЫЙ ПУНКТ НАЗНАЧЕНИЯ
E31: Doosan Enerbility | T31: Doosan Enerbility

Sheet PGU-DE-0311-DCS-INS-017
A1: SHIPPING MARK ГРУЗОВАЯ МАРКИРОВКА | P1: SHIPPING MARK ГРУЗОВАЯ МАРКИРОВКА
A2: ● NAME OF THE PROJECT | F2: : | G2: Construction of a 1000 MW CCGT Power Plant in the Sairam District of the | P2: ● NAME OF THE PROJECT | U2: : | V2: Construction of a 1000 MW CCGT Power Plant in the Sairam District of the
A3: НАЗВАНИЕ ПРОЕКТА | G3: Turkistan Region, Main Site. Without External Engineering Networks | P3: НАЗВАНИЕ ПРОЕКТА | V3: Turkistan Region, Main Site. Without External Engineering Networks
A5: ● CONSIGNEE | F5: : | G5: =CI!B13 -> Branch of JSC "Doosan Enerbility" in the Turkestan region | P5: ● CONSIGNEE | U5: : | V5: =G5 -> Branch of JSC "Doosan Enerbility" in the Turkestan region
A6: ГРУЗОПОЛУЧАТЕЛЬ | P6: ГРУЗОПОЛУЧАТЕЛЬ
A8: ● Shipper/Exporter | F8: : Doosan Enerbility Co., LTD | P8: ● Shipper/Exporter | U8: : Doosan Enerbility Co., LTD
A9: Грузоотправитель/Экспортер | F9: 22, Doosan Volvo-ro, Sengsan-gu, Changwon, Gyeongnam, South Korea | P9: Грузоотправитель/Экспортер | U9: 22, Doosan Volvo-ro, Sengsan-gu, Changwon, Gyeongnam, South Korea
A11: ● Number of Invoice | F11: : | G11: =CI!V8 -> PGU-DE-0311 | P11: ● Number of Invoice | U11: : | V11: =CI!V8 -> PGU-DE-0311
A12: № инвойса | P12: № инвойса
A14: ● CARGO DESCRIPTION | F14: : | G14: ='Summary PL'!D30 -> FO Cable Drum | P14: ● CARGO DESCRIPTION | U14: : | V14: =G14 -> FO Cable Drum
A15: ОПИСАНИЕ ГРУЗА | P15: ОПИСАНИЕ ГРУЗА
A17: ● PACKAGE NO. | F17: : | G17: ='Summary PL'!C30 -> PGU-DE-0311-DCS-INS-017 | P17: ● PACKAGE NO. | U17: : | V17: =G17 -> PGU-DE-0311-DCS-INS-017
A18: УПАКОВОЧНЫЙ НОМЕР | P18: УПАКОВОЧНЫЙ НОМЕР
A20: ● NET WEIGHT | F20: : | G20: ='Summary PL'!L30 -> 160 | H20: Kg | P20: ● NET WEIGHT | U20: : | V20: =G20 -> 160 | W20: Kg
A21: ВЕС НЕТТО | P21: ВЕС НЕТТО
A23: ● GROSS WEIGHT | F23: : | G23: ='Summary PL'!M30 -> 212 | H23: Kg | P23: ● GROSS WEIGHT | U23: : | V23: =G23 -> 212 | W23: Kg
A24: ВЕС БРУТТО | P24: ВЕС БРУТТО
A26: ● CBM(m3) | F26: : | G26: ='Summary PL'!K30 -> 0.469 | H26: m3 | P26: ● CBM(m3) | U26: : | V26: =G26 -> 0.469 | W26: m3
A27: РАЗМЕРЫ | P27: РАЗМЕРЫ
A29: ● FINAL DESTINATION | F29: : | G29: Turkestan Oblast, Sairam district, Karamurt rural district, quarter 171, Republic of Kazakhstan | P29: ● FINAL DESTINATION | U29: : | V29: =G29 -> Turkestan Oblast, Sairam district, Karamurt rural district, quarter 171, Republic of Kazakhstan
A30: КОНЕЧНЫЙ ПУНКТ НАЗНАЧЕНИЯ | P30: КОНЕЧНЫЙ ПУНКТ НАЗНАЧЕНИЯ
