Workbook
Name AnnullaInseriscidata: #REF!
Name AnnullaInseriscidata: #REF!
Name InserisciData: #REF!
Name InserisciData: #REF!

Sheet CI
W1: HEAD OFFICE & CHANGWON PLANT
W2: 22, DoosanVolvo-ro, Seongsan-gu, Changwon-Si,
W3: Gyeongsangnam-do, Korea
W4: (P.O.BOX 77, Changwon, Korea)
W5: TEL:(055)278-6114,7114 FAX:(055)264-5551/2
A6: PROFORMA INVOICE ПРОФОРМА ИНВОЙС
A8: 1. Shipper / Грузоотправитель | R8: 11. Invoice № : | V8: =PL!V8 -> PGU-DE-0481
B9: Doosan Enerbility Co., Ltd (DOOSAN) | R9: Инвойс №
B10: 22, DoosanVolvo-ro, Seongsan-gu, Changwon-si, Gyeongsangnam-do, | R10: 12. Date : | V10: =PL!V10 -> 45896
B11: Republic of Korea | R11: Дата
A12: 2. Consignee / Грузополучатель | R12: 13. Remarks / Примечания
B13: Branch of JSC "Doosan Enerbility" in the Turkestan region
B14: 321 Tauke Khan Avenue, Turkestan region, Turkestan, Kazakhstan, 161200 | S14: *Project Name / Название Проекта
B15: BIN: 230741006561 | S15: Construction of a 1000 MW CCGT Power Plant in the Sairam District of
S16: Turkistan Region, Main Site. Without External Engineering Networks
S17: *MANUFACTURER'S NAME / НАЗВАНИЕ ПРОИЗВОДИТЕЛЯ
A18: 3. Notify party / Уведомляемая сторона | S18: YPP (Iljin Electric)
B19: Wise Logistics | S19: *MANUFACTURE YEAR / ГОД ИЗГОТОВЛЕНИЯ
B20: ATTAN: MS. Aliya | S20: 2025
B21: (E): a.kipshakbayeva@wiselogistics.kz | S21: *COUNTRY OF ORIGIN / СТРАНА ПРОИСХОЖДЕНИЯ
B22: (T): +7 701 512 19 69 | S22: Republic of Korea
S23: *INCOTERMS / УСЛОВИЯ ПОСТАВКИ СОГЛАСНО ИНКОТЕРМС
S24: DDP Turkistan
A26: 4. Port of Loading / Порт погрузки | I26: 5. Carrier / Перевозчик | R26: 14. Mark and Numbers of PKGS / Маркировка и количество упаковок
B27: Busan, Korea | J27: Later
S28: PKG No. | X28: : | Y28: PGU-DE-0481-PoCable-001,…026
A29: 6. Port of Unloading / Порт разгрузки | I29: 7. Final Destination / Конечный пункт назначения | S29: Q-ty of Package | X29: : | Y29: =PL!Y29 -> 26 | AC29: PKGS
S30: Net Weight (kg) | X30: : | Y30: =PL!Y30 -> 21259 | AC30: KG
B31: Lianyungang, China | J31: Turkestan region, Sairam district | S31: Gross Weight (kg) | X31: : | Y31: =PL!Y31 -> 27223 | AC31: KG
S32: Dimension (m3) | X32: : | Y32: ='Summary PL'!K40 -> 44.135 | AC32: m3
A33: 8. Voyage No / Рейс № | I33: 9. Sailing on or about / Дата или ожидаемая дата
B35: LING YUN HE 746W | J35: 45978
A37: 10. Customs Place / Место таможенного оформления
A40: 15. Description of Goods / Описание товара | R40: 16. HS CODE / | W40: 17. Quantity / | AA40: 18. Total Price (USD)
R41: Код ТН ВЭД | W41: Количество | AA41: Общая сумма (Дол. США)
B42: 0.6/1kV CU/XLPE/LSZH for power cable | R42: 8544.49-2012 | W42: 1 | AA42: =CI_BD!I35 -> 1248453.8
B43: Кабель управления и кабель питания ОРУ | W43: / комплект
I45: Total (DDP Value) | AA45: =AA42 -> 1248453.8
S53: Signed by
A54: Doosan Enerbility Co., Ltd
...

Sheet CI_BD
J1: HEAD OFFICE & CHANGWON PLANT
J2: 22, DoosanVolvo-ro, Seongsan-gu, Changwon-Si,
J3: Gyeongsangnam-do, Korea
J4: (P.O.BOX 77, Changwon, Korea)
J5: TEL:(055)278-6114,7114 FAX:(055)264-5551/2
A6: INVOICE (Break-down)
A7: Invoice № : | B7: =CI!V8 -> PGU-DE-0481
A8: № | B8: № Package | C8: CNTR NO. | D8: Description of Goods Specification | E8: HS CODE | F8: Quantity | G8: Unit | H8: U/Price (USD) | I8: Amount (USD) | J8: Country of Origin | M8: Remark
A9: 1 | B9: PGU-DE-0481-AIS-PoCable-001 | C9: =VLOOKUP(B9,'[1]1113'!$C:$D,2,0) -> OCMU9396883 | D9: Power Cable | E9: 8544.49-2012 | F9: 1 | G9: EA | H9: 27777.35 | I9: =F9*H9 -> 27777.35 | J9: Korea
A10: 2 | B10: PGU-DE-0481-AIS-PoCable-002 | C10: =VLOOKUP(B10,'[1]1113'!$C:$D,2,0) -> OCMU9396883 | D10: Power Cable | E10: 8544.49-2012 | F10: 1 | G10: EA | H10: 27777.35 | I10: =F10*H10 -> 27777.35 | J10: Korea
A11: 3 | B11: PGU-DE-0481-AIS-PoCable-003 | C11: =VLOOKUP(B11,'[1]1113'!$C:$D,2,0) -> OCMU9396883 | D11: Power Cable | E11: 8544.49-2012 | F11: 1 | G11: EA | H11: 27777.35 | I11: =F11*H11 -> 27777.35 | J11: Korea
A12: 4 | B12: PGU-DE-0481-AIS-PoCable-004 | C12: =VLOOKUP(B12,'[1]1113'!$C:$D,2,0) -> OCMU9396883 | D12: Power Cable | E12: 8544.49-2012 | F12: 1 | G12: EA | H12: 27777.35 | I12: =F12*H12 -> 27777.35 | J12: Korea
A13: 5 | B13: PGU-DE-0481-AIS-PoCable-005 | C13: =VLOOKUP(B13,'[1]1113'!$C:$D,2,0) -> OCMU9396883 | D13: Power Cable | E13: 8544.49-2012 | F13: 1 | G13: EA | H13: 27777.35 | I13: =F13*H13 -> 27777.35 | J13: Korea
A14: 6 | B14: PGU-DE-0481-AIS-PoCable-006 | C14: =VLOOKUP(B14,'[1]1113'!$C:$D,2,0) -> OCMU9396883 | D14: Power Cable | E14: 8544.49-2012 | F14: 1 | G14: EA | H14: 27777.35 | I14: =F14*H14 -> 27777.35 | J14: Korea
A15: 7 | B15: PGU-DE-0481-AIS-PoCable-007 | C15: =VLOOKUP(B15,'[1]1113'!$C:$D,2,0) -> OCMU9396883 | D15: Power Cable | E15: 8544.49-2012 | F15: 1 | G15: EA | H15: 27777.35 | I15: =F15*H15 -> 27777.35 | J15: Korea
A16: 8 | B16: PGU-DE-0481-AIS-PoCable-008 | C16: =VLOOKUP(B16,'[1]1113'!$C:$D,2,0) -> OCMU9396883 | D16: Power Cable | E16: 8544.49-2012 | F16: 1 | G16: EA | H16: 27777.35 | I16: =F16*H16 -> 27777.35 | J16: Korea
A17: 9 | B17: PGU-DE-0481-AIS-PoCable-009 | C17: =VLOOKUP(B17,'[1]1113'!$C:$D,2,0) -> OCMU9396883 | D17: Power Cable | E17: 8544.49-2012 | F17: 1 | G17: EA | H17: 27777.35 | I17: =F17*H17 -> 27777.35 | J17: Korea
A18: 10 | B18: PGU-DE-0481-AIS-PoCable-010 | C18: =VLOOKUP(B18,'[1]1113'!$C:$D,2,0) -> OCMU9396883 | D18: Power Cable | E18: 8544.49-2012 | F18: 1 | G18: EA | H18: 27777.35 | I18: =F18*H18 -> 27777.35 | J18: Korea
A19: 11 | B19: PGU-DE-0481-AIS-PoCable-011 | C19: =VLOOKUP(B19,'[1]1113'!$C:$D,2,0) -> OCMU9396883 | D19: Power Cable | E19: 8544.49-2012 | F19: 1 | G19: EA | H19: 27777.35 | I19: =F19*H19 -> 27777.35 | J19: Korea
A20: 12 | B20: PGU-DE-0481-AIS-PoCable-012 | C20: =VLOOKUP(B20,'[1]1113'!$C:$D,2,0) -> KPHU6954002 | D20: Power Cable | E20: 8544.49-2012 | F20: 1 | G20: EA | H20: 27777.35 | I20: =F20*H20 -> 27777.35 | J20: Korea
... A34: 26 | B34: PGU-DE-0481-AIS-PoCable-026 | C34: =VLOOKUP(B34,'[1]1113'!$C:$D,2,0) -> KPHU6954002 | D34: Power Cable | E34: 8544.49-2012 | F34: 1 | G34: EA | H34: 28599.47 | I34: =F34*H34 -> 28599.47 | J34: Korea
A35: TOTAL | F35: =SUM(F9:F34) -> 26 | I35: =SUM(I9:I34) -> 1248453.8

Sheet PL
W1: HEAD OFFICE & CHANGWON PLANT
W2: 22, DoosanVolvo-ro, Seongsan-gu, Changwon-Si,
W3: Gyeongsangnam-do, Korea
W4: (P.O.BOX 77, Changwon, Korea)
W5: TEL:(055)278-6114,7114 FAX:(055)264-5551/2
A6: PACKING LIST УПАКОВОЧНЫЙ ЛИСТ
A8: 1. Shipper / Грузоотправитель | R8: 11. Invoice № : | V8: PGU-DE-0481
B9: Doosan Enerbility Co., Ltd (DOOSAN) | R9: Инвойс №
B10: 22, DoosanVolvo-ro, Seongsan-gu, Changwon-si, Gyeongsangnam-do, | R10: 12. Date : | V10: 45896
B11: Republic of Korea | R11: Дата
A12: 2. Consignee / Грузополучатель | R12: 13. Remarks / Примечания
B13: Branch of JSC "Doosan Enerbility" in the Turkestan region
B14: 321 Tauke Khan Avenue, Turkestan region, Turkestan, Kazakhstan, 161200 | S14: *Project Name / Название Проекта
B15: BIN: 230741006561 | S15: Construction of a 1000 MW CCGT Power Plant in the Sairam District of
S16: Turkistan Region, Main Site. Without External Engineering Networks
S17: *MANUFACTURER'S NAME / НАЗВАНИЕ ПРОИЗВОДИТЕЛЯ
A18: 3. Notify party / Уведомляемая сторона | S18: YPP (Iljin Electric)
B19: Wise Logistics | S19: *MANUFACTURE YEAR / ГОД ИЗГОТОВЛЕНИЯ
B20: ATTAN: MS. Aliya | S20: 2025
B21: (E): a.kipshakbayeva@wiselogistics.kz | S21: *COUNTRY OF ORIGIN / СТРАНА ПРОИСХОЖДЕНИЯ
B22: (T): +7 701 512 19 69 | S22: Republic of Korea
S23: *INCOTERMS / УСЛОВИЯ ПОСТАВКИ СОГЛАСНО ИНКОТЕРМС
S24: DDP Turkistan
A26: 4. Port of Loading / Порт погрузки | I26: 5. Carrier / Перевозчик | R26: 14. Mark and Numbers of PKGS / Маркировка и количество упаковок
B27: Busan, Korea | J27: Later
S28: PKG No. | X28: : | Y28: PGU-DE-0481-PoCable-001,…026
A29: 6. Port of Unloading / Порт разгрузки | I29: 7. Final Destination / Конечный пункт назначения | S29: Q-ty of Package | X29: : | Y29: =COUNT('Summary PL'!A14:A39) -> 26 | AC29: PKGS
S30: Net Weight (kg) | X30: : | Y30: ='Summary PL'!L40 -> 21259 | AC30: KG
B31: Lianyungang, China | J31: Turkestan region, Sairam district | S31: Gross Weight (kg) | X31: : | Y31: ='Summary PL'!M40 -> 27223 | AC31: KG
S32: Dimension (m3) | X32: : | Y32: ='Summary PL'!K40 -> 44.135 | AC32: m3
A33: 8. Voyage No / Рейс № | I33: 9. Sailing on or about / Дата или ожидаемая дата
B35: LING YUN HE 746W | J35: 45978
A37: 10. Customs Place / Место таможенного оформления
A40: 15. Description of Goods / Описание товара | R40: 16. Q-ty | U40: 17. Net Weight | Y40: 18. Gross Weight | AC40: 19. Measurement
R41: (EA) | U41: (kg) | Y41: (kg) | AC41: (CBM)
B42: 0.6/1kV CU/XLPE/LSZH for power cable | R42: 1 | U42: ='Summary PL'!L40 -> 21259 | Y42: ='Summary PL'!M40 -> 27223 | AC42: ='Summary PL'!K40 -> 44.135
B43: Кабель питания для ОРУ | R43: / комплект
R45: =SUM(R42:T44) -> 1 | U45: =SUM(U42:X43) -> 21259 | Y45: =SUM(Y42:AB43) -> 27223 | AC45: =SUM(AC42:AC43) -> 44.135
S53: Signed by
A54: Doosan Enerbility Co., Ltd
...

Sheet Summary PL
O1: HEAD OFFICE & CHANGWON PLANT | Q1: Note> | R1: Storage Classification "A" : | S1: Indoor with Air-conditioning
O2: 22, DoosanVolvo-ro, Seongsan-gu, Changwon-Si, | R2: Storage Classification "B" : | S2: Indoor without Air-conditioning
O3: Gyeongsangnam-do, Korea | R3: Storage Classification "C" : | S3: Outdoor with Waterproofing
O4: (P.O.BOX 77, Changwon, Korea) | R4: Storage Classification "D" : | S4: Outdoor without Waterproofing
O5: TEL:(055)278-6114,7114 FAX:(055)264-5551/2
A6: SUMMARY PACKING LIST CВОДНЫЙ УПАКОВОЧНЫЙ ЛИСТ
A7: Project Name: | B7: Construction of a 1000 MW CCGT Power Plant in the Sairam District of the Turkistan Region
B8: Main Site. Without External Engineering Networks
A9: Invoice №: | B9: =PL!V8 -> PGU-DE-0481
A10: Name of Consignee: | B10: =PL!B13 -> Branch of JSC "Doosan Enerbility" in the Turkestan region
A11: Consignee address: | B11: =PL!B14 -> 321 Tauke Khan Avenue, Turkestan region, Turkestan, Kazakhstan, 161200
A12: № | B12: CNTR No. / Seal No. / № контейнера / № пломбы | C12: Package No. / № упаковки | D12: Description / Описание | E12: Packing Style / Вид упаковки | F12: Quantity / Количество | H12: Shipping Dimension / Отгрузочные параметры | L12: Net Weight (kg) / Вес нетто (кг) | M12: Gross Weight (kg) / Вес брутто (кг) | N12: Hazardous Material (UN Number) | O12: Storage Class / Класс хранения | P12: Stackable / Штабелируемый
F13: Q'ty / Количество | G13: Unit / Ед.изм. | H13: L (cm) / Д (см) | I13: W (cm) / Ш (см) | J13: H (cm) / В (см) | K13: CBM (m3) / Объем (м3)
A14: 1 | C14: PGU-DE-0481-AIS-PoCable-001 | D14: Power Cable / Кабель питания для ОРУ | E14: Wooden drum | F14: 1 | G14: EA/ШТ. | H14: 127 | I14: 127 | J14: 75 | K14: =ROUND(J14*I14*H14/1000000,3) -> 1.21 | L14: 473 | M14: 641 | N14: NA | O14: D | P14: N
A15: 2 | C15: PGU-DE-0481-AIS-PoCable-002 | D15: Power Cable / Кабель питания для ОРУ | E15: Wooden drum | F15: 1 | G15: EA/ШТ. | H15: 127 | I15: 127 | J15: 75 | K15: =ROUND(J15*I15*H15/1000000,3) -> 1.21 | L15: 473 | M15: 641 | N15: NA | O15: D | P15: N
A16: 3 | C16: PGU-DE-0481-AIS-PoCable-003 | D16: Power Cable / Кабель питания для ОРУ | E16: Wooden drum | F16: 1 | G16: EA/ШТ. | H16: 127 | I16: 127 | J16: 75 | K16: =ROUND(J16*I16*H16/1000000,3) -> 1.21 | L16: 473 | M16: 641 | N16: NA | O16: D | P16: N
A17: 4 | C17: PGU-DE-0481-AIS-PoCable-004 | D17: Power Cable / Кабель питания для ОРУ | E17: Wooden drum | F17: 1 | G17: EA/ШТ. | H17: 127 | I17: 127 | J17: 75 | K17: =ROUND(J17*I17*H17/1000000,3) -> 1.21 | L17: 473 | M17: 641 | N17: NA | O17: D | P17: N
A18: 5 | C18: PGU-DE-0481-AIS-PoCable-005 | D18: Power Cable / Кабель питания для ОРУ | E18: Wooden drum | F18: 1 | G18: EA/ШТ. | H18: 127 | I18: 127 | J18: 75 | K18: =ROUND(J18*I18*H18/1000000,3) -> 1.21 | L18: 473 | M18: 641 | N18: NA | O18: D | P18: N
A19: 6 | C19: PGU-DE-0481-AIS-PoCable-006 | D19: Power Cable / Кабель питания для ОРУ | E19: Wooden drum | F19: 1 | G19: EA/ШТ. | H19: 127 | I19: 127 | J19: 75 | K19: =ROUND(J19*I19*H19/1000000,3) -> 1.21 | L19: 473 | M19: 641 | N19: NA | O19: D | P19: N
A20: 7 | C20: PGU-DE-0481-AIS-PoCable-007 | D20: Power Cable / Кабель питания для ОРУ | E20: Wooden drum | F20: 1 | G20: EA/ШТ. | H20: 127 | I20: 127 | J20: 75 | K20: =ROUND(J20*I20*H20/1000000,3) -> 1.21 | L20: 473 | M20: 641 | N20: NA | O20: D | P20: N
A21: 8 | C21: PGU-DE-0481-AIS-PoCable-008 | D21: Power Cable / Кабель питания для ОРУ | E21: Wooden drum | F21: 1 | G21: EA/ШТ. | H21: 127 | I21: 127 | J21: 75 | K21: =ROUND(J21*I21*H21/1000000,3) -> 1.21 | L21: 473 | M21: 641 | N21: NA | O21: D | P21: N
A22: 9 | C22: PGU-DE-0481-AIS-PoCable-009 | D22: Power Cable / Кабель питания для ОРУ | E22: Wooden drum | F22: 1 | G22: EA/ШТ. | H22: 127 | I22: 127 | J22: 75 | K22: =ROUND(J22*I22*H22/1000000,3) -> 1.21 | L22: 473 | M22: 641 | N22: NA | O22: D | P22: N
A23: 10 | C23: PGU-DE-0481-AIS-PoCable-010 | D23: Power Cable / Кабель питания для ОРУ | E23: Wooden drum | F23: 1 | G23: EA/ШТ. | H23: 127 | I23: 127 | J23: 75 | K23: =ROUND(J23*I23*H23/1000000,3) -> 1.21 | L23: 473 | M23: 641 | N23: NA | O23: D | P23: N
A24: 11 | C24: PGU-DE-0481-AIS-PoCable-011 | D24: Power Cable / Кабель питания для ОРУ | E24: Wooden drum | F24: 1 | G24: EA/ШТ. | H24: 127 | I24: 127 | J24: 75 | K24: =ROUND(J24*I24*H24/1000000,3) -> 1.21 | L24: 473 | M24: 641 | N24: NA | O24: D | P24: N
A25: 12 | C25: PGU-DE-0481-AIS-PoCable-012 | D25: Power Cable / Кабель питания для ОРУ | E25: Wooden drum | F25: 1 | G25: EA/ШТ. | H25: 127 | I25: 127 | J25: 75 | K25: =ROUND(J25*I25*H25/1000000,3) -> 1.21 | L25: 473 | M25: 641 | N25: NA | O25: D | P25: N
... A39: 26 | C39: PGU-DE-0481-AIS-PoCable-026 | D39: Power Cable / Кабель питания для ОРУ | E39: Wooden drum | F39: 1 | G39: EA/ШТ. | H39: 117 | I39: 117 | J39: 75 | K39: =ROUND(J39*I39*H39/1000000,3) -> 1.027 | L39: 487 | M39: 637 | N39: NA | O39: D | P39: N
A40: TOTAL / ИТОГО | F40: =SUM(F14:F39) -> 26 | K40: =SUM(K14:K39) -> 44.135 | L40: =SUM(L14:L39) -> 21259 | M40: =SUM(M14:M39) -> 27223

Sheet Detail PL
P1: HEAD OFFICE & CHANGWON PLANT
P2: 22, DoosanVolvo-ro, Seongsan-gu, Changwon-Si, | R2: Note> | S2: Storage Classification "A" : | T2: Indoor with Air-conditioning
P3: Gyeongsangnam-do, Korea | S3: Storage Classification "B" : | T3: Indoor without Air-conditioning
P4: (P.O.BOX 77, Changwon, Korea) | S4: Storage Classification "C" : | T4: Outdoor with Waterproofing
P5: TEL:(055)278-6114,7114 FAX:(055)264-5551/2 | S5: Storage Classification "D" : | T5: Outdoor without Waterproofing
A6: DETAILED PACKING LIST ПОДРОБНЫЙ УПАКОВОЧНЫЙ ЛИСТ
A7: Project Name: | B7: Construction of a 1000 MW CCGT Power Plant in the Sairam District of the Turkistan Region
B8: Main Site. Without External Engineering Networks
A9: Invoice №: | B9: =PL!V8 -> PGU-DE-0481
A10: Name of Consignee: | B10: ='Summary PL'!B10 -> Branch of JSC "Doosan Enerbility" in the Turkestan region
A11: Consignee address: | B11: ='Summary PL'!B11 -> 321 Tauke Khan Avenue, Turkestan region, Turkestan, Kazakhstan, 161200
A12: № | B12: Package No./ Номер упаковки | C12: Description / Описание | D12: HS Code / Код ТН ВЭД | E12: Quantity / Количество | G12: Shipping Dimension / Отгрузочные параметры | K12: Net Weight (kg) / Вес нетто (кг) | L12: Gross Weight (kg) / Вес брутто (кг) | M12: Drawing No. / № чертежа | N12: Tag No. / № Тег | O12: Unit Price (US$) / цена заединицу | P12: Total Price (US$) / Общая цена | Q12: Remark / Примечания
E13: Q'ty / Кол-во | F13: Unit / Ед. изм. | G13: L (cm) / Д (см) | H13: W (cm) / Ш (см) | I13: H (cm) / В (см) | J13: CBM (m3) / Объем (м3)
A14: 1 | B14: PGU-DE-0481-AIS-PoCable-001 | C14: 0.6/1kV CU/XLPE/LSZH 3Cx4sqmm, 2000m | D14: 8544.49.2012 | E14: 1 | F14: EA/ШТ. | M14: CCP-W-B022-35-EL-B16-0002
G15: 127 | H15: 127 | I15: 75 | J15: =ROUND(I15*H15*G15/1000000,3) -> 1.21 | K15: 473 | L15: 641
A16: 2 | B16: PGU-DE-0481-AIS-PoCable-002 | C16: 0.6/1kV CU/XLPE/LSZH 3Cx4sqmm, 2000m | D16: 8544.49.2012 | E16: 1 | F16: EA/ШТ. | M16: CCP-W-B022-35-EL-B16-0002
G17: 127 | H17: 127 | I17: 75 | J17: =ROUND(I17*H17*G17/1000000,3) -> 1.21 | K17: 473 | L17: 641
A18: 3 | B18: PGU-DE-0481-AIS-PoCable-003 | C18: 0.6/1kV CU/XLPE/LSZH 3Cx4sqmm, 2000m | D18: 8544.49.2012 | E18: 1 | F18: EA/ШТ. | M18: CCP-W-B022-35-EL-B16-0002
G19: 127 | H19: 127 | I19: 75 | J19: =ROUND(I19*H19*G19/1000000,3) -> 1.21 | K19: 473 | L19: 641
A20: 4 | B20: PGU-DE-0481-AIS-PoCable-004 | C20: 0.6/1kV CU/XLPE/LSZH 3Cx4sqmm, 2000m | D20: 8544.49.2012 | E20: 1 | F20: EA/ШТ. | M20: CCP-W-B022-35-EL-B16-0002
G21: 127 | H21: 127 | I21: 75 | J21: =ROUND(I21*H21*G21/1000000,3) -> 1.21 | K21: 473 | L21: 641
A22: 5 | B22: PGU-DE-0481-AIS-PoCable-005 | C22: 0.6/1kV CU/XLPE/LSZH 3Cx4sqmm, 2000m | D22: 8544.49.2012 | E22: 1 | F22: EA/ШТ. | M22: CCP-W-B022-35-EL-B16-0002
G23: 127 | H23: 127 | I23: 75 | J23: =ROUND(I23*H23*G23/1000000,3) -> 1.21 | K23: 473 | L23: 641
A24: 6 | B24: PGU-DE-0481-AIS-PoCable-006 | C24: 0.6/1kV CU/XLPE/LSZH 3Cx4sqmm, 2000m | D24: 8544.49.2012 | E24: 1 | F24: EA/ШТ. | M24: CCP-W-B022-35-EL-B16-0002
G25: 127 | H25: 127 | I25: 75 | J25: =ROUND(I25*H25*G25/1000000,3) -> 1.21 | K25: 473 | L25: 641
A26: 7 | B26: PGU-DE-0481-AIS-PoCable-007 | C26: 0.6/1kV CU/XLPE/LSZH 3Cx4sqmm, 2000m | D26: 8544.49.2012 | E26: 1 | F26: EA/ШТ. | M26: CCP-W-B022-35-EL-B16-0002
G27: 127 | H27: 127 | I27: 75 | J27: =ROUND(I27*H27*G27/1000000,3) -> 1.21 | K27: 473 | L27: 641
A28: 8 | B28: PGU-DE-0481-AIS-PoCable-008 | C28: 0.6/1kV CU/XLPE/LSZH 3Cx4sqmm, 2000m | D28: 8544.49.2012 | E28: 1 | F28: EA/ШТ. | M28: CCP-W-B022-35-EL-B16-0002
G29: 127 | H29: 127 | I29: 75 | J29: =ROUND(I29*H29*G29/1000000,3) -> 1.21 | K29: 473 | L29: 641
A30: 9 | B30: PGU-DE-0481-AIS-PoCable-009 | C30: 0.6/1kV CU/XLPE/LSZH 3Cx4sqmm, 2000m | D30: 8544.49.2012 | E30: 1 | F30: EA/ШТ. | M30: CCP-W-B022-35-EL-B16-0002
G31: 127 | H31: 127 | I31: 75 | J31: =ROUND(I31*H31*G31/1000000,3) -> 1.21 | K31: 473 | L31: 641
A32: 10 | B32: PGU-DE-0481-AIS-PoCable-010 | C32: 0.6/1kV CU/XLPE/LSZH 3Cx4sqmm, 2000m | D32: 8544.49.2012 | E32: 1 | F32: EA/ШТ. | M32: CCP-W-B022-35-EL-B16-0002
G33: 127 | H33: 127 | I33: 75 | J33: =ROUND(I33*H33*G33/1000000,3) -> 1.21 | K33: 473 | L33: 641
A34: 11 | B34: PGU-DE-0481-AIS-PoCable-011 | C34: 0.6/1kV CU/XLPE/LSZH 3Cx4sqmm, 2000m | D34: 8544.49.2012 | E34: 1 | F34: EA/ШТ. | M34: CCP-W-B022-35-EL-B16-0002
G35: 127 | H35: 127 | I35: 75 | J35: =ROUND(I35*H35*G35/1000000,3) -> 1.21 | K35: 473 | L35: 641
A36: 12 | B36: PGU-DE-0481-AIS-PoCable-012 | C36: 0.6/1kV CU/XLPE/LSZH 3Cx4sqmm, 2000m | D36: 8544.49.2012 | E36: 1 | F36: EA/ШТ. | M36: CCP-W-B022-35-EL-B16-0002
G37: 127 | H37: 127 | I37: 75 | J37: =ROUND(I37*H37*G37/1000000,3) -> 1.21 | K37: 473 | L37: 641
A38: 13 | B38: PGU-DE-0481-AIS-PoCable-013 | C38: 0.6/1kV CU/XLPE/LSZH 3Cx4sqmm, 2000m | D38: 8544.49.2012 | E38: 1 | F38: EA/ШТ. | M38: CCP-W-B022-35-EL-B16-0002
G39: 127 | H39: 127 | I39: 75 | J39: =ROUND(I39*H39*G39/1000000,3) -> 1.21 | K39: 473 | L39: 641
A40: 14 | B40: PGU-DE-0481-AIS-PoCable-014 | C40: 0.6/1kV CU/XLPE/LSZH 3Cx4sqmm, 900m | D40: 8544.49.2012 | E40: 1 | F40: EA/ШТ. | M40: CCP-W-B022-35-EL-B16-0002
...

Sheet Description
A1: Technical Description
A3: Name | B3: Q-ty | C3: Model-Part No. | D3: Kind of material | E3: Size/specification/ Usage | F3: Photo | G3: Manufacturer / Origin | H3: HS Code
A4: 0.6/1kV CU/XLPE/LSZH | B4: 8 EA | D4: XLPE, Copper | E4: Power cable for 220V AC/DC | G4: iljin Electric | H4: 8544.49.2012

Sheet Marking - 1
A3: SHIPPING MARK ГРУЗОВАЯ МАРКИРОВКА
A4: ● NAME OF THE PROJECT | F4: : | G4: Construction of a 1000 MW CCGT Power Plant in the Sairam District of the Turkistan Region, Main Site. Without External Engineering Networks
A5: НАЗВАНИЕ ПРОЕКТА
A7: ● CONSIGNEE | F7: : | G7: =PL!$B$13 -> Branch of JSC "Doosan Enerbility" in the Turkestan region
A8: ГРУЗОПОЛУЧАТЕЛЬ | G8: =PL!$B$14 -> 321 Tauke Khan Avenue, Turkestan region, Turkestan, Kazakhstan, 161200
G9: =PL!$B$15 -> BIN: 230741006561
A11: ● Shipper/Exporter | F11: : Doosan Enerbility Co., LTD
A12: Грузоотправитель/Экспортер | F12: 22, Doosan Volvo-ro, Sengsan-gu, Changwon, Gyeongnam, South Korea
A14: ● Number of Invoice | F14: : | G14: =PL!$V$8 -> PGU-DE-0481
A15: № инвойса
A17: ● CARGO DESCRIPTION | F17: : | G17: =VLOOKUP($P17,'Summary PL'!$A$14:$M$39,4,FALSE) -> Power Cable / Кабель питания для ОРУ | P17: 1
A18: ОПИСАНИЕ ГРУЗА
A20: ● PACKAGE NO. | F20: : | G20: =VLOOKUP($P17,'Summary PL'!$A$14:$M$39,3,FALSE) -> PGU-DE-0481-AIS-PoCable-001
A21: УПАКОВОЧНЫЙ НОМЕР
A23: ● NET WEIGHT | F23: : | G23: =VLOOKUP($P17,'Summary PL'!$A$14:$M$39,12,FALSE) -> 473 | H23: Kg
A24: ВЕС НЕТТО
A26: ● GROSS WEIGHT | F26: : | G26: =VLOOKUP($P17,'Summary PL'!$A$14:$M$39,13,FALSE) -> 641 | H26: Kg
A27: ВЕС БРУТТО
A29: ● CBM(m3) | F29: : | G29: =VLOOKUP($P17,'Summary PL'!$A$14:$M$39,11,FALSE) -> 1.21 | H29: m3
A30: РАЗМЕРЫ
A32: ● FINAL DESTINATION | F32: : later | G32: Republic of Kazakhstan, Turkestan Oblast, Sairam district, Karamurt rural district, quarter 171
A33: КОНЕЧНЫЙ ПУНКТ НАЗНАЧЕНИЯ
E36: Doosan Enerbility
A40: SHIPPING MARK ГРУЗОВАЯ МАРКИРОВКА
A41: ● NAME OF THE PROJECT | F41: : | G41: Construction of a 1000 MW CCGT Power Plant in the Sairam District of the Turkistan Region, Main Site. Without External Engineering Networks
A42: НАЗВАНИЕ ПРОЕКТА
A44: ● CONSIGNEE | F44: : | G44: =PL!$B$13 -> Branch of JSC "Doosan Enerbility" in the Turkestan region
A45: ГРУЗОПОЛУЧАТЕЛЬ | G45: =PL!$B$14 -> 321 Tauke Khan Avenue, Turkestan region, Turkestan, Kazakhstan, 161200
G46: =PL!$B$15 -> BIN: 230741006561
A48: ● Shipper/Exporter | F48: : Doosan Enerbility Co., LTD
A49: Грузоотправитель/Экспортер | F49: 22, Doosan Volvo-ro, Sengsan-gu, Changwon, Gyeongnam, South Korea
A51: ● Number of Invoice | F51: : | G51: =PL!$V$8 -> PGU-DE-0481
A52: № инвойса
A54: ● CARGO DESCRIPTION | F54: : | G54: =VLOOKUP($P54,'Summary PL'!$A$14:$M$39,4,FALSE) -> Power Cable / Кабель питания для ОРУ | P54: =P17+1 -> 2
A55: ОПИСАНИЕ ГРУЗА
A57: ● PACKAGE NO. | F57: : | G57: =VLOOKUP($P54,'Summary PL'!$A$14:$M$39,3,FALSE) -> PGU-DE-0481-AIS-PoCable-002
A58: УПАКОВОЧНЫЙ НОМЕР
A60: ● NET WEIGHT | F60: : | G60: =VLOOKUP($P54,'Summary PL'!$A$14:$M$39,12,FALSE) -> 473 | H60: Kg
A61: ВЕС НЕТТО
A63: ● GROSS WEIGHT | F63: : | G63: =VLOOKUP($P54,'Summary PL'!$A$14:$M$39,13,FALSE) -> 641 | H63: Kg
...
