Workbook
Name AnnullaInseriscidata: #REF!
Name AnnullaInseriscidata: #REF!
Name InserisciData: #REF!
Name InserisciData: #REF!

Sheet CI
W1: HEAD OFFICE & CHANGWON PLANT
W2: 22, DoosanVolvo-ro, Seongsan-gu, Changwon-Si,
W3: Gyeongsangnam-do, Korea
W4: (P.O.BOX 77, Changwon, Korea)
W5: TEL:(055)278-6114,7114 FAX:(055)264-5551/2
A6: PROFORMA INVOICE ПРОФОРМА ИНВОЙС
A8: 1. Shipper / Грузоотправитель | R8: 11. Invoice № : | V8: PGU-DE-0336
B9: Doosan Enerbility Co., Ltd (DOOSAN) | R9: Инвойс №
B10: 22, DoosanVolvo-ro, Seongsan-gu, Changwon-si, Gyeongsangnam-do | R10: 12. Date : | V10: 45756
B11: Republic of Korea | R11: Дата
A12: 2. Consignee / Грузополучатель | R12: 13. Remarks / Примечания
B13: Branch of JSC "Doosan Enerbility" in the Turkestan region
B14: 321 Tauke Khan Avenue, Turkestan region, Turkestan, Kazakhstan, 161200 | S14: *Project Name / Название Проекта
B15: BIN: 230741006561 | S15: Construction of a 1000 MW CCGT Power Plant in the Sairam District of Turkistan Region, Main Site. Without External Engineering Networks
S17: *MANUFACTURER'S NAME / НАЗВАНИЕ ПРОИЗВОДИТЕЛЯ
A18: 3. Notify party / Уведомляемая сторона | S18: Dasan DTS
B19: =CI!B19 -> Wise Logistics | S19: *MANUFACTURE YEAR / ГОД ИЗГОТОВЛЕНИЯ
B20: =CI!B20 -> ATTAN: MS. Aliya | S20: 2025
B21: =CI!B21 -> (E): a.kipshakbayeva@wiselogistics.kz | S21: *COUNTRY OF ORIGIN / СТРАНА ПРОИСХОЖДЕНИЯ
B22: =CI!B22 -> (T): +7 701 512 19 69 | S22: Republic of Korea
S23: *INCOTERMS / УСЛОВИЯ ПОСТАВКИ СОГЛАСНО ИНКОТЕРМС
S24: DDP Turkistan
A25: 4. Port of Loading / Порт погрузки | I25: 5. Carrier / Перевозчик
B26: Masan, Korea | J26: Later
A28: 6. Port of Unloading / Порт разгрузки | I28: 7. Final Destination / Конечный пункт назначения | R28: 14. Mark and Numbers of PKGS / Маркировка и количество упаковок
B30: Later | I30: Turkestan region, Sairam district, Karamurt rural district, quarter 171 | S30: PKG No. | X30: : | Y30: PGU-DE-0336-FGSS-001~187
S31: Q-ty of Package | X31: : | Y31: 129 | AC31: PKGS
A32: 8. Voyage No / Рейс № | I32: 9. Sailing on or about / Дата или ожидаемая дата | S32: Net Weight (kg) | X32: : | Y32: ='Summary PL'!L144 -> 503160.48 | AC32: KG
B33: Later | S33: Gross Weight (kg) | X33: : | Y33: ='Summary PL'!M144 -> 524302.3 | AC33: KG
J34: Later | S34: Dimension (m3) | X34: : | Y34: =PL!Y34 -> 2823.041 | AC34: m3
A36: 10. Customs Place / Место таможенного оформления
B37: Turkestan Oblast, Sairam district, Karamurt rural district, quarter 171
A39: 15. Description of Goods / Описание товара | R39: 16. HS CODE / | W39: 17. Quantity / | AA39: 18. Total Price (USD)
R40: Код ТН ВЭД | W40: Количество | AA40: Общая сумма (Дол. США)
B41: Fuel Gas Supply System | W41: 1 SET | AC41: =CI_BD!I138 -> 8581723
B42: Пункт подготовки газа | AD42: CD #5 Item 6.1
I44: Total (DDP Value)
S52: Signed by
A53: Doosan Enerbility Co., Ltd
A54: 155, Jeongjail-ro, Bundang-gu, Seongnam-si, Gyeonggi-do, Korea
...

Sheet CI_BD
J1: HEAD OFFICE & CHANGWON PLANT
J2: 22, DoosanVolvo-ro, Seongsan-gu, Changwon-Si,
J3: Gyeongsangnam-do, Korea
J4: (P.O.BOX 77, Changwon, Korea)
J5: TEL:(055)278-6114,7114 FAX:(055)264-5551/2
A6: PROFORMA INVOICE (Break-down) ПРОФОРМА-ИНВОЙС (Разбивка)
A7: Invoice № : | B7: PGU-DE-0XX
A8: № | B8: № Package | C8: Description of Goods Specification | D8: Material | E8: HS CODE | F8: Quantity | G8: Unit | H8: U/Price (USD) | I8: Amount (USD) | J8: Country of Origin | K8: Remark
A9: 1 | B9: PGU-DE-0336-FGSS-001 | C9: ESDV Skid | F9: 1 | G9: EA / ШТ. | H9: 235367 | I9: =F9*H9 -> 235367 | J9: Korea | M9: 5
A10: 2 | B10: PGU-DE-0336-FGSS-002 | C10: Filter Separator Skid | F10: 1 | G10: EA / ШТ. | H10: 573069 | I10: =F10*H10 -> 573069 | J10: Korea | M10: 1
A11: 3 | B11: PGU-DE-0336-FGSS-003 | C11: Filter Separator Skid | F11: 1 | G11: EA / ШТ. | H11: 573069 | I11: =F11*H11 -> 573069 | J11: Korea | M11: 1
A12: 4 | B12: PGU-DE-0336-FGSS-004 | C12: Metering Skid | F12: 1 | G12: EA / ШТ. | H12: 245601 | I12: =F12*H12 -> 245601 | J12: Korea | M12: 2
A13: 5 | B13: PGU-DE-0336-FGSS-005 | C13: Metering Skid | F13: 1 | G13: EA / ШТ. | H13: 245601 | I13: =F13*H13 -> 245601 | J13: Korea | M13: 2
A14: 6 | B14: PGU-DE-0336-FGSS-006 | C14: Gas Pre-Heater Piping Skid | F14: 1 | G14: EA / ШТ. | H14: 220017 | I14: =F14*H14 -> 220017 | J14: Korea | M14: 6
A15: 7 | B15: PGU-DE-0336-FGSS-007 | C15: PRV Skid | F15: 1 | G15: EA / ШТ. | H15: 479264 | I15: =F15*H15 -> 479264 | J15: Korea | M15: 4
A16: 8 | B16: PGU-DE-0336-FGSS-008 | C16: PRV Skid | F16: 1 | G16: EA / ШТ. | H16: 100628 | I16: =F16*H16 -> 100628 | J16: Korea | M16: 4
A17: 9 | B17: PGU-DE-0336-FGSS-009 | C17: Performance Heater Skid | F17: 1 | G17: EA / ШТ. | H17: 230251 | I17: =F17*H17 -> 230251 | J17: Korea | M17: 7
A18: 10 | B18: PGU-DE-0336-FGSS-010 | C18: Performance Heater Skid | F18: 1 | G18: EA / ШТ. | H18: 230251 | I18: =F18*H18 -> 230251 | J18: Korea | M18: 7
A19: 11 | B19: PGU-DE-0336-FGSS-011 | C19: Performance Heater Skid | F19: 1 | G19: EA / ШТ. | H19: 230251 | I19: =F19*H19 -> 230251 | J19: Korea | M19: 7
A20: 12 | B20: PGU-DE-0336-FGSS-012 | C20: Performance Heater Skid | F20: 1 | G20: EA / ШТ. | H20: 230251 | I20: =F20*H20 -> 230251 | J20: Korea | M20: 7
... A26: 18 | B26: PGU-DE-0336-FGSS-020 | C26: Final Filter & Drain Tank Skid Ladder Access | F26: 1 | G26: EA / ШТ. | H26: 11938 | I26: =F26*H26 -> 11938 | J26: Korea | M26: 8
A27: 19 | B27: PGU-DE-0336-FGSS-021 | C27: Filter Separator Skid Ladder Access | F27: 1 | G27: EA / ШТ. | H27: 10197 | I27: =F27*H27 -> 10197 | J27: Korea
A28: 20 | B28: PGU-DE-0336-FGSS-022 | C28: POV | F28: 1 | G28: EA / ШТ. | H28: 17141 | I28: =F28*H28 -> 17141 | J28: Korea
A29: 21 | B29: PGU-DE-0336-FGSS-023 | C29: POV | F29: 1 | G29: EA / ШТ. | H29: 17141 | I29: =F29*H29 -> 17141 | J29: Korea
A30: 22 | B30: PGU-DE-0336-FGSS-024 | C30: POV | F30: 1 | G30: EA / ШТ. | H30: 17141 | I30: =F30*H30 -> 17141 | J30: Korea
A31: 23 | B31: PGU-DE-0336-FGSS-025 | C31: POV | F31: 1 | G31: EA / ШТ. | H31: 17141 | I31: =F31*H31 -> 17141 | J31: Korea
A32: 24 | B32: PGU-DE-0336-FGSS-026 | C32: Pipe spool | F32: 1 | G32: EA / ШТ. | H32: 76206 | I32: =F32*H32 -> 76206 | J32: Korea | M32: 9
A33: 25 | B33: PGU-DE-0336-FGSS-027 | C33: Pipe spool | F33: 1 | G33: EA / ШТ. | H33: 65357 | I33: =F33*H33 -> 65357 | J33: Korea | M33: 9
A34: 26 | B34: PGU-DE-0336-FGSS-028 | C34: Pipe spool | F34: 1 | G34: EA / ШТ. | H34: 16015 | I34: =F34*H34 -> 16015 | J34: Korea | M34: 9
A35: 27 | B35: PGU-DE-0336-FGSS-029 | C35: Pipe spool | F35: 1 | G35: EA / ШТ. | H35: 58364 | I35: =F35*H35 -> 58364 | J35: Korea | M35: 9
A36: 28 | B36: PGU-DE-0336-FGSS-030 | C36: Pipe spool | F36: 1 | G36: EA / ШТ. | H36: 49120 | I36: =F36*H36 -> 49120 | J36: Korea | M36: 9
A37: 29 | B37: PGU-DE-0336-FGSS-031 | C37: Pipe spool | F37: 1 | G37: EA / ШТ. | H37: 80452 | I37: =F37*H37 -> 80452 | J37: Korea | M37: 9
A38: 30 | B38: PGU-DE-0336-FGSS-032 | C38: Pipe spool | F38: 1 | G38: EA / ШТ. | H38: 87402 | I38: =F38*H38 -> 87402 | J38: Korea | M38: 9
A39: 31 | B39: PGU-DE-0336-FGSS-033 | C39: Pipe spool | F39: 1 | G39: EA / ШТ. | H39: 80639 | I39: =F39*H39 -> 80639 | J39: Korea | M39: 9
A40: 32 | B40: PGU-DE-0336-FGSS-034 | C40: Pipe spool | F40: 1 | G40: EA / ШТ. | H40: 93311 | I40: =F40*H40 -> 93311 | J40: Korea | M40: 9
A41: 33 | B41: PGU-DE-0336-FGSS-035 | C41: Pipe spool | F41: 1 | G41: EA / ШТ. | H41: 26538 | I41: =F41*H41 -> 26538 | J41: Korea | M41: 9
A42: 34 | B42: PGU-DE-0336-FGSS-036 | C42: Pipe spool | F42: 1 | G42: EA / ШТ. | H42: 14669 | I42: =F42*H42 -> 14669 | J42: Korea | M42: 9
A43: 35 | B43: PGU-DE-0336-FGSS-037 | C43: Pipe spool | F43: 1 | G43: EA / ШТ. | H43: 9179 | I43: =F43*H43 -> 9179 | J43: Korea | M43: 9
... A48: 40 | B48: PGU-DE-0336-FGSS-042 | C48: Pipe support | F48: 1 | G48: EA / ШТ. | H48: 29772 | I48: =F48*H48 -> 29772 | J48: Korea | M48: 9
A49: 41 | B49: PGU-DE-0336-FGSS-047 | C49: Bolt & Nut | F49: 1 | G49: EA / ШТ. | H49: 31903 | I49: =F49*H49 -> 31903 | J49: Korea
...

Sheet PL
W1: HEAD OFFICE & CHANGWON PLANT
W2: 22, DoosanVolvo-ro, Seongsan-gu, Changwon-Si,
W3: Gyeongsangnam-do, Korea
W4: (P.O.BOX 77, Changwon, Korea)
W5: TEL:(055)278-6114,7114 FAX:(055)264-5551/2
A6: PACKING LIST УПАКОВОЧНЫЙ ЛИСТ
A8: 1. Shipper / Грузоотправитель | R8: 11. Invoice № : | V8: PGU-DE-0336
B9: Doosan Enerbility Co., Ltd (DOOSAN) | R9: Инвойс №
B10: 22, DoosanVolvo-ro, Seongsan-gu, Changwon-si, Gyeongsangnam-do, | R10: 12. Date : | V10: 45756
B11: Republic of Korea | R11: Дата
A12: 2. Consignee / Грузополучатель | R12: 13. Remarks / Примечания
B13: Branch of JSC "Doosan Enerbility" in the Turkestan region
B14: 321 Tauke Khan Avenue, Turkestan region, Turkestan, Kazakhstan, 161200 | S14: *Project Name / Название Проекта
B15: BIN: 230741006561 | S15: Construction of a 1000 MW CCGT Power Plant in the Sairam District of
S16: Turkistan Region, Main Site. Without External Engineering Networks
S17: *MANUFACTURER'S NAME / НАЗВАНИЕ ПРОИЗВОДИТЕЛЯ
A18: 3. Notify party / Уведомляемая сторона | S18: Dasan DTS
B19: =CI!B19 -> Wise Logistics | S19: *MANUFACTURE YEAR / ГОД ИЗГОТОВЛЕНИЯ
B20: =CI!B20 -> ATTAN: MS. Aliya | S20: 2025
B21: =CI!B21 -> (E): a.kipshakbayeva@wiselogistics.kz | S21: *COUNTRY OF ORIGIN / СТРАНА ПРОИСХОЖДЕНИЯ
B22: =CI!B22 -> (T): +7 701 512 19 69 | S22: Republic of Korea
S23: *INCOTERMS / УСЛОВИЯ ПОСТАВКИ СОГЛАСНО ИНКОТЕРМС
S24: =CI!S24 -> DDP Turkistan
A25: 4. Port of Loading / Порт погрузки | I25: 5. Carrier / Перевозчик
B26: Masan, Korea | J26: Later
A28: 6. Port of Unloading / Порт разгрузки | I28: 7. Final Destination / Конечный пункт назначения | R28: 14. Mark and Numbers of PKGS / Маркировка и количество упаковок
B30: Later | I30: Turkestan region, Sairam district, Karamurt rural district, quarter 171 | S30: PKG No. | X30: : | Y30: PGU-DE-0336-FGSS-001~187
S31: Q-ty of Package | X31: : | Y31: =COUNT('Summary PL'!A15:A271) -> 129 | AC31: PKGS
A32: 8. Voyage No / Рейс № | I32: 9. Sailing on or about / Дата или ожидаемая дата | S32: Net Weight (kg) | X32: : | Y32: ='Summary PL'!L144 -> 503160.48 | AC32: KG
B33: Later | S33: Gross Weight (kg) | X33: : | Y33: ='Summary PL'!M144 -> 524302.3 | AC33: KG
J34: Later | S34: Dimension (m3) | X34: : | Y34: ='Summary PL'!K144 -> 2823.041 | AC34: m3
A36: 10. Customs Place / Место таможенного оформления
B37: Turkestan Oblast, Sairam district, Karamurt rural district, quarter 171
A39: 15. Description of Goods / Описание товара | R39: 16. Q-ty | U39: 17. Net Weight | Y39: 18. Gross Weight | AC39: 19. Measurement
R40: (EA) | U40: (kg) | Y40: (kg) | AC40: (CBM)
B41: =CI!B41 -> Fuel Gas Supply System | R41: 1 SET | U41: ='Summary PL'!L144 -> 503160.48 | Y41: ='Summary PL'!M144 -> 524302.3 | AC41: ='Summary PL'!K144 -> 2823.041
B42: Пункт подготовки газа
U44: =U41 -> 503160.48 | Y44: =Y41 -> 524302.3 | AC44: =AC41 -> 2823.041
S52: Signed by
A53: Doosan Enerbility Co., Ltd
...

Sheet Summary PL
O1: HEAD OFFICE & CHANGWON PLANT | R1: Storage Classification "A" : | S1: Indoor with Air-conditioning
O2: 22, DoosanVolvo-ro, Seongsan-gu, Changwon-Si, | Q2: Note> | R2: Storage Classification "B" : | S2: Indoor without Air-conditioning
O3: Gyeongsangnam-do, Korea | R3: Storage Classification "C" : | S3: Outdoor with Waterproofing
O4: (P.O.BOX 77, Changwon, Korea) | R4: Storage Classification "D" : | S4: Outdoor without Waterproofing
O5: TEL:(055)278-6114,7114 FAX:(055)264-5551/2
A6: SUMMARY PACKING LIST CВОДНЫЙ УПАКОВОЧНЫЙ ЛИСТ
A8: Project Name: | B8: Construction of a 1000 MW CCGT Power Plant in the Sairam District of the Turkistan Region
B9: Main Site. Without External Engineering Networks
A10: Invoice №: | B10: PGU-DE-0336
A11: Name of Consignee: Branch of JSC "Doosan Enerbility" in the Turkistan region
A12: Consignee address: 321 Tauke Khan Avenue, Turkistan region, Turkistan, Kazakhstan, 161200
A13: № | B13: CNTR No. / Seal No. / № контейнера / № пломбы | C13: Package No. / № упаковки | D13: Description / Описание | E13: Packing Style / Вид упаковки | F13: Quantity / Количество | H13: Shipping Dimension / Отгрузочные параметры | L13: Net Weight (kg) / Вес нетто (кг) | M13: Gross Weight (kg) / Вес брутто (кг) | N13: Hazardous Material (UN Number) | O13: Storage Class / Класс хранения | P13: Stackable / Штабелируемый
F14: Q'ty / Количество | G14: Unit / Ед. изм. | H14: L (cm) / Д (см) | I14: W (cm) / Ш (см) | J14: H (cm) / В (см) | K14: CBM (m3) / Объем (м3)
A15: 1 | C15: PGU-DE-0336-FGSS-001 | D15: ESDV Skid | E15: Skid | F15: 1 | G15: EA / ШТ. | H15: 1091 | I15: 194 | J15: 281 | K15: 59.475 | L15: 13800 | M15: 14000
A16: 2 | C16: PGU-DE-0336-FGSS-002 | D16: Filter Separator Skid | E16: Skid | F16: 1 | G16: EA / ШТ. | H16: 1291 | I16: 301 | J16: 447 | K16: 173.7 | L16: 33600 | M16: 33800
A17: 3 | C17: PGU-DE-0336-FGSS-003 | D17: Filter Separator Skid | E17: Skid | F17: 1 | G17: EA / ШТ. | H17: 1291 | I17: 301 | J17: 447 | K17: 173.7 | L17: 33600 | M17: 33800
A18: 4 | C18: PGU-DE-0336-FGSS-004 | D18: Metering Skid | E18: Skid | F18: 1 | G18: EA / ШТ. | H18: 590 | I18: 310 | J18: 251.5 | K18: 45.999 | L18: 14400 | M18: 14600
A19: 5 | C19: PGU-DE-0336-FGSS-005 | D19: Metering Skid | E19: Skid | F19: 1 | G19: EA / ШТ. | H19: 571 | I19: 310 | J19: 375 | K19: 66.379 | L19: 14400 | M19: 14600
A20: 6 | C20: PGU-DE-0336-FGSS-006 | D20: Gas Pre-Heater Piping Skid | E20: Skid | F20: 1 | G20: EA / ШТ. | H20: 891 | I20: 180 | J20: 211.2 | K20: 33.872 | L20: 12900 | M20: 13100
A21: 7 | C21: PGU-DE-0336-FGSS-007 | D21: PRV Skid | E21: Skid | F21: 1 | G21: EA / ШТ. | H21: 1601 | I21: 290 | J21: 231.1 | K21: 107.297 | L21: 28100 | M21: 28300
A22: 8 | C22: PGU-DE-0336-FGSS-008 | D22: PRV Skid | E22: Skid | F22: 1 | G22: EA / ШТ. | H22: 491 | I22: 231 | J22: 280 | K22: 31.758 | L22: 5900 | M22: 6000
A23: 9 | C23: PGU-DE-0336-FGSS-009 | D23: Performance Heater Skid | E23: Skid | F23: 1 | G23: EA / ШТ. | H23: 747 | I23: 380 | J23: 344 | K23: 97.648 | L23: 13500 | M23: 13700
A24: 10 | C24: PGU-DE-0336-FGSS-010 | D24: Performance Heater Skid | E24: Skid | F24: 1 | G24: EA / ШТ. | H24: 747 | I24: 380 | J24: 344 | K24: 97.648 | L24: 13500 | M24: 13700
A25: 11 | C25: PGU-DE-0336-FGSS-011 | D25: Performance Heater Skid | E25: Skid | F25: 1 | G25: EA / ШТ. | H25: 747 | I25: 380 | J25: 344 | K25: 97.648 | L25: 13500 | M25: 13700
A26: 12 | C26: PGU-DE-0336-FGSS-012 | D26: Performance Heater Skid | E26: Skid | F26: 1 | G26: EA / ШТ. | H26: 747 | I26: 380 | J26: 344 | K26: 97.648 | L26: 13500 | M26: 13700
... A114: 100 | C114: PGU-DE-0336-FGSS-120 | D114: Insulation Material | E114: Wooden | F114: 1 | G114: EA / ШТ. | H114: 130 | I114: 100 | J114: 80 | K114: 1.04 | L114: 300 | M114: 400
A115: 101 | C115: PGU-DE-0336-FGSS-151 | D115: Cold Vent Stack | E115: Skid | F115: 1 | G115: EA / ШТ. | H115: 1580 | I115: 110 | J115: 140 | K115: 24.332 | L115: 2500 | M115: 2850 | N115: N | O115: B | P115: N
A116: 102 | C116: PGU-DE-0336-FGSS-152 | D116: Loose part for Cold Vent Stack | E116: Wooden | F116: 1 | G116: EA / ШТ. | H116: 110 | I116: 130 | J116: 125 | K116: 1.788 | L116: 172 | M116: 372 | N116: N | O116: B | P116: N
A117: 103 | C117: PGU-DE-0336-FGSS-161 | D117: Water Bath Heater | E117: Skid | F117: 1 | G117: EA / ШТ. | H117: 1300 | I117: 350 | J117: 402.5 | K117: 183.138 | L117: 42200 | M117: 42700
A118: 104 | C118: PGU-DE-0336-FGSS-162 | D118: Water Bath Heater | E118: Skid | F118: 1 | G118: EA / ШТ. | H118: 1300 | I118: 350 | J118: 402.5 | K118: 183.138 | L118: 42200 | M118: 42700
A119: 105 | C119: PGU-DE-0336-FGSS-163 | D119: Expansion Tank | E119: Pallet | F119: 1 | G119: EA / ШТ. | H119: 455 | I119: 250 | J119: 230 | K119: 26.163 | L119: 2000 | M119: 2200
A120: 106 | C120: PGU-DE-0336-FGSS-164 | D120: Stack | E120: Pallet | F120: 1 | G120: EA / ШТ. | H120: 605 | I120: 255 | J120: 170 | K120: 26.227 | L120: 3240 | M120: 3500
A121: 107 | C121: PGU-DE-0336-FGSS-165 | D121: Valve Box | E121: Pallet | F121: 1 | G121: EA / ШТ. | H121: 310 | I121: 165 | J121: 270 | K121: 13.811 | L121: 1000 | M121: 1200
A122: 108 | C122: PGU-DE-0336-FGSS-166 | D122: Valve Box | E122: Pallet | F122: 1 | G122: EA / ШТ. | H122: 310 | I122: 165 | J122: 270 | K122: 13.811 | L122: 1000 | M122: 1200
A123: 109 | C123: PGU-DE-0336-FGSS-167 | D123: Burner Box | E123: Pallet | F123: 1 | G123: EA / ШТ. | H123: 300 | I123: 235 | J123: 300 | K123: 21.15 | L123: 300 | M123: 500
A124: 110 | C124: PGU-DE-0336-FGSS-168 | D124: Burner Box | E124: Pallet | F124: 1 | G124: EA / ШТ. | H124: 300 | I124: 230 | J124: 300 | K124: 20.7 | L124: 300 | M124: 500
A125: 111 | C125: PGU-DE-0336-FGSS-169 | D125: Blower Box | E125: Pallet | F125: 1 | G125: EA / ШТ. | H125: 220 | I125: 180 | J125: 215 | K125: 8.514 | L125: 200 | M125: 400
A126: 112 | C126: PGU-DE-0336-FGSS-170 | D126: Blower Box | E126: Pallet | F126: 1 | G126: EA / ШТ. | H126: 220 | I126: 180 | J126: 215 | K126: 8.514 | L126: 200 | M126: 400
A127: 113 | C127: PGU-DE-0336-FGSS-171 | D127: Platform | E127: Pallet | F127: 1 | G127: EA / ШТ. | H127: 480 | I127: 240 | J127: 165 | K127: 19.008 | L127: 1200 | M127: 1400
A128: 114 | C128: PGU-DE-0336-FGSS-172 | D128: Platform | E128: Pallet | F128: 1 | G128: EA / ШТ. | H128: 310 | I128: 300 | J128: 165 | K128: 15.345 | L128: 1619.5 | M128: 2000
...

Sheet Detail PL 
P1: HEAD OFFICE & CHANGWON PLANT
P2: 22, DoosanVolvo-ro, Seongsan-gu, Changwon-Si, | R2: Note> | S2: Storage Classification "A" : | T2: Indoor with Air-conditioning
P3: Gyeongsangnam-do, Korea | S3: Storage Classification "B" : | T3: Indoor without Air-conditioning
P4: (P.O.BOX 77, Changwon, Korea) | S4: Storage Classification "C" : | T4: Outdoor with Waterproofing
P5: TEL:(055)278-6114,7114 FAX:(055)264-5551/2 | S5: Storage Classification "D" : | T5: Outdoor without Waterproofing
A6: DETAILED PACKING LIST ПОДРОБНЫЙ УПАКОВОЧНЫЙ ЛИСТ
A8: Project Name: | B8: Construction of a 1000 MW CCGT Power Plant in the Sairam District of the Turkistan Region
B9: Main Site. Without External Engineering Networks
A10: Invoice №: | B10: PGU-DE-0336
A11: Name of Consignee: Branch of JSC "Doosan Enerbility" in the Turkistan region
A12: Consignee address: 321 Tauke Khan Avenue, Turkistan region, Turkistan, Kazakhstan, 161200
A13: № | B13: Package No./ Номер упаковки | C13: Description / Описание | D13: HS Code / Код ТН ВЭД | E13: Quantity / Количество | G13: Shipping Dimension / Отгрузочные параметры | K13: Net Weight (kg) / Вес нетто (кг) | L13: Gross Weight (kg) / Вес брутто (кг) | M13: Drawing No. / № чертежа | N13: Tag No. / № Тег | O13: Unit Price (US$) / цена заединицу | P13: Total Price (US$) / Общая цена | Q13: Remark / Примечания
E14: Q'ty / Кол-во | F14: Unit / Ед. изм. | G14: L (cm) / Д (см) | H14: W (cm) / Ш (см) | I14: H (cm) / В (см) | J14: CBM (m3) / Объем (м3)
A15: 1 | B15: PGU-DE-0336-FGSS-001 | C15: ESDV Skid_1 | E15: 1 | F15: EA
G16: 1091 | H16: 194 | I16: 281 | J16: =ROUND(I16*H16*G16/1000000,3) -> 59.475 | K16: 13800 | L16: 14000
A17: 1 | B17: PGU-DE-0336-FGSS-002 | C17: Filter Separator Skid_2 | E17: 1 | F17: EA
G18: 1291 | H18: 301 | I18: 447 | J18: =ROUND(I18*H18*G18/1000000,3) -> 173.7 | K18: 33600 | L18: 33800
A19: 1 | B19: PGU-DE-0336-FGSS-003 | C19: Filter Separator Skid_3 | E19: 1 | F19: EA
G20: 1291 | H20: 301 | I20: 447 | J20: =ROUND(I20*H20*G20/1000000,3) -> 173.7 | K20: 33600 | L20: 33800
A21: 1 | B21: PGU-DE-0336-FGSS-004 | C21: Metering Skid_4 | E21: 1 | F21: EA
G22: 590 | H22: 310 | I22: 251.5 | J22: =ROUND(I22*H22*G22/1000000,3) -> 45.999 | K22: 14400 | L22: 14600
A23: 1 | B23: PGU-DE-0336-FGSS-005 | C23: Metering Skid_5 | E23: 1 | F23: EA
G24: 571 | H24: 310 | I24: 375 | J24: =ROUND(I24*H24*G24/1000000,3) -> 66.379 | K24: 14400 | L24: 14600
A25: 1 | B25: PGU-DE-0336-FGSS-006 | C25: Gas Pre-Heater Piping Skid_6 | E25: 1 | F25: EA
G26: 891 | H26: 180 | I26: 211.2 | J26: =ROUND(I26*H26*G26/1000000,3) -> 33.872 | K26: 12900 | L26: 13100
A27: 1 | B27: PGU-DE-0336-FGSS-007 | C27: PRV Skid_7 | E27: 1 | F27: EA
G28: 1601 | H28: 290 | I28: 231.1 | J28: =ROUND(I28*H28*G28/1000000,3) -> 107.297 | K28: 28100 | L28: 28300
A29: 1 | B29: PGU-DE-0336-FGSS-008 | C29: PRV Skid_8 | E29: 1 | F29: EA
G30: 491 | H30: 231 | I30: 280 | J30: =ROUND(I30*H30*G30/1000000,3) -> 31.758 | K30: 5900 | L30: 6000
A31: 1 | B31: PGU-DE-0336-FGSS-009 | C31: Performance Heater Skid_11 | E31: 1 | F31: EA
G32: 747 | H32: 380 | I32: 344 | J32: =ROUND(I32*H32*G32/1000000,3) -> 97.648 | K32: 13500 | L32: 13700
A33: 1 | B33: PGU-DE-0336-FGSS-010 | C33: Performance Heater Skid_13 | E33: 1 | F33: EA
G34: 747 | H34: 380 | I34: 344 | J34: =ROUND(I34*H34*G34/1000000,3) -> 97.648 | K34: 13500 | L34: 13700
A35: 1 | B35: PGU-DE-0336-FGSS-011 | C35: Performance Heater Skid_15 | E35: 1 | F35: EA
G36: 747 | H36: 380 | I36: 344 | J36: =ROUND(I36*H36*G36/1000000,3) -> 97.648 | K36: 13500 | L36: 13700
A37: 1 | B37: PGU-DE-0336-FGSS-012 | C37: Performance Heater Skid_17 | E37: 1 | F37: EA
G38: 747 | H38: 380 | I38: 344 | J38: =ROUND(I38*H38*G38/1000000,3) -> 97.648 | K38: 13500 | L38: 13700
A39: 1 | B39: PGU-DE-0336-FGSS-013 | C39: Final Filter & Drain Tank Skid_12 | E39: 1 | F39: EA
G40: 785 | H40: 305 | I40: 423.5 | J40: =ROUND(I40*H40*G40/1000000,3) -> 101.396 | K40: 21400 | L40: 21600
A41: 1 | B41: PGU-DE-0336-FGSS-014 | C41: Final Filter & Drain Tank Skid_14 | E41: 1 | F41: EA
...

Sheet Marking
A1: SHIPPING MARK ГРУЗОВАЯ МАРКИРОВКА | P1: SHIPPING MARK ГРУЗОВАЯ МАРКИРОВКА
A2: ● NAME OF THE PROJECT | F2: : | G2: Construction of a 1000 MW CCGT Power Plant in the Sairam District of the | P2: ● NAME OF THE PROJECT | U2: : | V2: Construction of a 1000 MW CCGT Power Plant in the Sairam District of the
A3: НАЗВАНИЕ ПРОЕКТА | G3: Turkistan Region, Main Site. Without External Engineering Networks | P3: НАЗВАНИЕ ПРОЕКТА | V3: Turkistan Region, Main Site. Without External Engineering Networks
A5: ● CONSIGNEE | F5: : | G5: CCGT Turkestan LLP | P5: ● CONSIGNEE | U5: : | V5: CCGT Turkestan LLP
A6: ГРУЗОПОЛУЧАТЕЛЬ | P6: ГРУЗОПОЛУЧАТЕЛЬ
A8: ● Shipper/Exporter | F8: : Doosan Enerbility Co., LTD | P8: ● Shipper/Exporter | U8: : Doosan Enerbility Co., LTD
A9: Грузоотправитель/Экспортер | F9: 22, Doosan Volvo-ro, Sengsan-gu, Changwon, Gyeongnam, South Korea | P9: Грузоотправитель/Экспортер | U9: 22, Doosan Volvo-ro, Sengsan-gu, Changwon, Gyeongnam, South Korea
A11: ● Number of Invoice | F11: : | G11: PGU-DE-0336 | P11: ● Number of Invoice | U11: : | V11: PGU-DE-0336
A12: № инвойса | P12: № инвойса
A14: ● CARGO DESCRIPTION | F14: : | G14: ='Detail PL '!C66 -> 0 | P14: ● CARGO DESCRIPTION | U14: : | V14: ='Detail PL '!C68 -> 0
A15: ОПИСАНИЕ ГРУЗА | P15: ОПИСАНИЕ ГРУЗА
A17: ● PACKAGE NO. | F17: : | G17: ='Detail PL '!B66 -> 0 | P17: ● PACKAGE NO. | U17: : | V17: ='Detail PL '!B68 -> 0
A18: УПАКОВОЧНЫЙ НОМЕР | P18: УПАКОВОЧНЫЙ НОМЕР
A20: ● NET WEIGHT | F20: : | G20: ='Detail PL '!K66 -> 1005 | H20: Kg | P20: ● NET WEIGHT | U20: : | V20: ='Detail PL '!K68 -> 1005 | W20: Kg
A21: ВЕС НЕТТО | P21: ВЕС НЕТТО
A23: ● GROSS WEIGHT | F23: : | G23: ='Detail PL '!L66 -> 1105 | H23: Kg | P23: ● GROSS WEIGHT | U23: : | V23: ='Detail PL '!L68 -> 1105 | W23: Kg
A24: ВЕС БРУТТО | P24: ВЕС БРУТТО
A26: ● CBM(m3) | F26: : | G26: ='Detail PL '!J66 -> 8.689 | H26: m3 | P26: ● CBM(m3) | U26: : | V26: ='Detail PL '!J68 -> 8.689 | W26: m3
A27: РАЗМЕРЫ | P27: РАЗМЕРЫ
A29: ● FINAL DESTINATION | F29: : | G29: Turkestan Oblast, Sairam district, Karamurt rural district, quarter 171, Republic of Kazakhstan | P29: ● FINAL DESTINATION | U29: : | V29: Turkestan Oblast, Sairam district, Karamurt rural district, quarter 171, Republic of Kazakhstan
A30: КОНЕЧНЫЙ ПУНКТ НАЗНАЧЕНИЯ | P30: КОНЕЧНЫЙ ПУНКТ НАЗНАЧЕНИЯ
E31: Doosan Enerbility | T31: Doosan Enerbility
A33: SHIPPING MARK ГРУЗОВАЯ МАРКИРОВКА | P33: SHIPPING MARK ГРУЗОВАЯ МАРКИРОВКА
A34: ● NAME OF THE PROJECT | F34: : | G34: Construction of a 1000 MW CCGT Power Plant in the Sairam District of the | P34: ● NAME OF THE PROJECT | U34: : | V34: Construction of a 1000 MW CCGT Power Plant in the Sairam District of the
A35: НАЗВАНИЕ ПРОЕКТА | G35: Turkistan Region, Main Site. Without External Engineering Networks | P35: НАЗВАНИЕ ПРОЕКТА | V35: Turkistan Region, Main Site. Without External Engineering Networks
A37: ● CONSIGNEE | F37: : | G37: CCGT Turkestan LLP | P37: ● CONSIGNEE | U37: : | V37: CCGT Turkestan LLP
A38: ГРУЗОПОЛУЧАТЕЛЬ | P38: ГРУЗОПОЛУЧАТЕЛЬ
A40: ● Shipper/Exporter | F40: : Doosan Enerbility Co., LTD | P40: ● Shipper/Exporter | U40: : Doosan Enerbility Co., LTD
A41: Грузоотправитель/Экспортер | F41: 22, Doosan Volvo-ro, Sengsan-gu, Changwon, Gyeongnam, South Korea | P41: Грузоотправитель/Экспортер | U41: 22, Doosan Volvo-ro, Sengsan-gu, Changwon, Gyeongnam, South Korea
A43: ● Number of Invoice | F43: : | G43: PGU-DE-0336 | P43: ● Number of Invoice | U43: : | V43: PGU-DE-0336
A44: № инвойса | P44: № инвойса
A46: ● CARGO DESCRIPTION | F46: : | G46: ='Detail PL '!C70 -> 0 | P46: ● CARGO DESCRIPTION | U46: : | V46: ='Detail PL '!C72 -> 0
A47: ОПИСАНИЕ ГРУЗА | P47: ОПИСАНИЕ ГРУЗА
A49: ● PACKAGE NO. | F49: : | G49: ='Detail PL '!B70 -> 0 | P49: ● PACKAGE NO. | U49: : | V49: ='Detail PL '!B72 -> 0
A50: УПАКОВОЧНЫЙ НОМЕР | P50: УПАКОВОЧНЫЙ НОМЕР
A52: ● NET WEIGHT | F52: : | G52: ='Detail PL '!K70 -> 1005 | H52: Kg | P52: ● NET WEIGHT | U52: : | V52: ='Detail PL '!K72 -> 1005 | W52: Kg
A53: ВЕС НЕТТО | P53: ВЕС НЕТТО
A55: ● GROSS WEIGHT | F55: : | G55: ='Detail PL '!L70 -> 1105 | H55: Kg | P55: ● GROSS WEIGHT | U55: : | V55: ='Detail PL '!L72 -> 1105 | W55: Kg
A56: ВЕС БРУТТО | P56: ВЕС БРУТТО
A58: ● CBM(m3) | F58: : | G58: ='Detail PL '!J70 -> 8.689 | H58: m3 | P58: ● CBM(m3) | U58: : | V58: ='Detail PL '!J72 -> 8.689 | W58: m3
...
