Workbook
Name AnnullaInseriscidata: #REF!
Name AnnullaInseriscidata: #REF!
Name InserisciData: #REF!
Name InserisciData: #REF!

Sheet CI
W1: HEAD OFFICE & CHANGWON PLANT
W2: 22, DoosanVolvo-ro, Seongsan-gu, Changwon-Si,
W3: Gyeongsangnam-do, Korea
W4: (P.O.BOX 77, Changwon, Korea)
W5: TEL:(055)278-6114,7114 FAX:(055)264-5551/2
A6: PROFORMA INVOICE ПРОФОРМА ИНВОЙС
A8: 1. Shipper / Грузоотправитель | R8: 11. Invoice № : | W8: =PL!V8 -> PGU-DE-0587
B9: Doosan Enerbility Co., Ltd (DOOSAN) | R9: Инвойс №
B10: 22, DoosanVolvo-ro, Seongsan-gu, Changwon-si, Gyeongsangnam-do, | R10: 12. Date : | W10: =PL!V10 -> 46169
B11: Republic of Korea | R11: Дата
A12: 2. Consignee / Грузополучатель | R12: 13. Remarks / Примечания
B13: Branch of JSC "Doosan Enerbility" in the Turkestan region
B14: 321 Tauke Khan Avenue, Turkestan region, Turkestan, Kazakhstan, 161200 | S14: *Project Name / Название Проекта
B15: BIN: 230741006561 | S15: Construction of a 1000 MW CCGT Power Plant in the Sairam District of
S16: Turkistan Region, Main Site. Without External Engineering Networks
S17: *MANUFACTURER'S NAME / НАЗВАНИЕ ПРОИЗВОДИТЕЛЯ
A18: 3. Notify party / Уведомляемая сторона | S18: Iljin Electric
B19: Wise Logistics | S19: *MANUFACTURE YEAR / ГОД ИЗГОТОВЛЕНИЯ
B20: ATTAN: MS. Aliya | S20: 2025
B21: (E): a.kipshakbayeva@wiselogistics.kz | S21: *COUNTRY OF ORIGIN / СТРАНА ПРОИСХОЖДЕНИЯ
B22: (T): +7 701 512 19 69 | S22: Republic of Korea
S23: *INCOTERMS / УСЛОВИЯ ПОСТАВКИ СОГЛАСНО ИНКОТЕРМС
S24: DAP Sairam District
A26: 4. Port of Loading / Порт погрузки | I26: 5. Carrier / Перевозчик | R26: 14. Mark and Numbers of PKGS / Маркировка и количество упаковок
B27: Later | J27: Later
S28: PKG No. | X28: : | Y28: =PL!Y28 -> PGU-DE-0587-CMcable-001,…004
A29: 6. Port of Unloading / Порт разгрузки | I29: 7. Final Destination / Конечный пункт назначения | S29: Q-ty of Package | X29: : | Y29: =PL!Y29 -> 4 | AC29: PKGS
S30: Net Weight (kg) | X30: : | Y30: =PL!Y30 -> 1493 | AC30: KG
B31: Later | J31: Later | S31: Gross Weight (kg) | X31: : | Y31: =PL!Y31 -> 1881 | AC31: KG
S32: Dimension (m3) | X32: : | Y32: =PL!Y32 -> 5.929 | AC32: m3
A33: 8. Voyage No / Рейс № | I33: 9. Sailing on or about / Дата или ожидаемая дата
B35: Later | J35: Later
A37: 10. Customs Place / Место таможенного оформления
B38: Later
A40: 15. Description of Goods / Описание товара | R40: 16. HS CODE / | W40: 17. Quantity / | AA40: 18. Total Price (USD)
R41: Код ТН ВЭД | W41: Количество | AA41: Общая сумма (Дол. США)
B42: =PL!B42 -> AIS_Communication cable | W42: 1 | AA42: =CI_BD!H13 -> 106341
I45: Total (DAP Value) | AA45: =AA42 -> 106341
S53: Signed by
A54: Doosan Enerbility Co., Ltd
...

Sheet CI_BD
I1: HEAD OFFICE & CHANGWON PLANT
I2: 22, DoosanVolvo-ro, Seongsan-gu, Changwon-Si,
I3: Gyeongsangnam-do, Korea
I4: (P.O.BOX 77, Changwon, Korea)
I5: TEL:(055)278-6114,7114 FAX:(055)264-5551/2
A6: INVOICE (Break-down)
A7: Invoice № : | B7: =CI!W8 -> PGU-DE-0587
A8: № | B8: № Package | C8: Description of Goods Specification | D8: HS CODE | E8: Quantity | F8: Unit | G8: U/Price (USD) | H8: Amount (USD) | I8: Country of Origin | J8: Remark
A9: 1 | B9: ='Summary PL'!C14 -> PGU-DE-0587-AIS-CMcable-001 | C9: FO / SFTP patchcord, 9842 cable | E9: 1 | F9: EA | G9: 15171.22 | H9: =E9*G9 -> 15171.22 | I9: Korea
A10: 2 | B10: ='Summary PL'!C15 -> PGU-DE-0587-AIS-CMcable-002 | C10: Optical Fiber Cable FR PSP SM 4C, 3500m | E10: 1 | F10: EA | G10: 51639.13 | H10: =E10*G10 -> 51639.13 | I10: Korea
A11: 3 | B11: ='Summary PL'!C16 -> PGU-DE-0587-AIS-CMcable-003 | C11: Optical Fiber Cable FR PSP SM 24C, 3000m | E11: 1 | F11: EA | G11: 32479.23 | H11: =E11*G11 -> 32479.23 | I11: Korea
A12: 4 | B12: ='Summary PL'!C17 -> PGU-DE-0587-AIS-CMcable-004 | C12: Optical Fiber Cable FR PSP MM 24C, 500m | E12: 1 | F12: EA | G12: 7051.42 | H12: =E12*G12 -> 7051.42 | I12: Korea
A13: TOTAL | H13: =SUM(H9:H12) -> 106341

Sheet PL
W1: HEAD OFFICE & CHANGWON PLANT
W2: 22, DoosanVolvo-ro, Seongsan-gu, Changwon-Si,
W3: Gyeongsangnam-do, Korea
W4: (P.O.BOX 77, Changwon, Korea)
W5: TEL:(055)278-6114,7114 FAX:(055)264-5551/2
A6: PACKING LIST УПАКОВОЧНЫЙ ЛИСТ
A8: 1. Shipper / Грузоотправитель | R8: 11. Invoice № : | V8: PGU-DE-0587
B9: Doosan Enerbility Co., Ltd (DOOSAN) | R9: Инвойс №
B10: 22, DoosanVolvo-ro, Seongsan-gu, Changwon-si, Gyeongsangnam-do, | R10: 12. Date : | V10: 46169
B11: Republic of Korea | R11: Дата
A12: 2. Consignee / Грузополучатель | R12: 13. Remarks / Примечания
B13: Branch of JSC "Doosan Enerbility" in the Turkestan region
B14: 321 Tauke Khan Avenue, Turkestan region, Turkestan, Kazakhstan, 161200 | S14: *Project Name / Название Проекта
B15: BIN: 230741006561 | S15: Construction of a 1000 MW CCGT Power Plant in the Sairam District of
S16: Turkistan Region, Main Site. Without External Engineering Networks
S17: *MANUFACTURER'S NAME / НАЗВАНИЕ ПРОИЗВОДИТЕЛЯ
A18: 3. Notify party / Уведомляемая сторона | S18: YPP
B19: Wise Logistics | S19: *MANUFACTURE YEAR / ГОД ИЗГОТОВЛЕНИЯ
B20: ATTAN: MS. Aliya | S20: 2026
B21: (E): a.kipshakbayeva@wiselogistics.kz | S21: *COUNTRY OF ORIGIN / СТРАНА ПРОИСХОЖДЕНИЯ
B22: (T): +7 701 512 19 69 | S22: Republic of Korea
S23: *INCOTERMS / УСЛОВИЯ ПОСТАВКИ СОГЛАСНО ИНКОТЕРМС
S24: DAP Sairam District
A26: 4. Port of Loading / Порт погрузки | I26: 5. Carrier / Перевозчик | R26: 14. Mark and Numbers of PKGS / Маркировка и количество упаковок
B27: Later | J27: Later
S28: PKG No. | X28: : | Y28: PGU-DE-0587-CMcable-001,…004
A29: 6. Port of Unloading / Порт разгрузки | I29: 7. Final Destination / Конечный пункт назначения | S29: Q-ty of Package | X29: : | Y29: =COUNT('Summary PL'!A14:A17) -> 4 | AC29: PKGS
S30: Net Weight (kg) | X30: : | Y30: ='Summary PL'!L18 -> 1493 | AC30: KG
B31: Later | J31: Sairam District of Turkistan Region | S31: Gross Weight (kg) | X31: : | Y31: ='Summary PL'!M18 -> 1881 | AC31: KG
S32: Dimension (m3) | X32: : | Y32: ='Summary PL'!K18 -> 5.929 | AC32: m3
A33: 8. Voyage No / Рейс № | I33: 9. Sailing on or about / Дата или ожидаемая дата
B34: Later
J35: Later
A37: 10. Customs Place / Место таможенного оформления
B38: Later
A40: 15. Description of Goods / Описание товара | R40: 16. Q-ty | U40: 17. Net Weight | Y40: 18. Gross Weight | AC40: 19. Measurement
R41: (EA) | U41: (kg) | Y41: (kg) | AC41: (CBM)
B42: AIS_Communication cable | R42: 1 | U42: ='Summary PL'!L18 -> 1493 | Y42: ='Summary PL'!M18 -> 1881 | AC42: ='Summary PL'!K18 -> 5.929
R43: / комплект
R45: =SUM(R42:T44) -> 1 | U45: =SUM(U42:X43) -> 1493 | Y45: =SUM(Y42:AB43) -> 1881 | AC45: =SUM(AC42:AC43) -> 5.929
...

Sheet Summary PL
O1: HEAD OFFICE & CHANGWON PLANT | Q1: Note> | R1: Storage Classification "A" : | S1: Indoor with Air-conditioning
O2: 22, DoosanVolvo-ro, Seongsan-gu, Changwon-Si, | R2: Storage Classification "B" : | S2: Indoor without Air-conditioning
O3: Gyeongsangnam-do, Korea | R3: Storage Classification "C" : | S3: Outdoor with Waterproofing
O4: (P.O.BOX 77, Changwon, Korea) | R4: Storage Classification "D" : | S4: Outdoor without Waterproofing
O5: TEL:(055)278-6114,7114 FAX:(055)264-5551/2
A6: SUMMARY PACKING LIST CВОДНЫЙ УПАКОВОЧНЫЙ ЛИСТ
A7: Project Name: | B7: Construction of a 1000 MW CCGT Power Plant in the Sairam District of the Turkistan Region
B8: Main Site. Without External Engineering Networks
A9: Invoice №: | B9: =PL!V8 -> PGU-DE-0587
A10: Name of Consignee: | B10: =PL!B13 -> Branch of JSC "Doosan Enerbility" in the Turkestan region
A11: Consignee address: | B11: =PL!B14 -> 321 Tauke Khan Avenue, Turkestan region, Turkestan, Kazakhstan, 161200
A12: № | B12: CNTR No. / Seal No. / № контейнера / № пломбы | C12: Package No. / № упаковки | D12: Description / Описание | E12: Packing Style / Вид упаковки | F12: Quantity / Количество | H12: Shipping Dimension / Отгрузочные параметры | L12: Net Weight (kg) / Вес нетто (кг) | M12: Gross Weight (kg) / Вес брутто (кг) | N12: Hazardous Material (UN Number) | O12: Storage Class / Класс хранения | P12: Stackable / Штабелируемый
F13: Q'ty / Количество | G13: Unit / Ед.изм. | H13: L (cm) / Д (см) | I13: W (cm) / Ш (см) | J13: H (cm) / В (см) | K13: CBM (m3) / Объем (м3)
A14: 1 | C14: PGU-DE-0587-AIS-CMcable-001 | D14: FO / SFTP patchcord, 9842 cable, Cable lug | E14: Wooden box | F14: 1 | G14: EA/ШТ. | H14: 122 | I14: 100 | J14: 172 | K14: =ROUND(J14*I14*H14/1000000,3) -> 2.098 | L14: 213 | M14: 232 | N14: NA | O14: D | P14: N
A15: 2 | C15: PGU-DE-0587-AIS-CMcable-002 | D15: Optical Fiber Cable FR PSP SM 4C, 3500m | E15: Wooden drum | F15: 1 | G15: EA/ШТ. | H15: 157 | I15: 75 | J15: 157 | K15: =ROUND(J15*I15*H15/1000000,3) -> 1.849 | L15: 725 | M15: 897 | N15: NA | O15: D | P15: N
A16: 3 | C16: PGU-DE-0587-AIS-CMcable-003 | D16: Optical Fiber Cable FR PSP SM 24C, 3000m | E16: Wooden drum | F16: 1 | G16: EA/ШТ. | H16: 142 | I16: 75 | J16: 142 | K16: =ROUND(J16*I16*H16/1000000,3) -> 1.512 | L16: 456 | M16: 599 | N16: NA | O16: D | P16: N
A17: 4 | C17: PGU-DE-0587-AIS-CMcable-004 | D17: Optical Fiber Cable FR PSP MM 4C, 500m | E17: Wooden drum | F17: 1 | G17: EA/ШТ. | H17: 97 | I17: 50 | J17: 97 | K17: =ROUND(J17*I17*H17/1000000,3) -> 0.47 | L17: 99 | M17: 153 | N17: NA | O17: D | P17: N
A18: TOTAL / ИТОГО | F18: =SUM(F14:F17) -> 4 | K18: =SUM(K14:K17) -> 5.929 | L18: =SUM(L14:L17) -> 1493 | M18: =SUM(M14:M17) -> 1881

Sheet Detail PL
P1: HEAD OFFICE & CHANGWON PLANT
P2: 22, DoosanVolvo-ro, Seongsan-gu, Changwon-Si, | R2: Note> | S2: Storage Classification "A" : | T2: Indoor with Air-conditioning
P3: Gyeongsangnam-do, Korea | S3: Storage Classification "B" : | T3: Indoor without Air-conditioning
P4: (P.O.BOX 77, Changwon, Korea) | S4: Storage Classification "C" : | T4: Outdoor with Waterproofing
P5: TEL:(055)278-6114,7114 FAX:(055)264-5551/2 | S5: Storage Classification "D" : | T5: Outdoor without Waterproofing
A6: DETAILED PACKING LIST ПОДРОБНЫЙ УПАКОВОЧНЫЙ ЛИСТ
A7: Project Name: | B7: Construction of a 1000 MW CCGT Power Plant in the Sairam District of the Turkistan Region
B8: Main Site. Without External Engineering Networks
A9: Invoice №: | B9: =PL!V8 -> PGU-DE-0587
A10: Name of Consignee: | B10: ='Summary PL'!B10 -> Branch of JSC "Doosan Enerbility" in the Turkestan region
A11: Consignee address: | B11: ='Summary PL'!B11 -> 321 Tauke Khan Avenue, Turkestan region, Turkestan, Kazakhstan, 161200
A12: № | B12: Package No./ Номер упаковки | C12: Description / Описание | D12: HS Code / Код ТН ВЭД | E12: Quantity / Количество | G12: Shipping Dimension / Отгрузочные параметры | K12: Net Weight (kg) / Вес нетто (кг) | L12: Gross Weight (kg) / Вес брутто (кг) | M12: Drawing No. / № чертежа | N12: Tag No. / № Тег | O12: Unit Price (US$) / цена заединицу | P12: Total Price (US$) / Общая цена | Q12: Remark / Примечания
E13: Q'ty / Кол-во | F13: Unit / Ед. изм. | G13: L (cm) / Д (см) | H13: W (cm) / Ш (см) | I13: H (cm) / В (см) | J13: CBM (m3) / Объем (м3)
A14: 1 | B14: PGU-DE-0587-AIS-CMcable-001 | C14: 9842 060(CHR) communication cable | D14: 8544.49.1011 | E14: 1 | F14: EA/ШТ. | G14: 45 | H14: 29 | I14: 45 | J14: =ROUND(I14*H14*G14/1000000,3) -> 0.059 | K14: 30 | M14: CCP-W-B022-35-EL-B16-0002
A15: 2 | B15: PGU-DE-0587-AIS-CMcable-001 | C15: SCADA-MM_Duplex (LC/UPC-LC/UPC)-2m | D15: 8544.70.0000 | E15: 41 | F15: EA/ШТ. | M15: CCP-W-B022-35-EL-B16-0002
A16: 3 | B16: PGU-DE-0587-AIS-CMcable-001 | C16: SCADA-MM_Duplex (LC/UPC-LC/UPC)-13m | D16: 8544.70.0000 | E16: 20 | F16: EA/ШТ. | M16: CCP-W-B022-35-EL-B16-0002
A17: 4 | B17: PGU-DE-0587-AIS-CMcable-001 | C17: SCADA-MM_Duplex (LC/UPC-LC/UPC)-14m | D17: 8544.70.0000 | E17: 5 | F17: EA/ШТ. | M17: CCP-W-B022-35-EL-B16-0002
A18: 5 | B18: PGU-DE-0587-AIS-CMcable-001 | C18: SCADA-MM_Duplex (LC/UPC-LC/UPC)-15m | D18: 8544.70.0000 | E18: 4 | F18: EA/ШТ. | M18: CCP-W-B022-35-EL-B16-0002
A19: 6 | B19: PGU-DE-0587-AIS-CMcable-001 | C19: SCADA-MM_Duplex (LC/UPC-LC/UPC)-18m | D19: 8544.70.0000 | E19: 3 | F19: EA/ШТ. | M19: CCP-W-B022-35-EL-B16-0002
A20: 7 | B20: PGU-DE-0587-AIS-CMcable-001 | C20: SCADA-MM_Duplex (LC/UPC-LC/UPC)-19m | D20: 8544.70.0000 | E20: 2 | F20: EA/ШТ. | M20: CCP-W-B022-35-EL-B16-0002
A21: 8 | B21: PGU-DE-0587-AIS-CMcable-001 | C21: SCADA-MM_Duplex (LC/UPC-LC/UPC)-20m | D21: 8544.70.0000 | E21: 2 | F21: EA/ШТ. | M21: CCP-W-B022-35-EL-B16-0002
A22: 9 | B22: PGU-DE-0587-AIS-CMcable-001 | C22: SCADA-MM_Duplex (LC/UPC-LC/UPC)-21m | D22: 8544.70.0000 | E22: 2 | F22: EA/ШТ. | M22: CCP-W-B022-35-EL-B16-0002
A23: 10 | B23: PGU-DE-0587-AIS-CMcable-001 | C23: SCADA-MM_Duplex (LC/UPC-LC/UPC)-22m | D23: 8544.70.0000 | E23: 2 | F23: EA/ШТ. | M23: CCP-W-B022-35-EL-B16-0002
A24: 11 | B24: PGU-DE-0587-AIS-CMcable-001 | C24: SCADA-MM_Duplex (LC/UPC-LC/UPC)-23m | D24: 8544.70.0000 | E24: 1 | F24: EA/ШТ. | M24: CCP-W-B022-35-EL-B16-0002
A25: 12 | B25: PGU-DE-0587-AIS-CMcable-001 | C25: SCADA-MM_Duplex (LC/UPC-LC/UPC)-24m | D25: 8544.70.0000 | E25: 1 | F25: EA/ШТ. | M25: CCP-W-B022-35-EL-B16-0002
A26: 13 | B26: PGU-DE-0587-AIS-CMcable-001 | C26: SCADA-MM_Duplex (LC/UPC-LC/UPC)-25m | D26: 8544.70.0000 | E26: 2 | F26: EA/ШТ. | M26: CCP-W-B022-35-EL-B16-0002
... A91: 78 | B91: PGU-DE-0587-AIS-CMcable-001 | C91: SPARE-SFTP Cat.6-72m | D91: 8544.42.1010 | E91: 1 | F91: EA/ШТ. | M91: CCP-W-B022-35-EL-B16-0002
A92: 79 | B92: PGU-DE-0587-AIS-CMcable-001 | C92: Insulated ferrules CE040012 | D92: 8536.90.9010 | E92: 7000 | F92: EA/ШТ.
A93: 80 | B93: PGU-DE-0587-AIS-CMcable-001 | C93: Insulated ferrules CE100012 | D93: 8536.90.9010 | E93: 1000 | F93: EA/ШТ.
A94: 81 | B94: PGU-DE-0587-AIS-CMcable-001 | C94: Insulated ferrules CE160012 | D94: 8536.90.9010 | E94: 1000 | F94: EA/ШТ.
A95: 82 | B95: PGU-DE-0587-AIS-CMcable-001 | C95: Insulated ferrules CE500020 | D95: 8536.90.9010 | E95: 100 | F95: EA/ШТ.
A96: 83 | B96: PGU-DE-0587-AIS-CMcable-001 | C96: Tubular cable lugs, CE 1H 50 8 | D96: 8536.90.9010 | E96: 200 | F96: EA/ШТ.
G97: 122 | H97: 100 | I97: 172 | J97: =ROUND(I97*H97*G97/1000000,3) -> 2.098 | K97: 213 | L97: 232
A98: 1 | B98: ='Summary PL'!C15 -> PGU-DE-0587-AIS-CMcable-002 | C98: Optical Fiber Cable FR PSP SM 4C, 3500m | D98: 8544.70.0000 | E98: 1 | F98: EA/ШТ. | M98: CCP-W-B022-35-EL-B16-0002
G99: 157 | H99: 75 | I99: 157 | J99: =ROUND(I99*H99*G99/1000000,3) -> 1.849 | K99: 725 | L99: 897
A100: 1 | B100: ='Summary PL'!C16 -> PGU-DE-0587-AIS-CMcable-003 | C100: Optical Fiber Cable FR PSP SM 24C, 3000m | D100: 8544.70.0000 | E100: 1 | F100: EA/ШТ. | M100: CCP-W-B022-35-EL-B16-0002
G101: 142 | H101: 75 | I101: 142 | J101: =ROUND(I101*H101*G101/1000000,3) -> 1.512 | K101: 456 | L101: 599
A102: 1 | B102: ='Summary PL'!C17 -> PGU-DE-0587-AIS-CMcable-004 | C102: Optical Fiber Cable FR PSP MM 4C, 500m | D102: 8544.70.0000 | E102: 1 | F102: EA/ШТ. | M102: CCP-W-B022-35-EL-B16-0002
G103: 97 | H103: 50 | I103: 97 | J103: =ROUND(I103*H103*G103/1000000,3) -> 0.47 | K103: 99 | L103: 153
A104: TOTAL/ ИТОГО | J104: =SUM(J97:J103) -> 5.929 | K104: =SUM(K97:K103) -> 1493 | L104: =SUM(L97:L103) -> 1881

Sheet Description
A1: Technical Description
A3: Name | B3: Q-ty | C3: Model-Part No. | D3: Kind of material | E3: Size/specification/ Usage | F3: Photo | G3: Manufacturer / Origin | H3: HS Code
A4: Optical Fiber Cable | E4: Communication cable | G4: Mercury Fiber Optics / Korea | H4: 8544.70.0000
A5: Fiber optic patchcord | E5: Communication cable | G5: Shinkwang / Korea | H5: 8544.70.0000
A6: SFTP patchcord | E6: Communication cable | G6: LS ELECTRIC / Korea | H6: 8544.42.1010
A7: 9842 060(CHR) communication cable | E7: Communication cable | G7: BELDEN / China | H7: 8544.49.1011
A8: Insulated ferrules | E8: Used for connecting cables to electrical appliances, other cables, surfaces, or mechanisms. | G8: JEONO / Korea | H8: 8536.90.9010
A9: Tubular cable lugs | E9: Used for connecting cables to electrical appliances, other cables, surfaces, or mechanisms. | G9: JEONO / Korea | H9: 8536.90.9010

Sheet Marking - 1
A3: SHIPPING MARK ГРУЗОВАЯ МАРКИРОВКА
A4: ● NAME OF THE PROJECT | F4: : | G4: Construction of a 1000 MW CCGT Power Plant in the Sairam District of the Turkistan Region, Main Site. Without External Engineering Networks
A5: НАЗВАНИЕ ПРОЕКТА
A7: ● CONSIGNEE | F7: : | G7: =PL!$B$13 -> Branch of JSC "Doosan Enerbility" in the Turkestan region
A8: ГРУЗОПОЛУЧАТЕЛЬ | G8: =PL!$B$14 -> 321 Tauke Khan Avenue, Turkestan region, Turkestan, Kazakhstan, 161200
G9: =PL!$B$15 -> BIN: 230741006561
A11: ● Shipper/Exporter | F11: : Doosan Enerbility Co., LTD
A12: Грузоотправитель/Экспортер | F12: 22, Doosan Volvo-ro, Sengsan-gu, Changwon, Gyeongnam, South Korea
A14: ● Number of Invoice | F14: : | G14: =PL!$V$8 -> PGU-DE-0587
A15: № инвойса
A17: ● CARGO DESCRIPTION | F17: : | G17: =VLOOKUP($P17,'Summary PL'!$A$14:$M$17,4,FALSE) -> FO / SFTP patchcord, 9842 cable, Cable lug | P17: 1
A18: ОПИСАНИЕ ГРУЗА
A20: ● PACKAGE NO. | F20: : | G20: =VLOOKUP($P17,'Summary PL'!$A$14:$M$17,3,FALSE) -> PGU-DE-0587-AIS-CMcable-001
A21: УПАКОВОЧНЫЙ НОМЕР
A23: ● NET WEIGHT | F23: : | G23: =VLOOKUP($P17,'Summary PL'!$A$14:$M$17,12,FALSE) -> 213 | H23: Kg
A24: ВЕС НЕТТО
A26: ● GROSS WEIGHT | F26: : | G26: =VLOOKUP($P17,'Summary PL'!$A$14:$M$17,13,FALSE) -> 232 | H26: Kg
A27: ВЕС БРУТТО
A29: ● CBM(m3) | F29: : | G29: =VLOOKUP($P17,'Summary PL'!$A$14:$M$17,11,FALSE) -> 2.098 | H29: m3
A30: РАЗМЕРЫ
A32: ● FINAL DESTINATION | F32: : later | G32: Republic of Kazakhstan, Turkestan Oblast, Sairam district, Karamurt rural district, quarter 171
A33: КОНЕЧНЫЙ ПУНКТ НАЗНАЧЕНИЯ
E36: Doosan Enerbility
A40: SHIPPING MARK ГРУЗОВАЯ МАРКИРОВКА
A41: ● NAME OF THE PROJECT | F41: : | G41: Construction of a 1000 MW CCGT Power Plant in the Sairam District of the Turkistan Region, Main Site. Without External Engineering Networks
A42: НАЗВАНИЕ ПРОЕКТА
A44: ● CONSIGNEE | F44: : | G44: =PL!$B$13 -> Branch of JSC "Doosan Enerbility" in the Turkestan region
A45: ГРУЗОПОЛУЧАТЕЛЬ | G45: =PL!$B$14 -> 321 Tauke Khan Avenue, Turkestan region, Turkestan, Kazakhstan, 161200
G46: =PL!$B$15 -> BIN: 230741006561
A48: ● Shipper/Exporter | F48: : Doosan Enerbility Co., LTD
A49: Грузоотправитель/Экспортер | F49: 22, Doosan Volvo-ro, Sengsan-gu, Changwon, Gyeongnam, South Korea
A51: ● Number of Invoice | F51: : | G51: =PL!$V$8 -> PGU-DE-0587
A52: № инвойса
A54: ● CARGO DESCRIPTION | F54: : | G54: =VLOOKUP($P54,'Summary PL'!$A$14:$M$17,4,FALSE) -> Optical Fiber Cable FR PSP SM 4C, 3500m | P54: =P17+1 -> 2
A55: ОПИСАНИЕ ГРУЗА
A57: ● PACKAGE NO. | F57: : | G57: =VLOOKUP($P54,'Summary PL'!$A$14:$M$17,3,FALSE) -> PGU-DE-0587-AIS-CMcable-002
A58: УПАКОВОЧНЫЙ НОМЕР
A60: ● NET WEIGHT | F60: : | G60: =VLOOKUP($P54,'Summary PL'!$A$14:$M$17,12,FALSE) -> 725 | H60: Kg
A61: ВЕС НЕТТО
A63: ● GROSS WEIGHT | F63: : | G63: =VLOOKUP($P54,'Summary PL'!$A$14:$M$17,13,FALSE) -> 897 | H63: Kg
...
