Workbook
Name AnnullaInseriscidata: #REF!
Name AnnullaInseriscidata: #REF!
Name InserisciData: #REF!
Name InserisciData: #REF!

Sheet CI
W1: HEAD OFFICE & CHANGWON PLANT
W2: 22, DoosanVolvo-ro, Seongsan-gu, Changwon-Si,
W3: Gyeongsangnam-do, Korea
W4: (P.O.BOX 77, Changwon, Korea)
W5: TEL:(055)278-6114,7114 FAX:(055)264-5551/2
A6: PROFORMA INVOICE ПРОФОРМА ИНВОЙС
A8: 1. Shipper / Грузоотправитель | R8: 11. Invoice № : | V8: PGU-DE-0219
B9: Doosan Enerbility Co., Ltd (DOOSAN) | R9: Инвойс №
B10: 22, DoosanVolvo-ro, Seongsan-gu, Changwon-si, Gyeongsangnam-do, | R10: 12. Date : | V10: 45693
B11: Republic of Korea | R11: Дата
A12: 2. Consignee / Грузополучатель | R12: 13. Remarks / Примечания
B13: Branch of JSC "Doosan Enerbility" in the Turkestan region
B14: 321 Tauke Khan Avenue, Turkestan region, Turkestan, Kazakhstan, 161200 | S14: *Project Name / Название Проекта
B15: BIN: 230741006561 | S15: Construction of a 1000 MW CCGT Power Plant in the Sairam District of
S16: Turkistan Region, Main Site. Without External Engineering Networks
S17: *MANUFACTURER'S NAME / НАЗВАНИЕ ПРОИЗВОДИТЕЛЯ
S18: Siemens-energy
A19: 3. Notify party / Уведомляемая сторона | S19: *MANUFACTURE YEAR / ГОД ИЗГОТОВЛЕНИЯ
B20: Wise Logistics | S20: 2024
B21: ATTAN: MS. Aliya | S21: *COUNTRY OF ORIGIN / СТРАНА ПРОИСХОЖДЕНИЯ
B22: (E): a.kipshakbayeva@wiselogistics.kz | S22: KOREA
B23: (T): +7 701 512 19 69 | S23: *INCOTERMS / УСЛОВИЯ ПОСТАВКИ СОГЛАСНО ИНКОТЕРМС
S24: DDP Turkistan
A26: 4. Port of Loading / Порт погрузки | I26: 5. Carrier / Перевозчик | R26: 14. Mark and Numbers of PKGS / Маркировка и количество упаковок
B27: Busan, Korea | J27: Later
S28: PKG No. | X28: : | Y28: PGU-DE-0219-DCS-FNT-001~018
A29: 6. Port of Unloading / Порт разгрузки | I29: 7. Final Destination / Конечный пункт назначения | S29: Q-ty of Package | X29: : | AA29: 18 | AB29: PKGS
S30: Net Weight (kg) | X30: : | Y30: ='Summary PL'!L32 -> 5951 | AB30: KG
B31: Later | S31: Gross Weight (kg) | X31: : | Y31: ='Summary PL'!M32 -> 10451 | AB31: KG
S32: Dimension (m3) | X32: : | Y32: ='Summary PL'!K32 -> 148.917 | AB32: m3
A33: 8. Voyage No / Рейс № | I33: 9. Sailing on or about / Дата или ожидаемая дата
B35: Later | J35: Later
A37: 10. Customs Place / Место таможенного оформления
A40: 15. Description of Goods / Описание товара | R40: 16. HS CODE / | W40: 17. Quantity / | AA40: 18. Total Price (USD)
R41: Код ТН ВЭД | W41: Количество | AA41: Общая сумма (Дол. США)
B42: Distributed Control System (DCS) | W42: 1 SET | AC42: =CI_BD!H27 -> 588918.99 | AD42: BOM 9.1
AD43: Распределенная система управления
I45: Total (DDP Value) | AA45: =AC42 -> 588918.99
S53: Signed by
A54: Doosan Enerbility Co., Ltd
...

Sheet CI_BD
I1: HEAD OFFICE & CHANGWON PLANT
I2: 22, DoosanVolvo-ro, Seongsan-gu, Changwon-Si,
I3: Gyeongsangnam-do, Korea
I4: (P.O.BOX 77, Changwon, Korea)
I5: TEL:(055)278-6114,7114 FAX:(055)264-5551/2
A6: INVOICE (Break-down)
A7: Invoice № :
A8: № | B8: № Package | C8: Description of Goods Specification | D8: HS CODE | E8: Quantity | F8: Unit | G8: U/Price (USD) | H8: Amount (USD) | I8: Country of Origin | J8: Remark
A9: 1 | B9: PGU-DE-0219-DCS-FNT-001 | C9: Operation Console | E9: 1 | F9: EA / ШТ. | G9: 43542.99 | H9: =E9*G9 -> 43542.99 | I9: Korea
A10: 2 | B10: PGU-DE-0219-DCS-FNT-002 | C10: Operation Console | E10: 1 | F10: EA / ШТ. | G10: 43542.99 | H10: =E10*G10 -> 43542.99 | I10: Korea
A11: 3 | B11: PGU-DE-0219-DCS-FNT-003 | C11: Operation Console | E11: 1 | F11: EA / ШТ. | G11: 10885.75 | H11: =E11*G11 -> 10885.75 | I11: Korea
A12: 4 | B12: PGU-DE-0219-DCS-FNT-004 | C12: Operation Console | E12: 1 | F12: EA / ШТ. | G12: 47501.45 | H12: =E12*G12 -> 47501.45 | I12: Korea
A13: 5 | B13: PGU-DE-0219-DCS-FNT-005 | C13: Operation Console | E13: 1 | F13: EA / ШТ. | G13: 47501.45 | H13: =E13*G13 -> 47501.45 | I13: Korea
A14: 6 | B14: PGU-DE-0219-DCS-FNT-006 | C14: Operation Console | E14: 1 | F14: EA / ШТ. | G14: 32657.25 | H14: =E14*G14 -> 32657.25 | I14: Korea
A15: 7 | B15: PGU-DE-0219-DCS-FNT-007 | C15: Desk | E15: 1 | F15: EA / ШТ. | G15: 25729.95 | H15: =E15*G15 -> 25729.95 | I15: Korea
A16: 8 | B16: PGU-DE-0219-DCS-FNT-008 | C16: Desk | E16: 1 | F16: EA / ШТ. | G16: 25729.95 | H16: =E16*G16 -> 25729.95 | I16: Korea
A17: 9 | B17: PGU-DE-0219-DCS-FNT-009 | C17: Desk | E17: 1 | F17: EA / ШТ. | G17: 25729.95 | H17: =E17*G17 -> 25729.95 | I17: Korea
A18: 10 | B18: PGU-DE-0219-DCS-FNT-010 | C18: Desk | E18: 1 | F18: EA / ШТ. | G18: 25729.95 | H18: =E18*G18 -> 25729.95 | I18: Korea
A19: 11 | B19: PGU-DE-0219-DCS-FNT-011 | C19: Desk | E19: 1 | F19: EA / ШТ. | G19: 31667.63 | H19: =E19*G19 -> 31667.63 | I19: Korea
A20: 12 | B20: PGU-DE-0219-DCS-FNT-012 | C20: Desk | E20: 1 | F20: EA / ШТ. | G20: 31667.63 | H20: =E20*G20 -> 31667.63 | I20: Korea
... A26: 18 | B26: PGU-DE-0219-DCS-FNT-018 | C26: Laser Printer | E26: 1 | F26: EA / ШТ. | G26: 36417.8 | H26: =E26*G26 -> 36417.8 | I26: Korea
C27: TOTAL | H27: =SUM(H9:H26) -> 588918.99

Sheet PL
W1: HEAD OFFICE & CHANGWON PLANT
W2: 22, DoosanVolvo-ro, Seongsan-gu, Changwon-Si,
W3: Gyeongsangnam-do, Korea
W4: (P.O.BOX 77, Changwon, Korea)
W5: TEL:(055)278-6114,7114 FAX:(055)264-5551/2
A6: PACKING LIST УПАКОВОЧНЫЙ ЛИСТ
A8: 1. Shipper / Грузоотправитель | R8: 11. Invoice № : | V8: =CI!V8 -> PGU-DE-0219
B9: Doosan Enerbility Co., Ltd (DOOSAN) | R9: Инвойс №
B10: 22, DoosanVolvo-ro, Seongsan-gu, Changwon-si, Gyeongsangnam-do, | R10: 12. Date : | V10: =CI!V10 -> 45693
B11: Republic of Korea | R11: Дата
A12: 2. Consignee / Грузополучатель | R12: 13. Remarks / Примечания
B13: Branch of JSC "Doosan Enerbility" in the Turkestan region
B14: 321 Tauke Khan Avenue, Turkestan region, Turkestan, Kazakhstan, 161200 | S14: *Project Name / Название Проекта
B15: BIN: 230741006561 | S15: Construction of a 1000 MW CCGT Power Plant in the Sairam District of
S16: Turkistan Region, Main Site. Without External Engineering Networks
S17: *MANUFACTURER'S NAME / НАЗВАНИЕ ПРОИЗВОДИТЕЛЯ
S18: Siemens-energy
A19: 3. Notify party / Уведомляемая сторона | S19: *MANUFACTURE YEAR / ГОД ИЗГОТОВЛЕНИЯ
B20: =CI!B20 -> Wise Logistics | S20: 2024
B21: =CI!B21 -> ATTAN: MS. Aliya | S21: *COUNTRY OF ORIGIN / СТРАНА ПРОИСХОЖДЕНИЯ
B22: =CI!B22 -> (E): a.kipshakbayeva@wiselogistics.kz | S22: KOREA
B23: =CI!B23 -> (T): +7 701 512 19 69 | S23: *INCOTERMS / УСЛОВИЯ ПОСТАВКИ СОГЛАСНО ИНКОТЕРМС
S24: =CI!S24 -> DDP Turkistan
A27: 4. Port of Loading / Порт погрузки | I27: 5. Carrier / Перевозчик | R27: 14. Mark and Numbers of PKGS / Маркировка и количество упаковок
B28: Busan, Korea | J28: Later
S29: PKG No. | X29: : | Y29: PGU-DE-0219-DCS-FNT-001~018
A30: 6. Port of Unloading / Порт разгрузки | I30: 7. Final Destination / Конечный пункт назначения | S30: Q-ty of Package | X30: : | AB30: =COUNT('Summary PL'!A14:A31) -> 18 | AC30: PKGS
S31: Net Weight (kg) | X31: : | Y31: ='Summary PL'!L32 -> 5951 | AC31: KG
B32: Later | S32: Gross Weight (kg) | X32: : | Y32: ='Summary PL'!M32 -> 10451 | AC32: KG
S33: Dimension (m3) | X33: : | Y33: ='Summary PL'!K32 -> 148.917 | AC33: m3
A34: 8. Voyage No / Рейс № | I34: 9. Sailing on or about / Дата или ожидаемая дата
B35: Later
J36: Later
A38: 10. Customs Place / Место таможенного оформления
B39: Turkestan Oblast, Sairam district, Karamurt rural district, quarter 171
A41: 15. Description of Goods / Описание товара | R41: 16. Q-ty | U41: 17. Net Weight | Y41: 18. Gross Weight | AC41: 19. Measurement
R42: (EA) | U42: (kg) | Y42: (kg) | AC42: (CBM)
B43: =CI!B42 -> Distributed Control System (DCS) | R43: 1 SET | U43: ='Summary PL'!L32 -> 5951 | Y43: ='Summary PL'!M32 -> 10451 | AC43: ='Summary PL'!K32 -> 148.917
B44: =CI!AD43 -> Распределенная система управления
U46: ='Summary PL'!L32 -> 5951 | Y46: ='Summary PL'!M32 -> 10451 | AC46: ='Summary PL'!K32 -> 148.917
...

Sheet Summary PL
O1: HEAD OFFICE & CHANGWON PLANT | R1: Note> | S1: Storage Classification "A" : | T1: Indoor with Air-conditioning
O2: 22, DoosanVolvo-ro, Seongsan-gu, Changwon-Si, | S2: Storage Classification "B" : | T2: Indoor without Air-conditioning
O3: Gyeongsangnam-do, Korea | S3: Storage Classification "C" : | T3: Outdoor with Waterproofing
O4: (P.O.BOX 77, Changwon, Korea) | S4: Storage Classification "D" : | T4: Outdoor without Waterproofing
O5: TEL:(055)278-6114,7114 FAX:(055)264-5551/2
A6: SUMMARY PACKING LIST CВОДНЫЙ УПАКОВОЧНЫЙ ЛИСТ
A7: Project Name: | B7: Construction of a 1000 MW CCGT Power Plant in the Sairam District of the Turkistan Region
B8: Main Site. Without External Engineering Networks
A9: Invoice №: | B9: =PL!V8 -> PGU-DE-0219
A10: Name of Consignee: | B10: =PL!B13 -> Branch of JSC "Doosan Enerbility" in the Turkestan region
A11: Consignee address: | B11: =PL!B14 -> 321 Tauke Khan Avenue, Turkestan region, Turkestan, Kazakhstan, 161200
A12: № | B12: CNTR No. / Seal No. / № контейнера / № пломбы | C12: Package No. / № упаковки | D12: Description / Описание | E12: Packing Style / Вид упаковки | F12: Quantity / Количество | H12: Shipping Dimension / Отгрузочные параметры | L12: Net Weight (kg) / Вес нетто (кг) | M12: Gross Weight (kg) / Вес брутто (кг) | N12: Hazardous Material (UN Number) | O12: Storage Class / Класс хранения | P12: Stackable / Штабелируемый | Q12: RT (Revenue Ton)
F13: Q'ty / Количество | G13: Unit / Ед.изм. | H13: L (cm) / Д (см) | I13: W (cm) / Ш (см) | J13: H (cm) / В (см) | K13: CBM (m3) / Объем (м3)
A14: 1 | C14: PGU-DE-0219-DCS-FNT-001 | D14: Operation Console | E14: Wooden | F14: 1 | G14: EA / ШТ. | H14: ='Detail PL'!G18 -> 270 | I14: ='Detail PL'!H18 -> 230 | J14: ='Detail PL'!I18 -> 135 | K14: ='Detail PL'!J18 -> 8.384 | L14: ='Detail PL'!K18 -> 440 | M14: ='Detail PL'!L18 -> 680 | N14: N/A | O14: B | P14: Y
A15: 2 | C15: PGU-DE-0219-DCS-FNT-002 | D15: Operation Console | E15: Wooden | F15: 1 | G15: EA / ШТ. | H15: ='Detail PL'!G23 -> 270 | I15: ='Detail PL'!H23 -> 230 | J15: ='Detail PL'!I23 -> 135 | K15: ='Detail PL'!J23 -> 8.384 | L15: ='Detail PL'!K23 -> 440 | M15: ='Detail PL'!L23 -> 680 | N15: N/A | O15: B | P15: Y
A16: 3 | C16: PGU-DE-0219-DCS-FNT-003 | D16: Operation Console | E16: Wooden | F16: 1 | G16: EA / ШТ. | H16: ='Detail PL'!G25 -> 140 | I16: ='Detail PL'!H25 -> 122 | J16: ='Detail PL'!I25 -> 128 | K16: ='Detail PL'!J25 -> 2.186 | L16: ='Detail PL'!K25 -> 110 | M16: ='Detail PL'!L25 -> 190 | N16: N/A | O16: B | P16: Y
A17: 4 | C17: PGU-DE-0219-DCS-FNT-004 | D17: Operation Console | E17: Wooden | F17: 1 | G17: EA / ШТ. | H17: ='Detail PL'!G30 -> 270 | I17: ='Detail PL'!H30 -> 230 | J17: ='Detail PL'!I30 -> 100 | K17: ='Detail PL'!J30 -> 6.21 | L17: ='Detail PL'!K30 -> 480 | M17: ='Detail PL'!L30 -> 730 | N17: N/A | O17: B | P17: Y
A18: 5 | C18: PGU-DE-0219-DCS-FNT-005 | D18: Operation Console | E18: Wooden | F18: 1 | G18: EA / ШТ. | H18: ='Detail PL'!G35 -> 270 | I18: ='Detail PL'!H35 -> 230 | J18: ='Detail PL'!I35 -> 135 | K18: ='Detail PL'!J35 -> 8.384 | L18: ='Detail PL'!K35 -> 480 | M18: ='Detail PL'!L35 -> 730 | N18: N/A | O18: B | P18: Y
A19: 6 | C19: PGU-DE-0219-DCS-FNT-006 | D19: Operation Console | E19: Wooden | F19: 1 | G19: EA / ШТ. | H19: ='Detail PL'!G40 -> 270 | I19: ='Detail PL'!H40 -> 230 | J19: ='Detail PL'!I40 -> 135 | K19: ='Detail PL'!J40 -> 8.384 | L19: ='Detail PL'!K40 -> 330 | M19: ='Detail PL'!L40 -> 580 | N19: N/A | O19: B | P19: Y
A20: 7 | C20: PGU-DE-0219-DCS-FNT-007 | D20: Desk | E20: Wooden | F20: 1 | G20: EA / ШТ. | H20: ='Detail PL'!G45 -> 270 | I20: ='Detail PL'!H45 -> 230 | J20: ='Detail PL'!I45 -> 135 | K20: ='Detail PL'!J45 -> 8.384 | L20: ='Detail PL'!K45 -> 260 | M20: ='Detail PL'!L45 -> 510 | N20: N/A | O20: B | P20: Y
A21: 8 | C21: PGU-DE-0219-DCS-FNT-008 | D21: Desk | E21: Wooden | F21: 1 | G21: EA / ШТ. | H21: ='Detail PL'!G50 -> 270 | I21: ='Detail PL'!H50 -> 230 | J21: ='Detail PL'!I50 -> 135 | K21: ='Detail PL'!J50 -> 8.384 | L21: ='Detail PL'!K50 -> 260 | M21: ='Detail PL'!L50 -> 510 | N21: N/A | O21: B | P21: Y
A22: 9 | C22: PGU-DE-0219-DCS-FNT-009 | D22: Desk | E22: Wooden | F22: 1 | G22: EA / ШТ. | H22: ='Detail PL'!G55 -> 270 | I22: ='Detail PL'!H55 -> 230 | J22: ='Detail PL'!I55 -> 135 | K22: ='Detail PL'!J55 -> 8.384 | L22: ='Detail PL'!K55 -> 260 | M22: ='Detail PL'!L55 -> 510 | N22: N/A | O22: B | P22: Y
A23: 10 | C23: PGU-DE-0219-DCS-FNT-010 | D23: Desk | E23: Wooden | F23: 1 | G23: EA / ШТ. | H23: ='Detail PL'!G60 -> 270 | I23: ='Detail PL'!H60 -> 230 | J23: ='Detail PL'!I60 -> 135 | K23: ='Detail PL'!J60 -> 8.384 | L23: ='Detail PL'!K60 -> 260 | M23: ='Detail PL'!L60 -> 510 | N23: N/A | O23: B | P23: Y
A24: 11 | C24: PGU-DE-0219-DCS-FNT-011 | D24: Desk | E24: Wooden | F24: 1 | G24: EA / ШТ. | H24: ='Detail PL'!G65 -> 270 | I24: ='Detail PL'!H65 -> 230 | J24: ='Detail PL'!I65 -> 210 | K24: ='Detail PL'!J65 -> 13.041 | L24: ='Detail PL'!K65 -> 320 | M24: ='Detail PL'!L65 -> 710 | N24: N/A | O24: B | P24: Y
A25: 12 | C25: PGU-DE-0219-DCS-FNT-012 | D25: Desk | E25: Wooden | F25: 1 | G25: EA / ШТ. | H25: ='Detail PL'!G70 -> 270 | I25: ='Detail PL'!H70 -> 230 | J25: ='Detail PL'!I70 -> 210 | K25: ='Detail PL'!J70 -> 13.041 | L25: ='Detail PL'!K70 -> 320 | M25: ='Detail PL'!L70 -> 710 | N25: N/A | O25: B | P25: Y
A26: 13 | C26: PGU-DE-0219-DCS-FNT-013 | D26: Desk | E26: Wooden | F26: 1 | G26: EA / ШТ. | H26: ='Detail PL'!G77 -> 270 | I26: ='Detail PL'!H77 -> 230 | J26: ='Detail PL'!I77 -> 235 | K26: ='Detail PL'!J77 -> 14.594 | L26: ='Detail PL'!K77 -> 500 | M26: ='Detail PL'!L77 -> 930 | N26: N/A | O26: B | P26: Y
A27: 14 | C27: PGU-DE-0219-DCS-FNT-014 | D27: Chair | E27: Wooden | F27: 1 | G27: EA / ШТ. | H27: ='Detail PL'!G94 -> 200 | I27: ='Detail PL'!H94 -> 200 | J27: ='Detail PL'!I94 -> 180 | K27: ='Detail PL'!J94 -> 7.2 | L27: ='Detail PL'!K94 -> 240 | M27: ='Detail PL'!L94 -> 450 | N27: N/A | O27: B | P27: Y
A28: 15 | C28: PGU-DE-0219-DCS-FNT-015 | D28: Chair | E28: Wooden | F28: 1 | G28: EA / ШТ. | H28: ='Detail PL'!G111 -> 200 | I28: ='Detail PL'!H111 -> 200 | J28: ='Detail PL'!I111 -> 180 | K28: ='Detail PL'!J111 -> 7.2 | L28: ='Detail PL'!K111 -> 240 | M28: ='Detail PL'!L111 -> 450 | N28: N/A | O28: B | P28: Y
A29: 16 | C29: PGU-DE-0219-DCS-FNT-016 | D29: Large Screen Display | E29: Wooden | F29: 1 | G29: EA / ШТ. | H29: ='Detail PL'!G113 -> 230 | I29: ='Detail PL'!H113 -> 120 | J29: ='Detail PL'!I113 -> 190 | K29: ='Detail PL'!J113 -> 5.244 | L29: ='Detail PL'!K113 -> 210 | M29: ='Detail PL'!L113 -> 370 | N29: N/A | O29: B | P29: Y
A30: 17 | C30: PGU-DE-0219-DCS-FNT-017 | D30: Monitor | E30: Wooden | F30: 1 | G30: EA / ШТ. | H30: ='Detail PL'!G125 -> 230 | I30: ='Detail PL'!H125 -> 230 | J30: ='Detail PL'!I125 -> 195 | K30: ='Detail PL'!J125 -> 10.316 | L30: ='Detail PL'!K125 -> 433 | M30: ='Detail PL'!L125 -> 743 | N30: N/A | O30: B | P30: Y
A31: 18 | C31: PGU-DE-0219-DCS-FNT-018 | D31: Laser Printer | E31: Wooden | F31: 1 | G31: EA / ШТ. | H31: ='Detail PL'!G134 -> 150 | I31: ='Detail PL'!H134 -> 150 | J31: ='Detail PL'!I134 -> 125 | K31: ='Detail PL'!J134 -> 2.813 | L31: ='Detail PL'!K134 -> 368 | M31: ='Detail PL'!L134 -> 458 | N31: N/A | O31: B | P31: Y
A32: TOTAL / ИТОГО | K32: =SUM(K14:K31) -> 148.917 | L32: =SUM(L14:L31) -> 5951 | M32: =SUM(M14:M31) -> 10451

Sheet Detail PL
O1: HEAD OFFICE & CHANGWON PLANT | R1: Note> | S1: Storage Classification "A" : | T1: Indoor with Air-conditioning
O2: 22, DoosanVolvo-ro, Seongsan-gu, Changwon-Si, | S2: Storage Classification "B" : | T2: Indoor without Air-conditioning
O3: Gyeongsangnam-do, Korea | S3: Storage Classification "C" : | T3: Outdoor with Waterproofing
O4: (P.O.BOX 77, Changwon, Korea) | S4: Storage Classification "D" : | T4: Outdoor without Waterproofing
O5: TEL:(055)278-6114,7114 FAX:(055)264-5551/2
A6: SUMMARY PACKING LIST CВОДНЫЙ УПАКОВОЧНЫЙ ЛИСТ
A7: Project Name: | B7: Construction of a 1000 MW CCGT Power Plant in the Sairam District of the Turkistan Region
B8: Main Site. Without External Engineering Networks
A9: Invoice №: | B9: PGU-DE-0219
A10: Name of Consignee: | B10: ='Summary PL'!B10 -> Branch of JSC "Doosan Enerbility" in the Turkestan region
A11: Consignee address: | B11: ='Summary PL'!B11 -> 321 Tauke Khan Avenue, Turkestan region, Turkestan, Kazakhstan, 161200
A12: № | B12: Package No./ Номер упаковки | C12: Description / Описание | D12: HS Code / Код ТН ВЭД | E12: Quantity / Количество | G12: Shipping Dimension / Отгрузочные параметры | K12: Net Weight (kg) / Вес нетто (кг) | L12: Gross Weight (kg) / Вес брутто (кг) | M12: Drawing No. / № чертежа | N12: Tag No. / № Тег | O12: Unit Price (US$) / Цена за единицу | P12: Total Price (US$) / Общая цена | Q12: Remark / Примечания
E13: Q'ty / Кол-во | F13: Unit / Ед. изм. | G13: L (cm) / Д (см) | H13: W (cm) / Ш (см) | I13: H (cm) / В (см) | J13: CBM (m3) / Объем (м3)
A14: 1 | B14: PGU-DE-0219-DCS-FNT-001 | C14: OPERATOR CONSOLE DESK 130W X 110D X 80H | E14: 1 | F14: EA / ШТ.
A15: 2 | B15: PGU-DE-0219-DCS-FNT-001 | C15: OPERATOR CONSOLE DESK 130W X 110D X 80H | E15: 1 | F15: EA / ШТ.
A16: 3 | B16: PGU-DE-0219-DCS-FNT-001 | C16: OPERATOR CONSOLE DESK 130W X 110D X 80H | E16: 1 | F16: EA / ШТ.
A17: 4 | B17: PGU-DE-0219-DCS-FNT-001 | C17: OPERATOR CONSOLE DESK 130W X 110D X 80H | E17: 1 | F17: EA / ШТ.
G18: 270 | H18: 230 | I18: 135 | J18: =ROUND(I18*H18*G18/1000000,3) -> 8.384 | K18: 440 | L18: 680
A19: 1 | B19: PGU-DE-0219-DCS-FNT-002 | C19: OPERATOR CONSOLE DESK 130W X 110D X 80H | E19: 1 | F19: EA / ШТ.
A20: 2 | B20: PGU-DE-0219-DCS-FNT-002 | C20: OPERATOR CONSOLE DESK 130W X 110D X 80H | E20: 1 | F20: EA / ШТ.
A21: 3 | B21: PGU-DE-0219-DCS-FNT-002 | C21: OPERATOR CONSOLE DESK 130W X 110D X 80H | E21: 1 | F21: EA / ШТ.
A22: 4 | B22: PGU-DE-0219-DCS-FNT-002 | C22: OPERATOR CONSOLE DESK 130W X 110D X 80H | E22: 1 | F22: EA / ШТ.
G23: 270 | H23: 230 | I23: 135 | J23: =ROUND(I23*H23*G23/1000000,3) -> 8.384 | K23: 440 | L23: 680
A24: 1 | B24: PGU-DE-0219-DCS-FNT-003 | C24: OPERATOR CONSOLE DESK 130W X 110D X 80H | E24: 1 | F24: EA / ШТ.
G25: 140 | H25: 122 | I25: 128 | J25: =ROUND(I25*H25*G25/1000000,3) -> 2.186 | K25: 110 | L25: 190
A26: 1 | B26: ='Summary PL'!C17 -> PGU-DE-0219-DCS-FNT-004 | C26: OPERATOR CONSOLE DESK (With EPB 2-HOLE) 130W X 110D X 87H | E26: 1 | F26: EA / ШТ.
A27: 2 | B27: PGU-DE-0219-DCS-FNT-004 | C27: OPERATOR CONSOLE DESK (With EPB 2-HOLE) 130W X 110D X 87H | E27: 1 | F27: EA / ШТ.
A28: 3 | B28: PGU-DE-0219-DCS-FNT-004 | C28: OPERATOR CONSOLE DESK (With EPB 2-HOLE) 130W X 110D X 87H | E28: 1 | F28: EA / ШТ.
A29: 4 | B29: PGU-DE-0219-DCS-FNT-004 | C29: OPERATOR CONSOLE DESK (With EPB 2-HOLE) 130W X 110D X 87H | E29: 1 | F29: EA / ШТ.
G30: 270 | H30: 230 | I30: 100 | J30: =ROUND(I30*H30*G30/1000000,3) -> 6.21 | K30: 480 | L30: 730
A31: 1 | B31: ='Summary PL'!C18 -> PGU-DE-0219-DCS-FNT-005 | C31: E.P.B TUPE CONSOLE DESK (With EPB 2-HOLE) 130W X 110D X 87H | E31: 1 | F31: EA / ШТ.
A32: 2 | B32: PGU-DE-0219-DCS-FNT-005 | C32: E.P.B TUPE CONSOLE DESK (With EPB 2-HOLE) 130W X 110D X 87H | E32: 1 | F32: EA / ШТ.
A33: 3 | B33: PGU-DE-0219-DCS-FNT-005 | C33: OPERATOR CONSOLE DESK (With EPB 2-HOLE) 130W X 110D X 87H | E33: 1 | F33: EA / ШТ.
A34: 4 | B34: PGU-DE-0219-DCS-FNT-005 | C34: OPERATOR CONSOLE DESK (With EPB 2-HOLE) 130W X 110D X 87H | E34: 1 | F34: EA / ШТ.
G35: 270 | H35: 230 | I35: 135 | J35: =ROUND(I35*H35*G35/1000000,3) -> 8.384 | K35: 480 | L35: 730
A36: 1 | B36: ='Summary PL'!C19 -> PGU-DE-0219-DCS-FNT-006 | C36: OPERATOR CONSOLE DESK (With EPB 1-HOLE) 130W X 110D X 87H | E36: 1 | F36: EA / ШТ.
A37: 2 | B37: PGU-DE-0219-DCS-FNT-006 | C37: 15˚ CORNER DESK - 2EA | E37: 2 | F37: EA / ШТ.
A38: 3 | B38: PGU-DE-0219-DCS-FNT-006 | C38: COMPUTER DESK 130W X 110D X 77H | E38: 1 | F38: EA / ШТ.
A39: 4 | B39: PGU-DE-0219-DCS-FNT-006 | C39: COMPUTER DESK 130W X 110D X 77H | E39: 1 | F39: EA / ШТ.
G40: 270 | H40: 230 | I40: 135 | J40: =ROUND(I40*H40*G40/1000000,3) -> 8.384 | K40: 330 | L40: 580
...

Sheet Marking
A1: SHIPPING MARK ГРУЗОВАЯ МАРКИРОВКА | P1: SHIPPING MARK ГРУЗОВАЯ МАРКИРОВКА
A2: ● NAME OF THE PROJECT | F2: : | G2: Construction of a 1000 MW CCGT Power Plant in the Sairam District of the | P2: ● NAME OF THE PROJECT | U2: : | V2: Construction of a 1000 MW CCGT Power Plant in the Sairam District of the
A3: НАЗВАНИЕ ПРОЕКТА | G3: Turkistan Region, Main Site. Without External Engineering Networks | P3: НАЗВАНИЕ ПРОЕКТА | V3: Turkistan Region, Main Site. Without External Engineering Networks
A5: ● CONSIGNEE | F5: : | G5: =#REF! -> #REF! | P5: ● CONSIGNEE | U5: : | V5: =#REF! -> #REF!
A6: ГРУЗОПОЛУЧАТЕЛЬ | P6: ГРУЗОПОЛУЧАТЕЛЬ
A8: ● Shipper/Exporter | F8: : Doosan Enerbility Co., LTD | P8: ● Shipper/Exporter | U8: : Doosan Enerbility Co., LTD
A9: Грузоотправитель/Экспортер | F9: 22, Doosan Volvo-ro, Sengsan-gu, Changwon, Gyeongnam, South Korea | P9: Грузоотправитель/Экспортер | U9: 22, Doosan Volvo-ro, Sengsan-gu, Changwon, Gyeongnam, South Korea
A11: ● Number of Invoice | F11: : | G11: =CI!V8 -> PGU-DE-0219 | P11: ● Number of Invoice | U11: : | V11: =CI!V8 -> PGU-DE-0219
A12: № инвойса | P12: № инвойса
A14: ● CARGO DESCRIPTION | F14: : | G14: ='Summary PL'!D14 -> Operation Console | P14: ● CARGO DESCRIPTION | U14: :
A15: ОПИСАНИЕ ГРУЗА | P15: ОПИСАНИЕ ГРУЗА
A17: ● PACKAGE NO. | F17: : | G17: ='Summary PL'!C14 -> PGU-DE-0219-DCS-FNT-001 | P17: ● PACKAGE NO. | U17: : | V17: ='Summary PL'!C15 -> PGU-DE-0219-DCS-FNT-002
A18: УПАКОВОЧНЫЙ НОМЕР | P18: УПАКОВОЧНЫЙ НОМЕР
A20: ● NET WEIGHT | F20: : | G20: ='Summary PL'!L14 -> 440 | H20: Kg | P20: ● NET WEIGHT | U20: : | V20: =#REF! -> #REF! | W20: Kg
A21: ВЕС НЕТТО | P21: ВЕС НЕТТО
A23: ● GROSS WEIGHT | F23: : | G23: ='Summary PL'!M14 -> 680 | H23: Kg | P23: ● GROSS WEIGHT | U23: : | V23: =#REF! -> #REF! | W23: Kg
A24: ВЕС БРУТТО | P24: ВЕС БРУТТО
A26: ● CBM(m3) | F26: : | G26: =#REF! -> #REF! | H26: m3 | P26: ● CBM(m3) | U26: : | V26: =#REF! -> #REF! | W26: m3
A27: РАЗМЕРЫ | P27: РАЗМЕРЫ
A29: ● FINAL DESTINATION | F29: : | G29: Turkestan Oblast, Sairam district, Karamurt rural district, quarter 171, Republic of Kazakhstan | P29: ● FINAL DESTINATION | U29: : | V29: =G29 -> Turkestan Oblast, Sairam district, Karamurt rural district, quarter 171, Republic of Kazakhstan
A30: КОНЕЧНЫЙ ПУНКТ НАЗНАЧЕНИЯ | P30: КОНЕЧНЫЙ ПУНКТ НАЗНАЧЕНИЯ
E31: Doosan Enerbility | T31: Doosan Enerbility
