Workbook
Name AnnullaInseriscidata: #REF!
Name InserisciData: #REF!

Sheet CI
W1: HEAD OFFICE & CHANGWON PLANT
W2: 22, DoosanVolvo-ro, Seongsan-gu, Changwon-Si,
W3: Gyeongsangnam-do, Korea
W4: (P.O.BOX 77, Changwon, Korea)
W5: TEL:(055)278-6114,7114 FAX:(055)264-5551/2
A6: PROFORMA INVOICE ПРОФОРМА ИНВОЙС
A8: 1. Shipper / Грузоотправитель | R8: 11. Invoice № : | V8: PGU-DE-0139-001
B9: Doosan Enerbility Co., Ltd (DOOSAN) | R9: Инвойс №
B10: 22, DoosanVolvo-ro, Seongsan-gu, Changwon-si, Gyeongsangnam-do, | R10: 12. Date : | V10: 45566
B11: Republic of Korea | R11: Дата
A12: 2. Consignee / Грузополучатель | R12: 13. Remarks / Примечания
B13: Branch of JSC "Doosan Enerbility" in the Turkestan region
B14: 321 Tauke Khan Avenue, Turkestan region, Turkestan, Kazakhstan, 161200 | S14: *Project Name / Название Проекта
B15: BIN: 230741006561 | S15: Construction of a 1000 MW CCGT Power Plant in the Sairam District of
S16: Turkistan Region, Main Site. Without External Engineering Networks
S17: *MANUFACTURER'S NAME / НАЗВАНИЕ ПРОИЗВОДИТЕЛЯ
S18: DTS
A19: 3. Notify party / Уведомляемая сторона | S19: *MANUFACTURE YEAR / ГОД ИЗГОТОВЛЕНИЯ
B20: Wise Logistics | S20: 2024
B21: ATTAN: MS. Aliya | S21: *COUNTRY OF ORIGIN / СТРАНА ПРОИСХОЖДЕНИЯ
B22: (E): a.kipshakbayeva@wiselogistics.kz | S22: =B11 -> Republic of Korea
B23: (T): +7 701 512 19 69 | S23: *INCOTERMS / УСЛОВИЯ ПОСТАВКИ СОГЛАСНО ИНКОТЕРМС
S24: DDP Turkistan
A26: 4. Port of Loading / Порт погрузки | I26: 5. Carrier / Перевозчик | R26: 14. Mark and Numbers of PKGS / Маркировка и количество упаковок
B27: Later | J27: Later
S28: PKG No. | X28: : | Y28: PGU-DE-0139-FFC-ROT-001~058
A29: 6. Port of Unloading / Порт разгрузки | I29: 7. Final Destination / Конечный пункт назначения | S29: Q-ty of Package | X29: : | Y29: =COUNT('Summary PL'!A13:A71) -> 58 | AC29: PKGS
S30: Net Weight (kg) | X30: : | Y30: ='Summary PL'!L72 -> 102698.03 | AC30: KG
B31: Later | I31: Turkestan region, Sairam district | S31: Gross Weight (kg) | X31: : | Y31: ='Summary PL'!M72 -> 110478.03 | AC31: KG
S32: Dimension (m3) | X32: : | Y32: ='Summary PL'!K72 -> 515.991 | AC32: m3
A33: 8. Voyage No / Рейс № | I33: 9. Sailing on or about / Дата или ожидаемая дата
B34: Later
J35: Later
A37: 10. Customs Place / Место таможенного оформления
B38: Later
A40: 15. Description of Goods / Описание товара | R40: 16. HS CODE / | W40: 17. Quantity / | AA40: 18. Total Price (USD)
R41: Код ТН ВЭД | W41: Количество | AA41: Общая сумма (Дол. США)
B42: Fin Fan Cooler_Rotating Parts | W42: 2 | AC42: =CI_BD!H67 -> 765557 | AE42: CD#3 Item 5.7
AE43: Сухая градирня (Системы замкнутого водяного охлаждения)
I45: Total (DDP Value) | AA45: =AC42 -> 765557
...

Sheet CI_BD
I1: HEAD OFFICE & CHANGWON PLANT
I2: 22, DoosanVolvo-ro, Seongsan-gu, Changwon-Si,
I3: Gyeongsangnam-do, Korea
I4: (P.O.BOX 77, Changwon, Korea)
I5: TEL:(055)278-6114,7114 FAX:(055)264-5551/2
A6: INVOICE (Break-down)
A7: Invoice № : | B7: =CI!V8 -> PGU-DE-0139-001
A8: № | B8: № Package | C8: Description of Goods Specification | D8: HS CODE | E8: Quantity | F8: Unit | G8: U/Price (USD) | H8: Amount (USD) | I8: Country of Origin | J8: Remark
A9: 1 | B9: PGU-DE-0139-FFC-ROT-001 | C9: MOTOR | E9: 1 | F9: EA / ШТ. | G9: 10268.83 | H9: =E9*G9 -> 10268.83 | I9: Korea | K9: 1 | L9: 2 | N9: 1092 | O9: =ROUND(N9*$M$73,2) -> 7639.53
A10: 2 | B10: PGU-DE-0139-FFC-ROT-002 | C10: MOTOR | E10: 1 | F10: EA / ШТ. | G10: 10268.83 | H10: =E10*G10 -> 10268.83 | I10: Korea | K10: 1 | L10: 2 | N10: 1092 | O10: =ROUND(N10*$M$73,2) -> 7639.53
A11: 3 | B11: PGU-DE-0139-FFC-ROT-003 | C11: MOTOR | E11: 1 | F11: EA / ШТ. | G11: 10268.83 | H11: =E11*G11 -> 10268.83 | I11: Korea | K11: 1 | L11: 2 | N11: 1092 | O11: =ROUND(N11*$M$73,2) -> 7639.53
A12: 4 | B12: PGU-DE-0139-FFC-ROT-004 | C12: MOTOR | E12: 1 | F12: EA / ШТ. | G12: 10268.83 | H12: =E12*G12 -> 10268.83 | I12: Korea | K12: 1 | L12: 2 | N12: 1092 | O12: =ROUND(N12*$M$73,2) -> 7639.53
A13: 5 | B13: PGU-DE-0139-FFC-ROT-005 | C13: MOTOR | E13: 1 | F13: EA / ШТ. | G13: 10268.83 | H13: =E13*G13 -> 10268.83 | I13: Korea | K13: 1 | L13: 2 | N13: 1092 | O13: =ROUND(N13*$M$73,2) -> 7639.53
A14: 6 | B14: PGU-DE-0139-FFC-ROT-006 | C14: MOTOR | E14: 1 | F14: EA / ШТ. | G14: 10268.83 | H14: =E14*G14 -> 10268.83 | I14: Korea | K14: 1 | L14: 2 | N14: 1092 | O14: =ROUND(N14*$M$73,2) -> 7639.53
A15: 7 | B15: PGU-DE-0139-FFC-ROT-007 | C15: MOTOR | E15: 1 | F15: EA / ШТ. | G15: 10268.83 | H15: =E15*G15 -> 10268.83 | I15: Korea | K15: 2 | L15: 2 | N15: 1092 | O15: =ROUND(N15*$M$73,2) -> 7639.53
A16: 8 | B16: PGU-DE-0139-FFC-ROT-008 | C16: MOTOR | E16: 1 | F16: EA / ШТ. | G16: 10268.83 | H16: =E16*G16 -> 10268.83 | I16: Korea | K16: 2 | L16: 2 | N16: 1092 | O16: =ROUND(N16*$M$73,2) -> 7639.53
A17: 9 | B17: PGU-DE-0139-FFC-ROT-009 | C17: MOTOR | E17: 1 | F17: EA / ШТ. | G17: 10268.83 | H17: =E17*G17 -> 10268.83 | I17: Korea | K17: 2 | L17: 2 | N17: 1092 | O17: =ROUND(N17*$M$73,2) -> 7639.53
A18: 10 | B18: PGU-DE-0139-FFC-ROT-010 | C18: MOTOR | E18: 1 | F18: EA / ШТ. | G18: 10268.83 | H18: =E18*G18 -> 10268.83 | I18: Korea | K18: 2 | L18: 2 | N18: 1092 | O18: =ROUND(N18*$M$73,2) -> 7639.53
A19: 11 | B19: PGU-DE-0139-FFC-ROT-011 | C19: MOTOR | E19: 1 | F19: EA / ШТ. | G19: 10268.83 | H19: =E19*G19 -> 10268.83 | I19: Korea | K19: 2 | L19: 2 | N19: 1092 | O19: =ROUND(N19*$M$73,2) -> 7639.53
A20: 12 | B20: PGU-DE-0139-FFC-ROT-012 | C20: MOTOR | E20: 1 | F20: EA / ШТ. | G20: 10268.83 | H20: =E20*G20 -> 10268.83 | I20: Korea | K20: 2 | L20: 2 | N20: 1092 | O20: =ROUND(N20*$M$73,2) -> 7639.53
... A27: 19 | B27: PGU-DE-0139-FFC-ROT-019 | C27: RIGHT GEAR | E27: 1 | F27: EA / ШТ. | G27: 11848.65 | H27: =E27*G27 -> 11848.65 | I27: Korea | K27: 2 | L27: 2 | N27: 1260 | O27: =ROUND(N27*$M$73,2) -> 8814.85
A28: 20 | B28: PGU-DE-0139-FFC-ROT-020 | C28: PUMP | E28: 1 | F28: EA / ШТ. | G28: 7658.79 | H28: =E28*G28 -> 7658.79 | I28: Korea | K28: 1 | L28: 1 | N28: 1200 | O28: =ROUND(N28*$M$72,2) -> 9528.17
A29: 21 | B29: PGU-DE-0139-FFC-ROT-021 | C29: PUMP | E29: 1 | F29: EA / ШТ. | G29: 7658.79 | H29: =E29*G29 -> 7658.79 | I29: Korea | K29: 2 | L29: 1 | N29: 1200 | O29: =ROUND(N29*$M$72,2) -> 9528.17
A30: 22 | B30: PGU-DE-0139-FFC-ROT-022 | C30: TANK | E30: 1 | F30: EA / ШТ. | G30: 12892.3 | H30: =E30*G30 -> 12892.3 | I30: Korea | K30: 1 | L30: 1 | N30: 2020 | O30: =ROUND(N30*$M$72,2) -> 16039.08
A31: 23 | B31: PGU-DE-0139-FFC-ROT-023 | C31: TANK | E31: 1 | F31: EA / ШТ. | G31: 38676.9 | H31: =E31*G31 -> 38676.9 | I31: Korea | K31: 2 | L31: 1 | N31: 6060 | O31: =ROUND(N31*$M$72,2) -> 48117.25
A32: 24 | B32: PGU-DE-0139-FFC-ROT-024 | C32: VALVE | E32: 1 | F32: EA / ШТ. | G32: 3829.4 | H32: =E32*G32 -> 3829.4 | I32: Korea | K32: 1 | L32: 1 | N32: 600 | O32: =ROUND(N32*$M$72,2) -> 4764.08
A33: 25 | B33: PGU-DE-0139-FFC-ROT-025 | C33: VALVE | E33: 1 | F33: EA / ШТ. | G33: 3829.4 | H33: =E33*G33 -> 3829.4 | I33: Korea | K33: 1 | L33: 1 | N33: 600 | O33: =ROUND(N33*$M$72,2) -> 4764.08
A34: 26 | B34: PGU-DE-0139-FFC-ROT-026 | C34: VALVE | E34: 1 | F34: EA / ШТ. | G34: 3829.4 | H34: =E34*G34 -> 3829.4 | I34: Korea | K34: 1 | L34: 1 | N34: 600 | O34: =ROUND(N34*$M$72,2) -> 4764.08
A35: 27 | B35: PGU-DE-0139-FFC-ROT-027 | C35: VALVE | E35: 1 | F35: EA / ШТ. | G35: 3829.4 | H35: =E35*G35 -> 3829.4 | I35: Korea | K35: 1 | L35: 1 | N35: 600 | O35: =ROUND(N35*$M$72,2) -> 4764.08
A36: 28 | B36: PGU-DE-0139-FFC-ROT-028 | C36: VALVE | E36: 1 | F36: EA / ШТ. | G36: 3829.4 | H36: =E36*G36 -> 3829.4 | I36: Korea | K36: 2 | L36: 1 | N36: 600 | O36: =ROUND(N36*$M$72,2) -> 4764.08
A37: 29 | B37: PGU-DE-0139-FFC-ROT-029 | C37: VALVE | E37: 1 | F37: EA / ШТ. | G37: 3829.4 | H37: =E37*G37 -> 3829.4 | I37: Korea | K37: 2 | L37: 1 | N37: 600 | O37: =ROUND(N37*$M$72,2) -> 4764.08
A38: 30 | B38: PGU-DE-0139-FFC-ROT-030 | C38: VALVE | E38: 1 | F38: EA / ШТ. | G38: 3829.4 | H38: =E38*G38 -> 3829.4 | I38: Korea | K38: 2 | L38: 1 | N38: 600 | O38: =ROUND(N38*$M$72,2) -> 4764.08
A39: 31 | B39: PGU-DE-0139-FFC-ROT-031 | C39: VALVE | E39: 1 | F39: EA / ШТ. | G39: 3829.4 | H39: =E39*G39 -> 3829.4 | I39: Korea | K39: 2 | L39: 1 | N39: 600 | O39: =ROUND(N39*$M$72,2) -> 4764.08
... A41: 33 | B41: PGU-DE-0139-FFC-ROT-033 | C41: AIR COMPRESSOR | E41: 1 | F41: EA / ШТ. | G41: 510.59 | H41: =E41*G41 -> 510.59 | I41: Korea | K41: 2 | L41: 1 | N41: 80 | O41: =ROUND(N41*$M$72,2) -> 635.21
A42: 34 | B42: PGU-DE-0139-FFC-ROT-034 | C42: SPECIAL TOOL | E42: 1 | F42: EA / ШТ. | G42: 564.22 | H42: =E42*G42 -> 564.22 | I42: Korea | K42: 2 | L42: 2 | N42: 60 | O42: =ROUND(N42*$M$73,2) -> 419.75
A43: 35 | B43: PGU-DE-0139-FFC-ROT-035 | C43: INSULATION | E43: 1 | F43: EA / ШТ. | G43: 1659.4 | H43: =E43*G43 -> 1659.4 | I43: Korea | K43: 1 | L43: 1 | N43: 260 | O43: =ROUND(N43*$M$72,2) -> 2064.44
A44: 36 | B44: PGU-DE-0139-FFC-ROT-036 | C44: INSULATION | E44: 1 | F44: EA / ШТ. | G44: 1659.4 | H44: =E44*G44 -> 1659.4 | I44: Korea | K44: 1 | L44: 1 | N44: 260 | O44: =ROUND(N44*$M$72,2) -> 2064.44
A45: 37 | B45: PGU-DE-0139-FFC-ROT-037 | C45: INSULATION | E45: 1 | F45: EA / ШТ. | G45: 1659.4 | H45: =E45*G45 -> 1659.4 | I45: Korea | K45: 1 | L45: 1 | N45: 260 | O45: =ROUND(N45*$M$72,2) -> 2064.44
A46: 38 | B46: PGU-DE-0139-FFC-ROT-038 | C46: INSULATION | E46: 1 | F46: EA / ШТ. | G46: 1659.4 | H46: =E46*G46 -> 1659.4 | I46: Korea | K46: 2 | L46: 1 | N46: 260 | O46: =ROUND(N46*$M$72,2) -> 2064.44
A47: 39 | B47: PGU-DE-0139-FFC-ROT-039 | C47: INSULATION | E47: 1 | F47: EA / ШТ. | G47: =29213.38-5033.77 -> 24179.61 | H47: =E47*G47 -> 24179.61 | I47: Korea | K47: 2 | L47: 2 | N47: 913 | O47: =ROUND(N47*$M$72,2) -> 7249.35
...

Sheet PL
W1: HEAD OFFICE & CHANGWON PLANT
W2: 22, DoosanVolvo-ro, Seongsan-gu, Changwon-Si,
W3: Gyeongsangnam-do, Korea
W4: (P.O.BOX 77, Changwon, Korea)
W5: TEL:(055)278-6114,7114 FAX:(055)264-5551/2
A6: PACKING LIST УПАКОВОЧНЫЙ ЛИСТ
A8: 1. Shipper / Грузоотправитель | R8: 11. Invoice № : | V8: PGU-DE-0139-001
B9: Doosan Enerbility Co., Ltd (DOOSAN) | R9: Инвойс №
B10: 22, DoosanVolvo-ro, Seongsan-gu, Changwon-si, Gyeongsangnam-do, | R10: 12. Date : | V10: 45566
B11: Republic of Korea | R11: Дата
A12: 2. Consignee / Грузополучатель | R12: 13. Remarks / Примечания
B13: Branch of JSC "Doosan Enerbility" in the Turkestan region
B14: 321 Tauke Khan Avenue, Turkestan region, Turkestan, Kazakhstan, 161200 | S14: *Project Name / Название Проекта
B15: BIN: 230741006561 | S15: Construction of a 1000 MW CCGT Power Plant in the Sairam District of
S16: Turkistan Region, Main Site. Without External Engineering Networks
S17: *MANUFACTURER'S NAME / НАЗВАНИЕ ПРОИЗВОДИТЕЛЯ
A18: 3. Notify party / Уведомляемая сторона | S18: DTS
B19: Wise Logistics | S19: *MANUFACTURE YEAR / ГОД ИЗГОТОВЛЕНИЯ
B20: ATTAN: MS. Aliya | S20: 2024
B21: (E): a.kipshakbayeva@wiselogistics.kz | S21: *COUNTRY OF ORIGIN / СТРАНА ПРОИСХОЖДЕНИЯ
B22: (T): +7 701 512 19 69 | S22: =B11 -> Republic of Korea
S23: *INCOTERMS / УСЛОВИЯ ПОСТАВКИ СОГЛАСНО ИНКОТЕРМС
S24: DDP Turkistan
A27: 4. Port of Loading / Порт погрузки | I27: 5. Carrier / Перевозчик | R27: 14. Mark and Numbers of PKGS / Маркировка и количество упаковок
B28: Later | J28: Later
S29: PKG No. | X29: : | Y29: PGU-DE-0139-FFC-ROT-001~058
A30: 6. Port of Unloading / Порт разгрузки | I30: 7. Final Destination / Конечный пункт назначения | S30: Q-ty of Package | X30: : | Y30: =COUNT('Summary PL'!A14:A71) -> 58 | AC30: PKGS
S31: Net Weight (kg) | X31: : | Y31: ='Summary PL'!L72 -> 102698.03 | AC31: KG
B32: Later | J32: Turkistan | S32: Gross Weight (kg) | X32: : | Y32: ='Summary PL'!M72 -> 110478.03 | AC32: KG
S33: Dimension (m3) | X33: : | Y33: ='Summary PL'!K72 -> 515.991 | AC33: m3
A34: 8. Voyage No / Рейс № | I34: 9. Sailing on or about / Дата или ожидаемая дата
B35: Later
J36: Later
A38: 10. Customs Place / Место таможенного оформления
B39: =B14 -> 321 Tauke Khan Avenue, Turkestan region, Turkestan, Kazakhstan, 161200
A41: 15. Description of Goods / Описание товара | R41: 16. Q-ty | U41: 17. Net Weight | Y41: 18. Gross Weight | AC41: 19. Measurement
R42: (EA) | U42: (kg) | Y42: (kg) | AC42: (CBM)
B43: =CI!B42 -> Fin Fan Cooler_Rotating Parts | R43: 2 | U43: ='Summary PL'!L72 -> 102698.03 | Y43: ='Summary PL'!M72 -> 110478.03 | AC43: ='Summary PL'!K72 -> 515.991
U46: =SUM(U43:X44) -> 102698.03 | Y46: =SUM(Y43:AB44) -> 110478.03 | AC46: =SUM(AC43:AC44) -> 515.991
S54: Signed by
...

Sheet Summary PL
O1: HEAD OFFICE & CHANGWON PLANT | R1: Storage Classification "A" : | S1: Indoor with Air-conditioning
O2: 22, DoosanVolvo-ro, Seongsan-gu, Changwon-Si, | Q2: Note> | R2: Storage Classification "B" : | S2: Indoor without Air-conditioning
O3: Gyeongsangnam-do, Korea | R3: Storage Classification "C" : | S3: Outdoor with Waterproofing
O4: (P.O.BOX 77, Changwon, Korea) | R4: Storage Classification "D" : | S4: Outdoor without Waterproofing
O5: TEL:(055)278-6114,7114 FAX:(055)264-5551/2
A6: SUMMARY PACKING LIST CВОДНЫЙ УПАКОВОЧНЫЙ ЛИСТ
A7: Project Name: | B7: Construction of a 1000 MW CCGT Power Plant in the Sairam District of the Turkistan Region
B8: Main Site. Without External Engineering Networks
A9: Invoice №: | B9: =PL!V8 -> PGU-DE-0139-001 | H9: 6
A10: Name of Consignee: | B10: =PL!B13 -> Branch of JSC "Doosan Enerbility" in the Turkestan region
A11: Consignee address: | B11: Republic of Kazakhstan, Turkestan Oblast, Sairam district, Karamurt rural district, quarter 171
A12: № | B12: CNTR No. / Seal No. / № контейнера / № пломбы | C12: Package No. / № упаковки | D12: Description / Описание | E12: Packing Style / Вид упаковки | F12: Quantity / Количество | H12: Shipping Dimension / Отгрузочные параметры | L12: Net Weight (kg) / Вес нетто (кг) | M12: Gross Weight (kg) / Вес брутто (кг) | N12: Hazardous Material (UN Number) | O12: Storage Class / Класс хранения | P12: Stackable / Штабелируемый
F13: Q'ty / Количество | G13: Unit / Ед.изм. | H13: L (cm) / Д (см) | I13: W (cm) / Ш (см) | J13: H (cm) / В (см) | K13: CBM (m3) / Объем (м3)
A14: 1 | C14: PGU-DE-0139-FFC-ROT-001 | D14: MOTOR | E14: WOODEN BOX | F14: 1 | G14: EA / ШТ. | H14: 200 | I14: 138 | J14: 120 | K14: 3.312 | L14: 1092 | M14: 1232 | O14: B | P14: N | R14: 진공
A15: 2 | C15: PGU-DE-0139-FFC-ROT-002 | D15: MOTOR | E15: WOODEN BOX | F15: 1 | G15: EA / ШТ. | H15: 200 | I15: 138 | J15: 120 | K15: 3.312 | L15: 1092 | M15: 1232 | O15: B | P15: N | R15: 진공
A16: 3 | C16: PGU-DE-0139-FFC-ROT-003 | D16: MOTOR | E16: WOODEN BOX | F16: 1 | G16: EA / ШТ. | H16: 200 | I16: 138 | J16: 120 | K16: 3.312 | L16: 1092 | M16: 1232 | O16: B | P16: N | R16: 진공
A17: 4 | C17: PGU-DE-0139-FFC-ROT-004 | D17: MOTOR | E17: WOODEN BOX | F17: 1 | G17: EA / ШТ. | H17: 200 | I17: 138 | J17: 120 | K17: 3.312 | L17: 1092 | M17: 1232 | O17: B | P17: N | R17: 진공
A18: 5 | C18: PGU-DE-0139-FFC-ROT-005 | D18: MOTOR | E18: WOODEN BOX | F18: 1 | G18: EA / ШТ. | H18: 200 | I18: 138 | J18: 120 | K18: 3.312 | L18: 1092 | M18: 1232 | O18: B | P18: N | R18: 진공
A19: 6 | C19: PGU-DE-0139-FFC-ROT-006 | D19: MOTOR | E19: WOODEN BOX | F19: 1 | G19: EA / ШТ. | H19: 200 | I19: 138 | J19: 120 | K19: 3.312 | L19: 1092 | M19: 1232 | O19: B | P19: N | R19: 진공
A20: 7 | C20: PGU-DE-0139-FFC-ROT-007 | D20: MOTOR | E20: WOODEN BOX | F20: 1 | G20: EA / ШТ. | H20: 200 | I20: 138 | J20: 120 | K20: 3.312 | L20: 1092 | M20: 1232 | O20: B | P20: N | R20: 진공
A21: 8 | C21: PGU-DE-0139-FFC-ROT-008 | D21: MOTOR | E21: WOODEN BOX | F21: 1 | G21: EA / ШТ. | H21: 200 | I21: 138 | J21: 120 | K21: 3.312 | L21: 1092 | M21: 1232 | O21: B | P21: N | R21: 진공
A22: 9 | C22: PGU-DE-0139-FFC-ROT-009 | D22: MOTOR | E22: WOODEN BOX | F22: 1 | G22: EA / ШТ. | H22: 200 | I22: 138 | J22: 120 | K22: 3.312 | L22: 1092 | M22: 1232 | O22: B | P22: N | R22: 진공
A23: 10 | C23: PGU-DE-0139-FFC-ROT-010 | D23: MOTOR | E23: WOODEN BOX | F23: 1 | G23: EA / ШТ. | H23: 200 | I23: 138 | J23: 120 | K23: 3.312 | L23: 1092 | M23: 1232 | O23: B | P23: N | R23: 진공
A24: 11 | C24: PGU-DE-0139-FFC-ROT-011 | D24: MOTOR | E24: WOODEN BOX | F24: 1 | G24: EA / ШТ. | H24: 200 | I24: 138 | J24: 120 | K24: 3.312 | L24: 1092 | M24: 1232 | O24: B | P24: N | R24: 진공
A25: 12 | C25: PGU-DE-0139-FFC-ROT-012 | D25: MOTOR | E25: WOODEN BOX | F25: 1 | G25: EA / ШТ. | H25: 200 | I25: 138 | J25: 120 | K25: 3.312 | L25: 1092 | M25: 1232 | O25: B | P25: N | R25: 진공
A26: 13 | C26: PGU-DE-0139-FFC-ROT-013 | D26: FAN | E26: WOODEN BOX | F26: 1 | G26: EA / ШТ. | H26: 280 | I26: 230 | J26: 210 | K26: 13.524 | L26: 1200 | M26: 1340 | O26: B | P26: N
A27: 14 | C27: PGU-DE-0139-FFC-ROT-014 | D27: FAN | E27: WOODEN BOX | F27: 1 | G27: EA / ШТ. | H27: 280 | I27: 230 | J27: 210 | K27: 13.524 | L27: 1200 | M27: 1340 | O27: B | P27: N
A28: 15 | C28: PGU-DE-0139-FFC-ROT-015 | D28: FAN | E28: WOODEN BOX | F28: 1 | G28: EA / ШТ. | H28: 280 | I28: 230 | J28: 255 | K28: 16.422 | L28: 1792 | M28: 1932 | O28: B | P28: N
A29: 16 | C29: PGU-DE-0139-FFC-ROT-016 | D29: RIGHT GEAR | E29: WOODEN BOX | F29: 1 | G29: EA / ШТ. | H29: 244 | I29: 165 | J29: 150 | K29: 6.039 | L29: 1260 | M29: 1360 | O29: B | P29: N
A30: 17 | C30: PGU-DE-0139-FFC-ROT-017 | D30: RIGHT GEAR | E30: WOODEN BOX | F30: 1 | G30: EA / ШТ. | H30: 244 | I30: 165 | J30: 150 | K30: 6.039 | L30: 1260 | M30: 1360 | O30: B | P30: N
A31: 18 | C31: PGU-DE-0139-FFC-ROT-018 | D31: RIGHT GEAR | E31: WOODEN BOX | F31: 1 | G31: EA / ШТ. | H31: 244 | I31: 165 | J31: 150 | K31: 6.039 | L31: 1260 | M31: 1360 | O31: B | P31: N
A32: 19 | C32: PGU-DE-0139-FFC-ROT-019 | D32: RIGHT GEAR | E32: WOODEN BOX | F32: 1 | G32: EA / ШТ. | H32: 250 | I32: 185 | J32: 150 | K32: 6.938 | L32: 1260 | M32: 1360 | O32: B | P32: N
A33: 20 | C33: PGU-DE-0139-FFC-ROT-020 | D33: PUMP | E33: WOODEN BOX | F33: 1 | G33: EA / ШТ. | H33: 250 | I33: 185 | J33: 110 | K33: 5.088 | L33: 1200 | M33: 1300 | O33: B | P33: N
A34: 21 | C34: PGU-DE-0139-FFC-ROT-021 | D34: PUMP | E34: WOODEN BOX | F34: 1 | G34: EA / ШТ. | H34: 250 | I34: 185 | J34: 110 | K34: 5.088 | L34: 1200 | M34: 1300 | O34: B | P34: N
A35: 22 | C35: PGU-DE-0139-FFC-ROT-022 | D35: TANK | E35: WOODEN PALLET | F35: 1 | G35: EA / ШТ. | H35: 370 | I35: 190 | J35: 210 | K35: 14.763 | L35: 2020 | M35: 2160 | O35: D | P35: N
A36: 23 | C36: PGU-DE-0139-FFC-ROT-023 | D36: TANK | E36: WOODEN PALLET | F36: 1 | G36: EA / ШТ. | H36: 370 | I36: 190 | J36: 210 | K36: 14.763 | L36: 6060 | M36: 6200 | O36: D | P36: N
A37: 24 | C37: PGU-DE-0139-FFC-ROT-024 | D37: VALVE | E37: WOODEN BOX | F37: 1 | G37: EA / ШТ. | H37: 136 | I37: 106 | J37: 101 | K37: 1.456 | L37: 600 | M37: 740 | O37: B | P37: N
... A71: 58 | C71: PGU-DE-0139-FFC-ROT-058 | D71: PIPE SUPPORT | E71: WOODEN BOX | F71: 1 | G71: EA / ШТ. | H71: 210 | I71: 160 | J71: 180 | K71: 6.048 | L71: 319.1991 | M71: 439.1991 | O71: B | P71: N
A72: TOTAL / ИТОГО | K72: =SUM(K14:K71) -> 515.991 | L72: =SUM(L14:L71) -> 102698.03 | M72: =SUM(M14:M71) -> 110478.03

Sheet 1&2항차
P1: HEAD OFFICE & CHANGWON PLANT
P2: 22, DoosanVolvo-ro, Seongsan-gu, Changwon-Si, | R2: Note> | S2: Storage Classification "A" :
P3: Gyeongsangnam-do, Korea | S3: Storage Classification "B" :
P4: (P.O.BOX 77, Changwon, Korea) | S4: Storage Classification "C" :
P5: TEL:(055)278-6114,7114 FAX:(055)264-5551/2 | S5: Storage Classification "D" :
A6: DETAILED PACKING LIST ПОДРОБНЫЙ УПАКОВОЧНЫЙ ЛИСТ
A7: Project Name: | B7: Construction of a 1000 MW CCGT Power Plant in the Sairam District of the Turkistan Region
B8: Main Site. Without External Engineering Networks
A9: Invoice №: | B9: =PL!V8 -> PGU-DE-0139-001
A10: Name of Consignee: | B10: =PL!B13 -> Branch of JSC "Doosan Enerbility" in the Turkestan region
A11: Consignee address: | B11: ='Summary PL'!B11 -> Republic of Kazakhstan, Turkestan Oblast, Sairam district, Karamurt rural district, quarter 171
A12: № | B12: Package No./ Номер упаковки | C12: Description / Описание | D12: HS Code / Код ТН ВЭД | E12: Quantity / Количество | G12: Shipping Dimension / Отгрузочные параметры | K12: Net Weight (kg) / Вес нетто (кг) | L12: Gross Weight (kg) / Вес брутто (кг) | M12: Drawing No. / № чертежа | N12: Tag No. / № Тег | O12: Unit Price (US$) / Цена заединицу | P12: Total Price (US$) / Общая цена | Q12: Remark / Примечания
E13: Q'ty / Кол-во | F13: Unit / Ед. изм. | G13: L (cm) / Д (см) | H13: W (cm) / Ш (см) | I13: H (cm) / В (см) | J13: CBM (m3) / Объем (м3)
A14: 1 | B14: PGU-DE-044-FFC-001 | C14: CHAMBER(DECK PLATE) 1DP1/PL4.5*817*3605 | D14: 7318.15.2000 | E14: 48 | F14: EA / ШТ. | K14: 1139.9 | M14: CCP-W-B182-09-ME-B27-0001 | N14: 1DP1 | Q14: CHAMBER BLOCK #1
A15: 2 | B15: PGU-DE-044-FFC-001 | C15: CHAMBER(SIDE PANEL) 1SP1/PL3*877*3482 | D15: 7318.15.2000 | E15: 24 | F15: EA / ШТ. | K15: =2287.3/2 -> 1143.65 | M15: CCP-W-B182-09-ME-B27-0001 | N15: 1SP1 | Q15: CHAMBER BLOCK #1
A16: 3 | B16: PGU-DE-044-FFC-001 | C16: CHAMBER(SIDE PANEL) 1SP3/PL3*1170*3090 | D16: 7318.15.2000 | E16: 24 | F16: EA / ШТ. | K16: =2767.9/2 -> 1383.95 | M16: CCP-W-B182-09-ME-B27-0001 | N16: 1SP3 | Q16: CHAMBER BLOCK #1
A17: 4 | B17: PGU-DE-044-FFC-001 | C17: CHAMBER(SIDE PANEL) 1SP7/PL3*1057*2272 | D17: 7318.15.2000 | E17: 24 | F17: EA / ШТ. | K17: =1542.9/2 -> 771.45 | M17: CCP-W-B182-09-ME-B27-0001 | N17: 1SP7 | Q17: CHAMBER BLOCK #1 | Y17: =Y14 -> 0 | Z17: =Z14 -> 0 | AA17: =AA14 -> 0 | AB17: =AB14 -> 0 | AC17: =AC14 -> 0 | AD17: =AD14 -> 0
A18: 5 | B18: PGU-DE-044-FFC-001 | C18: CHAMBER(SIDE PANEL) 1SP6/PL3*971*2511 | D18: 7318.15.2000 | E18: 24 | F18: EA / ШТ. | K18: =1570.4/2 -> 785.2 | M18: CCP-W-B182-09-ME-B27-0001 | N18: 1SP6 | Q18: CHAMBER BLOCK #1
A19: 6 | B19: PGU-DE-044-FFC-001 | C19: CHAMBER(STIFFINER PLATE) 1ST1/PL4.5*210*520 | D19: 7318.15.2000 | E19: 24 | F19: EA / ШТ. | K19: =185.2/2 -> 92.6 | M19: CCP-W-B182-09-ME-B27-0001 | N19: 1ST1 | Q19: CHAMBER BLOCK #1
A20: 7 | B20: PGU-DE-044-FFC-001 | C20: CHAMBER(STIFFINER PLATE) 1ST2/PL4.5*210*850 | D20: 7318.15.2000 | E20: 24 | F20: EA / ШТ. | K20: =302.7/2 -> 151.35 | M20: CCP-W-B182-09-ME-B27-0001 | N20: 1ST2 | Q20: CHAMBER BLOCK #1 | Y20: 85 | Z20: 60 | AA20: 120 | AB20: =ROUND(AA20*Z20*Y20/1000000,3) -> 0.612 | AC20: =SUM(AC15:AC16) -> 0 | AD20: =SUM(AD15:AD16) -> 0
A21: 8 | B21: PGU-DE-044-FFC-001 | C21: LIGHTING SUPPORT 1LS1/PL6*150*440 | D21: 7318.15.2000 | E21: 9 | F21: EA / ШТ. | K21: =56/2 -> 28 | M21: CCP-W-B182-09-ME-B27-0001 | N21: 1LS1 | Q21: LIGHTINGSUPPORT
A22: 9 | B22: PGU-DE-044-FFC-001 | C22: COUPLING COVER 1CP1/PL3*400*1106 | D22: 7318.15.2000 | E22: 6 | F22: EA / ШТ. | K22: =124.6/2 -> 62.3 | M22: CCP-W-B182-09-ME-B27-0001 | N22: 1CP1 | Q22: COUPLING COVER
A23: #1 | B23: =RIGHT(B22, 1)*1 -> 1 | C23: CHAMBER(SIDE PANEL,DECK PLATE etc..) | E23: =SUM(E14:E22) -> 207 | G23: 386 | H23: 226 | I23: 141 | J23: =ROUND(I23*H23*G23/1000000,3) -> 12.3 | K23: =SUM(K14:K22) -> 5558.4 | L23: =K23+140 -> 5698.4
A24: 1 | B24: PGU-DE-044-FFC-002 | C24: CHAMBER(SIDE PANEL) 1SP2/PL3*877*3482 | D24: 7318.15.2000 | E24: 24 | F24: EA / ШТ. | K24: =2287.3/2 -> 1143.65 | M24: CCP-W-B182-09-ME-B27-0001 | N24: 1SP2 | Q24: CHAMBER BLOCK #1
A25: 2 | B25: PGU-DE-044-FFC-002 | C25: CHAMBER(SIDE PANEL) 1SP4/PL3*1170*3090 | D25: 7318.15.2000 | E25: 24 | F25: EA / ШТ. | K25: =2767.9/2 -> 1383.95 | M25: CCP-W-B182-09-ME-B27-0001 | N25: 1SP4 | Q25: CHAMBER BLOCK #1
A26: 3 | B26: PGU-DE-044-FFC-002 | C26: CHAMBER(SIDE PANEL) 1SP5/PL3*1057*2272 | D26: 7318.15.2000 | E26: 24 | F26: EA / ШТ. | K26: =1542.9/2 -> 771.45 | M26: CCP-W-B182-09-ME-B27-0001 | N26: 1SP5 | Q26: CHAMBER BLOCK #1 | Y26: =Y20 -> 85 | Z26: =Z20 -> 60 | AA26: =AA20 -> 120 | AB26: =AB20 -> 0.612 | AC26: =AC20 -> 0 | AD26: =AD20 -> 0
A27: 4 | B27: PGU-DE-044-FFC-002 | C27: CHAMBER(SIDE PANEL) 1SP8/PL3*971*2511 | D27: 7318.15.2000 | E27: 24 | F27: EA / ШТ. | K27: =1570.4/2 -> 785.2 | M27: CCP-W-B182-09-ME-B27-0001 | N27: 1SP8 | Q27: CHAMBER BLOCK #1
A28: 5 | B28: PGU-DE-044-FFC-002 | C28: CHAMBER(STIFFINER PLATE) 1ST1/PL4.5*210*520 | D28: 7318.15.2000 | E28: 24 | F28: EA / ШТ. | K28: =185.2/2 -> 92.6 | M28: CCP-W-B182-09-ME-B27-0001 | N28: 1ST1 | Q28: CHAMBER BLOCK #1
A29: 6 | B29: PGU-DE-044-FFC-002 | C29: CHAMBER(STIFFINER PLATE) 1ST2/PL4.5*210*850 | D29: 7318.15.2000 | E29: 24 | F29: EA / ШТ. | K29: =302.7/2 -> 151.35 | M29: CCP-W-B182-09-ME-B27-0001 | N29: 1ST2 | Q29: CHAMBER BLOCK #1 | Y29: 85 | Z29: 60 | AA29: 120 | AB29: =ROUND(AA29*Z29*Y29/1000000,3) -> 0.612 | AC29: =SUM(AC24:AC25) -> 0 | AD29: =SUM(AD24:AD25) -> 0
A30: 7 | B30: PGU-DE-044-FFC-002 | C30: LIGHTING SUPPORT 1LS1/PL6*150*440 | D30: 7318.15.2000 | E30: 9 | F30: EA / ШТ. | K30: =56/2 -> 28 | M30: CCP-W-B182-09-ME-B27-0001 | N30: 1LS1 | Q30: LIGHTINGSUPPORT
A31: 8 | B31: PGU-DE-044-FFC-002 | C31: COUPLING COVER 1CP1/PL3*400*1106 | D31: 7318.15.2000 | E31: 6 | F31: EA / ШТ. | K31: =124.6/2 -> 62.3 | M31: CCP-W-B182-09-ME-B27-0001 | N31: 1CP1 | Q31: COUPLING COVER
A32: #2 | B32: =RIGHT(B31, 1)*1 -> 2 | C32: CHAMBER(SIDE PANEL,COUPLING COVER) | E32: =SUM(E24:E31) -> 159 | G32: 386 | H32: 226 | I32: 141 | J32: =ROUND(I32*H32*G32/1000000,3) -> 12.3 | K32: =SUM(K24:K31) -> 4418.5 | L32: =K32+140 -> 4558.5
A33: 1 | B33: PGU-DE-044-FFC-003 | C33: TOP BEAM 1TB5/H194*150*6*9*6090 | D33: 7318.15.2000 | E33: 6 | F33: EA / ШТ. | K33: 1122.5 | M33: CCP-W-B182-09-ME-B27-0001 | N33: 1TB5 | Q33: TOPBEAM | R33: BLOCK #1
A34: 2 | B34: PGU-DE-044-FFC-003 | C34: TOP BEAM 1TB7/H194*150*6*9*6090 | D34: 7318.15.2000 | E34: 6 | F34: EA / ШТ. | K34: 1122.5 | M34: CCP-W-B182-09-ME-B27-0001 | N34: 1TB7 | Q34: TOPBEAM | R34: BLOCK #1
A35: 3 | B35: PGU-DE-044-FFC-003 | C35: COLUMN 1CO1/H150*150*7*10*4168 | D35: 7318.15.2000 | E35: 1 | F35: EA / ШТ. | K35: 173.2 | M35: CCP-W-B182-09-ME-B27-0001 | N35: 1CO1 | Q35: COLUMN | R35: BLOCK #1
A36: 4 | B36: PGU-DE-044-FFC-003 | C36: COLUMN 1CO3/H150*150*7*10*4168 | D36: 7318.15.2000 | E36: 2 | F36: EA / ШТ. | K36: =843/5*2 -> 337.2 | M36: CCP-W-B182-09-ME-B27-0001 | N36: 1CO3 | Q36: COLUMN
A37: 5 | B37: PGU-DE-044-FFC-003 | C37: COLUMN 1CO5/H150*150*7*10*4480 | D37: 7318.15.2000 | E37: 1 | F37: EA / ШТ. | K37: 197.5 | M37: CCP-W-B182-09-ME-B27-0001 | N37: 1CO5 | Q37: COLUMN
A38: 6 | B38: PGU-DE-044-FFC-003 | C38: COLUMN 1CO6/H150*150*7*10*4480 | D38: 7318.15.2000 | E38: 5 | F38: EA / ШТ. | K38: 899.6 | M38: CCP-W-B182-09-ME-B27-0001 | N38: 1CO6 | Q38: COLUMN
A39: 7 | B39: PGU-DE-044-FFC-003 | C39: COLUMN 1CO10/H150*150*7*10*4168 | D39: 7318.15.2000 | E39: 2 | F39: EA / ШТ. | K39: =822.1/5*2 -> 328.84 | M39: CCP-W-B182-09-ME-B27-0001 | N39: 1CO10 | Q39: COLUMN
A40: 8 | B40: PGU-DE-044-FFC-003 | C40: COLUMN 1CO12/H150*150*7*10*4168 | D40: 7318.15.2000 | E40: 1 | F40: EA / ШТ. | K40: 171.4 | M40: CCP-W-B182-09-ME-B27-0001 | N40: 1CO12 | Q40: COLUMN
...

Sheet Detail PL
P1: HEAD OFFICE & CHANGWON PLANT
P2: 22, DoosanVolvo-ro, Seongsan-gu, Changwon-Si, | R2: Note> | S2: Storage Classification "A" :
P3: Gyeongsangnam-do, Korea | S3: Storage Classification "B" :
P4: (P.O.BOX 77, Changwon, Korea) | S4: Storage Classification "C" :
P5: TEL:(055)278-6114,7114 FAX:(055)264-5551/2 | S5: Storage Classification "D" :
A6: DETAILED PACKING LIST ПОДРОБНЫЙ УПАКОВОЧНЫЙ ЛИСТ
A7: Project Name: | B7: Construction of a 1000 MW CCGT Power Plant in the Sairam District of the Turkistan Region
B8: Main Site. Without External Engineering Networks
A9: Invoice №: | B9: =PL!V8 -> PGU-DE-0139-001
A10: Name of Consignee: | B10: =PL!B13 -> Branch of JSC "Doosan Enerbility" in the Turkestan region
A11: Consignee address: | B11: Republic of Kazakhstan, Turkestan Oblast, Sairam district, Karamurt rural district, quarter 171
A12: № | B12: Package No./ Номер упаковки | C12: Description / Описание | D12: HS Code / Код ТН ВЭД | E12: Quantity / Количество | G12: Shipping Dimension / Отгрузочные параметры | K12: Net Weight (kg) / Вес нетто (кг) | L12: Gross Weight (kg) / Вес брутто (кг) | M12: Drawing No. / № чертежа | N12: Tag No. / № Тег | O12: Unit Price (US$) / Цена заединицу | P12: Total Price (US$) / Общая цена | Q12: Remark / Примечания
E13: Q'ty / Кол-во | F13: Unit / Ед. изм. | G13: L (cm) / Д (см) | H13: W (cm) / Ш (см) | I13: H (cm) / В (см) | J13: CBM (m3) / Объем (м3)
A14: 1 | B14: PGU-DE-0139-FFC-ROT-001 | C14: DOL MOTOR/45KW/380V/B1-C(M)-66001 | D14: 7318.15.2000 | E14: 1 | F14: EA / ШТ. | K14: 546 | M14: CCP-W-B182-09-ME-E26-0001 | N14: B1-C(M)-66001
A15: 2 | B15: PGU-DE-0139-FFC-ROT-001 | C15: DOL MOTOR/45KW/380V/B1-C(M)-66002 | D15: 7318.15.2000 | E15: 1 | F15: EA / ШТ. | K15: 546 | M15: CCP-W-B182-09-ME-E26-0001 | N15: B1-C(M)-66002
E16: =SUM(E14:E15) -> 2 | G16: 200 | H16: 138 | I16: 120 | J16: =ROUND(I16*H16*G16/1000000,3) -> 3.312 | K16: =SUM(K14:K15) -> 1092 | L16: =K16+140 -> 1232
A17: 1 | B17: PGU-DE-0139-FFC-ROT-002 | C17: DOL MOTOR/45KW/380V/B1-C(M)-66003 | D17: 7318.15.2000 | E17: 1 | F17: EA / ШТ. | K17: 546 | M17: CCP-W-B182-09-ME-E26-0001 | N17: B1-C(M)-66003
A18: 2 | B18: PGU-DE-0139-FFC-ROT-002 | C18: DOL MOTOR/45KW/380V/B1-C(M)-66004 | D18: 7318.15.2000 | E18: 1 | F18: EA / ШТ. | K18: 546 | M18: CCP-W-B182-09-ME-E26-0001 | N18: B1-C(M)-66004 | Y18: =Y14 -> 0 | Z18: =Z14 -> 0 | AA18: =AA14 -> 0 | AB18: =AB14 -> 0 | AC18: =AC14 -> 0 | AD18: =AD14 -> 0
E19: =SUM(E17:E18) -> 2 | G19: 200 | H19: 138 | I19: 120 | J19: =ROUND(I19*H19*G19/1000000,3) -> 3.312 | K19: =SUM(K17:K18) -> 1092 | L19: =K19+140 -> 1232
A20: 1 | B20: PGU-DE-0139-FFC-ROT-003 | C20: DOL MOTOR/45KW/380V/B1-C(M)-66005 | D20: 7318.15.2000 | E20: 1 | F20: EA / ШТ. | K20: 546 | M20: CCP-W-B182-09-ME-E26-0001 | N20: B1-C(M)-66005
A21: 2 | B21: PGU-DE-0139-FFC-ROT-003 | C21: DOL MOTOR/45KW/380V/B1-C(M)-66006 | D21: 7318.15.2000 | E21: 1 | F21: EA / ШТ. | K21: 546 | M21: CCP-W-B182-09-ME-E26-0001 | N21: B1-C(M)-66006
E22: =SUM(E20:E21) -> 2 | G22: 200 | H22: 138 | I22: 120 | J22: =ROUND(I22*H22*G22/1000000,3) -> 3.312 | K22: =SUM(K20:K21) -> 1092 | L22: =K22+140 -> 1232
A23: 1 | B23: PGU-DE-0139-FFC-ROT-004 | C23: DOL MOTOR/45KW/380V/B1-C(M)-66007 | D23: 7318.15.2000 | E23: 1 | F23: EA / ШТ. | K23: 546 | M23: CCP-W-B182-09-ME-E26-0001 | N23: B1-C(M)-66007 | Y23: 85 | Z23: 60 | AA23: 120 | AB23: =ROUND(AA23*Z23*Y23/1000000,3) -> 0.612 | AC23: =SUM(AC15:AC17) -> 0 | AD23: =SUM(AD15:AD17) -> 0
A24: 2 | B24: PGU-DE-0139-FFC-ROT-004 | C24: DOL MOTOR/45KW/380V/B1-C(M)-66008 | D24: 7318.15.2000 | E24: 1 | F24: EA / ШТ. | K24: 546 | M24: CCP-W-B182-09-ME-E26-0001 | N24: B1-C(M)-66008
E25: =SUM(E23:E24) -> 2 | G25: 200 | H25: 138 | I25: 120 | J25: =ROUND(I25*H25*G25/1000000,3) -> 3.312 | K25: =SUM(K23:K24) -> 1092 | L25: =K25+140 -> 1232
A26: 1 | B26: PGU-DE-0139-FFC-ROT-005 | C26: DOL MOTOR/45KW/380V/B1-C(M)-66009 | D26: 7318.15.2000 | E26: 1 | F26: EA / ШТ. | K26: 546 | M26: CCP-W-B182-09-ME-E26-0001 | N26: B1-C(M)-66009
A27: 2 | B27: PGU-DE-0139-FFC-ROT-005 | C27: DOL MOTOR/45KW/380V/B1-C(M)-66010 | D27: 7318.15.2000 | E27: 1 | F27: EA / ШТ. | K27: 546 | M27: CCP-W-B182-09-ME-E26-0001 | N27: B1-C(M)-66010
E28: =SUM(E26:E27) -> 2 | G28: 200 | H28: 138 | I28: 120 | J28: =ROUND(I28*H28*G28/1000000,3) -> 3.312 | K28: =SUM(K26:K27) -> 1092 | L28: =K28+140 -> 1232
A29: 1 | B29: PGU-DE-0139-FFC-ROT-006 | C29: DOL MOTOR/45KW/380V/B1-C(M)-66011 | D29: 7318.15.2000 | E29: 1 | F29: EA / ШТ. | K29: 546 | M29: CCP-W-B182-09-ME-E26-0001 | N29: B1-C(M)-66011
A30: 2 | B30: PGU-DE-0139-FFC-ROT-006 | C30: DOL MOTOR/45KW/380V/B1-C(M)-66012 | D30: 7318.15.2000 | E30: 1 | F30: EA / ШТ. | K30: 546 | M30: CCP-W-B182-09-ME-E26-0001 | N30: B1-C(M)-66012
E31: =SUM(E29:E30) -> 2 | G31: 200 | H31: 138 | I31: 120 | J31: =ROUND(I31*H31*G31/1000000,3) -> 3.312 | K31: =SUM(K29:K30) -> 1092 | L31: =K31+140 -> 1232
A32: 1 | B32: PGU-DE-0139-FFC-ROT-007 | C32: DOL MOTOR/45KW/380V/B2-C(M)-66001 | D32: 7318.15.2000 | E32: 1 | F32: EA / ШТ. | K32: 546 | M32: CCP-W-B182-09-ME-E26-0001 | N32: B2-C(M)-66001
A33: 2 | B33: PGU-DE-0139-FFC-ROT-007 | C33: DOL MOTOR/45KW/380V/B2-C(M)-66002 | D33: 7318.15.2000 | E33: 1 | F33: EA / ШТ. | K33: 546 | M33: CCP-W-B182-09-ME-E26-0001 | N33: B2-C(M)-66002
E34: =SUM(E32:E33) -> 2 | G34: 200 | H34: 138 | I34: 120 | J34: =ROUND(I34*H34*G34/1000000,3) -> 3.312 | K34: =SUM(K32:K33) -> 1092 | L34: =K34+140 -> 1232
A35: 1 | B35: PGU-DE-0139-FFC-ROT-008 | C35: DOL MOTOR/45KW/380V/B2-C(M)-66003 | D35: 7318.15.2000 | E35: 1 | F35: EA / ШТ. | K35: 546 | M35: CCP-W-B182-09-ME-E26-0001 | N35: B2-C(M)-66003
A36: 2 | B36: PGU-DE-0139-FFC-ROT-008 | C36: DOL MOTOR/45KW/380V/B2-C(M)-66004 | D36: 7318.15.2000 | E36: 1 | F36: EA / ШТ. | K36: 546 | M36: CCP-W-B182-09-ME-E26-0001 | N36: B2-C(M)-66004
E37: =SUM(E35:E36) -> 2 | G37: 200 | H37: 138 | I37: 120 | J37: =ROUND(I37*H37*G37/1000000,3) -> 3.312 | K37: =SUM(K35:K36) -> 1092 | L37: =K37+140 -> 1232
A38: 1 | B38: PGU-DE-0139-FFC-ROT-009 | C38: DOL MOTOR/45KW/380V/B2-C(M)-66005 | D38: 7318.15.2000 | E38: 1 | F38: EA / ШТ. | K38: 546 | M38: CCP-W-B182-09-ME-E26-0001 | N38: B2-C(M)-66005
A39: 2 | B39: PGU-DE-0139-FFC-ROT-009 | C39: DOL MOTOR/45KW/380V/B2-C(M)-66006 | D39: 7318.15.2000 | E39: 1 | F39: EA / ШТ. | K39: 546 | M39: CCP-W-B182-09-ME-E26-0001 | N39: B2-C(M)-66006
E40: =SUM(E38:E39) -> 2 | G40: 200 | H40: 138 | I40: 120 | J40: =ROUND(I40*H40*G40/1000000,3) -> 3.312 | K40: =SUM(K38:K39) -> 1092 | L40: =K40+140 -> 1232
...

Sheet Description
A1: Technical Description
A2: № | B2: Name | C2: Q-ty | D2: Model-Part No. | E2: Kind of material | F2: Size/specification/ Usage | G2: Photo | H2: Manufacturer / Origin | I2: HS Code
A3: 1 | B3: =VLOOKUP("#"&A3,'1&2항차'!$A$14:$Q$530,3,FALSE) -> CHAMBER(SIDE PANEL,DECK PLATE etc..) | C3: =VLOOKUP("#"&A3,'1&2항차'!$A$14:$Q$530,5,FALSE) -> 207 | E3: A36 | F3: PL3*877*3482 | H3: (유)근영하이테크/KOREA | I3: 7318.15.2000
A4: 2 | B4: =VLOOKUP("#"&A4,'1&2항차'!$A$14:$Q$530,3,FALSE) -> CHAMBER(SIDE PANEL,COUPLING COVER) | C4: =VLOOKUP("#"&A4,'1&2항차'!$A$14:$Q$530,5,FALSE) -> 159 | E4: A36 | F4: PL3*1057*2272 | H4: (유)근영하이테크/KOREA | I4: 7318.15.2000
A5: 3 | B5: =VLOOKUP("#"&A5,'1&2항차'!$A$14:$Q$530,3,FALSE) -> CHAMBER(SIDE PANEL,DECK PLATE,STIFFINER PLATE) | C5: =VLOOKUP("#"&A5,'1&2항차'!$A$14:$Q$530,5,FALSE) -> 207 | E5: S275J2 | F5: H150*150*7/10*4168 | H5: (유)만성스틸/KOREA | I5: 7318.15.2000
A6: 4 | B6: =VLOOKUP("#"&A6,'1&2항차'!$A$14:$Q$530,3,FALSE) -> CHAMBER(SIDE PANEL,COUPLING COVER) | C6: =VLOOKUP("#"&A6,'1&2항차'!$A$14:$Q$530,5,FALSE) -> 159 | E6: S275J2 | F6: H150*150*7/10*4168 | H6: (유)만성스틸/KOREA | I6: 7318.15.2000
A7: 5 | B7: =VLOOKUP("#"&A7,'1&2항차'!$A$14:$Q$530,3,FALSE) -> PLATFORM | C7: =VLOOKUP("#"&A7,'1&2항차'!$A$14:$Q$530,5,FALSE) -> 8 | E7: S275J2 | F7: H150*150*7/10*4168 | H7: (유)만성스틸/KOREA | I7: 7318.15.2000
A8: 6 | B8: =VLOOKUP("#"&A8,'1&2항차'!$A$14:$Q$530,3,FALSE) -> PLATFORM | C8: =VLOOKUP("#"&A8,'1&2항차'!$A$14:$Q$530,5,FALSE) -> 8 | E8: S275J2 | F8: H150*150*7/10*748 | H8: (유)만성스틸/KOREA | I8: 7318.15.2000
A9: 7 | B9: =VLOOKUP("#"&A9,'1&2항차'!$A$14:$Q$530,3,FALSE) -> PLATFORM | C9: =VLOOKUP("#"&A9,'1&2항차'!$A$14:$Q$530,5,FALSE) -> 8 | E9: S275J2 | F9: H150*150*7/10*615 | H9: (유)만성스틸/KOREA | I9: 7318.15.2000
A10: 8 | B10: =VLOOKUP("#"&A10,'1&2항차'!$A$14:$Q$530,3,FALSE) -> PLATFORM | C10: =VLOOKUP("#"&A10,'1&2항차'!$A$14:$Q$530,5,FALSE) -> 8 | E10: A36 | F10: Ø4*1844*4747 | H10: (유)만성스틸/KOREA | I10: 7318.15.2000
A11: 9 | B11: =VLOOKUP("#"&A11,'1&2항차'!$A$14:$Q$530,3,FALSE) -> FAN RING & FIXING PLATE | C11: =VLOOKUP("#"&A11,'1&2항차'!$A$14:$Q$530,5,FALSE) -> 96 | E11: A36 | F11: Ø4*1844*4747 | H11: (유)만성스틸/KOREA | I11: 7318.15.2000
A12: 10 | B12: =VLOOKUP("#"&A12,'1&2항차'!$A$14:$Q$530,3,FALSE) -> FAN RING & FIXING PLATE | C12: =VLOOKUP("#"&A12,'1&2항차'!$A$14:$Q$530,5,FALSE) -> 96 | E12: A36 | F12: PL3*700*3917 | H12: ㈜해성/KOREA | I12: 7318.15.2000
A13: 11 | B13: =VLOOKUP("#"&A13,'1&2항차'!$A$14:$Q$530,3,FALSE) -> FAN RING & FIXING PLATE | C13: =VLOOKUP("#"&A13,'1&2항차'!$A$14:$Q$530,5,FALSE) -> 96 | E13: A36 | F13: PL3*700*3917 | H13: ㈜해성/KOREA | I13: 7318.15.2000
A14: 12 | B14: =VLOOKUP("#"&A14,'1&2항차'!$A$14:$Q$530,3,FALSE) -> FAN RING & FIXING PLATE | C14: =VLOOKUP("#"&A14,'1&2항차'!$A$14:$Q$530,5,FALSE) -> 96 | E14: A36 | F14: PL45*1000*1850 | H14: (유)만성스틸/KOREA | I14: 7318.15.2000
... A116: 114 | B116: =VLOOKUP("#"&A116,'1&2항차'!$A$14:$Q$530,3,FALSE) -> #N/A | C116: =VLOOKUP("#"&A116,'1&2항차'!$A$14:$Q$530,5,FALSE) -> #N/A | E116: N/A | F116: N/A | H116: N/A | I116: 7318.15.2000

Sheet Shipping Mark
A1: SHIPPING MARK ГРУЗОВАЯ МАРКИРОВКА
A2: ● NAME OF THE PROJECT | F2: : | G2: Construction of a 1000 MW CCGT Power Plant in the Sairam District of the
A3: НАЗВАНИЕ ПРОЕКТА | G3: Turkistan Region, Main Site. Without External Engineering Networks
A5: ● CONSIGNEE | F5: : | G5: =PL!$B$13 -> Branch of JSC "Doosan Enerbility" in the Turkestan region
A6: ГРУЗОПОЛУЧАТЕЛЬ | G6: =PL!$B$14 -> 321 Tauke Khan Avenue, Turkestan region, Turkestan, Kazakhstan, 161200
G7: =PL!$B$15 -> BIN: 230741006561
A9: ● Shipper/Exporter | F9: : Doosan Enerbility Co., LTD
A10: Грузоотправитель/Экспортер | F10: 22, Doosan Volvo-ro, Sengsan-gu, Changwon, Gyeongnam, South Korea
A12: ● Number of Invoice | F12: : | G12: =PL!$V$8 -> PGU-DE-0139-001
A13: № инвойса
A15: ● CARGO DESCRIPTION | F15: : | G15: =VLOOKUP(G18, 'Detail PL'!$B$14:$Q$799,2) -> #N/A
A16: ОПИСАНИЕ ГРУЗА
A18: ● PACKAGE NO. | F18: : | G18: 1 | P18: <=package no.에 숫자만 입력
A19: УПАКОВОЧНЫЙ НОМЕР
A21: ● NET WEIGHT | F21: : | G21: =VLOOKUP(G18, 'Detail PL'!$B$14:$Q$799, 10) -> #N/A | H21: KG
A22: ВЕС НЕТТО
A24: ● GROSS WEIGHT | F24: : | G24: =VLOOKUP(G18, 'Detail PL'!$B$14:$Q$799, 11) -> #N/A | H24: KG
A25: ВЕС БРУТТО
A27: ● CBM(m3) | F27: : | G27: =VLOOKUP(G18, 'Detail PL'!$B$14:$Q$799, 9) -> #N/A | H27: m3
A28: РАЗМЕРЫ
A30: ● FINAL DESTINATION | F30: : | G30: 161100 Republic of Kazakhstan, Turkistan region, Sairam district, Karamurt rural district, 2 km southwest of the Madeniyet village
A31: КОНЕЧНЫЙ ПУНКТ НАЗНАЧЕНИЯ
A32: Doosan Enerbility
A36: SHIPPING MARK ГРУЗОВАЯ МАРКИРОВКА
A37: ● NAME OF THE PROJECT | F37: : | G37: Construction of a 1000 MW CCGT Power Plant in the Sairam District of the
A38: НАЗВАНИЕ ПРОЕКТА | G38: Turkistan Region, Main Site. Without External Engineering Networks
A40: ● CONSIGNEE | F40: : | G40: =PL!$B$13 -> Branch of JSC "Doosan Enerbility" in the Turkestan region
A41: ГРУЗОПОЛУЧАТЕЛЬ | G41: =PL!$B$14 -> 321 Tauke Khan Avenue, Turkestan region, Turkestan, Kazakhstan, 161200
G42: =PL!$B$15 -> BIN: 230741006561
A44: ● Shipper/Exporter | F44: : Doosan Enerbility Co., LTD
A45: Грузоотправитель/Экспортер | F45: 22, Doosan Volvo-ro, Sengsan-gu, Changwon, Gyeongnam, South Korea
A47: ● Number of Invoice | F47: : | G47: =PL!$V$8 -> PGU-DE-0139-001
A48: № инвойса
A50: ● CARGO DESCRIPTION | F50: : | G50: =VLOOKUP(G53, 'Detail PL'!$B$14:$Q$799,2) -> #N/A
A51: ОПИСАНИЕ ГРУЗА
A53: ● PACKAGE NO. | F53: : | G53: =G18+1 -> 2
A54: УПАКОВОЧНЫЙ НОМЕР
A56: ● NET WEIGHT | F56: : | G56: =VLOOKUP(G53, 'Detail PL'!$B$14:$Q$799, 10) -> #N/A | H56: KG
A57: ВЕС НЕТТО
A59: ● GROSS WEIGHT | F59: : | G59: =VLOOKUP(G53, 'Detail PL'!$B$14:$Q$799, 11) -> #N/A | H59: KG
...
