Workbook
Name _____THK1: #REF!
Name ____THK1: #REF!
Name ___THK1: #REF!
Name __THK1: #REF!
Name _LV4: #REF!
Name _Order1: 255
Name _Order2: 255
Name _Regression_Int: 1
Name _THK1: #REF!
Name \a: #N/A
Name \q: #N/A
Name \z: #N/A
Name Access_Button: "PJTFINAL_F02F11_List"
Name ALLOY: [1]TABLE!$C$5:$D$1005
Name asd: #REF!
Name B: [0]!B
Name cable: #REF!
Name cal: #REF!
Name calculation: [0]!calculation
Name CALCULATION_1: [0]!CALCULATION_1
Name CARBON: [1]TABLE!$A$5:$B$765
Name D: [0]!D
Name d_cooler_flow: #REF!
Name DATA_1: #REF!
Name DATA_10: #REF!
Name DATA_11: #REF!
Name DATA_114: #REF!
Name DATA_12: #REF!
Name DATA_13: #REF!
Name DATA_14: #REF!
Name DATA_15: #REF!
Name DATA_16: #REF!
Name DATA_17: #REF!
Name DATA_18: #REF!
Name DATA_19: #REF!
Name DATA_2: #REF!
Name DATA_20: #REF!
Name DATA_21: #REF!
Name DATA_22: #REF!
Name DATA_23: #REF!
Name DATA_24: #REF!
Name DATA_25: #REF!
Name DATA_3: #REF!
Name DATA_4: #REF!
Name DATA_5: #REF!
Name DATA_6: #REF!
Name DATA_7: #REF!
Name DATA_8: #REF!
Name DATA_9: #REF!
Name dcooler_pdrop: #REF!
Name design: #REF!
Name DFSF: [0]!DFSF
Name dgn: #REF!
Name dtnps: #REF!
Name ECL: [2]ECL!$A$1:$L$65536
Name f_a: #REF!
Name ff: #REF!
Name FIL: #REF!
Name FINC2: #REF!
Name flow: #REF!

Sheet 1. IO Database (HW) Legend
A1: 1. INPUT & OUTPUT DATABASE
A2: LEGEND (HARDWIRED)
A3: PJT Name : Turkistan CCGT Project, Date : 2023-03-30, Revision : A
A4: COLUMN NUMBER | B4: DESCRIPTION
A6: 1 | B6: NO. : This column shows a serial sequence of the measurements in the list.
B7: This number has no relation with the signal numbers.
A9: 2 | B9: TAG NO. : Instrument Identification Number as following NUMBERING METHOD for Instrument Tag and Equipment Tag.
A11: 3 | B11: SIGNAL NO. : Signal Status Number
B12: A B nn | D12: A: Signal Origin | F12: B: Signal Area | H12: nn: Serial Number (01~99)
D13: X : Input signal | F13: B : Binary Input Signal
D14: Y : Output signal | F14: G: Binary Set Value
F15: N: Binary Output Signal
F16: Q : Analog Signal
C18: SIGANAL | E18: PROCESS | F18: VALVE | I18: MOTOR (PP, FAN, etc.) | J18: ELECTRICAL | K18: HARDWIRED INTERFACE WITH DCS | L18: REMARK
C19: TYPE | D19: NO. | F19: MOV, ACTUATOR | G19: SOV | H19: CV
C20: AO | D20: YQ01 | E20: ANALOG OUTPUT INTERFACE | H20: POSITION DEMAND | I20: VARIABLE SPEED CONTROL COMMAND | J20: ELECTRICAL EQUIPMENT INTERFACE | K20: PACKAGE INTERFACE | L20: MULTIPLE AO: YQ01~99
C21: AI | D21: XQ01 | E21: ANALOG INPUT | F21: POSITION FEEDBACK | H21: POSITION FEEDBACK | I21: VARIABLE SPEED CONTROL FEEDBACK | J21: ELECTRICAL EQUIPMENT INTERFACE | K21: PACKAGE INTERFACE
D22: XQ02 | E22: ANALOG INPUT (RTD) | L22: IN CASE OF DIRECT CONNECTION BETWEEN FIELD AND DCS.
D23: XQ03 | E23: ANALOG INPUT (THERMOCOUPLE) | L23: IN CASE OF DIRECT CONNECTION BETWEEN FIELD AND DCS.
D24: XQ11 | I24: CURRENT | J24: CURRENT | K24: CURRENT | L24: MULTIPLE AI (XQ11, XQ12, XQ13, ~)
D25: XQ21 | I25: VOLTAGE | J25: VOLTAGE | K25: VOLTAGE | L25: MULTIPLE AI (XQ21, XQ22, XQ23, ~)
D26: XQ31 | J26: ACTIVE POWER (W, KW, MW)
D27: XQ32 | J27: REACTIVE POWER (VAR, MVAR)
D28: XQ41 | J28: FREQUENCY
D29: XQ42 | J29: POWER FACTOR
D30: XQ61~99 | J30: OTHER ELECTRICAL INTERFACE | K30: OTHER PACKAGE INTERFACE (IF REQUIRED)
C31: DO | D31: YN51 | F31: OPEN COMMAND | G31: SOV ENERGIZE TO OPEN COMMAND
D32: YN52 | F32: CLOSE COMMAND | G32: SOV ENERGIZE TO CLOSE COMMAND
D33: YN54 | I33: PP START COMMAND | J33: BKR CLOSE COMMAND
D34: YN55 | I34: PP STOP COMMAND | J34: BKR OPEN COMMAND
D35: YBn1 | K35: - GROUP START COMMAND - PP/FAN START COMMAND - VALVE OPEN COMMAND - VFD(INVERTER) ON COMMAND | L35: n = 0~3 (YB01, YB11, YB21, YB31)
D36: YBn2 | K36: - GROUP STOP COMMAND - PP/FAN STOP COMMAND - VALVE CLOSE COMMAND - VFD(INVERTER) OFF COMMAND | L36: n = 0~3 (YB02, YB12, YB22, YB32)
D37: YB51~60 | K37: STATUS FEEDBACK TO LCP (IF REQUIRED) | L37: EX. LCP LAMP POWER (PUMP RUNNING, STOPPED, FAULT, etc.)
D38: YB61~99 | J38: OTHER ELECTRICAL EQUIPMENT INTERFACE (IF REQUIRED) | K38: OTHER PACKAGE INTERFACE (IF REQUIRED)
C39: DI | D39: XB01 | F39: VLV OPENED FEEDBACK | G39: VLV OPENED FEEDBACK | H39: VLV OPENED FEEDBACK | I39: PP RUNNING FEEDBACK | J39: BKR CLOSED FEEDBACK
D40: XB02 | F40: VLV CLOSED FEEDBACK | G40: VLV CLOSED FEEDBACK | H40: VLV CLOSED FEEDBACK | I40: PP STOPPED FEEDBACK | J40: BKR OPENED FEEDBACK
D41: XB03 | F41: MOV INTERMEDIATE OPENED FEEDBACK
D42: XB06 | E42: PULSE INPUT | J42: PULSE INPUT
D43: XB11 | F43: MOV TOQ OPEN FEEDBACK
D44: XB12 | F44: MOV TOQ CLOSE FEEDBACK
...

Sheet FI_CS_Cable_list
A1: FI CS CABLE LIST
A2: (TCS/TPS SYSTEM)
A3: PJT Name : Turkistan CCGT Project, Date : 2024-06-04, Revision: R03
A4: Ele | B4: SYSTEM | C4: CABLE | D4: CABLE | F4: SIGNAL | G4: LENGTH | H4: FROM | K4: TO | N4: CABLE ROUTE | O4: REMARK
C5: NUMBER | D5: TYPE | E5: SPEC. | F5: TYPE | G5: (M) | H5: KKS NO. | I5: DESCRIPTION | J5: LOCATION / DWG NO | K5: KKS NO. | L5: DESCRIPTION | M5: LOCATION / DWG NO
A6: =Query!A3 -> 20000 | B6: =MID(Query!B3,1,2) -> B1 | C6: =MID(Query!B3,4,50) -> CP-13501-C4003 | D6: =Query!C3 -> 1- C5XFE-R /ST/ | E6: =Query!D3 -> 2 x 2 x 1.0 mm² | F6: 24V DC | G6: =Query!E3 -> 30 | H6: =Query!F3 -> B1-TCS-1301B-XD54 | I6: =Query!G3 -> TCS I/O and marshaling cabinet | J6: Eletric room | K6: =Query!K3 -> B1-CP-13501+ER-X100 | L6: =Query!L3 -> BOX OF GEN.EXCITATION | M6: Eletric room | O6: =Query!O3 -> DSPW/SUPP.FI
A7: =Query!A4 -> 20001 | B7: =MID(Query!B4,1,2) -> B1 | C7: =MID(Query!B4,4,50) -> CP-13501-C4004 | D7: =Query!C4 -> 1- C5XFE-R /ST/ | E7: =Query!D4 -> 2 x 2 x 1.0 mm² | F7: 24V DC | G7: =Query!E4 -> 30 | H7: =Query!F4 -> B1-TCS-1301B-XD45 | I7: =Query!G4 -> TCS I/O and marshaling cabinet | J7: Eletric room | K7: =Query!K4 -> B1-CP-13501+ER-X110 | L7: =Query!L4 -> BOX OF GEN.EXCITATION | M7: Eletric room | O7: =Query!O4 -> DSPW/SUPP.FI
A8: =Query!A5 -> 20002 | B8: =MID(Query!B5,1,2) -> B1 | C8: =MID(Query!B5,4,50) -> CP-13501-C4005 | D8: =Query!C5 -> 1- C5XFE-R /ST/ | E8: =Query!D5 -> 5 x 2 x 1.0 mm² | F8: 24V DC | G8: =Query!E5 -> 30 | H8: =Query!F5 -> B1-TCS-1301B-XD54 | I8: =Query!G5 -> TCS I/O and marshaling cabinet | J8: Eletric room | K8: =Query!K5 -> B1-CP-13501+ER-X200 | L8: =Query!L5 -> BOX OF GEN.EXCITATION | M8: Eletric room | O8: =Query!O5 -> DSPW/SUPP.FI
A9: =Query!A6 -> 20003 | B9: =MID(Query!B6,1,2) -> B1 | C9: =MID(Query!B6,4,50) -> CP-13501-C4006 | D9: =Query!C6 -> 1- C5XFE-R /ST/ | E9: =Query!D6 -> 10 x 2 x 1.0 mm² | F9: 24V DC | G9: =Query!E6 -> 30 | H9: =Query!F6 -> B1-TCS-1301B-XD45 | I9: =Query!G6 -> TCS I/O and marshaling cabinet | J9: Eletric room | K9: =Query!K6 -> B1-CP-13501+ER-X210 | L9: =Query!L6 -> BOX OF GEN.EXCITATION | M9: Eletric room | O9: =Query!O6 -> DSPW/SUPP.FI
A10: =Query!A7 -> 20004 | B10: =MID(Query!B7,1,2) -> B1 | C10: =MID(Query!B7,4,50) -> CP-13501-C4007 | D10: =Query!C7 -> 1- C5XFE-R /ST/ | E10: =Query!D7 -> 10 x 2 x 1.0 mm² | F10: 24V DC | G10: =Query!E7 -> 30 | H10: =Query!F7 -> B1-TCS-1301B-XD54 | I10: =Query!G7 -> TCS I/O and marshaling cabinet | J10: Eletric room | K10: =Query!K7 -> B1-CP-13501+ER-X300 | L10: =Query!L7 -> BOX OF GEN.EXCITATION | M10: Eletric room | O10: =Query!O7 -> DSPW/SUPP.FI
A11: =Query!A8 -> 20005 | B11: =MID(Query!B8,1,2) -> B1 | C11: =MID(Query!B8,4,50) -> CP-13501-C4008 | D11: =Query!C8 -> 1- C5XFE-R /ST/ | E11: =Query!D8 -> 10 x 2 x 1.0 mm² | F11: 24V DC | G11: =Query!E8 -> 30 | H11: =Query!F8 -> B1-TCS-1301B-XD45 | I11: =Query!G8 -> TCS I/O and marshaling cabinet | J11: Eletric room | K11: =Query!K8 -> B1-CP-13501+ER-X310 | L11: =Query!L8 -> BOX OF GEN.EXCITATION | M11: Eletric room | O11: =Query!O8 -> DSPW/SUPP.FI
A12: =Query!A9 -> 20006 | B12: =MID(Query!B9,1,2) -> B1 | C12: =MID(Query!B9,4,50) -> CP-13501-I6001 | D12: =Query!C9 -> 1- C5XFE-R /ST/ | E12: =Query!D9 -> 2 x 2 x 1.0 mm² | F12: 4-20mA | G12: =Query!E9 -> 30 | H12: =Query!F9 -> B1-TCS-1301B-XD44 | I12: =Query!G9 -> TCS I/O and marshaling cabinet | J12: Eletric room | K12: =Query!K9 -> B1-CP-13501+ER-U514 | L12: =Query!L9 -> BOX OF GEN.EXCITATION | M12: Eletric room | O12: =Query!O9 -> DSPW/SUPP.FI
A13: =Query!A10 -> 20007 | B13: =MID(Query!B10,1,2) -> B1 | C13: =MID(Query!B10,4,50) -> CP-13501-I6003 | D13: =Query!C10 -> 1- C5XFE-R /ST/ | E13: =Query!D10 -> 2 x 2 x 1.0 mm² | F13: 4-20mA | G13: =Query!E10 -> 30 | H13: =Query!F10 -> B1-TCS-1301B-XD44 | I13: =Query!G10 -> TCS I/O and marshaling cabinet | J13: Eletric room | K13: =Query!K10 -> B1-CP-13501+ER-U501 | L13: =Query!L10 -> BOX OF GEN.EXCITATION | M13: Eletric room | O13: =Query!O10 -> DSPW/SUPP.FI
A14: =Query!A11 -> 20008 | B14: =MID(Query!B11,1,2) -> B1 | C14: =MID(Query!B11,4,50) -> CP-13701-C4006 | D14: =Query!C11 -> 1- C5XFE-R /ST/ | E14: =Query!D11 -> 5 x 2 x 1.0 mm² | F14: 24V DC | G14: =Query!E11 -> 30 | H14: =Query!F11 -> B1-TCS-1301B-XD52 | I14: =Query!G11 -> TCS I/O and marshaling cabinet | J14: Eletric room | K14: =Query!K11 -> B1-CP-13701-XC4 | L14: =Query!L11 -> BOX OF GEN.AVR, SYNCHR.AND MEAS. | M14: Eletric room | O14: =Query!O11 -> DSPW/SUPP.FI
A15: =Query!A12 -> 20009 | B15: =MID(Query!B12,1,2) -> B1 | C15: =MID(Query!B12,4,50) -> CP-13701-C4008 | D15: =Query!C12 -> 1- C5XFE-R /ST/ | E15: =Query!D12 -> 5 x 2 x 1.0 mm² | F15: 24V DC | G15: =Query!E12 -> 30 | H15: =Query!F12 -> B1-TCS-1301B-XD42 | I15: =Query!G12 -> TCS I/O and marshaling cabinet | J15: Eletric room | K15: =Query!K12 -> B1-CP-13701-XS4 | L15: =Query!L12 -> BOX OF GEN.AVR, SYNCHR.AND MEAS. | M15: Eletric room | O15: =Query!O12 -> DSPW/SUPP.FI
A16: =Query!A13 -> 20010 | B16: =MID(Query!B13,1,2) -> B1 | C16: =MID(Query!B13,4,50) -> CP-13701-C4010 | D16: =Query!C13 -> 1- C5XFE-R /ST/ | E16: =Query!D13 -> 5 x 2 x 1.0 mm² | F16: 24V DC | G16: =Query!E13 -> 30 | H16: =Query!F13 -> B1-TCS-1301B-XD42 | I16: =Query!G13 -> TCS I/O and marshaling cabinet | J16: Eletric room | K16: =Query!K13 -> B1-CP-13701-XS4 | L16: =Query!L13 -> BOX OF GEN.AVR, SYNCHR.AND MEAS. | M16: Eletric room | O16: =Query!O13 -> DSPW/SUPP.FI
A17: =Query!A14 -> 20011 | B17: =MID(Query!B14,1,2) -> B1 | C17: =MID(Query!B14,4,50) -> CP-13701-C4011 | D17: =Query!C14 -> 1- C5XFE-R /ST/ | E17: =Query!D14 -> 5 x 2 x 1.0 mm² | F17: 24V DC | G17: =Query!E14 -> 30 | H17: =Query!F14 -> B1-TCS-1301B-XD42 | I17: =Query!G14 -> TCS I/O and marshaling cabinet | J17: Eletric room | K17: =Query!K14 -> B1-CP-13701-XS4 | L17: =Query!L14 -> BOX OF GEN.AVR, SYNCHR.AND MEAS. | M17: Eletric room | O17: =Query!O14 -> DSPW/SUPP.FI
... A56: =Query!A53 -> 20050 | B56: =MID(Query!B53,1,2) -> B1 | C56: =MID(Query!B53,4,50) -> PI-I-5235 | D56: =Query!C53 -> 1- C5XFE-R /ST/ | E56: =Query!D53 -> 2 x 2 x 1.0 mm² | F56: 4-20mA | G56: =Query!E53 -> 200 | H56: =Query!F53 -> B1-TCS-1311-X11 | I56: =Query!G53 -> BOX TPC/OPS | J56: Eletric room | K56: =Query!K53 -> B1JB10-13311C HAN 6A | L56: =Query!L53 -> HARTING Speed OPS | M56: Machine hall | O56: =Query!O53 -> DSPW/SUPP.FI
A57: =Query!A54 -> 20051 | B57: =MID(Query!B54,1,2) -> B1 | C57: =MID(Query!B54,4,50) -> PI-I-5236 | D57: =Query!C54 -> 1- C5XFE-R /ST/ | E57: =Query!D54 -> 5 x 2 x 1.0 mm² | F57: 4-20mA | G57: =Query!E54 -> 200 | H57: =Query!F54 -> B1-TCS-1311-X12 | I57: =Query!G54 -> BOX TPC/OPS | J57: Eletric room | K57: =Query!K54 -> B1-HZ-13303-S01 | L57: =Query!L54 -> PUSH-BUTTON CONTROL ROOM | M57: =Query!M54 -> ++Control room | O57: =Query!O54 -> DSPW/SUPP.FI
A58: =Query!A55 -> 20052 | B58: =MID(Query!B55,1,2) -> B1 | C58: =MID(Query!B55,4,50) -> PI-I-5237 | D58: =Query!C55 -> 1- C5XFE-R /ST/ | E58: =Query!D55 -> 5 x 2 x 1.0 mm² | F58: 4-20mA | G58: =Query!E55 -> 100 | H58: =Query!F55 -> B1-TCS-1311-X12 | I58: =Query!G55 -> BOX TPC/OPS | J58: Eletric room | K58: =Query!K55 -> B1-HZ-13302-S01 | L58: =Query!L55 -> PUSH-BUTTON STG TRIP - MACHINE HALL | M58: Machine hall | O58: =Query!O55 -> DSPW/SUPP.FI
A59: =Query!A56 -> 20053 | B59: =MID(Query!B56,1,2) -> B1 | C59: =MID(Query!B56,4,50) -> PI-I-5241 | D59: =Query!C56 -> Cu | E59: =Query!D56 -> 2 x 2.5 mm² | F59: 4-20mA | G59: =Query!E56 -> 100 | H59: =Query!F56 -> B1-TCS-1311-X21 | I59: =Query!G56 -> BOX TPC/OPS | J59: Eletric room | K59: =Query!K56 -> B1-JBAY-1341-X01 | L59: =Query!L56 -> JB HPH FI | M59: Machine hall | O59: =Query!O56 -> DSPW/SUPP.FI
A60: =Query!A57 -> 20054 | B60: =MID(Query!B57,1,2) -> B1 | C60: =MID(Query!B57,4,50) -> PI-I-5243 | D60: =Query!C57 -> Cu | E60: =Query!D57 -> 2 x 2.5 mm² | F60: 4-20mA | G60: =Query!E57 -> 100 | H60: =Query!F57 -> B1-TCS-1311-X21 | I60: =Query!G57 -> BOX TPC/OPS | J60: Eletric room | K60: =Query!K57 -> B1-JBAY-1341-X01 | L60: =Query!L57 -> JB HPH FI | M60: Machine hall | O60: =Query!O57 -> DSPW/SUPP.FI
A61: =Query!A58 -> 20055 | B61: =MID(Query!B58,1,2) -> B1 | C61: =MID(Query!B58,4,50) -> PI-I-5245 | D61: =Query!C58 -> Cu | E61: =Query!D58 -> 2 x 2.5 mm² | F61: 4-20mA | G61: =Query!E58 -> 100 | H61: =Query!F58 -> B1-TCS-1311-X21 | I61: =Query!G58 -> BOX TPC/OPS | J61: Eletric room | K61: =Query!K58 -> B1-JBAY-1341-X01 | L61: =Query!L58 -> JB HPH FI | M61: Machine hall | O61: =Query!O58 -> DSPW/SUPP.FI
A62: =Query!A59 -> 20056 | B62: =MID(Query!B59,1,2) -> B1 | C62: =MID(Query!B59,4,50) -> PRP-13701-C4001 | D62: =Query!C59 -> 1- C5XFE-R /ST/ | E62: =Query!D59 -> 2 x 2 x 1.0 mm² | F62: 24V DC | G62: =Query!E59 -> 30 | H62: =Query!F59 -> B1-TCS-1301B-XD53 | I62: =Query!G59 -> TCS I/O and marshaling cabinet | J62: Eletric room | K62: =Query!K59 -> B1-PRP-13701-XC7 | L62: =Query!L59 -> BOX OF GEN.PROTECTIONS | M62: Eletric room | O62: =Query!O59 -> DSPW/SUPP.FI
A63: =Query!A60 -> 20057 | B63: =MID(Query!B60,1,2) -> B1 | C63: =MID(Query!B60,4,50) -> PRP-13701-C4002 | D63: =Query!C60 -> 1- C5XFE-R /ST/ | E63: =Query!D60 -> 2 x 2 x 1.0 mm² | F63: 24V DC | G63: =Query!E60 -> 30 | H63: =Query!F60 -> B1-TCS-1301B-XD53 | I63: =Query!G60 -> TCS I/O and marshaling cabinet | J63: Eletric room | K63: =Query!K60 -> B1-PRP-13701-XC7 | L63: =Query!L60 -> BOX OF GEN.PROTECTIONS | M63: Eletric room | O63: =Query!O60 -> DSPW/SUPP.FI
A64: =Query!A61 -> 20058 | B64: =MID(Query!B61,1,2) -> B1 | C64: =MID(Query!B61,4,50) -> PRP-13701-C4010 | D64: =Query!C61 -> 1- C5XFE-R /ST/ | E64: =Query!D61 -> 2 x 2 x 1.0 mm² | F64: 24V DC | G64: =Query!E61 -> 30 | H64: =Query!F61 -> B1-TCS-1301C-XD55 | I64: =Query!G61 -> TPS I/O and marshaling cabinet | J64: Eletric room | K64: =Query!K61 -> B1-PRP-13701-XS1 | L64: =Query!L61 -> BOX OF GEN.PROTECTIONS | M64: Eletric room | O64: =Query!O61 -> DSPW/SUPP.FI
A65: =Query!A62 -> 20059 | B65: =MID(Query!B62,1,2) -> B1 | C65: =MID(Query!B62,4,50) -> PRP-13701-C4011 | D65: =Query!C62 -> 1- C5XFE-R /ST/ | E65: =Query!D62 -> 2 x 2 x 1.0 mm² | F65: 24V DC | G65: =Query!E62 -> 30 | H65: =Query!F62 -> B1-TCS-1301C-XD55 | I65: =Query!G62 -> TPS I/O and marshaling cabinet | J65: Eletric room | K65: =Query!K62 -> B1-PRP-13701-XS1 | L65: =Query!L62 -> BOX OF GEN.PROTECTIONS | M65: Eletric room | O65: =Query!O62 -> DSPW/SUPP.FI
A66: =Query!A63 -> 20060 | B66: =MID(Query!B63,1,2) -> B1 | C66: =MID(Query!B63,4,50) -> PRP-13701-C4012 | D66: =Query!C63 -> 1- C5XFE-R /ST/ | E66: =Query!D63 -> 2 x 2 x 1.0 mm² | F66: 24V DC | G66: =Query!E63 -> 30 | H66: =Query!F63 -> B1-TCS-1301C-XD55 | I66: =Query!G63 -> TPS I/O and marshaling cabinet | J66: Eletric room | K66: =Query!K63 -> B1-PRP-13701-XS1 | L66: =Query!L63 -> BOX OF GEN.PROTECTIONS | M66: Eletric room | O66: =Query!O63 -> DSPW/SUPP.FI
A67: =Query!A64 -> 20061 | B67: =MID(Query!B64,1,2) -> B1 | C67: =MID(Query!B64,4,50) -> PRP-13701-C4013 | D67: =Query!C64 -> 1- C5XFE-R /ST/ | E67: =Query!D64 -> 2 x 2 x 1.0 mm² | F67: 24V DC | G67: =Query!E64 -> 30 | H67: =Query!F64 -> B1-TCS-1301B-XD43 | I67: =Query!G64 -> TCS I/O and marshaling cabinet | J67: Eletric room | K67: =Query!K64 -> B1-PRP-13701-XS1 | L67: =Query!L64 -> BOX OF GEN.PROTECTIONS | M67: Eletric room | O67: =Query!O64 -> DSPW/SUPP.FI
A68: =Query!A65 -> 20062 | B68: =MID(Query!B65,1,2) -> B1 | C68: =MID(Query!B65,4,50) -> PRP-13701-C4014 | D68: =Query!C65 -> 1- C5XFE-R /ST/ | E68: =Query!D65 -> 2 x 2 x 1.0 mm² | F68: 24V DC | G68: =Query!E65 -> 30 | H68: =Query!F65 -> B1-TCS-1301B-XD43 | I68: =Query!G65 -> TCS I/O and marshaling cabinet | J68: Eletric room | K68: =Query!K65 -> B1-PRP-13701-XS1 | L68: =Query!L65 -> BOX OF GEN.PROTECTIONS | M68: Eletric room | O68: =Query!O65 -> DSPW/SUPP.FI
A69: =Query!A66 -> 20063 | B69: =MID(Query!B66,1,2) -> B1 | C69: =MID(Query!B66,4,50) -> PRP-13701-C4024 | D69: =Query!C66 -> 1- C5XFE-R /ST/ | E69: =Query!D66 -> 10 x 2 x 1.0 mm² | F69: 24V DC | G69: =Query!E66 -> 30 | H69: =Query!F66 -> B1-TCS-1301B-XD43 | I69: =Query!G66 -> TCS I/O and marshaling cabinet | J69: Eletric room | K69: =Query!K66 -> B1-PRP-13701-XS4 | L69: =Query!L66 -> BOX OF GEN.PROTECTIONS | M69: Eletric room | O69: =Query!O66 -> DSPW/SUPP.FI
... A116: =Query!A113 -> 20110 | B116: =MID(Query!B113,1,2) -> B1 | C116: =MID(Query!B113,4,50) -> SKD-13107-PYV02-C4002 | D116: =Query!C113 -> Cu | E116: =Query!D113 -> 2 x 2.5 mm² | F116: 24V DC | G116: =Query!E113 -> 100 | H116: =Query!F113 -> B1-TCS-1311-X31 | I116: =Query!G113 -> BOX TPC/OPS | J116: Eletric room | K116: =Query!K113 -> B1-SKD-13107-PYV02 HAN 3A | L116: =Query!L113 -> SOLENOID PopV LPCF | M116: Machine hall | O116: =Query!O113 -> DSPW/SUPP.FI
A117: =Query!A114 -> 20111 | B117: =MID(Query!B114,1,2) -> B1 | C117: =MID(Query!B114,4,50) -> TCS-1301A-E8001 | D117: Ethernet | E117: CAT6 | F117: 4-20mA | G117: =Query!E114 -> 30 | H117: =Query!F114 -> B1-TCS-1301A-A21 | I117: =Query!G114 -> TCS/TPS CPU and PWR cabinet | J117: Eletric room | K117: =Query!K114 -> B1-CP-13701-P4 | L117: =Query!L114 -> BOX OF GEN.AVR, SYNCHR.AND MEAS. | M117: Eletric room | O117: =Query!O114 -> DSPW/SUPP.FI
A118: =Query!A115 -> 20112 | B118: =MID(Query!B115,1,2) -> B1 | C118: =MID(Query!B115,4,50) -> TCS-1301A-E8002 | D118: Ethernet | E118: CAT6 | F118: 4-20mA | G118: =Query!E115 -> 30 | H118: =Query!F115 -> B1-TCS-1301A-A21 | I118: =Query!G115 -> TCS/TPS CPU and PWR cabinet | J118: Eletric room | K118: =Query!K115 -> B1-CP-13501+ER-U100 | L118: =Query!L115 -> BOX OF GEN.EXCITATION | M118: Eletric room | O118: =Query!O115 -> DSPW/SUPP.FI
A119: =Query!A116 -> 20113 | B119: =MID(Query!B116,1,2) -> B1 | C119: =MID(Query!B116,4,50) -> TCS-1301A-E8003 | D119: Ethernet | E119: CAT6 | F119: 4-20mA | G119: =Query!E116 -> 30 | H119: =Query!F116 -> B1-TCS-1301A-A21 | I119: =Query!G116 -> TCS/TPS CPU and PWR cabinet | J119: Eletric room | K119: =Query!K116 -> B1-CP-13501+ER-U100 | L119: =Query!L116 -> BOX OF GEN.EXCITATION | M119: Eletric room | O119: =Query!O116 -> DSPW/SUPP.FI
A120: =Query!A117 -> 20114 | B120: =MID(Query!B117,1,2) -> B1 | C120: =MID(Query!B117,4,50) -> TCS-1301A-E8004 | D120: Ethernet | E120: CAT6 | F120: 4-20mA | G120: =Query!E117 -> 30 | H120: =Query!F117 -> B1-TCS-1301A-A21 | I120: =Query!G117 -> TCS/TPS CPU and PWR cabinet | J120: Eletric room | K120: =Query!K117 -> B1XXX-XXX | L120: =Query!L117 -> Generator monitoring | M120: Eletric room | O120: =Query!O117 -> DSPW/SUPP.FI
A121: =Query!A118 -> 20115 | B121: =MID(Query!B118,1,2) -> B1 | C121: =MID(Query!B118,4,50) -> TCS-1301A-E8005 | D121: Ethernet | E121: CAT6 | F121: 4-20mA | G121: =Query!E118 -> 30 | H121: B1-TCS-1320-A20 | I121: TCS SERVER CABINET | J121: Eletric room | K121: =Query!K118 -> B1-TCS-1320-A20 | L121: =Query!L118 -> TCS SERVER CABINET | M121: Eletric room | O121: =Query!O118 -> DSPW/SUPP.FI
A122: =Query!A119 -> 20116 | B122: =MID(Query!B119,1,2) -> B1 | C122: =MID(Query!B119,4,50) -> TCS-1301A-E8006 | D122: Ethernet | E122: CAT6 | F122: 4-20mA | G122: =Query!E119 -> 30 | H122: =Query!F119 -> B1-TCS-1320-A20 | I122: =Query!G119 -> TCS SERVER CABINET | J122: Eletric room | M122: Eletric room | O122: =Query!O119 -> DSPW/SUPP.FI
A123: =Query!A120 -> 20117 | B123: =MID(Query!B120,1,2) -> B1 | C123: =MID(Query!B120,4,50) -> TCS-1301A-E8007 | D123: Ethernet | E123: CAT6 | F123: 4-20mA | G123: =Query!E120 -> 30 | H123: =Query!F120 -> B1-TCS-1320-A21 | I123: =Query!G120 -> TCS SERVER CABINET | J123: Eletric room | M123: Eletric room | O123: =Query!O120 -> DSPW/SUPP.FI
A124: =Query!A121 -> 20118 | B124: =MID(Query!B121,1,2) -> B1 | C124: =MID(Query!B121,4,50) -> TCS-1301A-E8008 | D124: Ethernet | E124: CAT6 | F124: 4-20mA | G124: =Query!E121 -> 30 | H124: =Query!F121 -> B1-TCS-1320-A21 | I124: =Query!G121 -> TCS SERVER CABINET | J124: Eletric room | M124: Eletric room | O124: =Query!O121 -> DSPW/SUPP.FI
...

Sheet Query
A1: F1 | B1: F2 | C1: F3 | D1: F4 | E1: F5 | F1: F6 | G1: F7 | H1: F8 | I1: F9 | J1: F10 | K1: F11 | L1: F12 | M1: F13 | N1: F14 | O1: F15 | P1: F16 | Q1: F17 | R1: F18 | S1: F19 | T1: F20 | U1: F21 | V1: F22 | W1: F23 | X1: F24 | Y1: F25 | Z1: F26 | AA1: F27 | AB1: ComosSystemInfo
A2: Origin key | B2: Cable number | C2: Cable type | D2: Cable cross-section | E2: Proj. max. length (m) | F2: Cable from | G2: Desc_from | H2: Location_From | I2: Connector from | J2: Connector to | K2: Cable to | L2: Desc_To | M2: Location_To | N2: Cable type code | O2: Supplier | P2: Number | Q2: Cable type | R2: Base object | S2: Output Prokabel | T2: Room from | U2: Function to | V2: Item to | W2: Function from | X2: Item from | Y2: Room to | Z2: Date / User | AA2: Remark | AB2: @@UU@@C@@AP/kAJrSYQxjHOc50IQhCUISpCFJSlK1JUlKVKSpKVLWpSlLWtTFrWtamLAtQGAWAAAMUwDAMYtYALWADAMWAAFgWwCwAYpS1qWBbGMApa1sYpjAMAAAGAAAAAAAAAAAAAAAAAAAGAAAAAAAAAAAAAAAAAAAAAAAAAAAAAAAAAAAAAAAAAAAAAAAAAAAAAAAAAAAGAYAAAAAAAAAAAAAAAAAAAYAAAi6ZX2w+4x8n9FZ8/+WYVPdn78A+7876UyR+1M/htnBP9P3JomKsJpH8E2TZOZP9U3psn703JuTZOZPyy1TemibJomUHQmifU1TGWLFLmjcqxVibJqn0pomiaJlbbVpR3hSOGFWk46Y6jV0url+b8/6vz/N/d+nrTnT/ZO+nP0cujm5tOjo6O0RddQxOpNE0TIxMJ2ywmmEyUYqxMTRNHexMyYxZMTMS/slX54oc2idqryJoWZDS+WtE/t2/L5uzHDTdvTZMTpYzMMTgmyb01TVNya2uLemhPyWDfk3sVZircoYnZP8cfrbJsmJhMVbiYmJpv9HH83Nq16eCcFXWVVcdOkzH5o3Nhq4xkcI3p86bJvKcszMzN/DWa4zMxmZw002479OPDlQU+W9i6lR+vr0J0+2+nw/U0dj0vIlO/rWet2XPFI/RQmFXqwVbLCLfirudqbtr5hxrH6cZplZHHNMM00rvtfQTWremYJmFmJxTNKb8rTGmDGM/ZH4Y/RTdhOlu0ExpExhhmYzJvrMsEa/RrrT3dMuFYxwTbOxOGsm9vym7WcU15tZ1dPPNd0TnaXCMTNS4+HSnma8/fTobk12+Ldy5JpvG7bR5ePHmtd1NDfXNx4byaDSMZx5bE7xOHPTye9/h9fx/Z97+P2Nvd5p2YWn2eOrdo5vRu3Dh0dPHo6NOnm5+nmp05GbtEp4cqKmkJG0TExkkxMixMV3Yqp38p3ZriTswnXg9jGZUjwZ24UG2fq9Pj/TsmgrVNUW2E+7gmyYqW4miYqtE5k1TQlNhpmiYmJiaKupNRVqmqaIske48kvmV/O91snb7b3WOLE10VU8xV1J86cn0bzknfT4Sp5086fQTd38k/YofA7z7TwR2KspirVN5MdLGNE0rinzE0Tu+jM771ngcU31OZPUn8k2VdbtTfqnyKuAn32qdd4pdaeJV7Ka13nNTUnOVaJxE3J3NS/a+18XrOl5E5J8bi0KniKm7nJqmykdH4XkVbE5J2lWze8VfCq2T0JyKuJNk52iZ5fA8Lmck8pNFXBNCr5E60xORon3+p3OCB7irvp5E1TknK7L6k2T10xOpNE0VYq+SPYeJz8nWniKvG9f1P3Pa6QnHCdKYngTCc6c6ap5k64pbk3JwdxV9eW7oc6eHiT0Jzp9YT6Typ401ryqvvKtU1u+nsIUfg3KtU9ZOuPfToTgKRom1qmV1Jqq5JulWonmTCeh3Jyfd8Blv2tL8Y+G9lzp2pwT2TrVfGmqfUVPhTCpibJ+Iqk9KpaoHrqqfCKmlPtIvUgeN9hNU1VdXuJ8BOZOD+Ux7yB/umqYmC60/90Vap5xiZdadpPM7fQi3UtW6QbCb011RcE2Twpqq24kTYmeZOuVOwTuT/lPURd9Vtbuwmqa1iaxs1enHlTE0ZvihoVYVViZgjCxMK37lVMlpWkGYTTSszNFIxJkUtE03lTQTimibk1E4pwVU8SfjQO3tbKvMTiTgnMn3iL1+5P+OTH3MalWj39E8KeHtTUnU6k17U6E3IvCncmiU6Orfppqnk2TuKvt6bJ4PaifKwnSnTQ7U8KcUDCak9BV2PSncE86ZJ2k+EynnTIqnPhedMVdyZsUW9NS1VF30nqJoVee7ye4nMTyp3Jqnq8jVNmielPvJ5XiJuil6NFWid6Jz1VgTSg+sTvJoVYm9P4pp3iYndedA3u+mthMT2mrwJ7Lwz1lWhMTTjA4KqYq4Ot8SeZV404aE0TTmKpONJ7Tcmj/OxuVXJs3ql3k6dU3bIH9T+smxTiT3qm9NOBMp0OKqmiJqTCbyrcmirsTgq0TXYTFXxp94mvJEtyrMFWJaZE/+wm9zCpvKvxE7Nk8ick6bWnDgnvE+ue2q8b7ZV6Sp6E17Q3p0KqbqTUwnWlHFSMT4FVPhTcnoJ5ydhNXJPgTRO1PAnrJ98RTuTOCeclsi3Oqg98nPU6Xo5qpOROKBp7ick95PXTZOZyoVrQalXBhbg8RibPxJtuTKq5iYnsJ7dPsM0T2VW5NetNU9ZNk4Ddw7taXxtWqdnaTSquDs//cxV1JwelOxOhOlOdNk2T105t2qLnTCroTeJwUOKeATZOSbJ405J3irsTkTROSBwTVPWd5VyTqJp0J05WMTCaJhNCdBO8yhXr8Ocm9O8nCp6nT0Cp2JoVSf9fCq6idKe3LdSeUq3CfE4pvd9Pf6XsuxO8xOlOKbJo/pbFXvKuUGhehF6iLViFGehOkq8Crwentfg+t+QiqH4P+9KkQ/8yoVUfl+5olFU0yqVQfLiqB/ftofzA=
A3: 20000 | B3: B1-CP-13501-C4003 | C3: 1- C5XFE-R /ST/ | D3: 2 x 2 x 1.0 mm² | E3: 30 | F3: B1-TCS-1301B-XD54 | G3: TCS I/O and marshaling cabinet | H3: B1 | I3: 002 | J3: 002 | K3: B1-CP-13501+ER-X100 | L3: BOX OF GEN.EXCITATION | M3: B1-CP-13501 | O3: DSPW/SUPP.FI | P3: -C4003 | Q3: 1- C5XFE-R /ST/ 2 x 2 x 1.0 | R3: LOCAL Base Objects|Cable|A30|Z20|0502 | V3: -X100 | X3: -XD54 | Z3: 2024-06-12 / Harasta, T. | AB3: @@UU@@C@@AA80AApOUQpTGOc5jHOcxjmMc6EpSo6EoSlCkoShSQHSlIEJQhCAJQACQKUpSgKApSgAUACgJUBSgHUpSUJAkCgJQBKFKQkAFJApSlIUACVJQlKgAAAAAAAAAAAAAAAAAAAAAAAAAAAAAAAAAAAAUAAAAAAAFAAAAAAAAAAAAAAAAAAAAAAAAAAAAAAAAAAAAAAAAAAAAAAAAAAAAAAAAAAAAAAAABCy/LwdJzifX+P8iebugnrE6fy9VH7b39fMfUZlj7l1mujxhr8ujonV6P78/kvKupLJ5fHL//t+/XTZIoljvQZ9SQD/wAdfb5UIt0gZbRay/DLAK8gl8frrpWM9UxYM3Myg/OUiUoIaYlAeQlKSzkT2ROSY0SAkAYoPMBYJAkimCiCUMEESCVHbiULSLyc9ASEgxMAaRIw4aYm0rnCROzLjrSEOXBbKQHKhTT1aNq5CoTOVlLzdnmtaydWAFw4vPOjcADiBH9w4hOIhZMPaEiURBwQko4eUThG6AkJAnokJPdsAkJ+jtZOtp6wksGiJbaHHuYEKjnsEsFaF7AGoTH3+usvhEg+C/LV4e7sV459Am9k4ajjnnEnVXGjNqrLaaC23ToUPTqx019y/v3asuPFxlsUbgmwJtZdE9JZXit2KekTEhdMKLr8mQTJxXSq7Adm7K7fvmHPmwZATtgUaNrcxR/HiE3YEv0XCZM9GzwRi3YbIEp6DfEjueoTZBMlvVEsE3qxNswb/gEj4vaJWJ7BIE/wTtAl4JVm92Yx7MHpADCJb6+99EyYllArozgl4khM6kwTNME+mVIlImFSDBg9j3tnYE90CUGITdP9E9tVZjEgqaQSsSfyABgEvBIEuE8QkCXVkHx3CagTwCHzxHhTfYdH4fYIoK+8A
A4: 20001 | B4: B1-CP-13501-C4004 | C4: 1- C5XFE-R /ST/ | D4: 2 x 2 x 1.0 mm² | E4: 30 | F4: B1-TCS-1301B-XD45 | G4: TCS I/O and marshaling cabinet | H4: B1 | I4: 002 | J4: 002 | K4: B1-CP-13501+ER-X110 | L4: BOX OF GEN.EXCITATION | M4: B1-CP-13501 | O4: DSPW/SUPP.FI | P4: -C4004 | Q4: 1- C5XFE-R /ST/ 2 x 2 x 1.0 | R4: LOCAL Base Objects|Cable|A30|Z20|0502 | V4: -X110 | X4: -XD45 | Z4: 2024-06-12 / Harasta, T. | AB4: @@UU@@C@@AA80AApMSQpjGMc5jHOc6DGMc5zpSk6DgShCEJOBAEoSBCUIShCAJQkClKUBSgKUoCgAUBQAJUBSgHAlSkJAkCgJQBCVKQBQFKApSlIUACVJQlKgAAAAAAAAAAAAAAAAAAAAAAAAAAAAAAAAAAAAUAAAAAAAFAAAAAAAAAAAAAAAAAAAAAAAAAAAAAAAAAAAAAAAAAAAAAAAAAAAAAAAAAAAAAAAABCxfJx9h1CfV5/5E9PhBPYJ2ff+0/68P9fKfSWLH2rrNc/mDX6MvXNV0/36vwuKs8sPo+zzf/H3a58cieWC5BmzyAf+ADTt9CEbGgDFYLWXXpUivOJdH566FjzyF9bbgkfjKRKUEBREoCIzk0LIm2RJc8DRICQBfg9IGMSBJFEE8EoYIIkyiJ9UShaBefqnCQkF1TIDQJF+/TEzQtLNjxYK0hC90EPQhPP257YWxC+JcTk73un142onoBab3qmr74AcoI/uHKJykLJh3BIlEQccJKOToE5BtgJCQJ0yEm1YwJCfk6cPc7vdElTliW0hzbtKFR1YxMYrOvCBviYODSst4SDcuxVeTw5q8E231icOLkrOabKJNWaM92/WW0zltltWZQp2eKj9PBZ4oy4q8PMYYn74mYTvZMs2yYKy/oz0dgl9CyYJ7O5hwictuzVtO3didzSZLKMIJqAny7Wo/j4BN6BNGTNK0TDkmo08kVb0OOBKOs8YkeDUJpBMVnbE2BPFWJuFPFwiR8PuErE9okCf4JuglwJVZ77DBpg6gAvCbHs4PnmJhMc4rlyAlwkhMikwJZMCfRKgSgS8pBTT7Xg2cwnvgScvibp/onuqrMAkFTQCViTfGAFIlwJAlonjEgS2sg+K0TfBOIQ+aI8nlDjYc2v6xFBXtA==
A5: 20002 | B5: B1-CP-13501-C4005 | C5: 1- C5XFE-R /ST/ | D5: 5 x 2 x 1.0 mm² | E5: 30 | F5: B1-TCS-1301B-XD54 | G5: TCS I/O and marshaling cabinet | H5: B1 | I5: 002 | J5: 002 | K5: B1-CP-13501+ER-X200 | L5: BOX OF GEN.EXCITATION | M5: B1-CP-13501 | O5: DSPW/SUPP.FI | P5: -C4005 | Q5: 1- C5XFE-R /ST/ 5 x 2 x 1.0 | R5: LOCAL Base Objects|Cable|A30|Z20|0505 | V5: -X200 | X5: -XD54 | Z5: 2024-06-12 / Harasta, T. | AB5: @@UU@@C@@AA80AApNSQpTGMc5jHOc5znMdCFIQdJznUlCkIQlAFIShKkJShBwJQBSVAUpSgASoCgAUBQAKUBSgHAlSkJAkCgJQBCVKQBQFKApSlIUACVJQlKgAAAAAAAAAAAAAAAAAAAAAAAAAAAAAAAAAAAAUAAAAAAAFAAAAAAAAAAAAAAAAAAAAAAAAAAAAAAAAAAAAAAAAAAAAAAAAAAAAAAAAAAAAAAAABCwfLydh1CfT5f5E8/eBPUJ2ff+1H68f9fN5PoMix9q6zXR9Ya/Ns9c6+n+/R+GUr2pX/Nkt//7Pu10wYqIv5UGd2QD/wAaNzoQjF2wMGMWwtuSqFecS2Pz10rHlkL6WyD8ZWzJzghpiUJES50JE9Am3MaZASQLsHnAwiQJIpgogllkyIImEqd+JQtQvP1UBISCtgDtiRcii5JpXYCeLDesSELnQR0IUUbdF2DEhdEtylCyIfd6bjdJ0KPpiq56J2bwAagR/cNQmohZMO6JEoiDkhJRy9AnKNsBISBOmQk+7hAkJ+Tov7ebMJKrYiXcQ5t2pCs6sImEVoXjA7wl7v6FlwCQdy3BX4uLZsvT6xOK/y1nNPKJOs2MfDWd3HVSY8WfZUNuNGDh7/H8Fv6YM1mDmMcU74m0Jue5tT0mey7mzU9gl1C2YUW5798TVku+87uS+z0aS3FVeBNIFGXTvn8eMTggTJl1WiX8tOjPVKvghwwFMDVLrOQSPf3hM4Jgx7QmITjvCbhV4fAJHxewSwT1iQJ/gm8CWgleP24y9og6gAuCYvVxeSZMTDQK7GUEtEkJlUmCY5gnzypEpEuKQVVet4s+yJ7YEoLomk/0T2V2F4SCtpBLBJ/IAFQloJAmQTxiQJksIPjyCcIJ4BD4YjxQHhYdjX9Qigr2gA==
A6: 20003 | B6: B1-CP-13501-C4006 | C6: 1- C5XFE-R /ST/ | D6: 10 x 2 x 1.0 mm² | E6: 30 | F6: B1-TCS-1301B-XD45 | G6: TCS I/O and marshaling cabinet | H6: B1 | I6: 003 | J6: 003 | K6: B1-CP-13501+ER-X210 | L6: BOX OF GEN.EXCITATION | M6: B1-CP-13501 | O6: DSPW/SUPP.FI | P6: -C4006 | Q6: 1- C5XFE-R /ST/ 10 x 2 x 1.0 | R6: LOCAL Base Objects|Cable|A30|Z20|0510 | V6: -X210 | X6: -XD45 | Z6: 2024-06-12 / Harasta, T. | AB6: @@UU@@C@@AA82AApTSQpTGMc5jnMgxznMc50KQhCEnSlClIShR1KQhIEJQhCAISBSVAUpSlAUoCgAUBQAKUpIAHApSUJAkClKQBCVKQAAFJApSlIUACVJQlKgAAAAAAAAAAAAAAAAAAAAAAAAAAAAAAAAAAAAUAAAAAAAFAAAAAAAAAAAAAAAAAAAAAAAAAAAAAAAAAAAAAAAAAAAAAAAAAAAAAAAAAAAAAAAABC1vk4+w6hPq+/+RPNvgnpE7Pw9FH7cP9fLi+khY8a6jVR9gavL15519P9/n5LivXlZ5fH9v//dPVFsicsNyDPXkA/8AHb3OhCMW0BZjFwF16VQrziXR+uqkCM0hfO4IPxlIldORDTEoSIl5CRCz2xOegaZASEvwh5gLRIEkUwUQShggiQSo70SgCkXn6qAkJBf14JAbQkX6b82laswTox22YUhCm90S6EKNiqiq3GhWJlKcsRDEL3LOnE2FFILVe/KeDz7oAcoI/uHKJykpLBD7gkSiIOOElHJ0Ccg3QEhIE6ZCT3sQEhP0e5Zs6NkTPO9KJe2h4dFSFZ1WiWitC8IG+Jh7+hZaRINF2tXzcGfBhn1ie7ZyVnNPKJOszY9+sxU0GK3azKEadNen3tjgyVWYMPMWxRuiZhNFuWe2bGC/kz09gl9DJMKMntWWCcmS/3ceFzhubJ3cuO9YCd4CjNo3T+PgE3oEuzXCYctHb8EX96HWgSnrOISNPoE2wSzFriWicOATcKuLwCR8PrEwCeoSBP8E3QS4Erx+zGYduDqAC8Ji9Pf+eZMS2gVzZQS4SQmVSYJjmCfRKkSkS8pBVV6ng284nsgSgvicR/onrrwGESCtpBMAk/jACoS4EgTIJ4hIEyYCD4sgnvgnEIfNEeHxBxsOfV9aigr2g==
A7: 20004 | B7: B1-CP-13501-C4007 | C7: 1- C5XFE-R /ST/ | D7: 10 x 2 x 1.0 mm² | E7: 30 | F7: B1-TCS-1301B-XD54 | G7: TCS I/O and marshaling cabinet | H7: B1 | I7: 001 | J7: 001 | K7: B1-CP-13501+ER-X300 | L7: BOX OF GEN.EXCITATION | M7: B1-CP-13501 | O7: DSPW/SUPP.FI | P7: -C4007 | Q7: 1- C5XFE-R /ST/ 10 x 2 x 1.0 | R7: LOCAL Base Objects|Cable|A30|Z20|0510 | V7: -X300 | X7: -XD54 | Z7: 2024-06-12 / Harasta, T. | AB7: @@UU@@C@@AA82AApRUQpjGOY5zGOc5zHMZJ0oSo50HUA51IUgCQIQlCkJQg4AISBSFKUBSgAUoCgAUBQAKAlSlHUpKlIAkCgJQlKVKQAAFJApSlIUACVJQlKgAAAAAAAAAAAAAAAAAAAAAAAAAAAAAAAAAAAAUAAAAAAAFAAAAAAAAAAAAAAAAAAAAAAAAAAAAAAAAAAAAAAAAAAAAAAAAAAAAAAAAAAAAAAAABCxfJy9h1CfT+H8iePhBPSJ2eL0T/tx/18uT6CFj7F2m2f6w29HXmmweb+/J+Npg7csPR9vh//w/dtoySJ5YbkGbckA/8AGnX0oRZoAxZRai6mV4V/IS6P1++gCPFIXztUH5ykSlbIk0RKAiCUHcQm3ROicaJASAvwp4wMYkCSKIJ4JQwQRIJT78SgCgXo6pwkJBfYAziRTPTM0LcE2TFXUkIU9MHShNuUT5EKRPbuLihmg9zzYZ6KFxtZTMo0RRf1TV+6AGwEf3DYJsJSWCHWJEoiDkhJRy+QTlG2AkJAnlkJN72MCQnnf004s+7oElTmiWpDwb15DAdWQTIKzrxgcIlfFpWXdEgttxYObvZqq5usTew7MBzTXCTdyqqM2XhrLKJyynPmUOLRKvCcHFZgrplzGKJ9Ylwmm26bOblV/g7dHYJfQsmCey7DhE2Zb+qyt1BrzluS9WCbwE92nRrj+PgE34Et7VomG6fd5Iv78OOBKOs74kd30CaATDk3BMYnv1Cai93+MSPh9YlQnqEgT/BN4EtBMFnssK9EHUAFImT08XzTEwmOcV7VwJaJIS5SYEsmBPnlQJQJSpBevep72jMJ7IEnL4nIf6J68FRWJBgaASoSb4wAvCWgkCZROcSBMtRB8WUTgBOQQ54jwc4bGHNt+pRQV9oA=
A8: 20005 | B8: B1-CP-13501-C4008 | C8: 1- C5XFE-R /ST/ | D8: 10 x 2 x 1.0 mm² | E8: 30 | F8: B1-TCS-1301B-XD45 | G8: TCS I/O and marshaling cabinet | H8: B1 | I8: 001 | J8: 001 | K8: B1-CP-13501+ER-X310 | L8: BOX OF GEN.EXCITATION | M8: B1-CP-13501 | O8: DSPW/SUPP.FI | P8: -C4008 | Q8: 1- C5XFE-R /ST/ 10 x 2 x 1.0 | R8: LOCAL Base Objects|Cable|A30|Z20|0510 | V8: -X310 | X8: -XD45 | Z8: 2024-06-12 / Harasta, T. | AB8: @@UU@@C@@AA82AApOSQpTGOY5jHOc5zHMdB0JAdCDpSA6UoQpSVKQhCUAQg4AISpIEqABSlAUoCgAUBQAKUpSgHAlSkJAkClJQpKVKQAAFJApSlIUACVJQlKgAAAAAAAAAAAAAAAAAAAAAAAAAAAAAAAAAAAAUAAAAAAAFAAAAAAAAAAAAAAAAAAAAAAAAAAAAAAAAAAAAAAAAAAAAAAAAAAAAAAAAAAAAAAAABCxfFy9Z0ifR4/5E8vACeoTr+/00ftx/18eT5yFj7V2Gyj6g2eTqzzr8/9+b8Livblh8lf2f/9f3bKSCcsFyDPbkA/8AGnV0IRk3AMNothdVK8K84l0frspAjxyF9DZB+MpEpXSJNMSgIiUPOhPSJooGmQEgL8B5QMYkCSQpgoglDBBEglRvxKAKRefpoCQkF9gDcEiqiqbSuYJ5MWCxIQq6I6EJ9mmgyIVCXFxQ9vz4MTZSRTJRvQBFX5Ts090ANYI/uGsTWSksEPcEiURByQko5fMJyjdASEgT85CT38gEhPQ5NOLRu7gkqs/6X50akPBRvX0MB02iWitC8YHAJh4u2su8JBbmxV83Dt2YJ9Ql2HXWc08wk6zat4KzRbepLcm5nUO9VZilRu8NF2CmzmMUUahMwmm7HPQYLL/vW09Yl9C2YUW7eHCJry9+vVlwuoO5oM1t7CCbwFG12tw/jwie5Am/mz3CYc1HazxXvw44Ep6jjEj3fSJugmG3siYxOKwTUXuPviR4vYJYJ6xIE/wTeBLgSu322mDTB0gBUJk9XF8syYmOgV2swJcJITMpMEtmCfNKkSkSpSC9e9bw7ucT2wJQXxOQ/0T2V2GASCtpBLBJ/CAF4S4EgTKJ4RIEy2EHiyie+Ccgh8kR4PgDWw59n0qKCvY
A9: 20006 | B9: B1-CP-13501-I6001 | C9: 1- C5XFE-R /ST/ | D9: 2 x 2 x 1.0 mm² | E9: 30 | F9: B1-TCS-1301B-XD44 | G9: TCS I/O and marshaling cabinet | H9: B1 | I9: 008 | J9: 008 | K9: B1-CP-13501+ER-U514 | L9: BOX OF GEN.EXCITATION | M9: B1-CP-13501 | O9: DSPW/SUPP.FI | P9: -I6001 | Q9: 1- C5XFE-R /ST/ 2 x 2 x 1.0 | R9: LOCAL Base Objects|Cable|A30|Z20|0502 | V9: -U514 | X9: -XD44 | Z9: 2024-07-10 / Panek, P. | AB9: @@UU@@C@@AA80AApQSQhjGOY5zHMc5zmOdCDoSk6EJSlCFIUlSlAQhKEpQcCkAQACkqABSlAUoCQAUBQAJABIAHAlSVJAlKlKQBKVKOBQFKApSlIUACVJQlKgAAAAAAAAAAAAAAAAAAAAAAAAAAAAAAAAAAAAUAAAAAAAFAAAAAAAAAAAAAAAAAAAAAAAAAAAAAAAAAAAAAAAAAAAAAAAAAAAAAAAAAAAAAAAABCxfNq6jYJ9fk/kTz8QJ6xOr7f2p/Xvf1854TKseNdfh11eINfm6dFFnp/v8fLnMG5Nvm8Xj/+Z1zikmbLkGjRID/wAb2/0IRj0gW5BbC6ubwr9wl0fnrqWPJIvqbIPvmSZzSYihvRRFCwzFEM6RJO3A0yBKt+DzgYxIEkqgpgmGCCJZiCnhiYWoXy7KQkSC+QB2BIArrqigqiFzhRkxYbEhCvoick0+jIhWJcVeg0IT2oK8FHprxtJTeBb9Vd+myrgADUCP7hqE1ELLD2xImIg78JMcv4Cco5oCRIE6JEo4cgEiep3bevp7Ak3tETzfl715DAbMYmMVpXkA3RMPHx9paPgEgxZqsdnNxbeG2ivpEi3VODmp40OvtiVYTRm2WXVUl2XToUNrBV+l3xc/JdbZbUYop4BNsTs5slGU3LL/FtVdQl9DLQFOXRbaJ8d1/fy4XfeCNObJewgnCBTn3uE/j5BOCBLs/v5hLc9W9qjB3IccCVdJ3xI+HuCboJbl3BMYndsE3y93uQSPB7RLBPYJAn+CcIJmBMGX3ZTDvQbAArEyevu/TQUCY6RXazgmYSRM6lAJloBPqmoSoStSC9e9jx7u2J7oEpL4nKf6J7cFhhEgwNQJYJR8oAXhMwJAlwnOJAl1hB4LhOIE5RD6IjnkNTDta/sEUFesA==
A10: 20007 | B10: B1-CP-13501-I6003 | C10: 1- C5XFE-R /ST/ | D10: 2 x 2 x 1.0 mm² | E10: 30 | F10: B1-TCS-1301B-XD44 | G10: TCS I/O and marshaling cabinet | H10: B1 | I10: 001 | J10: 001 | K10: B1-CP-13501+ER-U501 | L10: BOX OF GEN.EXCITATION | M10: B1-CP-13501 | O10: DSPW/SUPP.FI | P10: -I6003 | Q10: 1- C5XFE-R /ST/ 2 x 2 x 1.0 | R10: LOCAL Base Objects|Cable|A30|Z20|0502 | V10: -U501 | X10: -XD44 | Z10: 2024-07-10 / Panek, P. | AB10: @@UU@@C@@AA80AApMUQpTGOc5zHOc5zGOZBzoQhCEIOhKUISlKgKSlCUJOdKkASoCQKUpSgAUkCQAUBQAKUBKlHAlSkpAlSkqQBKQJQAAFJApSlIUACVJQlKgAAAAAAAAAAAAAAAAAAAAAAAAAAAAAAAAAAAAUAAAAAAAFAAAAAAAAAAAAAAAAAAAAAAAAAAAAAAAAAAAAAAAAAAAAAAAAAAAAAAAAAAAAAAAABCxfRq6TnE+vx/yJ5uyCewTp/H10ftyf19J4StY8S6/Drp+0Nfl6M86vR/f6/laX9mWHy/d9//+L8NdOSRRLDagz2pAP/ABo4eZCK94DFYLUW3ZXBXyCWx6vHSsWyF9LVB+kpEpQZZNMTgMRKUlnJnuidSY0SAkAXofMBjEgSRTBRBKGCCJBKjrRKFpF8nPQEhILxAG2JF27TEymIW0JE8mLBUkIU80ASySo0ZELolh+ZnQuhbo9FzI4Si4C3qcE8HVADUCP7hqE1ELJh4BIlEQdyElGnziaRsgJCQJzSEnxYwJCel2bd7Ht7u2JK9niRy8NKF458gmQVoXjAxiVdn1b6z7AkE7MV/l+LNVgn0CdvDqvz5aONDazCXMF2M+XnoLKaCyivczqHyZs2nt797ky4qqO8ZIo4hNkTgs2J1m5Ve7WenpEvIVzCivaw4RPjsvcNeB4uI3YMuS5gBOuBRbo2z+O+JwwJZbYJgy8FO9oi/14ccBuQNzoNIkfD6xN4Ex2bQlYnJUJ1C5p7gkfL7hKhPaJAn+CdYEygl+v31mDfg5wAuiZPZx/VMmJjoFdi0EyiSEtUmCVzBPBKkSkS6pBcue1493MJ74EoLwmk/0T3X6jAJBfaQSoSfzgBcEygkCWCd8SBLKiD5rBO0Cd0Q8ER3k7rDsa/sEUFfg
A11: 20008 | B11: B1-CP-13701-C4006 | C11: 1- C5XFE-R /ST/ | D11: 5 x 2 x 1.0 mm² | E11: 30 | F11: B1-TCS-1301B-XD52 | G11: TCS I/O and marshaling cabinet | H11: B1 | I11: 009 | J11: 009 | K11: B1-CP-13701-XC4 | L11: BOX OF GEN.AVR, SYNCHR.AND MEAS. | M11: B1 | O11: DSPW/SUPP.FI | P11: -C4006 | Q11: 1- C5XFE-R /ST/ 5 x 2 x 1.0 | R11: LOCAL Base Objects|Cable|A30|Z20|0505 | V11: -XC4 | X11: -XD52 | Z11: 2024-07-21 / Panek, P. | AB11: @@UU@@C@@AA9KAApaUQpTGOY5jGQg5zmOc50IQhB0JOlAEHAhKAKUlSUnQhSEKABQFJUpQEgSpQFASACQAUBSgKQpIEoQpQFJSpSVKQkClKApSlIUACVJQlKgAAAAAAAAAAAAAAAAAAAAAAAAAAAAAAAAAAAAUAAAAAAAFAAAAAAAAAAAAAAAAAAAAAAAAAAAAAAAAAAAAAAAAAAAAAAAAAAAAAAAAAAAAAAAABC1/k4+s6RPD9nh/kT7e2J78CekTr8f7Ufrxf13/l+cyLGFfr8nNT9Ac3P1bU7Px/vy+TKeLblr9H1Wf/9M+aIKJxZjQZ7UgH/gAwaNPmQjDnA18QtFpf2r874rziY4/PNSseOQvndaD75SJSgySaYnAREuckQsTzidExpkBJC/An3AYBIEkUwUQSvyZEETCVPaiULeF6OmgJCQcJAG6JFVFU2kDKE8WG2xIQqPMhuT3KKb9QmQouiIEuQ7Pnqa6YokC3qss7++AHICP7hyCchCyYbhIlEQcUJKOPyicY3QEhIE/CQk9/ABIT3vydOrBLbM+4JK/sbUp7yHDpqQ3jpxiYxW9SvdA0e2Jre7NZcIkHLljBXy7Ndmx1CatbVXP3OWnMJTitNGGUzDu5VCrVer2K8vc7mtdbVvYqJGtonXf0iVCdinNPObNFWKjrEqQsmFHoyb1dol36cGzbv3YHJ3s+l34ySqwInZA2NFl7+PhE7UCZinEJZdj2tFfBDggNu2Q1W9RxiRw5xN0Ew3bIlwndtE3i9xahI73rEsE9QkCf4JpBMYJXi9mIt7EHoACoTD6e34JkxMFArlyAmMSQmRSYJimCfNKkSkSpSC9e9Toz5hPZAlBfE1H+ieuuwtEgraQSwSfxgBeExgkCXCfAJAl1hB8VwnACcQh4Ijv+AONhzc3iRBFfaA
A12: 20009 | B12: B1-CP-13701-C4008 | C12: 1- C5XFE-R /ST/ | D12: 5 x 2 x 1.0 mm² | E12: 30 | F12: B1-TCS-1301B-XD42 | G12: TCS I/O and marshaling cabinet | H12: B1 | I12: 001 | J12: 001 | K12: B1-CP-13701-XS4 | L12: BOX OF GEN.AVR, SYNCHR.AND MEAS. | M12: B1 | O12: DSPW/SUPP.FI | P12: -C4008 | Q12: 1- C5XFE-R /ST/ 5 x 2 x 1.0 | R12: LOCAL Base Objects|Cable|A30|Z20|0505 | V12: -XS4 | X12: -XD42 | Z12: 2024-06-12 / Harasta, T. | AB12: @@UU@@C@@AA9KAApaUQpTGMYxjnOc5znOdB0nQhCEJQk6knUhJwKUlAFHQhAEqABIFKUpIFKAgClASBQFKAoAEoAhSkoAkCkpSBKQJQBAEqApSlIUACVJQlKgAAAAAAAAAAAAAAAAAAAAAAAAAAAAAAAAAAAAUAAAAAAAFAAAAAAAAAAAAAAAAAAAAAAAAAAAAAAAAAAAAAAAAAAAAAAAAAAAAAAAAAAAAAAAABCv+Di6zoE8PN4f5E8ndE+aBPYJ1/n+1Hr4f6+vk+4yrGFeU5aPxDl5+rPO30f35v0yn37Mr/Pb4v//LxTogicXMiDPPIB/4AMHZ7fnQjDtgX8QtF0s2bJ2CvjEyR6s1KxzSF9Leg/WUiUoMsmmJwERKDxoRPcE55jTICS2QHkAwCQJISmCiCUMEESCVG/EoWkXn6KAkJB3GAN0SK6K5tK39gKMWG9dSELDzIap7dFNlYmUulLjQ0eittpIokCFVexOzSAHGCP7hxicZCyYe2JEoiDXCSjh8onCOOAkJAnnkJPTgAkJs+l068Eto3NsSVnYiWhDVt6a0NB0ZBMgrXSvygfGJe4NCy1CQerYjBb3s9tzsdQmu9rtKqPk71WYSqnFdMESMG5lUODgs6cWHpqqz3bdGODi0U74lIm9hvz3TDXsT6xKkMUwspz6J3BI7Wb4tqi58OK+5Po2yve2skNk8KJ3AM29dp/j5xNUCXinEJcx5PXvW78OCAuQNW1d6jjEjVuCboJhx7ImMTXeE0FXFwiR9PuEuCe0SBP8E0gmQEtxe/EXezB0gBWJh9nd5JkxMFArsZQTIJITKpMExTBPtlSJSJWpBVV7Xd3MwnvgSgsE1n+ie624XRILWkEuCT8AAVCZASBMYnfEgTHcIPqxib4JwiHJEfZ3w4mHNzfgiCK/AA==
A13: 20010 | B13: B1-CP-13701-C4010 | C13: 1- C5XFE-R /ST/ | D13: 5 x 2 x 1.0 mm² | E13: 30 | F13: B1-TCS-1301B-XD42 | G13: TCS I/O and marshaling cabinet | H13: B1 | I13: 007 | J13: 007 | K13: B1-CP-13701-XS4 | L13: BOX OF GEN.AVR, SYNCHR.AND MEAS. | M13: B1 | O13: DSPW/SUPP.FI | P13: -C4010 | Q13: 1- C5XFE-R /ST/ 5 x 2 x 1.0 | R13: LOCAL Base Objects|Cable|A30|Z20|0505 | V13: -XS4 | X13: -XD42 | Z13: 2024-06-12 / Harasta, T. | AB13: @@UU@@C@@AA9KAApbSQpTGMY5zHQcxzmOc50HShCEoSlCEpQhKEpAhIEoOdSEqAACVJABKlKUpQFASBSgKUACgIUlSlIAkCgIUpKlISpSlKApSlIUACVJQlKgAAAAAAAAAAAAAAAAAAAAAAAAAAAAAAAAAAAAUAAAAAAAFAAAAAAAAAAAAAAAAAAAAAAAAAAAAAAAAAAAAAAAAAAAAAAAAAAAAAAAAAAAAAAAABCw+PV0noE8nl8n8iebhE9uBPSJ0/V+1H66f6974fjMqxiXkOSj5g5OXo0Tv+f++b68p8nVlh5YP/+f6OSiDDRFmRBnokA/8AFu32fuQjFsgW2i0YC91b07wr9gmSOfPSseWSB+DrQfbKRKUEZYKYnAREoJbInLPliEhhgpmBJb0HmAtEgSRTBRBKGCCJKSo34lCw0i8vompISDtsAdYSK6K5tK5gnjxYLEhCs5kJbE6Kq6xODKZCtuQ3PPecBOlR54rvZ5394AOMEf3DjE4yFkw9oSJREGmElGrmE1DkgJCQJ98hJ71oEhNf8Xe02y2Tb2hJXteJbqHc3qkOwbdwlwrVSvfA7omDvbm4s+ASDnzRis8GizBr9AnFrcXesK6eHwV6BKqbtYxRIxdbOobEadH56MPFxWYL+7dBq3ae2JSJu5tE7TZr159IlSGOYUXZ7LBN3Nv7Fnax4XJ7m0de7eK4LUTgApz9jJg/jwiVdyQlLTjEsuoyfp17/BDbAVQNVnQcYkd3ZE2gS3HoExiacAm4Ve1qEjxesSwT1CQJ/gnZBMgJfx+zGYNuD8gArExenh+CZMS2gVzZQTIJITKpMExzBPilSJSJWpBVV6nh2s4nsgSgvCcR/onrv2GASC+0glgk/dACoTICQJcJ4RIEusIPHcJvgmkQ8UR7+kTN9PyogivUA=
A14: 20011 | B14: B1-CP-13701-C4011 | C14: 1- C5XFE-R /ST/ | D14: 5 x 2 x 1.0 mm² | E14: 30 | F14: B1-TCS-1301B-XD42 | G14: TCS I/O and marshaling cabinet | H14: B1 | I14: 003 | J14: 003 | K14: B1-CP-13701-XS4 | L14: BOX OF GEN.AVR, SYNCHR.AND MEAS. | M14: B1 | O14: DSPW/SUPP.FI | P14: -C4011 | Q14: 1- C5XFE-R /ST/ 5 x 2 x 1.0 | R14: LOCAL Base Objects|Cable|A30|Z20|0505 | V14: -XS4 | X14: -XD42 | Z14: 2024-06-12 / Harasta, T. | AB14: @@UU@@C@@AA9KAApcSQpTGMcxzHQc5znMc6EIQlB0IShCEIOhKEKUhSkoOhSEKABKQKABSkgSpQFASBSgJAACgIUlSlIAkCgIUpKlISoCVKApSlIUACVJQlKgAAAAAAAAAAAAAAAAAAAAAAAAAAAAAAAAAAAAUAAAAAAAFAAAAAAAAAAAAAAAAAAAAAAAAAAAAAAAAAAAAAAAAAAAAAAAAAAAAAAAAAAAAAAAABCv/Hydh6BPH5fH/Inm4hPhgT1Cdn2ftR+uj+vD8vzmRYwrznPR5A5+jr1Z3fP/fT9uQ+jWlf6PIf/H1c8oL8ostQZ6sgH/gAwbO7+CEYdcC/iFovFetXOsV+4S2OrTpWPLIX8nSg++UiUoIaMkpwEROCWuJ0TDoggCKZgSWuDzAYBIEkUwUQSskyIImsqd+JQtQvR6KBZCQd1gDYEita6a6GpcoTvYa7EhC4dKEu3Oi5UJctMZU8GNDb891vE6gW5XlnX1ZwA5QR/cOUTlIWTDvCRKIg0Qko5OkTkG2AkJAn4yEnnwgSE1Pzc+jBLMbOYSVermlPcQ4c9xDaM1olorVSveA9wS9722suASDqyxvYbObWsvavWJx3+O6VUe7zVaglVOO8YIkYNjKod/i3O97+7o4539KyrHBc3aeASkTct1J9w7dzSn2CVIYZhRrb1lgm76eHNZv4r7br5jax1b5giATYWUU6e1Z/HgEp4ZCadOIS9jtp9Pcu92HBAUkDVKzrOYSOHXEzAmDFqiYhOTSE2yrl+ASPi9glgnrEgT/BN0EtBLuL24i9swfoAFwTD6uLxTJiYKBXLkBLRJCZFJgmKYJ80qRKRLikFVXreLNpie2BKCsTjP9E9l2wvCQXWkEsEn4QAqEtBIExieASBMdhB8mMTOCaBDvxHikGhhy/X9KIIr2g==
... A16: 20013 | B16: B1-CP-13701-I6002 | C16: 1- C5XFE-R /ST/ | D16: 2 x 2 x 1.0 mm² | E16: 30 | F16: B1-TCS-1301B-XA10 | G16: TCS I/O and marshaling cabinet | H16: B1 | I16: 002 | J16: 002 | K16: B1-CP-13701-XP1 | L16: BOX OF GEN.AVR, SYNCHR.AND MEAS. | M16: B1 | O16: DSPW/SUPP.FI | P16: -I6002 | Q16: 1- C5XFE-R /ST/ 2 x 2 x 1.0 | R16: LOCAL Base Objects|Cable|A30|Z20|0502 | V16: -XP1 | X16: -XA10 | Z16: 2024-06-12 / Harasta, T. | AB16: @@UU@@C@@AA9KAApeUQpTGMc5zHOc5zHMhB0nUo50IQlCEIUcCUgUhSEHOdSlKAACkpABKlKUBQFASoCgJUACgIUpSVIAgCQJUBKQIQoCVKApSlIUACVJQlKgAAAAAAAAAAAAAAAAAAAAAAAAAAAAAAAAAAAAUAAAAAAAFAAAAAAAAAAAAAAAAAAAAAAAAAAAAAAAAAAAAAAAAAAAAAAAAAAAAAAAAAAAAAAAABCw+DZ2HUJ4fw8P8idHGJ8cCekTs/H9qP11/18x9RasYl5jmo8Qc3P19qd7zf35fHafXmlh57fF//2/dzU45FEsG2gzpkA/8AGPd4fzQizQBhyC0Xy77l2d0V/ITajp7VKxlkL53BB5JSJSghojanLGQwspUQSzic81okBIAuwdAGISBJFMFEEoYIIkEqOKJQtIvj6qEkJB0MAaBIuXJFMpNK4NsJrXTZTOtIQpIxynQJTYdBlQqaLEN7zTMDfKKlGiLt7ane4AA2Aj+4bBNhCyYd8SJREHLCSjV5BNQ2wEhIE8shJ8OJdUTE1+d93VjluG9uCSu5uqU+7pqQ3SrIJkFaqV5QOASv3+2su4JB02xivZst6vb6xOWeDl01lPT8VXIhmEqqtwlkSLNGVQ5KpbhTx8nJnrub+SDVwU6RKROC3NPtme5bPsEqQsmFHt8VdYnD6NOivTZhbe9unDkqwoncAzlMGXfr/j5BKuKQmWmwS/kt9G9e7sOKArgaq+s+ESPeziaATFZmEsE13xN8q+DYJHf9YlYnqEgT/BOEEtBL1nssL+7B+gAXBMfp4/omTExUCu3tAlokhNpSYJZME+mVIlIlxSCqr1PHoyieyBKC6JqP9E9d6sviQXmkErEn8oAVCWgkCZBO8JAmSsg8GQTSCaxDvxHz6w2MOX7/sRBFfa
A17: 20014 | B17: B1-LS-13101-C4001 | C17: Cu | D17: 2 x 2 x 0,75 mm² | E17: 20 | F17: B1-JBAY-1341-X01 | G17: JB HPH FI | H17: B1 | I17: 002 | J17: 002 | K17: B1-LS-13101-B01 | L17: LEVEL 1.2 IN CONTROL OIL TANK | O17: DSPW/SKID | P17: -C4001 | Q17: Cu 2 x 2 x 0,75 | R17: LOCAL Base Objects|Cable|A30|Z20|0522 | U17: B1-LS-13101-B01 | V17: -B01 | X17: -X01 | Z17: 2024-06-12 / Panek, P. | AB17: @@UU@@C@@ABAmAAshSQpjmMY5jHOY5jmOc50HSA6UoShKVIQdQFKSlCEHOBCAJUlSlKApCgAAoClKAAAEJUpSQKUoCUJSBKVJUpIEpSoCgKAoCkJUACFJQlKgAAAAAAAAAAAAAAAAAAAAAAAAAAAAAAAAAAAAUAAAAAAAFAAAAAAAAAAAAAAAAAAAAAAAAAAAAAAAAAAAAAAAAAAAAAAAAAAAAAAAAAAAAAAAABCs5Pi6e/H3eoTl+z5f6Ep3wToEl0zcHPSfS8i9/yR4Yfr8U0/KHg9f4S2sH6f3XtZDxc0rMfL9v/y+/wSxSIkZUGNEgH/gEr8vmQyxixAYaBa28K+FTzzL+Nm5ML+ugCCqDySQkSlBnJPNF+9JC8sMovQSxiSL8KwBAsQeMAxQJCEiiC9BJCGCCKpmaIvxOYJSWkWlDm9E4SEg4AgA2xIAx1VUQXmgd0LLa0cQlE8S/NCy9Nnno1XxLspBO6PH2N25wE1AIU11TYsfcATYCP8BsE1kLJhxiQSg55SIgNflE2DkgJCQJ5pCTb1oEhN9tMPa8+nj9KE01/avze8hK/u7dVolorhTXwgcUhMXBaksAkHoyd23BljNgnq1nrE19uvVRdXnEw5J7soEXtXe6tM56buHH3qM+Ht681nZqsKZIV1R6tNOy/ZqEziXWy0kqNvpE0kg6xl4c+dDessE05498DJ1abt7VuITaCbrZbATAs8aiaDTi/n5hMqHwSE6+b98gmDNZPhq7sPYhcgEOjnOMTuCZQTaEsEoE7RxbBPn9omgT2CQJ/gm4CYgTRb7rTbs/YBKROjGdAlm+K5AS4T5BMqkwJIE+q6cScSlSCj2fDpzie6BLxSJqP9E9tRWJBfLwJUJ9ACWiZASBLhOISBLqyDkuE2AnCI/HEccg32HN+XKoIAHUA==
A18: 20015 | B18: B1-LS-13101-C4002 | C18: Cu | D18: 2 x 2 x 0,75 mm² | E18: 20 | F18: B1-JBAY-1341-X01 | G18: JB HPH FI | H18: B1 | I18: 002 | J18: 002 | K18: B1-LS-13101-B01 | L18: LEVEL 1.2 IN CONTROL OIL TANK | O18: DSPW/SKID | P18: -C4002 | Q18: Cu 2 x 2 x 0,75 | R18: LOCAL Base Objects|Cable|A30|Z20|0522 | U18: B1-LS-13101-B01 | V18: -B01 | X18: -X01 | Z18: 2024-06-12 / Panek, P. | AB18: @@UU@@C@@ABAmAAseUQpjGMY5znMY5znMc5znOhCEIQlSUHShIAAUpCUHQhKQKSlQFKAlAAKApSlKAAAEIApSQJAoCEJSBKVJUpIEpSoCgKAoCkJUACFJQlKgAAAAAAAAAAAAAAAAAAAAAAAAAAAAAAAAAAAAUAAAAAAAFAAAAAAAAAAAAAAAAAAAAAAAAAAAAAAAAAAAAAAAAAAAAAAAAAAAAAAAAAAAAAAAABCs5O/180fh7BOX7/o/oSrgBOoSXXN3Omo+t5F5vNHPD93kmo5Q8Xtjx57/6f3ez2nk6JWYrdv/+b8fFRhkROZUGJ5AP/AJe8/oQyRgwAV0i3mcV51PTMvjs7Ewv66AILsHmkhIlKCHniVUkOghhZpTwSxCXJlYAgAiDygGCBIQkUwTwSQhggi7MFyegvyktQtSHR6qAkJBshABuCRiu3ZimRJpHUElsw3kcAk5+aFk2aejfnqEyFpS39Hl3dWNsJqgQuV3psHygJxAj/AcQmshZMOESCUHTKREBr84nEOOAkJAnokJN2sAEhOB269PZ9O13vWhNNd0S3kKtVWETCK3k18IHHISvuY8Cb09YkHqyfNVisyRmspvVaz2ia5tN+m29nEryb9NuYCKN/wZ7lB67ePL4Kc9em5bPTlvlUkJp49mx2OG5XqEzCY+KW2Spx9Ym0SC00beVDcrrE2MsdoDHoqr3tW6hkzk2zTYCX1oiWoNjB/P0iZEO3ITay/vctEv5bKaLvfh3IDvQ5AIdPSd0TfEygmgTAJSJ2Tj1ieH3iaRPcJAn+CfGCYATTh+GE3bP2ASoTqxHUJZwCtoJjE+cTIpMCSBPtx0CUCVKQU+75NnMJ8IEnKhO2f6J77peEguE4JdE5AEwiWgkCYxO6JAmO8QeHGJxgmsR+yI+rjDhYc35cqggAfE
A19: 20016 | B19: B1-LS-13102B-C4001 | C19: Cu | D19: 2 x 2 x 0,75 mm² | E19: 20 | F19: B1-JBAY-1341-X01 | G19: JB HPH FI | H19: B1 | I19: 001 | J19: 001 | K19: B1-LS-13102B-B01 | L19: LEVEL 2 IN CONTROL OIL TANK | O19: DSPW/SKID | P19: -C4001 | Q19: Cu 2 x 2 x 0,75 | R19: LOCAL Base Objects|Cable|A30|Z20|0522 | U19: B1-LS-13102B-B01 | V19: -B01 | X19: -X01 | Z19: 2024-06-12 / Panek, P. | AB19: @@UU@@C@@ABA0AAsiSQpjGMY5zIOYxzmMg5zoOlCEpOBAEHSlIFAUlB0nQpSAKSlQFKSpKgAAkClKAAAEJAkCQJAoCUJSBKVJUpIEpUgAAKAoCkJUACFJQlKgAAAAAAAAAAAAAAAAAAAAAAAAAAAAAAAAAAAAUAAAAAAAFAAAAAAAAAAAAAAAAAAAAAAAAAAAAAAAAAAAAAAAAAAAAAAAAAAAAAAAAAAAAAAAABCs8Hd6fFHj/cTk/L7P6Eq4QToEl0za+eo8L4F8XpjzQ/j55qOQPJ748ufa/X+68955+WVmTk8f/yl5JWSIlXegyzyAf+ASv1etC+LbQLKRaycV8ynsmXy2aZhf2zgQYYPTJCRKUHKSeWJsEkJ1hmieCWQSQLgQhiD0AFsCQhIpgngkhDBBGGZmiMFBKFpFpQ5fbQEhINYQBoEgDGYKIJgogCE1Bitwo2CUn6IYps09HZqEvKbil3PRp1XOImpBCrarms7YCcQI/wHEJsIWTDjEglBzykRAbPUJxDdASEgT1yEm7FoEhOF3sW/7N7Lx+5CefDRKAOBCrVVaJaK1ps7gH0SExa6MSTViQe3J9VtXD2JZsVNew94mDt16Kbq8wmK+mm7bAiifs96/BSe66rmzU/XGezaydcnoy2FUkMFEc1WnuYMPAJmEu4pbvViJqr+kS8kG3vZUM+LEJoyxqA136MFPBq0obe4Tb19oJYtES1Bu5P574mVDtSE612/eJtZd22myvvQ9eF2wIdHOcQnzCZQTcEtEpE3zZrE+74iaBPgJAn+Cb4JaCaMfyxmmzmASoToyHQJZwit4JcJ3RNtSYEkCfhdQJQJUpBT8Pn3cwnygScqE7R/onxwlYkGAnBMInfATGJeCQJcJxiQJdWQfbcJ9IJsA4wIE8MR98g1sOb8+QRQAOoA=
A20: 20017 | B20: B1-LS-13102C-C4001 | C20: Cu | D20: 2 x 2 x 0,75 mm² | E20: 20 | F20: B1-JBAY-1341-X01 | G20: JB HPH FI | H20: B1 | I20: 001 | J20: 001 | K20: B1-LS-13102C-B01 | L20: LEVEL 3 IN CONTROL OIL TANK | O20: DSPW/SKID | P20: -C4001 | Q20: Cu 2 x 2 x 0,75 | R20: LOCAL Base Objects|Cable|A30|Z20|0522 | U20: B1-LS-13102C-B01 | V20: -B01 | X20: -X01 | Z20: 2024-06-12 / Panek, P. | AB20: @@UU@@C@@ABA0AAsjSQpjmMYxzHOYxznOcyEHQlB1IQhSEKQhCFAAhCEHQlSgAUgCgJUlSQAAkClKAAAEIApSQKAkCkIUpSAJUpIEpSoCgKAoCkJUACFJQlKgAAAAAAAAAAAAAAAAAAAAAAAAAAAAAAAAAAAAUAAAAAAAFAAAAAAAAAAAAAAAAAAAAAAAAAAAAAAAAAAAAAAAAAAAAAAAAAAAAAAAAAAAAAAAABCs+n5u46Pt9YnP9nh/oSjiBO0SXdNx9njPI+Nej84/CH6+qafnDy+yPvz4P0/uvPlOrplZj6Mn/y+7yytkRLpuQZZ5AP/AJg6/OhdGLEBZQLWXhXpU9Ey+azamF/XWAgvwdckJEpQdRJ4ImqkheWGaL0EsYkgWpCGIPyALYEhCRRBegkhDBBF+ZmiKpyULQLQh1emcJCQcgQBtCQBiqngmZ4QhN4J8Nt9GwSnfjQhZe1b1G1UJmMpO61X47W7mcJNSCFWCuazhATlBH+A5RNJCyYcYkEoOyUiIDT1ico5ICQkCeeQk29aBITjfgw7fo0fL6kJpqtWUbqFO5TaJaK0AVpy6QPkkJh5KElWJB6cfBbglGauarSbvsE5OGujHXcJhyT48oEXrea2mc9WPg39HNTqWWTYMee60p2JkK5Vy9eHZn479m4JqiZtMtBVNTrmx3CXEg19jUQv4cIme6PiAyZ6bdvc0IZtUm18toJhWeJbgd/F/PhEuQ3pCaLtTk/ea4SzPiptwc0OzC3AQ19h4BPjEuBM4lglAm2cvIJ4vcJrCe0SBP8E+EEtBM+L34jZs/YBKRO3GdolnEK5QTIJzCZlJgSQJ9WScScSlSCj28OvqCe+BLxSJvn+ie6+ViQVF4EvieIBMQmUEgTIJpEgTJWQfRkE8AJpAzAQJ5Ij55BxMOp5ucRQAO8A=
A21: 20018 | B21: B1-LSH-13001-401 | C21: MEGAFLEX500 | D21: 2 x 2 x 0,75 mm² | E21: 20 | F21: B1JBA-1301-X05 | G21: Generator JB | H21: B1 | I21: 001 | J21: 001 | K21: B1-LSH-13001-B01 | L21: LVL.WATER LEAKAGE GEN COOLER - TE | O21: DSPW/SKID | P21: -401 | Q21: MEGAFLEX500 2 x 2 x 0,75 | R21: LOCAL Base Objects|Cable|A30|Z20|0522 | U21: B1-LSH-13001-B01 | V21: -B01 | X21: -X05 | Z21: 2024-06-12 / Panek, P. | AB21: @@UU@@C@@ABAgAAsRUQpjGOcxzHMc5jGOdB0HSlCjoSpSEIOlSUqSlCEHUhAEgUhQAKUhCgAAoCgAUoCVAUBIEpUpSUoABSkJUpSFJSgAAAUBQFISkCkqOlSgAAAAAAAAAAAAAAAAAAAAAAAAAAAAAAAAAAAAUAAAAAAAFAAAAAAAAAAAAAAAAAAAAAAAAAAAAAAAAAAAAAAAAAAAAAAAAAAAAAAAAAAAAAAAABCxc3x+PWeL0ifX66P5E74J/QnJrm4OvmPoeZfN+XiSbFPLwhb6v08mbDR66vJcTylhxfVT/8vs+2U8iJFqDGWQD/wCYNno50PL+dlgGOkWvoigV8qnTMt3jusnF/XOBBhgskhIlKD75MRK/ICYCAmiUEtAn4E86DJYGmDnALIEhCRRBPBJDbkyIImZRDORC0C6fROEhIO+wAdoSALb9EExREDvOC2ALIqRvFKE2eafnvCe7lMhefNnutcNcT3gKYBacM3nn2O8AmoEf3DUJwkLJh3BIJQR1yZQ6vxE+JcsMhIE6JCTdvZsAmE6Q4e5j0dPw+lDuTT4OzKv4L9glgrUm1qAgSrgwpLAJB+3ot7tWOiRN7+avUYvUJlx6rLyF2Pfw5hLL94DBN3sVBXdXPiz8mGbN1V244wYqe7OhNt5+SRFW/RuiYRLurRduWz00axNok8dujYQlXiElvZWNIGOJ81d29pyZjsoTbuWwErAj3trTKD+PlE2UPBIS3FaJVk5NzsYJoduFyAQ9jrOITSJoBM4lYnLfE3Di1CcvtEziaxIE/sTdBLATPwVXf5cdqfqASkT2XHsEx8IrlBMgnyCbCkwJIE+nJQJQJfUgvGvg0bIm1Ak5bSJ2z/RKqvbBISDATglQnKAlomUEhTIJviQJkqIPmyCcYJxCPgiPnkHGw7H3eEAQAPc
A22: 20019 | B22: B1-LSH-13002-401 | C22: MEGAFLEX500 | D22: 2 x 2 x 0,75 mm² | E22: 20 | F22: B1JBA-1301-X05 | G22: Generator JB | H22: B1 | I22: 001 | J22: 001 | K22: B1-LSH-13002-B01 | L22: LVL.WATER LEAKAGE GEN COOLER - TE | O22: DSPW/SKID | P22: -401 | Q22: MEGAFLEX500 2 x 2 x 0,75 | R22: LOCAL Base Objects|Cable|A30|Z20|0522 | U22: B1-LSH-13002-B01 | V22: -B01 | X22: -X05 | Z22: 2024-06-12 / Panek, P. | AB22: @@UU@@C@@ABAgAAsSUQhjGOdBzGOc5jnOc50HQlCTpQBAEIQpSVKQlCEHUhKlAShSgKUhAAAAoCgAUoCQJABIEpUpSUoABSkJUpSFJSgAAAUBQFISkCkqQlSgAAAAAAAAAAAAAAAAAAAAAAAAAAAAAAAAAAAAUAAAAAAAFAAAAAAAAAAAAAAAAAAAAAAAAAAAAAAAAAAAAAAAAAAAAAAAAAAAAAAAAAAAAAAAABCwc3g8nYeP1Cfb7Kv5E7wJ/QnJ2UcPXzH1PMvn/LxpRgpnwhi9f6eXPZV7K/LjKZmzB9ni/+fFRNkkTlxoMzID/wCXtfo50PN+dtoGHWFv9EVCvmU6aFx+THbSL+ugCCyC2UJJmCH74m7KFEMAUTME6RPwKaQCVhXWg5wC2BIQkqgpgnBAEsEEUMxBSRC1C73ppCRIO8wB3BIAxXZqkkqiB3WQMVaFsVo06IvIU6KKue6Js5jKXHz5sTWTSBcgFsu10+jeua++AmoEf3DUJxELLDnEgmCOuWYdX4ifGuaGRIE6JEo9/btAoE6Q4u7h7nT8XqQnRTes7VE/BdtEtFa02dQFkiWcN9JrEg/b04vhstqkoozWai/6xMuDVhuIY6+CzOJhu3AL1G/gqL+K/s73a5L+DYz6L2LJbbeoQnT3YPB1RZv3NwSwS/1bWm2i7T2CaSXv7WVDDZfEz5GNkDDnu7m7jzG2hRVuY8AJYBG3VsTm3X+PoEzofLImt27cgl/LyaL0w6YXKBDo6zjE3hO2CbAlgnLdE2zj1CcvuE0CdgkCf2JugloJr8VeP/MZtU9QCawntxntEw8ArlBMgnzCZlKASQT68lQlQl1SC4dm9p1xNmBKTFrCbx/oldfugkSC8UglYnKAmITKCQpkE4BIEyVkH05BOME4wOECBPkiPnkO+w5/u8IAgAe8
A23: 20020 | B23: B1-LSH-13003-401 | C23: MEGAFLEX500 | D23: 2 x 2 x 0,75 mm² | E23: 20 | F23: B1JBA-1301-X05 | G23: Generator JB | H23: B1 | I23: 001 | J23: 001 | K23: B1-LSH-13003-B01 | L23: LVL.WATER LEAKAGE GEN COOLER - EE | O23: DSPW/SKID | P23: -401 | Q23: MEGAFLEX500 2 x 2 x 0,75 | R23: LOCAL Base Objects|Cable|A30|Z20|0522 | U23: B1-LSH-13003-B01 | V23: -B01 | X23: -X05 | Z23: 2024-06-12 / Panek, P. | AB23: @@UU@@C@@ABAgAAsQUQpjGMcyDHOc5jmMc5zoOdCjoUpCUoQpSQKQpKEnQhKVJUpIAASpCgAAoAFAUoCkAUBIFIApSUoABSkKUpSFJSBAAAUBQFISkCkqOlSgAAAAAAAAAAAAAAAAAAAAAAAAAAAAAAAAAAAAUAAAAAAAFAAAAAAAAAAAAAAAAAAAAAAAAAAAAAAAAAAAAAAAAAAAAAAAAAAAAAAAAAAAAAAAABCw8vx/bsPJ6BPB9Xqp/kTugn9CbJcXZynzvKvm/HyJNgnl9YWen9OfNfo9VfPaTylfw/TL/5c32SvyIlzWoMssgH/gE2tvp6EPL+ePGBZULg6YoFfKp1TLdz2lk4v66AIL8FkkJEpQQ5YlCF6GaaAJRBLUJ95POrJYAKoOgAsgSEJFEE8EkIYIIkyiCYiFnF7nnnCQkfCwBuiQBZeoiaIKIgd9lZWhiitGcSpCbPNP0UiblxaUvmz2NZKcCmANMAl6uf8p83CAmsEf3DWJ3iFkw7wkEoI7JModf4Cca5IZCQJ0yEm97esAmE6g4u5i1dWn0ISmq5NPBPh9+rGJjFb6e3rAgTBxYEltCQft57cldOKmY+D4s+GnjMXpEy3+PHShdVnv5xLL1IG1Nw4aDBbgqwafk3J+uvVPRitow1TIS23r2+GNdHbErEt693c3bJ6qNgmok5PBoyoV4MIlORjgAxZvc3+C7MbyE3buwgl8De0xwP8eMTMh4ZCadWLRcJhy+Kc0VzQ7sLkAh0dhyCb4moE0CYBOW8J2jk1icvsE0CbBIE/sTfBLATb71dv+Wnuz9YCVCeu09YmLiFcgJcJ4hMqkwJIE+i6gSgS8pBSbO1qzibkCTmOoTgP9Err9kEhINonBKxPlATGJkBIUuE7okCXVkHjuE74JyAfMBAnhiJSDvsOX7uYAQAPa
A24: 20021 | B24: B1-LSH-13004-401 | C24: MEGAFLEX500 | D24: 2 x 2 x 0,75 mm² | E24: 20 | F24: B1JBA-1301-X05 | G24: Generator JB | H24: B1 | I24: 001 | J24: 001 | K24: B1-LSH-13004-B01 | L24: LVL.WATER LEAKAGE GEN COOLER - EE | O24: DSPW/SKID | P24: -401 | Q24: MEGAFLEX500 2 x 2 x 0,75 | R24: LOCAL Base Objects|Cable|A30|Z20|0522 | U24: B1-LSH-13004-B01 | V24: -B01 | X24: -X05 | Z24: 2024-06-12 / Panek, P. | AB24: @@UU@@C@@ABAgAAsRUQpTHMc5zHOc5jGMdCEHOlCEoUhAFIShKkAUlCEoQcCEASBAFAUA6gKAoAFAUoCkqUBIFIApSVIUACUqSpSUJUBAAAUBQFISkCkqQlSgAAAAAAAAAAAAAAAAAAAAAAAAAAAAAAAAAAAAUAAAAAAAFAAAAAAAAAAAAAAAAAAAAAAAAAAAAAAAAAAAAAAAAAAAAAAAAAAAAAAAAAAAAAAAABCyavF93aeT9hOX6vZT/InCCf0J2y4uzUfO6l/HzeRJ46JfWFfr/To18V72VdFpRKWLJ9J/8eP7ZYpES+y1BlrSAf+ASrP5+lDy+iywCvALj88XhXyqema3dFtdAv66AIMUFckJEpQQ/hEoQvwyiYkEtsTYKKFZLABgg6QCuBIQkXoKIJemAJMEETZYZSLxELSLweqgJCRo4WQHviQBbgpgm3oge824rYQxI0uBCeidEAflSJ3bDMXnp0VtRKgCmAWnDP0Ua/gATkBH9w5BOMhZMPwCQSgjskyh5PMJpW6GQkCfnISff3KwJidQeHgy7XV8XwoSng0aZ4+/frErFak2eMCBMXBjSWESDq9Vl1VOWmZwXa2TjMvrE1sXH1230M1fFjziWX6QKp3+HwV3zLmyRcc+Pbs4qtNlE8d+aEtD12T594TCJZPr29nw5aMN7tE2iTzbu1mQlkyib+ZjOBl19He37s5uIT3rsgJiA3O5G+fx8gktdDxTE28mzaJjzc+xnqnDtwGzDrAQ9yfYcom0JUCaBMYmrAJunLpE1e4TQJ2iQJ/Ym8CVgmfiqt/y03aOsBMAnttPaJl4hXMCXCfGJrKTBJAn0XXhLwl9SCk7e73dgTZgSgswCb5/olVXugkJBhKASoT5QEsEzAkKXCcIkCXVEGq4TSCaQOYCBOaI+aQcrDr/f4wBAA94
A25: 20022 | B25: B1-LSH-13236-I6001 | C25: 1- C5XFE-R /ST/ | D25: 2 x 2 x 1.0 mm² | E25: 100 | F25: B1JBA-1309-TB2 | G25: Junction box IOS | H25: B1 | I25: 001 | J25: 001 | K25: B1-LSH-13236-B01 | L25: LVL.COLLECTING OIL SUMP | O25: DSPW/SKID | P25: -I6001 | Q25: 1- C5XFE-R /ST/ 2 x 2 x 1.0 | R25: LOCAL Base Objects|Cable|A30|Z20|0502 | U25: B1-LSH-13236-B01 | V25: -B01 | X25: -TB2 | Z25: 2024-06-12 / Panek, P. | AB25: @@UU@@C@@ABA4AAsoUQpTHMY5zHOY5znOc51IQg6EqOhJ0qQhKUIQpB0IAhClASpQFIUpIAKAoAAAApAFAUpKlKQBSkJSBSkAUlCQJQAAAKAoCkJUACFJQlKgAAAAAAAAAAAAAAAAAAAAAAAAAAAAAAAAAAAAUAAAAAAAFAAAAAAAAAAAAAAAAAAAAAAAAAAAAAAAAAAAAAAAAAAAAAAAAAAAAAAAAAAAAAAAABCs8nH3HWJH9Cc26J98Cdondanv9nKfU3l+1/OH9/NOjmDy+uPx6PRd/uvnxF79pWYPsxf/L7vLKLIiJ5EGimQD/wCdPR50L9+wCu+LdNEWhX9FPT+FCxTJX0e+BBOCySEiUoKyTzxOEJrjkziiCWwJJVtweYAsgSEKZkQUQSQhggiTKInpiULaFjn00BISOroZAaBIAt1WVSouoQVR3pDc0Jiw4L6MIXkLlUTxSnapElSdF6OlCp8FAHfwt0lbpBC355zKpb4CcII/wHEJwELJh0iQSg7JSYh4f1E4kxQkhIE6ZCT3O/hAmJ1N7Y8WdDqnTHpubtPJYJYK1jo2wIEu6s4y8QkFmG3fj1Y69R6xNvVXQh8SFWUSvDvYcOMCumdMHju4d7FK5v5uDe4N6/Ky3fmhPr+DxmaU8F+nbEzCZOuWeVqrR3CbJnmmbayod6ywTi2skeEDX1/B8M8usbKFGbHYiVgVbn8/OJpTKhuTEy8nhwYxLMma5uw6IDPDlAh1pdhyCbomyCbAl4SoSzScfEJHL7RNcT2CQJ/gm0CYASvB7sBtXvUAlQnbGE7RLNQrjBMQnzCZFJgkgT68VoS0JUpDTP2cGfMJ7oEobYnGX/9E9t0vCQXCgErE8gCYRMYJAk8YnyiQJ9GS6QR9OQTUCfGBwgQJyxHLIPkYdb8uYFQAPeA=
A26: 20023 | B26: B1-MS-13701-C4001 | C26: 1- C5XFE-R /ST/ | D26: 2 x 2 x 1.0 mm² | E26: 30 | F26: B1-TCS-1301C-XD33 | G26: TPS I/O and marshaling cabinet | H26: B1 | I26: 001 | J26: 001 | K26: B1-MS-13701-X95 | L26: BOX OF DC STARTER | M26: B1 | O26: DSPW/SUPP.FI | P26: -C4001 | Q26: 1- C5XFE-R /ST/ 2 x 2 x 1.0 | R26: LOCAL Base Objects|Cable|A30|Z20|0502 | V26: -X95 | X26: -XD33 | Z26: 2024-06-12 / Panek, P. | AB26: @@UU@@C@@AA8sAApPUQhTGOc5jnOc5znOc6EHQpSEHSoCDpQhCkqQlCUJShKAKApIEpABSkgUBQEqAoCgASpQAJSpQEpQlIEqUpClIQlQFKApSlIUACVJQlKgAAAAAAAAAAAAAAAAAAAAAAAAAAAAAAAAAAAAUAAAAAAAFAAAAAAAAAAAAAAAAAAAAAAAAAAAAAAAAAAAAAAAAAAAAAAAAAAAAAAAAAAAAAAAABCwfJxdJ9HOJ9v8iebfE+mBPUJ0/d+1X69n+u+eAyLH2Pgh8U+avwh4uTRPRd5f7+/yZidE3+Tw/X/85fHOCSZ05kGmiQH/gA07amH3gL2IWw/GKxXyiZI5vHWsZpF/Jsg9EyTMHkJa4pFFyy0iqCdkSTkgapAlW5B5wMIkCSVwVQT1ZZIIozEFe7EwtoXy89QSJB5wgDbEgC3brigVj+euGOvLkwX0hCw0oTsUqrEuHKaxW9bmzoapphbxVaEK4Et2aKWXbdvcADjBH9w4xOMhZYdQkTEQcUJMdv8BO2OaAkSBOWRKb2QCROZ2r/u84kVkU2ttDftRuXNfAJgFbQ8IHXEwb3B740oJBvY8FmDLZd6/QJZxZbN34sWcSrHv+nCUJzibF3cKfH1rNiysT9O5m4cSFJLWoTKJ1NaumnRb006RMchkq2OoXromrscOTav7nVzUza6EaXVmw24BMIGLY0YNH8d0TSG9IlzVmEv5s+tc3Yb8CVdB2RI+DUJsgl7FoEwCcF0TUWuHsCR3vYJdE9YkCf4JqBMoJZj9uMvbUHpAC2Ji9XB81CgmGoVz5gTKJImZSgJjoCfPNYlYltSC1a9bwbOsJ7YEqLgm8f6J7LLpeEgsawS6JTvABaEygkCZBO4JAmS6Qd3IJ8IJ2hDvxHyyHaYc/j+oUQV9wA==
A27: 20024 | B27: B1-MS-13701-C4002 | C27: 1- C5XFE-R /ST/ | D27: 2 x 2 x 1.0 mm² | E27: 30 | F27: B1-TCS-1301C-XD33 | G27: TPS I/O and marshaling cabinet | H27: B1 | I27: 002 | J27: 002 | K27: B1-MS-13701-X95 | L27: BOX OF DC STARTER | M27: B1 | O27: DSPW/SUPP.FI | P27: -C4002 | Q27: 1- C5XFE-R /ST/ 2 x 2 x 1.0 | R27: LOCAL Base Objects|Cable|A30|Z20|0502 | V27: -X95 | X27: -XD33 | Z27: 2024-06-12 / Panek, P. | AB27: @@UU@@C@@AA8sAApLSQhjGMc5zHQc5jnOZCDnSlKEIUlR0IShAFKQhCUKQhAFJAoCUgApQFAUBQEqAoCgAUBAAJQpIFJQlSlJAhSkqQlQFKApSlIUACVJQlKgAAAAAAAAAAAAAAAAAAAAAAAAAAAAAAAAAAAAUAAAAAAAFAAAAAAAAAAAAAAAAAAAAAAAAAAAAAAAAAAAAAAAAAAAAAAAAAAAAAAAAAAAAAAAABCxfJx9Z9HSJ9n8iebeE+mBPUJ1+T9qf1+D+vlPEZVjlfFD4581X1h4+eNHVZ+P9+f7bidE6nPm5f/5buarHJTOzqoNFUgP/ABs6VMfbAw2i4DoioV8omWPz5qljySL+Tgg/CZJmCGmJjOZpZWiaYJ1xOegaZAlAvwfcBjEgSSqCmCduWSCKAmrciYWsXy9NISJB0feEgbQkX78lcyFQ+jQFC03ZcWokIVF3uIUdqmqsT3rxkM5W03IacTYTUC1389F7BtgByAj+4cgnIQssOkSJiIOKEmOPzicY5oCRIE6JEo3LQJE9D062xj7XSJF6uJp2NKFW8Xu7gpxiYxWoeEDfExbvBf7g00iQbuTFZiusw7/UJx5r+58NuUSnJkzxiKD06olXZNXet1t/RZgE/T4r/DkQooK9IlwmzoqottvW0dYmSQoz7JZgE08NvZ4cOjTmoza6Edt93NjvQCYwLdGfFn/jwCbL3YkS/3LhNS7Wz4NuHUgSnqOESNzaE2ATDboExCb9gmkr73AJHh9glgnrEgT/BNoEzAmDJ7chh2IPSAF4S31b/zUFAmOkV1bgTMJIlylAJkoBPnmoSoS8pBXX63g19YT2wJSXxN0/0T2YLDCJBgagSwSjwgBWJmBIEyid8SBMthB4MonvgnEId+I+PvBxMOtzfUKIK9g
A28: 20025 | B28: B1-MS-13701-C4003 | C28: 1- C5XFE-R /ST/ | D28: 5 x 2 x 1.0 mm² | E28: 30 | F28: B1-TCS-1301C-XD33 | G28: TPS I/O and marshaling cabinet | H28: B1 | I28: 001 | J28: 001 | K28: B1-MS-13701-X99 | L28: BOX OF DC STARTER | M28: B1 | O28: DSPW/SUPP.FI | P28: -C4003 | Q28: 1- C5XFE-R /ST/ 5 x 2 x 1.0 | R28: LOCAL Base Objects|Cable|A30|Z20|0505 | V28: -X99 | X28: -XD33 | Z28: 2024-06-12 / Panek, P. | AB28: @@UU@@C@@AA8sAApJSQpTGOc5jHOc5znMc5znOABzpQlJ0oShAFJUhCTpSdAEgUACUgABIEgUpQEqAoCgAUBKgJSlQFJQlQFJAlKkpQlQFKApSlIUACVJQlKgAAAAAAAAAAAAAAAAAAAAAAAAAAAAAAAAAAAAUAAAAAAAFAAAAAAAAAAAAAAAAAAAAAAAAAAAAAAAAAAAAAAAAAAAAAAAAAAAAAAAAAAAAAAAABCv9/d0H1cwnl/kTz/KJ9cCe4To+/9qP17X9eD6PCWLHifDD45een7Q8fLGnnr9X9+j8MpLTK9y+LJ//3ZPJTBgojeyoM9MgH/gA3usph1AXsQtR6YpFfMJZHs8tKxZIX82qD8pSJSghoiUY4fMTlJaJE9YnLMaJASQLkH4gYBIEkUwUQS68mRBEwlTwxKFtC8vNQEhIN4IA2CRbotzCkfXnCZRZivXUhClDpoS0zot5bYkHqMxafkyIbLjWSpBbVzPO3VvgByAj+4cgnIQsmHYJEoiDtwko3egTcNkBISBPTISfBhAkJ63Ve0+wSKdESo1dVDsFvfq5sAmAVpHaBxCX+Hj6gzmJBw4rt+u/Tkru8VznEnunZXwT7mKQlF7FP23yZLIJo+bJ2qcF/s6K6xP0r2mJCUqdglgmu9TPVnt459AmGQTzayuoTZtw6a9nVxzx6kI1O3eswXIBMAGHRnwZ/47onX6YSEzVdTMJfzZ7VW/DegSjnNokcGwTWCXcOgS+JxVibC12eMSO98BKxPeJAn+Cb4JYCVYvjiLuuD2gBbEw+7i+eZMTBQK5cgJYJITIpMExTBPplSJSJbUgtWve8erMJ8YEoLgnCf6J8Kqy6JBU0glYk+8AFoSwEgTGJ3BIEx1kHdxidgE3CHgiO+nbYcvk+wUQV6Q
A29: 20026 | B29: B1-MS-13701-I6001 | C29: 1- C5XFE-R /ST/ | D29: 2 x 2 x 1.0 mm² | E29: 30 | F29: B1-TCS-1301C-XD33 | G29: TPS I/O and marshaling cabinet | H29: B1 | I29: 001 | J29: 001 | K29: B1-MS-13701-X91 | L29: BOX OF DC STARTER | M29: B1 | O29: DSPW/SUPP.FI | P29: -I6001 | Q29: 1- C5XFE-R /ST/ 2 x 2 x 1.0 | R29: LOCAL Base Objects|Cable|A30|Z20|0502 | V29: -X91 | X29: -XD33 | Z29: 2024-06-12 / Panek, P. | AB29: @@UU@@C@@AA8sAApKSQpTGOc5zGOY5zmOc5zoUdSEIQpCEIQhSkAOlKUJUg4FAAlSkqApQFAUBQEqAoCgASBQAISlQEqQlIEpAlKkpQlQFKApSlIUACVJQlKgAAAAAAAAAAAAAAAAAAAAAAAAAAAAAAAAAAAAUAAAAAAAFAAAAAAAAAAAAAAAAAAAAAAAAAAAAAAAAAAAAAAAAAAAAAAAAAAAAAAAAAAAAAAAABCs+nl6j7egTwfyJ4tQn3QJ6xOr8f2o/Xtf19R3S1Y/B7sPNLxU94ObnjY6avP/fl8OUlsSwc/ex//KXflgkSltZEGeiQD/wAbW6pZpArwi3zzRSK/kJjj081Kx4JC/m34PJKRKUFZJpicTWC2JxRBL3xJHPA0SAkreg8YGESBJFMFEEt+TIgibKIKeGJQtwXw9FASEg8YQBuiQBdu0xMKR9GgKMmPBWkIXiMkp0CaMp5yPITQuPHlQ3rGslSC3b2id2rgADWCP7hrE1kLJh3RIlEQfHCSjl8onKOSAkJAnmkJPixASE9Ds4NPpEikie173GXOC90WCWCtI8gHwCWcXX3BnMSDhx2X7Ml+rV0icuS9w/Jiw6kM4lyLdVWGiKD1TziabddWXN8PY04K6xP07ddaESi5viZxNzTTPbz3dufUJjkE8WQqvib/Ji03auDftnbuIRsuzbhuwCYQMWjPyYdH8fMJvQJthft3cwmHNo2KuKGyBKOk7QkfFvCbYJXbpEsE7FQm8XOTsiR3PaJUJ7BIE/wThBMgJfx+7GV7cHqAC6Ji9fX+uZMTDQK5soJkEkJlUmCY5gn2SpEpEuqQXLnsezs5xPdAlBeE4z/RPbfqKxIL7SCVCT+cALgmQEgS0TtiQJbUQdy0TUCaxD5Yj6JBrYc3f+8UQV6w=
A30: 20027 | B30: B1-PI-I-5201 | C30: 1- C5XFE-R /ST/ | D30: 10 x 2 x 1.0 mm² | E30: 200 | F30: B1-TCS-1321-X11 | G30: BOX OF VMS | H30: B1 | I30: 006 | J30: 006 | K30: B1JBX-1321-X01 | L30: JUNCTION BOX VMS | M30: B1 | O30: DSPW/SUPP.FI | P30: -PI-I-5201 | Q30: 1- C5XFE-R /ST/ 10 x 2 x 1.0 | R30: LOCAL Base Objects|Cable|A30|Z20|0510 | V30: -X01 | X30: -X11 | Z30: 2024-07-21 / Panek, P. | AB30: @@UU@@C@@AA78AAoiSQhjGMY5jnOc5zmMdCToSg6EqOlKUIUgCkoSlCUJSpKlKUBSkqUBSgASAAAAAlQEqUhSkgSpSkAUpKVAUpSEJUoAAKAoCkJUACFJQlKgAAAAAAAAAAAAAAAAAAAAAAAAAAAAAAAAAAAAUAAAAAAAFAAAAAAAAAAAAAAAAAAAAAAAAAAAAAAAAAAAAAAAAAAAAAAAAAAAAAAAAAAAAAAAABCyfN7vQcX7Cf0J+O+Cc4k+Pop7fN8uPwwsH0/bEQx4yn6A4rvTODL+f9+byXHnIx/f4vq/+eL65yyTMXoMaZAf+ADz5OrGMQy7QGPMLiPyioV+5Tk+ykCK5Fzfo0Qe1MkzBD5YmGmJiiCdQlJQsLC1wcYBiEgksgpgmGCCJZiKirciiAKxfLy0hJHVEgCuis40MJUEiXBly4UyFeiJ0TTiQrE2bDbAuOMwOvesq0WXuQnAC222ZAKb+yAHACP8BwCcBMrBDcJExEHNMj3PwE4RvgJEgTzSJRubBmAoE/Vx7XIJXNR155NJq63o96lzCZhXGncA23fEy9fetSjOJBuaM+LYtw9n0id7v+4hvoaRMO91M/TApnJBy0iX21W7VFlZQ6Pfr/cwUUFGjat7AnUE73oZ024LNRk6BLpDZQsqjTjxCX326+tpLjPlptBN0Dar3P5+MTRAnd3d6HRiN64Sb9Bs68ftw7cCVaQL3FzHdE7Am2CahMoloms4eATwesTUJ6hIE/wTOCZQTZzezMa8nKAFgnPnOcTJ2hW8EuE+ATQpQCSCeG6oSoSxSCv1dvV0xPZAlJYJwn+ieu0wiQYCkEtE+QAMwl4JAlwnwiQJdhIPBcJ2gTdA+cSIj4pDvsOx5PEKqi9I
